File: code/data/data_source2/CuSe_AlN-150w-10min-CuSe-150w-10min.csv
[Measurement conditions]
Sample identification,
Comment - 1,"Configuration=Filmes Finos 19_1_2015, Owner=User-1, Creation date=19/01/2015 21:17:15"
Comment - 2,"Goniometer=PW3050/60 (Theta/Theta); Minimum step size 2Theta:0.001; Minimum step size Omega:0.001"
Comment - 3,"Sample stage=PW3071/xx Bracket"
Comment - 4,"Diffractometer system=XPERT-PRO"
Comment - 5,"Measurement program=C:\PANalytical\Data Collector\Programs\GrazingIncidence.xrdmp, Identifier={4483F2A9-C408-41C9-9DE0-B97C17B2593E}"
Anode material,Cu
K-Alpha1 wavelength,1.5405980
K-Alpha2 wavelength,1.5444260
Ratio K-Alpha2/K-Alpha1,0.500
Receiving slit,0.10
Monochromator used,YES
Generator voltage, 40
Tube current, 40
File date and time,15/Apr/2016 00:24
Unit cell,
h k l, 0 0 0
Scan axis,2Theta
Scan range,20.000,56.380
Scan step size,0.0200000
No. of points, 1820
Scan type,PRE-SET COUNTS
Omega,2.000
Time per step,1.50
[Scan points]
Angle,Intensity
20.000, 9
20.040, 6
20.080,17
20.120,11
20.160, 6
20.200,10
20.240,16
20.280, 8
20.320, 7
20.360,12
20.400,13
20.440,13
20.480,14
20.520,11
20.560, 9
20.600, 9
20.640, 8
20.680,11
20.720, 9
20.760,14
20.800, 9
20.840,10
20.880,13
20.920, 7
20.960,16
21.000,12
21.040, 9
21.080,12
21.120,11
21.160,11
21.200,11
21.240, 9
21.280, 3
21.320, 8
21.360,11
21.400,14
21.440, 8
21.480,12
21.520,11
21.560, 9
21.600,12
21.640, 9
21.680, 8
21.720,13
21.760,10
21.800,14
21.840,12
21.880,17
21.920,13
21.960,12
22.000,14
22.040,10
22.080,12
22.120,17
22.160, 9
22.200,11
22.240,12
22.280,14
22.320,16
22.360,12
22.400, 8
22.440,10
22.480,13
22.520,17
22.560,11
22.600, 9
22.640,10
22.680,10
22.720,22
22.760, 8
22.800,18
22.840, 6
22.880,21
22.920,17
22.960,14
23.000,11
23.040,12
23.080,19
23.120,16
23.160,13
23.200, 8
23.240,25
23.280,14
23.320,15
23.360,13
23.400,15
23.440, 8
23.480,20
23.520,17
23.560,14
23.600,13
23.640,16
23.680,15
23.720,16
23.760,19
23.800,19
23.840, 9
23.880,16
23.920,13
23.960,11
24.000,15
24.040,13
24.080, 9
24.120,15
24.160,10
24.200,14
24.240, 9
24.280,12
24.320,13
24.360,10
24.400,14
24.440,14
24.480,24
24.520,11
24.560,18
24.600,14
24.640,14
24.680,19
24.720,16
24.760,20
24.800,20
24.840,17
24.880,18
24.920,20
24.960,14
25.000,16
25.040,16
25.080,12
25.120,17
25.160,15
25.200,19
25.240,18
25.280,19
25.320,18
25.360,14
25.400,18
25.440,23
25.480,17
25.520,26
25.560,18
25.600,20
25.640,24
25.680,25
25.720,12
25.760,15
25.800,23
25.840,14
25.880,17
25.920,18
25.960,22
26.000,17
26.040,27
26.080,24
26.120,24
26.160,25
26.200,13
26.240,20
26.280,25
26.320,21
26.360,24
26.400,24
26.440,25
26.480,26
26.520,29
26.560,25
26.600,23
26.640,29
26.680,24
26.720,24
26.760,28
26.800,35
26.840,28
26.880,18
26.920,19
26.960,29
27.000,23
27.040,36
27.080,32
27.120,24
27.160,28
27.200,29
27.240,32
27.280,28
27.320,29
27.360,31
27.400,27
27.440,21
27.480,31
27.520,32
27.560,35
27.600,36
27.640,31
27.680,31
27.720,22
27.760,31
27.800,21
27.840,33
27.880,29
27.920,37
27.960,25
28.000,26
28.040,26
28.080,27
28.120,24
28.160,31
28.200,32
28.240,20
28.280,27
28.320,32
28.360,19
28.400,25
28.440,18
28.480,19
28.520,28
28.560,34
28.600,15
28.640,22
28.680,25
28.720,26
28.760,37
28.800,28
28.840,29
28.880,25
28.920,24
28.960,24
29.000,28
29.040,19
29.080,34
29.120,25
29.160,24
29.200,24
29.240,34
29.280,20
29.320,17
29.360,19
29.400,26
29.440,34
29.480,35
29.520,19
29.560,27
29.600,15
29.640,22
29.680,27
29.720,34
29.760,22
29.800,23
29.840,27
29.880,23
29.920,28
29.960,31
30.000,27
30.040,21
30.080,25
30.120,29
30.160,43
30.200,21
30.240,39
30.280,34
30.320,36
30.360,28
30.400,35
30.440,31
30.480,27
30.520,17
30.560,20
30.600,30
30.640,27
30.680,23
30.720,20
30.760,30
30.800,27
30.840,26
30.880,26
30.920,22
30.960,27
31.000,22
31.040,26
31.080,29
31.120,20
31.160,22
31.200,24
31.240,27
31.280,31
31.320,29
31.360,14
31.400,26
31.440,21
31.480,22
31.520,13
31.560,24
31.600,21
31.640,30
31.680,22
31.720,27
31.760,32
31.800,27
31.840,28
31.880,20
31.920,29
31.960,23
32.000,26
32.040,29
32.080,22
32.120,22
32.160,29
32.200,30
32.240,24
32.280,18
32.320,19
32.360,21
32.400,17
32.440,18
32.480,21
32.520,17
32.560,28
32.600,15
32.640,23
32.680,23
32.720,21
32.760,23
32.800,26
32.840,23
32.880,21
32.920,17
32.960,27
33.000,17
33.040,24
33.080,25
33.120,13
33.160,25
33.200,18
33.240,16
33.280,20
33.320,15
33.360,14
33.400,28
33.440,21
33.480,19
33.520,22
33.560,20
33.600,18
33.640,24
33.680,28
33.720,21
33.760,22
33.800,16
33.840,20
33.880,23
33.920,14
33.960,21
34.000,16
34.040,16
34.080,17
34.120,21
34.160,16
34.200,15
34.240,26
34.280,16
34.320,20
34.360,18
34.400,16
34.440,20
34.480,20
34.520,16
34.560,16
34.600,20
34.640,34
34.680,25
34.720,13
34.760,20
34.800,11
34.840,19
34.880,17
34.920,15
34.960,24
35.000,13
35.040,19
35.080,12
35.120,12
35.160,12
35.200,22
35.240,13
35.280,14
35.320,15
35.360,22
35.400,17
35.440,16
35.480,13
35.520,16
35.560,13
35.600,16
35.640,18
35.680,17
35.720,13
35.760,11
35.800,16
35.840,18
35.880,17
35.920,18
35.960,20
36.000,14
36.040, 8
36.080,14
36.120,20
36.160,15
36.200,17
36.240,17
36.280,11
36.320,12
36.360,14
36.400,18
36.440,20
36.480,14
36.520,21
36.560,11
36.600,22
36.640, 4
36.680,10
36.720,15
36.760,16
36.800,13
36.840,13
36.880,16
36.920, 9
36.960,14
37.000, 8
37.040, 9
37.080,14
37.120,12
37.160,14
37.200,10
37.240,17
37.280,18
37.320,13
37.360,11
37.400,12
37.440,17
37.480,11
37.520, 9
37.560,12
37.600,19
37.640, 9
37.680,12
37.720, 8
37.760, 9
37.800,24
37.840,19
37.880, 9
37.920, 8
37.960,11
38.000,17
38.040,14
38.080,13
38.120,11
38.160,10
38.200,13
38.240,10
38.280,12
38.320,11
38.360,12
38.400,13
38.440,17
38.480,15
38.520,13
38.560,12
38.600,10
38.640,13
38.680,12
38.720,17
38.760, 9
38.800,11
38.840,10
38.880,11
38.920,17
38.960,15
39.000,13
39.040,15
39.080,15
39.120,12
39.160,14
39.200,13
39.240, 5
39.280,16
39.320,13
39.360,17
39.400,11
39.440,14
39.480,10
39.520,14
39.560,16
39.600, 4
39.640,15
39.680,10
39.720,10
39.760,17
39.800,13
39.840,10
39.880, 9
39.920, 8
39.960, 8
40.000,13
40.040, 7
40.080,11
40.120, 3
40.160,11
40.200,17
40.240,11
40.280,10
40.320,15
40.360,12
40.400,10
40.440,10
40.480, 6
40.520,12
40.560,15
40.600,11
40.640,15
40.680,10
40.720,14
40.760,10
40.800,11
40.840, 9
40.880,11
40.920, 8
40.960, 7
41.000, 5
41.040,14
41.080,11
41.120, 8
41.160,17
41.200,11
41.240, 8
41.280, 6
41.320,10
41.360,15
41.400, 9
41.440,15
41.480,12
41.520,11
41.560,14
41.600, 8
41.640, 9
41.680,16
41.720,12
41.760,11
41.800,11
41.840,10
41.880,17
41.920, 9
41.960,18
42.000, 3
42.040,12
42.080,13
42.120,17
42.160,11
42.200,14
42.240, 9
42.280,13
42.320,11
42.360, 8
42.400,14
42.440, 9
42.480,13
42.520,17
42.560,14
42.600, 9
42.640,12
42.680,12
42.720,15
42.760,10
42.800,18
42.840,11
42.880, 7
42.920,10
42.960,12
43.000,19
43.040,18
43.080,12
43.120,10
43.160,12
43.200,12
43.240, 8
43.280, 9
43.320,11
43.360, 9
43.400,11
43.440, 6
43.480,13
43.520, 4
43.560,15
43.600,25
43.640, 7
43.680,11
43.720,18
43.760,12
43.800,13
43.840, 8
43.880,10
43.920, 4
43.960,12
44.000, 7
44.040, 9
44.080,16
44.120, 7
44.160, 9
44.200,20
44.240, 9
44.280,18
44.320,13
44.360,21
44.400,10
44.440,13
44.480,12
44.520, 8
44.560,14
44.600,10
44.640,10
44.680,12
44.720,13
44.760,10
44.800, 9
44.840,15
44.880,14
44.920,15
44.960,12
45.000,14
45.040,18
45.080,16
45.120,16
45.160,17
45.200,14
45.240,22
45.280,20
45.320,18
45.360,16
45.400,18
45.440,16
45.480,13
45.520,18
45.560,17
45.600,12
45.640,13
45.680,12
45.720,13
45.760,23
45.800,15
45.840,18
45.880,21
45.920,17
45.960,17
46.000, 8
46.040,23
46.080,18
46.120,12
46.160,15
46.200,17
46.240,13
46.280,10
46.320,15
46.360,13
46.400,10
46.440, 6
46.480,13
46.520, 8
46.560,13
46.600,16
46.640,10
46.680,12
46.720,12
46.760,18
46.800,18
46.840,19
46.880,15
46.920, 8
46.960,17
47.000,19
47.040,17
47.080,11
47.120,16
47.160,10
47.200,12
47.240,17
47.280,17
47.320,15
47.360,13
47.400,20
47.440,21
47.480,17
47.520,15
47.560,13
47.600,20
47.640,16
47.680,17
47.720,11
47.760,14
47.800,20
47.840,21
47.880,22
47.920,19
47.960,18
48.000,16
48.040,13
48.080,16
48.120,20
48.160,11
48.200, 9
48.240,15
48.280,12
48.320, 7
48.360,15
48.400,12
48.440,17
48.480,16
48.520,16
48.560,10
48.600,20
48.640,19
48.680,16
48.720,16
48.760,20
48.800,17
48.840,18
48.880,15
48.920,16
48.960,17
49.000,10
49.040,14
49.080,19
49.120,22
49.160,22
49.200,14
49.240,20
49.280,16
49.320,16
49.360,10
49.400,19
49.440,16
49.480,15
49.520,22
49.560,15
49.600,24
49.640,10
49.680,12
49.720,10
49.760,14
49.800,13
49.840, 9
49.880,23
49.920,17
49.960,16
50.000,16
50.040,14
50.080,15
50.120,25
50.160,23
50.200,14
50.240,15
50.280,14
50.320,18
50.360,27
50.400,16
50.440,10
50.480,20
50.520,10
50.560,14
50.600,12
50.640,13
50.680,12
50.720,15
50.760,31
50.800,15
50.840,15
50.880,17
50.920,12
50.960,13
51.000,16
51.040,18
51.080,20
51.120,10
51.160,17
51.200,17
51.240,19
51.280,21
51.320,17
51.360,15
51.400,20
51.440,22
51.480,14
51.520,17
51.560,40
51.600,17
51.640,11
51.680,22
51.720,18
51.760,26
51.800,17
51.840,25
51.880,11
51.920,20
51.960,16
52.000,14
52.040,23
52.080,14
52.120, 7
52.160,18
52.200,20
52.240,18
52.280,18
52.320,19
52.360,20
52.400,23
52.440,15
52.480,21
52.520,21
52.560,18
52.600,19
52.640,19
52.680,15
52.720,21
52.760,21
52.800,16
52.840,15
52.880,18
52.920,16
52.960,22
53.000,13
53.040,29
53.080,21
53.120,16
53.160,21
53.200,12
53.240,16
53.280, 8
53.320,22
53.360,22
53.400,15
53.440,15
53.480,15
53.520,21
53.560,14
53.600,12
53.640,18
53.680, 7
53.720,21
53.760,21
53.800,29
53.840,18
53.880,14
53.920,16
53.960,17
54.000, 9
54.040,17
54.080,14
54.120,14
54.160,19
54.200,16
54.240,21
54.280,23
54.320,15
54.360,18
54.400,12
54.440,22
54.480,24
54.520,30
54.560,19
54.600,16
54.640,20
54.680,22
54.720,23
54.760,23
54.800,26
54.840, 7
54.880,18
54.920,18
54.960,14
55.000,30
55.040,28
55.080,17
55.120,20
55.160,15
55.200,15
55.240,12
55.280,25
55.320,25
55.360,17
55.400,28
55.440,21
55.480,21
55.520,25
55.560,13
55.600,19
55.640,30
55.680,14
55.720,13
55.760,18
55.800,15
55.840,14
55.880,21
55.920,17
55.960,17
56.000,21
56.040,23
56.080,23
56.120,28
56.160,15
56.200,12
56.240,20
56.280,17
56.320,11
56.360,22
56.380,19