File: code/data/data_source2/CuSe_AlN-150w-10min-CuSe-70w-36min.csv
[Measurement conditions]
Sample identification,
Comment - 1,"Configuration=Filmes Finos 19_1_2015, Owner=User-1, Creation date=19/01/2015 21:17:15"
Comment - 2,"Goniometer=PW3050/60 (Theta/Theta); Minimum step size 2Theta:0.001; Minimum step size Omega:0.001"
Comment - 3,"Sample stage=PW3071/xx Bracket"
Comment - 4,"Diffractometer system=XPERT-PRO"
Comment - 5,"Measurement program=C:\PANalytical\Data Collector\Programs\GrazingIncidence.xrdmp, Identifier={56BCC7D6-C695-42C6-9FE3-F6764B4E71BD}"
Anode material,Cu
K-Alpha1 wavelength,1.5405980
K-Alpha2 wavelength,1.5444260
Ratio K-Alpha2/K-Alpha1,0.500
Receiving slit,0.10
Monochromator used,YES
Generator voltage, 40
Tube current, 40
File date and time,15/Apr/2016 01:43
Unit cell,
h k l, 0 0 0
Scan axis,2Theta
Scan range,20.000,60.000
Scan step size,0.0200000
No. of points, 2001
Scan type,PRE-SET COUNTS
Omega,1.500
Time per step,15.00
[Scan points]
Angle,Intensity
20.000,45
20.040,37
20.080,22
20.120,39
20.160,36
20.200,35
20.240,40
20.280,43
20.320,21
20.360,39
20.400,43
20.440,37
20.480,37
20.520,36
20.560,29
20.600,33
20.640,37
20.680,38
20.720,26
20.760,35
20.800,46
20.840,22
20.880,34
20.920,29
20.960,30
21.000,37
21.040,33
21.080,40
21.120,34
21.160,46
21.200,26
21.240,31
21.280,34
21.320,46
21.360,38
21.400,31
21.440,24
21.480,30
21.520,43
21.560,34
21.600,29
21.640,33
21.680,31
21.720,34
21.760,36
21.800,35
21.840,40
21.880,35
21.920,38
21.960,37
22.000,36
22.040,38
22.080,31
22.120,35
22.160,28
22.200,39
22.240,35
22.280,29
22.320,30
22.360,41
22.400,40
22.440,29
22.480,36
22.520,36
22.560,40
22.600,43
22.640,39
22.680,36
22.720,40
22.760,34
22.800,50
22.840,49
22.880,41
22.920,27
22.960,43
23.000,35
23.040,42
23.080,43
23.120,41
23.160,31
23.200,45
23.240,38
23.280,51
23.320,49
23.360,43
23.400,29
23.440,40
23.480,35
23.520,38
23.560,50
23.600,35
23.640,32
23.680,38
23.720,47
23.760,45
23.800,35
23.840,44
23.880,51
23.920,51
23.960,51
24.000,51
24.040,42
24.080,40
24.120,39
24.160,51
24.200,53
24.240,56
24.280,52
24.320,52
24.360,46
24.400,48
24.440,54
24.480,51
24.520,69
24.560,46
24.600,49
24.640,45
24.680,49
24.720,59
24.760,68
24.800,70
24.840,69
24.880,75
24.920,61
24.960,68
25.000,67
25.040,81
25.080,92
25.120,123
25.160,116
25.200,139
25.240,173
25.280,235
25.320,353
25.360,441
25.400,571
25.440,672
25.480,826
25.520,868
25.560,950
25.600,1008
25.640,982
25.680,949
25.720,929
25.760,873
25.800,789
25.840,806
25.880,761
25.920,737
25.960,735
26.000,735
26.040,716
26.080,727
26.120,710
26.160,721
26.200,762
26.240,727
26.280,732
26.320,813
26.360,898
26.400,844
26.440,898
26.480,979
26.520,1033
26.560,1124
26.600,1254
26.640,1445
26.680,1515
26.720,1639
26.760,1770
26.800,1919
26.840,1834
26.880,1817
26.920,1746
26.960,1724
27.000,1605
27.040,1447
27.080,1305
27.120,1231
27.160,1123
27.200,1058
27.240,1116
27.280,1093
27.320,1062
27.360,1093
27.400,1133
27.440,1128
27.480,1081
27.520,1158
27.560,1075
27.600,1068
27.640,997
27.680,884
27.720,862
27.760,731
27.800,663
27.840,644
27.880,550
27.920,411
27.960,383
28.000,372
28.040,319
28.080,316
28.120,268
28.160,231
28.200,241
28.240,207
28.280,218
28.320,198
28.360,171
28.400,209
28.440,182
28.480,167
28.520,166
28.560,155
28.600,151
28.640,152
28.680,161
28.720,140
28.760,160
28.800,165
28.840,142
28.880,145
28.920,134
28.960,154
29.000,146
29.040,172
29.080,163
29.120,151
29.160,157
29.200,168
29.240,162
29.280,179
29.320,158
29.360,166
29.400,142
29.440,185
29.480,196
29.520,181
29.560,191
29.600,192
29.640,211
29.680,229
29.720,221
29.760,217
29.800,215
29.840,192
29.880,202
29.920,220
29.960,224
30.000,216
30.040,218
30.080,176
30.120,185
30.160,183
30.200,185
30.240,180
30.280,175
30.320,180
30.360,176
30.400,150
30.440,163
30.480,140
30.520,134
30.560,142
30.600,136
30.640,140
30.680,113
30.720,132
30.760,118
30.800,118
30.840,124
30.880,118
30.920,124
30.960,106
31.000,98
31.040,94
31.080,91
31.120,90
31.160,85
31.200,92
31.240,85
31.280,80
31.320,83
31.360,82
31.400,80
31.440,73
31.480,65
31.520,69
31.560,91
31.600,60
31.640,73
31.680,74
31.720,75
31.760,74
31.800,69
31.840,82
31.880,80
31.920,72
31.960,56
32.000,69
32.040,71
32.080,62
32.120,82
32.160,54
32.200,72
32.240,54
32.280,56
32.320,62
32.360,61
32.400,67
32.440,63
32.480,59
32.520,76
32.560,76
32.600,61
32.640,70
32.680,49
32.720,72
32.760,58
32.800,62
32.840,67
32.880,65
32.920,55
32.960,70
33.000,80
33.040,55
33.080,75
33.120,60
33.160,60
33.200,63
33.240,75
33.280,74
33.320,75
33.360,60
33.400,64
33.440,63
33.480,62
33.520,64
33.560,67
33.600,53
33.640,67
33.680,53
33.720,74
33.760,65
33.800,66
33.840,60
33.880,68
33.920,60
33.960,50
34.000,58
34.040,63
34.080,57
34.120,74
34.160,61
34.200,67
34.240,56
34.280,61
34.320,71
34.360,59
34.400,64
34.440,68
34.480,54
34.520,56
34.560,63
34.600,69
34.640,63
34.680,54
34.720,63
34.760,73
34.800,67
34.840,59
34.880,55
34.920,64
34.960,44
35.000,59
35.040,69
35.080,63
35.120,60
35.160,54
35.200,77
35.240,56
35.280,75
35.320,55
35.360,48
35.400,64
35.440,54
35.480,53
35.520,56
35.560,64
35.600,59
35.640,63
35.680,55
35.720,59
35.760,76
35.800,62
35.840,65
35.880,61
35.920,54
35.960,67
36.000,63
36.040,58
36.080,50
36.120,59
36.160,62
36.200,67
36.240,58
36.280,64
36.320,64
36.360,66
36.400,60
36.440,69
36.480,72
36.520,68
36.560,58
36.600,58
36.640,57
36.680,54
36.720,71
36.760,50
36.800,55
36.840,70
36.880,51
36.920,52
36.960,75
37.000,52
37.040,64
37.080,51
37.120,52
37.160,56
37.200,54
37.240,59
37.280,53
37.320,59
37.360,55
37.400,55
37.440,54
37.480,54
37.520,51
37.560,56
37.600,74
37.640,47
37.680,54
37.720,51
37.760,49
37.800,57
37.840,54
37.880,69
37.920,52
37.960,62
38.000,57
38.040,70
38.080,54
38.120,57
38.160,55
38.200,57
38.240,51
38.280,60
38.320,57
38.360,65
38.400,60
38.440,49
38.480,61
38.520,60
38.560,44
38.600,55
38.640,61
38.680,53
38.720,45
38.760,47
38.800,54
38.840,56
38.880,53
38.920,76
38.960,55
39.000,54
39.040,41
39.080,50
39.120,50
39.160,55
39.200,48
39.240,54
39.280,53
39.320,48
39.360,62
39.400,48
39.440,48
39.480,53
39.520,57
39.560,46
39.600,46
39.640,50
39.680,55
39.720,51
39.760,59
39.800,55
39.840,49
39.880,64
39.920,43
39.960,63
40.000,49
40.040,49
40.080,51
40.120,53
40.160,41
40.200,55
40.240,58
40.280,55
40.320,56
40.360,63
40.400,57
40.440,46
40.480,63
40.520,71
40.560,46
40.600,53
40.640,58
40.680,48
40.720,55
40.760,53
40.800,50
40.840,47
40.880,48
40.920,57
40.960,47
41.000,51
41.040,54
41.080,62
41.120,55
41.160,62
41.200,55
41.240,61
41.280,64
41.320,52
41.360,68
41.400,44
41.440,58
41.480,53
41.520,57
41.560,61
41.600,60
41.640,53
41.680,56
41.720,46
41.760,53
41.800,57
41.840,55
41.880,58
41.920,51
41.960,48
42.000,74
42.040,66
42.080,60
42.120,55
42.160,68
42.200,58
42.240,52
42.280,58
42.320,63
42.360,68
42.400,73
42.440,56
42.480,58
42.520,47
42.560,57
42.600,50
42.640,53
42.680,47
42.720,47
42.760,57
42.800,67
42.840,65
42.880,68
42.920,67
42.960,55
43.000,52
43.040,58
43.080,56
43.120,49
43.160,60
43.200,62
43.240,63
43.280,77
43.320,65
43.360,66
43.400,55
43.440,62
43.480,70
43.520,59
43.560,66
43.600,63
43.640,90
43.680,76
43.720,72
43.760,63
43.800,70
43.840,67
43.880,64
43.920,67
43.960,84
44.000,75
44.040,94
44.080,64
44.120,98
44.160,80
44.200,75
44.240,76
44.280,87
44.320,98
44.360,114
44.400,106
44.440,114
44.480,144
44.520,142
44.560,168
44.600,196
44.640,244
44.680,274
44.720,342
44.760,408
44.800,465
44.840,502
44.880,661
44.920,788
44.960,866
45.000,1013
45.040,1150
45.080,1310
45.120,1270
45.160,1321
45.200,1303
45.240,1198
45.280,1154
45.320,1060
45.360,830
45.400,750
45.440,641
45.480,527
45.520,424
45.560,358
45.600,304
45.640,245
45.680,250
45.720,207
45.760,177
45.800,163
45.840,131
45.880,151
45.920,126
45.960,119
46.000,104
46.040,88
46.080,101
46.120,106
46.160,104
46.200,83
46.240,120
46.280,100
46.320,86
46.360,92
46.400,88
46.440,81
46.480,84
46.520,94
46.560,102
46.600,100
46.640,90
46.680,88
46.720,109
46.760,78
46.800,92
46.840,81
46.880,98
46.920,89
46.960,92
47.000,85
47.040,81
47.080,97
47.120,90
47.160,99
47.200,84
47.240,80
47.280,87
47.320,85
47.360,83
47.400,88
47.440,87
47.480,96
47.520,92
47.560,87
47.600,85
47.640,84
47.680,101
47.720,81
47.760,103
47.800,85
47.840,102
47.880,85
47.920,112
47.960,99
48.000,100
48.040,102
48.080,83
48.120,89
48.160,86
48.200,88
48.240,83
48.280,71
48.320,85
48.360,79
48.400,90
48.440,75
48.480,86
48.520,87
48.560,95
48.600,70
48.640,87
48.680,96
48.720,75
48.760,82
48.800,63
48.840,84
48.880,82
48.920,74
48.960,95
49.000,69
49.040,62
49.080,74
49.120,62
49.160,59
49.200,74
49.240,68
49.280,59
49.320,60
49.360,68
49.400,74
49.440,72
49.480,67
49.520,91
49.560,80
49.600,77
49.640,73
49.680,68
49.720,55
49.760,70
49.800,96
49.840,63
49.880,61
49.920,70
49.960,66
50.000,64
50.040,72
50.080,69
50.120,64
50.160,71
50.200,64
50.240,69
50.280,88
50.320,85
50.360,61
50.400,72
50.440,71
50.480,74
50.520,81
50.560,63
50.600,58
50.640,81
50.680,53
50.720,64
50.760,81
50.800,62
50.840,66
50.880,64
50.920,57
50.960,75
51.000,69
51.040,63
51.080,69
51.120,74
51.160,55
51.200,56
51.240,66
51.280,63
51.320,64
51.360,71
51.400,70
51.440,63
51.480,77
51.520,76
51.560,64
51.600,62
51.640,62
51.680,61
51.720,60
51.760,67
51.800,52
51.840,64
51.880,70
51.920,63
51.960,73
52.000,69
52.040,62
52.080,85
52.120,67
52.160,74
52.200,71
52.240,84
52.280,82
52.320,94
52.360,100
52.400,81
52.440,114
52.480,125
52.520,121
52.560,129
52.600,122
52.640,144
52.680,168
52.720,200
52.760,211
52.800,277
52.840,286
52.880,321
52.920,335
52.960,403
53.000,382
53.040,408
53.080,481
53.120,445
53.160,460
53.200,469
53.240,446
53.280,414
53.320,417
53.360,367
53.400,361
53.440,332
53.480,319
53.520,315
53.560,284
53.600,249
53.640,207
53.680,235
53.720,237
53.760,230
53.800,217
53.840,213
53.880,181
53.920,199
53.960,186
54.000,166
54.040,187
54.080,165
54.120,153
54.160,178
54.200,143
54.240,154
54.280,143
54.320,133
54.360,143
54.400,154
54.440,154
54.480,142
54.520,158
54.560,164
54.600,149
54.640,139
54.680,167
54.720,157
54.760,156
54.800,169
54.840,160
54.880,170
54.920,161
54.960,190
55.000,193
55.040,180
55.080,191
55.120,187
55.160,186
55.200,216
55.240,225
55.280,190
55.320,193
55.360,210
55.400,201
55.440,208
55.480,197
55.520,222
55.560,206
55.600,225
55.640,231
55.680,206
55.720,202
55.760,206
55.800,197
55.840,191
55.880,174
55.920,168
55.960,162
56.000,157
56.040,173
56.080,142
56.120,150
56.160,152
56.200,117
56.240,108
56.280,104
56.320,94
56.360,94
56.400,83
56.440,81
56.480,71
56.520,81
56.560,60
56.600,66
56.640,69
56.680,64
56.720,54
56.760,72
56.800,54
56.840,67
56.880,58
56.920,57
56.960,48
57.000,51
57.040,54
57.080,62
57.120,48
57.160,59
57.200,55
57.240,48
57.280,51
57.320,36
57.360,54
57.400,44
57.440,53
57.480,38
57.520,44
57.560,45
57.600,48
57.640,36
57.680,39
57.720,46
57.760,35
57.800,57
57.840,48
57.880,46
57.920,43
57.960,52
58.000,38
58.040,40
58.080,50
58.120,38
58.160,48
58.200,49
58.240,48
58.280,42
58.320,34
58.360,36
58.400,50
58.440,40
58.480,45
58.520,36
58.560,30
58.600,31
58.640,43
58.680,36
58.720,35
58.760,34
58.800,33
58.840,46
58.880,43
58.920,44
58.960,43
59.000,39
59.040,34
59.080,31
59.120,38
59.160,39
59.200,37
59.240,40
59.280,29
59.320,37
59.360,40
59.400,43
59.440,41
59.480,33
59.520,34
59.560,30
59.600,42
59.640,41
59.680,50
59.720,27
59.760,39
59.800,27
59.840,38
59.880,38
59.920,32
59.960,42
60.000,36