File: code/data/data_source2/CuSe_AlN-150w-10min-CuSe-130w-16min.csv
[Measurement conditions]
Sample identification,
Comment - 1,"Configuration=Filmes Finos 19_1_2015, Owner=User-1, Creation date=19/01/2015 21:17:15"
Comment - 2,"Goniometer=PW3050/60 (Theta/Theta); Minimum step size 2Theta:0.001; Minimum step size Omega:0.001"
Comment - 3,"Sample stage=PW3071/xx Bracket"
Comment - 4,"Diffractometer system=XPERT-PRO"
Comment - 5,"Measurement program=C:\PANalytical\Data Collector\Programs\GrazingIncidence.xrdmp, Identifier={B51BE67D-6868-4A28-BA5C-FF73AA0576E0}"
Anode material,Cu
K-Alpha1 wavelength,1.5405980
K-Alpha2 wavelength,1.5444260
Ratio K-Alpha2/K-Alpha1,0.500
Receiving slit,0.10
Monochromator used,YES
Generator voltage, 40
Tube current, 40
File date and time,17/Apr/2016 10:48
Unit cell,
h k l, 0 0 0
Scan axis,2Theta
Scan range,20.000,59.060
Scan step size,0.0200000
No. of points, 1954
Scan type,PRE-SET COUNTS
Omega,1.500
Time per step,15.00
[Scan points]
Angle,Intensity
20.000,108
20.040,86
20.080,84
20.120,74
20.160,89
20.200,86
20.240,75
20.280,76
20.320,88
20.360,73
20.400,105
20.440,74
20.480,98
20.520,92
20.560,72
20.600,80
20.640,80
20.680,87
20.720,101
20.760,79
20.800,98
20.840,81
20.880,81
20.920,90
20.960,80
21.000,99
21.040,81
21.080,72
21.120,92
21.160,91
21.200,97
21.240,84
21.280,95
21.320,95
21.360,104
21.400,75
21.440,97
21.480,105
21.520,94
21.560,104
21.600,95
21.640,99
21.680,109
21.720,100
21.760,89
21.800,91
21.840,102
21.880,94
21.920,92
21.960,100
22.000,114
22.040,95
22.080,96
22.120,97
22.160,91
22.200,99
22.240,118
22.280,124
22.320,87
22.360,112
22.400,120
22.440,100
22.480,115
22.520,103
22.560,120
22.600,106
22.640,107
22.680,107
22.720,120
22.760,102
22.800,104
22.840,110
22.880,126
22.920,121
22.960,122
23.000,106
23.040,121
23.080,119
23.120,129
23.160,118
23.200,124
23.240,113
23.280,112
23.320,138
23.360,89
23.400,126
23.440,106
23.480,108
23.520,122
23.560,108
23.600,123
23.640,150
23.680,116
23.720,133
23.760,145
23.800,130
23.840,149
23.880,137
23.920,126
23.960,125
24.000,131
24.040,145
24.080,120
24.120,126
24.160,137
24.200,146
24.240,132
24.280,138
24.320,142
24.360,122
24.400,133
24.440,147
24.480,145
24.520,142
24.560,144
24.600,134
24.640,136
24.680,172
24.720,161
24.760,147
24.800,150
24.840,151
24.880,163
24.920,162
24.960,182
25.000,150
25.040,165
25.080,153
25.120,187
25.160,164
25.200,195
25.240,197
25.280,170
25.320,154
25.360,194
25.400,190
25.440,189
25.480,202
25.520,205
25.560,187
25.600,194
25.640,196
25.680,188
25.720,228
25.760,231
25.800,246
25.840,243
25.880,227
25.920,216
25.960,245
26.000,226
26.040,251
26.080,275
26.120,226
26.160,241
26.200,246
26.240,242
26.280,233
26.320,259
26.360,265
26.400,308
26.440,258
26.480,258
26.520,243
26.560,264
26.600,266
26.640,271
26.680,282
26.720,298
26.760,308
26.800,274
26.840,296
26.880,266
26.920,312
26.960,312
27.000,302
27.040,331
27.080,362
27.120,357
27.160,372
27.200,343
27.240,362
27.280,373
27.320,334
27.360,369
27.400,314
27.440,316
27.480,336
27.520,359
27.560,305
27.600,314
27.640,316
27.680,313
27.720,330
27.760,336
27.800,317
27.840,349
27.880,309
27.920,350
27.960,314
28.000,308
28.040,333
28.080,332
28.120,294
28.160,324
28.200,321
28.240,326
28.280,290
28.320,311
28.360,315
28.400,305
28.440,285
28.480,286
28.520,321
28.560,294
28.600,294
28.640,297
28.680,321
28.720,278
28.760,315
28.800,294
28.840,292
28.880,332
28.920,319
28.960,305
29.000,293
29.040,322
29.080,312
29.120,315
29.160,298
29.200,312
29.240,310
29.280,325
29.320,331
29.360,322
29.400,302
29.440,327
29.480,322
29.520,319
29.560,310
29.600,290
29.640,288
29.680,299
29.720,309
29.760,302
29.800,313
29.840,334
29.880,274
29.920,312
29.960,303
30.000,289
30.040,282
30.080,302
30.120,299
30.160,292
30.200,298
30.240,304
30.280,319
30.320,305
30.360,295
30.400,315
30.440,302
30.480,301
30.520,297
30.560,301
30.600,320
30.640,281
30.680,293
30.720,282
30.760,296
30.800,304
30.840,288
30.880,309
30.920,270
30.960,305
31.000,324
31.040,276
31.080,297
31.120,290
31.160,274
31.200,259
31.240,295
31.280,277
31.320,287
31.360,284
31.400,261
31.440,276
31.480,282
31.520,270
31.560,279
31.600,279
31.640,280
31.680,287
31.720,252
31.760,270
31.800,277
31.840,279
31.880,283
31.920,265
31.960,254
32.000,263
32.040,254
32.080,231
32.120,259
32.160,242
32.200,271
32.240,228
32.280,220
32.320,235
32.360,246
32.400,219
32.440,241
32.480,225
32.520,231
32.560,238
32.600,255
32.640,237
32.680,248
32.720,228
32.760,227
32.800,237
32.840,224
32.880,212
32.920,193
32.960,214
33.000,230
33.040,231
33.080,207
33.120,245
33.160,231
33.200,223
33.240,218
33.280,215
33.320,223
33.360,185
33.400,209
33.440,205
33.480,230
33.520,213
33.560,196
33.600,195
33.640,207
33.680,186
33.720,216
33.760,210
33.800,226
33.840,205
33.880,213
33.920,185
33.960,198
34.000,211
34.040,201
34.080,195
34.120,192
34.160,210
34.200,169
34.240,188
34.280,207
34.320,186
34.360,202
34.400,203
34.440,195
34.480,174
34.520,174
34.560,183
34.600,213
34.640,170
34.680,202
34.720,169
34.760,183
34.800,175
34.840,168
34.880,167
34.920,188
34.960,164
35.000,184
35.040,146
35.080,187
35.120,158
35.160,162
35.200,166
35.240,172
35.280,146
35.320,157
35.360,207
35.400,154
35.440,164
35.480,168
35.520,150
35.560,169
35.600,173
35.640,175
35.680,160
35.720,141
35.760,172
35.800,182
35.840,168
35.880,152
35.920,149
35.960,171
36.000,155
36.040,144
36.080,144
36.120,152
36.160,150
36.200,161
36.240,156
36.280,144
36.320,143
36.360,156
36.400,134
36.440,172
36.480,142
36.520,137
36.560,164
36.600,125
36.640,134
36.680,126
36.720,158
36.760,148
36.800,133
36.840,152
36.880,138
36.920,157
36.960,144
37.000,129
37.040,134
37.080,155
37.120,133
37.160,144
37.200,129
37.240,140
37.280,130
37.320,126
37.360,144
37.400,137
37.440,130
37.480,158
37.520,137
37.560,141
37.600,149
37.640,134
37.680,155
37.720,144
37.760,128
37.800,130
37.840,139
37.880,153
37.920,135
37.960,126
38.000,140
38.040,138
38.080,118
38.120,147
38.160,142
38.200,158
38.240,154
38.280,159
38.320,163
38.360,156
38.400,140
38.440,150
38.480,127
38.520,143
38.560,126
38.600,136
38.640,130
38.680,135
38.720,136
38.760,128
38.800,124
38.840,102
38.880,130
38.920,123
38.960,115
39.000,117
39.040,111
39.080,115
39.120,115
39.160,112
39.200,115
39.240,138
39.280,110
39.320,114
39.360,132
39.400,123
39.440,123
39.480,137
39.520,123
39.560,110
39.600,116
39.640,121
39.680,108
39.720,119
39.760,110
39.800,123
39.840,107
39.880,135
39.920,121
39.960,106
40.000,120
40.040,108
40.080,115
40.120,124
40.160,125
40.200,130
40.240,134
40.280,130
40.320,132
40.360,128
40.400,132
40.440,118
40.480,97
40.520,139
40.560,119
40.600,113
40.640,110
40.680,131
40.720,128
40.760,110
40.800,109
40.840,120
40.880,119
40.920,108
40.960,120
41.000,124
41.040,111
41.080,104
41.120,100
41.160,117
41.200,121
41.240,123
41.280,124
41.320,115
41.360,111
41.400,121
41.440,126
41.480,124
41.520,118
41.560,114
41.600,112
41.640,127
41.680,105
41.720,122
41.760,141
41.800,117
41.840,134
41.880,137
41.920,100
41.960,122
42.000,123
42.040,110
42.080,129
42.120,108
42.160,123
42.200,132
42.240,105
42.280,99
42.320,123
42.360,129
42.400,132
42.440,132
42.480,118
42.520,141
42.560,106
42.600,128
42.640,109
42.680,107
42.720,123
42.760,119
42.800,132
42.840,110
42.880,99
42.920,132
42.960,125
43.000,130
43.040,119
43.080,129
43.120,115
43.160,143
43.200,118
43.240,133
43.280,145
43.320,123
43.360,114
43.400,139
43.440,122
43.480,100
43.520,123
43.560,143
43.600,123
43.640,142
43.680,119
43.720,109
43.760,125
43.800,133
43.840,129
43.880,146
43.920,112
43.960,131
44.000,109
44.040,123
44.080,132
44.120,149
44.160,127
44.200,154
44.240,134
44.280,153
44.320,133
44.360,140
44.400,140
44.440,145
44.480,116
44.520,135
44.560,131
44.600,152
44.640,140
44.680,141
44.720,144
44.760,141
44.800,132
44.840,140
44.880,172
44.920,137
44.960,163
45.000,163
45.040,165
45.080,157
45.120,163
45.160,165
45.200,168
45.240,162
45.280,180
45.320,169
45.360,154
45.400,141
45.440,170
45.480,167
45.520,159
45.560,160
45.600,177
45.640,175
45.680,189
45.720,171
45.760,174
45.800,178
45.840,187
45.880,148
45.920,174
45.960,182
46.000,161
46.040,160
46.080,177
46.120,171
46.160,160
46.200,156
46.240,158
46.280,164
46.320,187
46.360,178
46.400,161
46.440,152
46.480,148
46.520,161
46.560,146
46.600,183
46.640,189
46.680,169
46.720,175
46.760,179
46.800,152
46.840,178
46.880,172
46.920,149
46.960,159
47.000,155
47.040,167
47.080,174
47.120,161
47.160,169
47.200,190
47.240,196
47.280,196
47.320,187
47.360,171
47.400,169
47.440,177
47.480,226
47.520,166
47.560,184
47.600,181
47.640,199
47.680,188
47.720,186
47.760,168
47.800,185
47.840,228
47.880,195
47.920,185
47.960,173
48.000,172
48.040,182
48.080,206
48.120,186
48.160,188
48.200,168
48.240,203
48.280,174
48.320,180
48.360,179
48.400,197
48.440,198
48.480,164
48.520,190
48.560,191
48.600,210
48.640,183
48.680,202
48.720,202
48.760,201
48.800,186
48.840,188
48.880,194
48.920,216
48.960,223
49.000,178
49.040,209
49.080,206
49.120,170
49.160,197
49.200,184
49.240,191
49.280,199
49.320,201
49.360,189
49.400,198
49.440,223
49.480,217
49.520,211
49.560,186
49.600,206
49.640,191
49.680,216
49.720,205
49.760,192
49.800,199
49.840,192
49.880,210
49.920,204
49.960,207
50.000,220
50.040,200
50.080,221
50.120,240
50.160,212
50.200,207
50.240,229
50.280,199
50.320,200
50.360,224
50.400,211
50.440,201
50.480,211
50.520,201
50.560,224
50.600,196
50.640,210
50.680,190
50.720,209
50.760,213
50.800,234
50.840,230
50.880,222
50.920,196
50.960,192
51.000,195
51.040,225
51.080,207
51.120,180
51.160,178
51.200,227
51.240,209
51.280,209
51.320,194
51.360,228
51.400,195
51.440,221
51.480,212
51.520,210
51.560,203
51.600,230
51.640,226
51.680,196
51.720,198
51.760,239
51.800,198
51.840,219
51.880,190
51.920,224
51.960,213
52.000,197
52.040,199
52.080,207
52.120,209
52.160,220
52.200,196
52.240,218
52.280,243
52.320,210
52.360,205
52.400,180
52.440,212
52.480,197
52.520,202
52.560,206
52.600,199
52.640,185
52.680,172
52.720,192
52.760,197
52.800,164
52.840,186
52.880,197
52.920,196
52.960,187
53.000,180
53.040,208
53.080,209
53.120,200
53.160,202
53.200,211
53.240,169
53.280,199
53.320,197
53.360,211
53.400,202
53.440,194
53.480,183
53.520,186
53.560,197
53.600,200
53.640,189
53.680,214
53.720,205
53.760,197
53.800,206
53.840,195
53.880,223
53.920,200
53.960,205
54.000,200
54.040,217
54.080,199
54.120,173
54.160,174
54.200,180
54.240,170
54.280,184
54.320,159
54.360,190
54.400,192
54.440,167
54.480,194
54.520,177
54.560,160
54.600,176
54.640,149
54.680,186
54.720,175
54.760,184
54.800,174
54.840,176
54.880,167
54.920,193
54.960,186
55.000,212
55.040,186
55.080,172
55.120,185
55.160,171
55.200,186
55.240,183
55.280,204
55.320,176
55.360,174
55.400,167
55.440,176
55.480,149
55.520,178
55.560,201
55.600,188
55.640,181
55.680,182
55.720,175
55.760,167
55.800,177
55.840,177
55.880,190
55.920,161
55.960,141
56.000,159
56.040,167
56.080,164
56.120,159
56.160,157
56.200,155
56.240,143
56.280,151
56.320,148
56.360,155
56.400,99
56.440,178
56.480,149
56.520,150
56.560,162
56.600,143
56.640,139
56.680,143
56.720,118
56.760,117
56.800,146
56.840,129
56.880,133
56.920,131
56.960,120
57.000,116
57.040,133
57.080,120
57.120,139
57.160,116
57.200,110
57.240,122
57.280,109
57.320,128
57.360,125
57.400,102
57.440,121
57.480,110
57.520,119
57.560,99
57.600,122
57.640,103
57.680,98
57.720,90
57.760,106
57.800,88
57.840,118
57.880,78
57.920,94
57.960,115
58.000,101
58.040,102
58.080,105
58.120,96
58.160,110
58.200,108
58.240,116
58.280,102
58.320,101
58.360,80
58.400,104
58.440,95
58.480,95
58.520,93
58.560,83
58.600,94
58.640,92
58.680,87
58.720,88
58.760,89
58.800,84
58.840,88
58.880,88
58.920,97
58.960,85
59.000,90
59.040,93
59.060,99