File: code/data/data_source2/CuSe_AlN-150w-10min-CuSe-90w-25min.csv
[Measurement conditions]
Sample identification,
Comment - 1,"Configuration=Filmes Finos 19_1_2015, Owner=User-1, Creation date=19/01/2015 21:17:15"
Comment - 2,"Goniometer=PW3050/60 (Theta/Theta); Minimum step size 2Theta:0.001; Minimum step size Omega:0.001"
Comment - 3,"Sample stage=PW3071/xx Bracket"
Comment - 4,"Diffractometer system=XPERT-PRO"
Comment - 5,"Measurement program=C:\PANalytical\Data Collector\Programs\GrazingIncidence.xrdmp, Identifier={BC538F88-BCB7-49B1-B949-146FB158B101}"
Anode material,Cu
K-Alpha1 wavelength,1.5405980
K-Alpha2 wavelength,1.5444260
Ratio K-Alpha2/K-Alpha1,0.500
Receiving slit,0.10
Monochromator used,YES
Generator voltage, 40
Tube current, 40
File date and time,19/Apr/2016 01:03
Unit cell,
h k l, 0 0 0
Scan axis,2Theta
Scan range,20.000,58.200
Scan step size,0.0200000
No. of points, 1911
Scan type,PRE-SET COUNTS
Omega,1.500
Time per step,15.00
[Scan points]
Angle,Intensity
20.000,52
20.040,38
20.080,36
20.120,33
20.160,43
20.200,41
20.240,35
20.280,32
20.320,35
20.360,43
20.400,38
20.440,36
20.480,43
20.520,38
20.560,51
20.600,38
20.640,35
20.680,36
20.720,34
20.760,39
20.800,30
20.840,30
20.880,41
20.920,36
20.960,32
21.000,28
21.040,26
21.080,38
21.120,34
21.160,42
21.200,36
21.240,39
21.280,34
21.320,46
21.360,39
21.400,41
21.440,43
21.480,41
21.520,37
21.560,38
21.600,29
21.640,32
21.680,34
21.720,39
21.760,39
21.800,42
21.840,40
21.880,27
21.920,38
21.960,35
22.000,42
22.040,30
22.080,35
22.120,40
22.160,40
22.200,24
22.240,33
22.280,37
22.320,45
22.360,33
22.400,37
22.440,41
22.480,39
22.520,39
22.560,41
22.600,35
22.640,28
22.680,49
22.720,38
22.760,39
22.800,35
22.840,35
22.880,37
22.920,38
22.960,38
23.000,37
23.040,38
23.080,43
23.120,36
23.160,28
23.200,44
23.240,40
23.280,51
23.320,39
23.360,45
23.400,42
23.440,52
23.480,53
23.520,39
23.560,29
23.600,38
23.640,43
23.680,46
23.720,59
23.760,45
23.800,50
23.840,56
23.880,38
23.920,53
23.960,41
24.000,44
24.040,67
24.080,44
24.120,43
24.160,56
24.200,41
24.240,38
24.280,56
24.320,56
24.360,51
24.400,68
24.440,53
24.480,53
24.520,48
24.560,59
24.600,59
24.640,63
24.680,49
24.720,64
24.760,62
24.800,71
24.840,69
24.880,83
24.920,61
24.960,57
25.000,65
25.040,72
25.080,77
25.120,102
25.160,86
25.200,101
25.240,120
25.280,120
25.320,120
25.360,165
25.400,210
25.440,255
25.480,318
25.520,449
25.560,557
25.600,688
25.640,798
25.680,972
25.720,1050
25.760,1096
25.800,1093
25.840,1115
25.880,1087
25.920,1089
25.960,1056
26.000,985
26.040,1029
26.080,988
26.120,965
26.160,889
26.200,892
26.240,958
26.280,989
26.320,975
26.360,1006
26.400,976
26.440,1025
26.480,1100
26.520,1195
26.560,1226
26.600,1323
26.640,1388
26.680,1461
26.720,1607
26.760,1793
26.800,1836
26.840,2024
26.880,2185
26.920,2237
26.960,2424
27.000,2476
27.040,2569
27.080,2460
27.120,2439
27.160,2378
27.200,2199
27.240,2066
27.280,2008
27.320,1910
27.360,1900
27.400,1813
27.440,1785
27.480,1846
27.520,1825
27.560,1841
27.600,1810
27.640,1830
27.680,1843
27.720,1707
27.760,1634
27.800,1503
27.840,1373
27.880,1164
27.920,1072
27.960,957
28.000,862
28.040,771
28.080,641
28.120,548
28.160,490
28.200,445
28.240,413
28.280,390
28.320,348
28.360,312
28.400,311
28.440,259
28.480,284
28.520,249
28.560,247
28.600,220
28.640,262
28.680,216
28.720,192
28.760,176
28.800,175
28.840,197
28.880,166
28.920,180
28.960,180
29.000,179
29.040,193
29.080,176
29.120,156
29.160,166
29.200,191
29.240,179
29.280,174
29.320,165
29.360,194
29.400,190
29.440,209
29.480,181
29.520,206
29.560,210
29.600,205
29.640,241
29.680,193
29.720,220
29.760,204
29.800,206
29.840,208
29.880,248
29.920,210
29.960,196
30.000,209
30.040,256
30.080,233
30.120,228
30.160,211
30.200,240
30.240,205
30.280,190
30.320,214
30.360,189
30.400,165
30.440,165
30.480,168
30.520,185
30.560,169
30.600,153
30.640,140
30.680,139
30.720,147
30.760,149
30.800,131
30.840,129
30.880,131
30.920,129
30.960,135
31.000,127
31.040,120
31.080,108
31.120,118
31.160,101
31.200,99
31.240,114
31.280,96
31.320,104
31.360,110
31.400,96
31.440,91
31.480,84
31.520,86
31.560,73
31.600,79
31.640,81
31.680,79
31.720,89
31.760,75
31.800,76
31.840,82
31.880,79
31.920,72
31.960,72
32.000,67
32.040,71
32.080,76
32.120,70
32.160,83
32.200,82
32.240,58
32.280,77
32.320,60
32.360,79
32.400,84
32.440,62
32.480,67
32.520,78
32.560,74
32.600,61
32.640,68
32.680,68
32.720,62
32.760,84
32.800,56
32.840,73
32.880,63
32.920,67
32.960,52
33.000,79
33.040,78
33.080,71
33.120,66
33.160,54
33.200,73
33.240,53
33.280,67
33.320,62
33.360,75
33.400,71
33.440,66
33.480,58
33.520,57
33.560,66
33.600,84
33.640,60
33.680,85
33.720,64
33.760,62
33.800,76
33.840,62
33.880,47
33.920,67
33.960,67
34.000,57
34.040,73
34.080,56
34.120,74
34.160,68
34.200,68
34.240,68
34.280,59
34.320,74
34.360,73
34.400,64
34.440,65
34.480,68
34.520,57
34.560,77
34.600,77
34.640,53
34.680,52
34.720,66
34.760,69
34.800,46
34.840,74
34.880,65
34.920,59
34.960,62
35.000,74
35.040,54
35.080,65
35.120,59
35.160,64
35.200,69
35.240,64
35.280,75
35.320,61
35.360,71
35.400,86
35.440,68
35.480,74
35.520,68
35.560,55
35.600,85
35.640,72
35.680,73
35.720,77
35.760,69
35.800,59
35.840,71
35.880,72
35.920,57
35.960,75
36.000,63
36.040,55
36.080,55
36.120,68
36.160,70
36.200,80
36.240,64
36.280,73
36.320,68
36.360,55
36.400,74
36.440,68
36.480,65
36.520,63
36.560,61
36.600,52
36.640,54
36.680,72
36.720,70
36.760,60
36.800,54
36.840,63
36.880,58
36.920,62
36.960,49
37.000,59
37.040,58
37.080,52
37.120,63
37.160,56
37.200,56
37.240,69
37.280,50
37.320,56
37.360,74
37.400,50
37.440,69
37.480,47
37.520,54
37.560,58
37.600,48
37.640,54
37.680,53
37.720,55
37.760,70
37.800,66
37.840,58
37.880,50
37.920,66
37.960,58
38.000,58
38.040,50
38.080,71
38.120,59
38.160,70
38.200,70
38.240,56
38.280,76
38.320,67
38.360,78
38.400,65
38.440,60
38.480,46
38.520,70
38.560,54
38.600,64
38.640,67
38.680,57
38.720,61
38.760,55
38.800,59
38.840,68
38.880,66
38.920,47
38.960,60
39.000,47
39.040,67
39.080,51
39.120,61
39.160,61
39.200,55
39.240,67
39.280,62
39.320,67
39.360,59
39.400,48
39.440,62
39.480,44
39.520,64
39.560,51
39.600,52
39.640,47
39.680,56
39.720,49
39.760,51
39.800,56
39.840,62
39.880,63
39.920,63
39.960,60
40.000,51
40.040,53
40.080,44
40.120,49
40.160,65
40.200,67
40.240,59
40.280,67
40.320,64
40.360,65
40.400,64
40.440,65
40.480,63
40.520,50
40.560,53
40.600,76
40.640,69
40.680,72
40.720,46
40.760,58
40.800,64
40.840,58
40.880,58
40.920,48
40.960,54
41.000,55
41.040,67
41.080,58
41.120,66
41.160,49
41.200,57
41.240,60
41.280,54
41.320,61
41.360,58
41.400,53
41.440,66
41.480,62
41.520,61
41.560,59
41.600,54
41.640,58
41.680,68
41.720,63
41.760,60
41.800,63
41.840,58
41.880,63
41.920,68
41.960,56
42.000,60
42.040,68
42.080,68
42.120,54
42.160,62
42.200,48
42.240,59
42.280,68
42.320,53
42.360,57
42.400,67
42.440,70
42.480,68
42.520,75
42.560,75
42.600,50
42.640,56
42.680,62
42.720,64
42.760,66
42.800,68
42.840,56
42.880,65
42.920,70
42.960,62
43.000,57
43.040,69
43.080,70
43.120,66
43.160,47
43.200,64
43.240,56
43.280,70
43.320,73
43.360,61
43.400,80
43.440,72
43.480,64
43.520,78
43.560,73
43.600,58
43.640,80
43.680,69
43.720,79
43.760,76
43.800,89
43.840,75
43.880,84
43.920,71
43.960,79
44.000,82
44.040,80
44.080,76
44.120,89
44.160,94
44.200,92
44.240,90
44.280,96
44.320,89
44.360,92
44.400,88
44.440,101
44.480,103
44.520,101
44.560,104
44.600,107
44.640,149
44.680,147
44.720,163
44.760,170
44.800,206
44.840,235
44.880,271
44.920,346
44.960,454
45.000,512
45.040,721
45.080,760
45.120,1063
45.160,1276
45.200,1504
45.240,1645
45.280,1746
45.320,1769
45.360,1774
45.400,1665
45.440,1560
45.480,1354
45.520,1175
45.560,962
45.600,810
45.640,676
45.680,585
45.720,475
45.760,376
45.800,308
45.840,288
45.880,228
45.920,223
45.960,169
46.000,174
46.040,159
46.080,147
46.120,151
46.160,120
46.200,146
46.240,121
46.280,117
46.320,107
46.360,144
46.400,115
46.440,114
46.480,106
46.520,121
46.560,112
46.600,114
46.640,111
46.680,107
46.720,108
46.760,104
46.800,111
46.840,105
46.880,102
46.920,115
46.960,107
47.000,93
47.040,95
47.080,108
47.120,91
47.160,97
47.200,97
47.240,100
47.280,86
47.320,103
47.360,106
47.400,95
47.440,117
47.480,94
47.520,104
47.560,85
47.600,94
47.640,85
47.680,78
47.720,101
47.760,117
47.800,116
47.840,111
47.880,118
47.920,106
47.960,106
48.000,99
48.040,115
48.080,124
48.120,110
48.160,110
48.200,121
48.240,100
48.280,110
48.320,99
48.360,88
48.400,101
48.440,111
48.480,101
48.520,94
48.560,82
48.600,97
48.640,90
48.680,83
48.720,85
48.760,76
48.800,77
48.840,72
48.880,71
48.920,83
48.960,83
49.000,87
49.040,88
49.080,82
49.120,85
49.160,75
49.200,87
49.240,92
49.280,88
49.320,90
49.360,73
49.400,74
49.440,91
49.480,69
49.520,81
49.560,77
49.600,93
49.640,70
49.680,86
49.720,78
49.760,70
49.800,60
49.840,75
49.880,83
49.920,66
49.960,72
50.000,72
50.040,89
50.080,86
50.120,62
50.160,75
50.200,68
50.240,88
50.280,79
50.320,81
50.360,68
50.400,87
50.440,84
50.480,74
50.520,77
50.560,86
50.600,59
50.640,63
50.680,81
50.720,65
50.760,62
50.800,73
50.840,81
50.880,80
50.920,80
50.960,62
51.000,54
51.040,68
51.080,62
51.120,67
51.160,72
51.200,71
51.240,67
51.280,60
51.320,76
51.360,73
51.400,46
51.440,83
51.480,63
51.520,66
51.560,73
51.600,56
51.640,64
51.680,74
51.720,62
51.760,61
51.800,67
51.840,76
51.880,76
51.920,69
51.960,54
52.000,55
52.040,63
52.080,76
52.120,73
52.160,68
52.200,80
52.240,72
52.280,74
52.320,90
52.360,68
52.400,87
52.440,84
52.480,98
52.520,110
52.560,103
52.600,102
52.640,112
52.680,129
52.720,122
52.760,133
52.800,145
52.840,172
52.880,159
52.920,163
52.960,150
53.000,189
53.040,216
53.080,232
53.120,243
53.160,260
53.200,296
53.240,273
53.280,327
53.320,318
53.360,299
53.400,329
53.440,374
53.480,326
53.520,327
53.560,300
53.600,309
53.640,330
53.680,297
53.720,274
53.760,271
53.800,259
53.840,231
53.880,279
53.920,225
53.960,239
54.000,230
54.040,207
54.080,225
54.120,185
54.160,188
54.200,173
54.240,173
54.280,153
54.320,173
54.360,165
54.400,171
54.440,170
54.480,170
54.520,167
54.560,164
54.600,160
54.640,162
54.680,163
54.720,175
54.760,147
54.800,152
54.840,158
54.880,131
54.920,140
54.960,186
55.000,156
55.040,192
55.080,182
55.120,183
55.160,181
55.200,206
55.240,195
55.280,205
55.320,235
55.360,221
55.400,213
55.440,217
55.480,261
55.520,242
55.560,253
55.600,209
55.640,236
55.680,239
55.720,240
55.760,219
55.800,255
55.840,246
55.880,262
55.920,221
55.960,215
56.000,213
56.040,219
56.080,221
56.120,206
56.160,160
56.200,156
56.240,187
56.280,168
56.320,165
56.360,127
56.400,125
56.440,96
56.480,114
56.520,98
56.560,123
56.600,92
56.640,81
56.680,113
56.720,68
56.760,95
56.800,70
56.840,77
56.880,69
56.920,71
56.960,75
57.000,84
57.040,62
57.080,72
57.120,70
57.160,61
57.200,65
57.240,55
57.280,64
57.320,66
57.360,59
57.400,60
57.440,58
57.480,57
57.520,66
57.560,49
57.600,54
57.640,71
57.680,49
57.720,58
57.760,58
57.800,60
57.840,56
57.880,50
57.920,63
57.960,47
58.000,42
58.040,43
58.080,51
58.120,41
58.160,47
58.200,63