File: code/data/data_source2/CuSe_AlN-150w-10min-CuSe-40w-75min.csv
[Measurement conditions]
Sample identification,
Comment - 1,"Configuration=Filmes Finos 19_1_2015, Owner=User-1, Creation date=19/01/2015 21:17:15"
Comment - 2,"Goniometer=PW3050/60 (Theta/Theta); Minimum step size 2Theta:0.001; Minimum step size Omega:0.001"
Comment - 3,"Sample stage=PW3071/xx Bracket"
Comment - 4,"Diffractometer system=XPERT-PRO"
Comment - 5,"Measurement program=C:\PANalytical\Data Collector\Programs\GrazingIncidence.xrdmp, Identifier={BC538F88-BCB7-49B1-B949-146FB158B101}"
Anode material,Cu
K-Alpha1 wavelength,1.5405980
K-Alpha2 wavelength,1.5444260
Ratio K-Alpha2/K-Alpha1,0.500
Receiving slit,0.10
Monochromator used,YES
Generator voltage, 40
Tube current, 40
File date and time,17/Apr/2016 23:08
Unit cell,
h k l, 0 0 0
Scan axis,2Theta
Scan range,20.000,65.360
Scan step size,0.0200000
No. of points, 2269
Scan type,PRE-SET COUNTS
Omega,1.500
Time per step,15.00
[Scan points]
Angle,Intensity
20.000,39
20.040,46
20.080,44
20.120,39
20.160,36
20.200,39
20.240,37
20.280,38
20.320,36
20.360,36
20.400,33
20.440,51
20.480,36
20.520,43
20.560,48
20.600,33
20.640,45
20.680,40
20.720,30
20.760,48
20.800,36
20.840,26
20.880,43
20.920,36
20.960,30
21.000,31
21.040,41
21.080,29
21.120,38
21.160,34
21.200,36
21.240,40
21.280,36
21.320,30
21.360,36
21.400,40
21.440,43
21.480,29
21.520,44
21.560,31
21.600,31
21.640,38
21.680,42
21.720,37
21.760,52
21.800,37
21.840,42
21.880,45
21.920,43
21.960,41
22.000,39
22.040,39
22.080,41
22.120,40
22.160,40
22.200,33
22.240,37
22.280,43
22.320,46
22.360,31
22.400,35
22.440,32
22.480,38
22.520,25
22.560,40
22.600,47
22.640,29
22.680,45
22.720,31
22.760,36
22.800,36
22.840,56
22.880,38
22.920,38
22.960,55
23.000,44
23.040,42
23.080,37
23.120,38
23.160,40
23.200,26
23.240,57
23.280,40
23.320,42
23.360,31
23.400,43
23.440,48
23.480,43
23.520,46
23.560,35
23.600,62
23.640,47
23.680,40
23.720,53
23.760,42
23.800,32
23.840,51
23.880,41
23.920,48
23.960,52
24.000,50
24.040,52
24.080,65
24.120,56
24.160,44
24.200,50
24.240,51
24.280,63
24.320,35
24.360,52
24.400,58
24.440,68
24.480,52
24.520,59
24.560,65
24.600,53
24.640,55
24.680,55
24.720,46
24.760,66
24.800,65
24.840,60
24.880,71
24.920,42
24.960,72
25.000,70
25.040,82
25.080,76
25.120,90
25.160,77
25.200,94
25.240,95
25.280,102
25.320,124
25.360,148
25.400,191
25.440,227
25.480,286
25.520,344
25.560,490
25.600,625
25.640,767
25.680,890
25.720,929
25.760,1022
25.800,1095
25.840,1021
25.880,1026
25.920,974
25.960,975
26.000,938
26.040,862
26.080,814
26.120,825
26.160,793
26.200,824
26.240,847
26.280,846
26.320,873
26.360,823
26.400,940
26.440,973
26.480,970
26.520,1048
26.560,1142
26.600,1220
26.640,1263
26.680,1416
26.720,1561
26.760,1686
26.800,1742
26.840,1975
26.880,2155
26.920,2336
26.960,2363
27.000,2424
27.040,2411
27.080,2438
27.120,2432
27.160,2354
27.200,2149
27.240,2013
27.280,1935
27.320,1837
27.360,1810
27.400,1737
27.440,1633
27.480,1750
27.520,1682
27.560,1646
27.600,1696
27.640,1620
27.680,1639
27.720,1494
27.760,1485
27.800,1380
27.840,1341
27.880,1156
27.920,1033
27.960,937
28.000,861
28.040,745
28.080,628
28.120,546
28.160,532
28.200,462
28.240,425
28.280,386
28.320,330
28.360,352
28.400,302
28.440,276
28.480,243
28.520,239
28.560,248
28.600,226
28.640,214
28.680,220
28.720,243
28.760,192
28.800,190
28.840,202
28.880,178
28.920,184
28.960,171
29.000,190
29.040,180
29.080,185
29.120,188
29.160,190
29.200,197
29.240,187
29.280,182
29.320,179
29.360,185
29.400,178
29.440,192
29.480,204
29.520,213
29.560,216
29.600,193
29.640,229
29.680,193
29.720,201
29.760,235
29.800,207
29.840,236
29.880,236
29.920,213
29.960,199
30.000,248
30.040,227
30.080,211
30.120,212
30.160,206
30.200,222
30.240,227
30.280,205
30.320,203
30.360,194
30.400,202
30.440,188
30.480,184
30.520,178
30.560,170
30.600,137
30.640,143
30.680,173
30.720,127
30.760,129
30.800,131
30.840,138
30.880,136
30.920,112
30.960,126
31.000,105
31.040,111
31.080,106
31.120,115
31.160,93
31.200,111
31.240,86
31.280,106
31.320,74
31.360,84
31.400,82
31.440,87
31.480,91
31.520,79
31.560,77
31.600,84
31.640,83
31.680,67
31.720,87
31.760,64
31.800,95
31.840,74
31.880,86
31.920,86
31.960,73
32.000,70
32.040,94
32.080,61
32.120,61
32.160,70
32.200,66
32.240,71
32.280,72
32.320,76
32.360,70
32.400,63
32.440,51
32.480,61
32.520,69
32.560,47
32.600,73
32.640,64
32.680,60
32.720,54
32.760,70
32.800,64
32.840,59
32.880,74
32.920,69
32.960,55
33.000,69
33.040,50
33.080,64
33.120,56
33.160,62
33.200,71
33.240,57
33.280,68
33.320,70
33.360,69
33.400,72
33.440,51
33.480,53
33.520,71
33.560,61
33.600,61
33.640,58
33.680,65
33.720,60
33.760,80
33.800,62
33.840,73
33.880,66
33.920,68
33.960,51
34.000,59
34.040,63
34.080,75
34.120,65
34.160,64
34.200,60
34.240,61
34.280,77
34.320,56
34.360,70
34.400,59
34.440,59
34.480,66
34.520,60
34.560,62
34.600,70
34.640,66
34.680,47
34.720,58
34.760,58
34.800,73
34.840,77
34.880,62
34.920,74
34.960,62
35.000,67
35.040,69
35.080,75
35.120,71
35.160,65
35.200,68
35.240,73
35.280,65
35.320,66
35.360,64
35.400,74
35.440,71
35.480,60
35.520,65
35.560,54
35.600,54
35.640,50
35.680,68
35.720,61
35.760,74
35.800,70
35.840,66
35.880,63
35.920,62
35.960,61
36.000,51
36.040,76
36.080,61
36.120,57
36.160,75
36.200,73
36.240,50
36.280,58
36.320,65
36.360,69
36.400,75
36.440,56
36.480,64
36.520,66
36.560,59
36.600,91
36.640,62
36.680,64
36.720,57
36.760,52
36.800,67
36.840,70
36.880,57
36.920,61
36.960,76
37.000,72
37.040,53
37.080,47
37.120,57
37.160,48
37.200,52
37.240,55
37.280,68
37.320,53
37.360,57
37.400,52
37.440,72
37.480,78
37.520,56
37.560,57
37.600,75
37.640,55
37.680,70
37.720,50
37.760,57
37.800,47
37.840,63
37.880,53
37.920,59
37.960,71
38.000,42
38.040,58
38.080,52
38.120,60
38.160,56
38.200,61
38.240,60
38.280,65
38.320,79
38.360,43
38.400,60
38.440,55
38.480,56
38.520,52
38.560,59
38.600,64
38.640,53
38.680,50
38.720,62
38.760,70
38.800,47
38.840,54
38.880,46
38.920,74
38.960,55
39.000,61
39.040,61
39.080,52
39.120,56
39.160,60
39.200,50
39.240,46
39.280,45
39.320,49
39.360,48
39.400,47
39.440,48
39.480,56
39.520,59
39.560,62
39.600,64
39.640,54
39.680,58
39.720,57
39.760,52
39.800,54
39.840,51
39.880,65
39.920,54
39.960,56
40.000,54
40.040,63
40.080,55
40.120,59
40.160,49
40.200,46
40.240,67
40.280,52
40.320,50
40.360,68
40.400,57
40.440,45
40.480,63
40.520,60
40.560,63
40.600,43
40.640,52
40.680,50
40.720,60
40.760,55
40.800,53
40.840,61
40.880,62
40.920,37
40.960,68
41.000,54
41.040,47
41.080,69
41.120,54
41.160,58
41.200,45
41.240,53
41.280,56
41.320,47
41.360,53
41.400,64
41.440,64
41.480,55
41.520,50
41.560,48
41.600,58
41.640,61
41.680,54
41.720,54
41.760,46
41.800,50
41.840,53
41.880,61
41.920,63
41.960,50
42.000,51
42.040,57
42.080,48
42.120,62
42.160,52
42.200,54
42.240,60
42.280,46
42.320,53
42.360,55
42.400,48
42.440,69
42.480,47
42.520,55
42.560,69
42.600,68
42.640,70
42.680,60
42.720,58
42.760,50
42.800,61
42.840,55
42.880,76
42.920,52
42.960,50
43.000,57
43.040,69
43.080,58
43.120,60
43.160,60
43.200,58
43.240,64
43.280,66
43.320,50
43.360,62
43.400,64
43.440,55
43.480,53
43.520,68
43.560,63
43.600,69
43.640,73
43.680,66
43.720,71
43.760,59
43.800,72
43.840,61
43.880,57
43.920,73
43.960,87
44.000,62
44.040,62
44.080,68
44.120,76
44.160,59
44.200,86
44.240,85
44.280,72
44.320,90
44.360,80
44.400,87
44.440,98
44.480,106
44.520,91
44.560,92
44.600,115
44.640,114
44.680,139
44.720,142
44.760,165
44.800,212
44.840,222
44.880,238
44.920,270
44.960,341
45.000,449
45.040,540
45.080,650
45.120,794
45.160,858
45.200,1061
45.240,1174
45.280,1249
45.320,1294
45.360,1327
45.400,1281
45.440,1136
45.480,1057
45.520,961
45.560,775
45.600,654
45.640,520
45.680,419
45.720,344
45.760,266
45.800,238
45.840,202
45.880,210
45.920,158
45.960,144
46.000,127
46.040,105
46.080,136
46.120,92
46.160,114
46.200,113
46.240,101
46.280,107
46.320,96
46.360,125
46.400,93
46.440,83
46.480,76
46.520,85
46.560,96
46.600,101
46.640,97
46.680,91
46.720,81
46.760,90
46.800,90
46.840,79
46.880,86
46.920,78
46.960,91
47.000,106
47.040,94
47.080,76
47.120,92
47.160,81
47.200,88
47.240,89
47.280,72
47.320,90
47.360,88
47.400,92
47.440,97
47.480,100
47.520,100
47.560,105
47.600,83
47.640,87
47.680,67
47.720,88
47.760,92
47.800,90
47.840,85
47.880,107
47.920,109
47.960,73
48.000,100
48.040,99
48.080,84
48.120,99
48.160,93
48.200,97
48.240,74
48.280,88
48.320,81
48.360,72
48.400,88
48.440,102
48.480,74
48.520,83
48.560,87
48.600,84
48.640,90
48.680,88
48.720,78
48.760,89
48.800,71
48.840,65
48.880,79
48.920,91
48.960,73
49.000,70
49.040,92
49.080,75
49.120,74
49.160,77
49.200,74
49.240,78
49.280,86
49.320,61
49.360,58
49.400,69
49.440,71
49.480,74
49.520,73
49.560,66
49.600,66
49.640,70
49.680,85
49.720,71
49.760,71
49.800,70
49.840,91
49.880,65
49.920,78
49.960,75
50.000,61
50.040,58
50.080,65
50.120,62
50.160,62
50.200,56
50.240,71
50.280,78
50.320,53
50.360,81
50.400,61
50.440,70
50.480,87
50.520,47
50.560,70
50.600,62
50.640,65
50.680,60
50.720,73
50.760,53
50.800,53
50.840,71
50.880,56
50.920,88
50.960,68
51.000,75
51.040,68
51.080,66
51.120,66
51.160,52
51.200,45
51.240,64
51.280,59
51.320,68
51.360,76
51.400,59
51.440,60
51.480,61
51.520,37
51.560,61
51.600,64
51.640,47
51.680,43
51.720,53
51.760,66
51.800,56
51.840,81
51.880,59
51.920,77
51.960,77
52.000,69
52.040,65
52.080,70
52.120,52
52.160,65
52.200,81
52.240,65
52.280,88
52.320,63
52.360,78
52.400,90
52.440,80
52.480,75
52.520,101
52.560,98
52.600,77
52.640,111
52.680,104
52.720,103
52.760,131
52.800,148
52.840,148
52.880,170
52.920,142
52.960,193
53.000,212
53.040,236
53.080,275
53.120,282
53.160,308
53.200,311
53.240,357
53.280,348
53.320,374
53.360,406
53.400,399
53.440,416
53.480,424
53.520,420
53.560,360
53.600,353
53.640,339
53.680,319
53.720,310
53.760,272
53.800,267
53.840,245
53.880,216
53.920,221
53.960,199
54.000,205
54.040,216
54.080,207
54.120,184
54.160,158
54.200,177
54.240,177
54.280,143
54.320,185
54.360,141
54.400,142
54.440,155
54.480,173
54.520,153
54.560,136
54.600,165
54.640,163
54.680,173
54.720,174
54.760,165
54.800,186
54.840,225
54.880,197
54.920,180
54.960,220
55.000,202
55.040,198
55.080,191
55.120,195
55.160,201
55.200,231
55.240,196
55.280,226
55.320,234
55.360,215
55.400,239
55.440,234
55.480,246
55.520,246
55.560,225
55.600,262
55.640,247
55.680,240
55.720,208
55.760,188
55.800,218
55.840,218
55.880,225
55.920,251
55.960,193
56.000,184
56.040,197
56.080,194
56.120,178
56.160,174
56.200,151
56.240,161
56.280,163
56.320,144
56.360,132
56.400,129
56.440,118
56.480,113
56.520,88
56.560,105
56.600,97
56.640,103
56.680,98
56.720,81
56.760,70
56.800,87
56.840,109
56.880,85
56.920,68
56.960,61
57.000,74
57.040,79
57.080,71
57.120,56
57.160,66
57.200,64
57.240,61
57.280,62
57.320,60
57.360,72
57.400,44
57.440,46
57.480,55
57.520,58
57.560,42
57.600,64
57.640,53
57.680,41
57.720,47
57.760,64
57.800,57
57.840,53
57.880,51
57.920,53
57.960,39
58.000,45
58.040,58
58.080,40
58.120,36
58.160,46
58.200,60
58.240,27
58.280,44
58.320,53
58.360,35
58.400,39
58.440,45
58.480,42
58.520,42
58.560,46
58.600,49
58.640,42
58.680,35
58.720,41
58.760,31
58.800,36
58.840,31
58.880,39
58.920,42
58.960,45
59.000,41
59.040,38
59.080,32
59.120,31
59.160,33
59.200,49
59.240,31
59.280,43
59.320,57
59.360,41
59.400,45
59.440,39
59.480,44
59.520,43
59.560,34
59.600,24
59.640,33
59.680,31
59.720,32
59.760,39
59.800,38
59.840,38
59.880,35
59.920,32
59.960,30
60.000,38
60.040,35
60.080,25
60.120,37
60.160,34
60.200,30
60.240,26
60.280,39
60.320,46
60.360,41
60.400,33
60.440,30
60.480,28
60.520,32
60.560,39
60.600,28
60.640,38
60.680,26
60.720,46
60.760,31
60.800,34
60.840,30
60.880,44
60.920,30
60.960,28
61.000,40
61.040,35
61.080,25
61.120,26
61.160,36
61.200,41
61.240,25
61.280,38
61.320,36
61.360,37
61.400,34
61.440,36
61.480,29
61.520,32
61.560,31
61.600,30
61.640,30
61.680,32
61.720,22
61.760,41
61.800,31
61.840,40
61.880,30
61.920,32
61.960,37
62.000,37
62.040,30
62.080,39
62.120,30
62.160,30
62.200,38
62.240,30
62.280,27
62.320,37
62.360,26
62.400,22
62.440,28
62.480,40
62.520,32
62.560,31
62.600,40
62.640,40
62.680,28
62.720,38
62.760,30
62.800,32
62.840,24
62.880,34
62.920,32
62.960,39
63.000,42
63.040,32
63.080,40
63.120,29
63.160,27
63.200,26
63.240,30
63.280,31
63.320,37
63.360,31
63.400,24
63.440,20
63.480,36
63.520,40
63.560,34
63.600,24
63.640,32
63.680,30
63.720,25
63.760,30
63.800,33
63.840,35
63.880,27
63.920,20
63.960,28
64.000,26
64.040,22
64.080,43
64.120,25
64.160,31
64.200,32
64.240,26
64.280,26
64.320,36
64.360,21
64.400,27
64.440,49
64.480,22
64.520,33
64.560,22
64.600,24
64.640,31
64.680,35
64.720,30
64.760,30
64.800,31
64.840,30
64.880,30
64.920,48
64.960,25
65.000,36
65.040,38
65.080,34
65.120,43
65.160,33
65.200,45
65.240,28
65.280,40
65.320,34
65.360,29