File: code/data/data_source2/CuSe_ AlN-150w-10min-CuSe-30w-125min.csv
[Measurement conditions]
Sample identification,
Comment - 1,"Configuration=Filmes Finos 19_1_2015, Owner=User-1, Creation date=19/01/2015 21:17:15"
Comment - 2,"Goniometer=PW3050/60 (Theta/Theta); Minimum step size 2Theta:0.001; Minimum step size Omega:0.001"
Comment - 3,"Sample stage=PW3071/xx Bracket"
Comment - 4,"Diffractometer system=XPERT-PRO"
Comment - 5,"Measurement program=C:\PANalytical\Data Collector\Programs\GrazingIncidence.xrdmp, Identifier={56BCC7D6-C695-42C6-9FE3-F6764B4E71BD}"
Anode material,Cu
K-Alpha1 wavelength,1.5405980
K-Alpha2 wavelength,1.5444260
Ratio K-Alpha2/K-Alpha1,0.500
Receiving slit,0.10
Monochromator used,YES
Generator voltage, 40
Tube current, 40
File date and time,15/Apr/2016 14:39
Unit cell,
h k l, 0 0 0
Scan axis,2Theta
Scan range,20.000,60.000
Scan step size,0.0200000
No. of points, 2001
Scan type,PRE-SET COUNTS
Omega,1.500
Time per step,15.00
[Scan points]
Angle,Intensity
20.000,36
20.040,29
20.080,34
20.120,48
20.160,32
20.200,37
20.240,42
20.280,33
20.320,42
20.360,46
20.400,34
20.440,41
20.480,47
20.520,32
20.560,33
20.600,42
20.640,32
20.680,45
20.720,31
20.760,38
20.800,45
20.840,23
20.880,36
20.920,37
20.960,40
21.000,54
21.040,36
21.080,41
21.120,29
21.160,39
21.200,50
21.240,35
21.280,31
21.320,37
21.360,49
21.400,41
21.440,43
21.480,32
21.520,40
21.560,45
21.600,44
21.640,39
21.680,29
21.720,47
21.760,40
21.800,33
21.840,43
21.880,29
21.920,27
21.960,39
22.000,38
22.040,45
22.080,45
22.120,45
22.160,46
22.200,39
22.240,34
22.280,41
22.320,39
22.360,47
22.400,37
22.440,42
22.480,27
22.520,34
22.560,47
22.600,38
22.640,36
22.680,43
22.720,34
22.760,45
22.800,45
22.840,46
22.880,44
22.920,44
22.960,46
23.000,29
23.040,42
23.080,41
23.120,48
23.160,36
23.200,41
23.240,34
23.280,49
23.320,54
23.360,39
23.400,59
23.440,49
23.480,36
23.520,41
23.560,45
23.600,40
23.640,37
23.680,47
23.720,44
23.760,62
23.800,48
23.840,69
23.880,45
23.920,46
23.960,40
24.000,69
24.040,47
24.080,45
24.120,39
24.160,50
24.200,49
24.240,48
24.280,50
24.320,50
24.360,46
24.400,43
24.440,65
24.480,63
24.520,50
24.560,57
24.600,66
24.640,50
24.680,62
24.720,69
24.760,70
24.800,64
24.840,66
24.880,56
24.920,76
24.960,66
25.000,64
25.040,78
25.080,71
25.120,97
25.160,105
25.200,78
25.240,82
25.280,113
25.320,123
25.360,150
25.400,184
25.440,227
25.480,312
25.520,366
25.560,520
25.600,621
25.640,729
25.680,940
25.720,1018
25.760,1049
25.800,1123
25.840,1072
25.880,1121
25.920,1036
25.960,1022
26.000,1045
26.040,996
26.080,948
26.120,988
26.160,953
26.200,903
26.240,1013
26.280,1064
26.320,1029
26.360,1079
26.400,1089
26.440,1153
26.480,1193
26.520,1267
26.560,1343
26.600,1473
26.640,1549
26.680,1691
26.720,1795
26.760,1957
26.800,2185
26.840,2275
26.880,2511
26.920,2667
26.960,2751
27.000,3017
27.040,3003
27.080,3085
27.120,2991
27.160,2855
27.200,2705
27.240,2542
27.280,2270
27.320,2177
27.360,2040
27.400,2094
27.440,2041
27.480,1983
27.520,2058
27.560,2090
27.600,2046
27.640,2181
27.680,2085
27.720,2071
27.760,1921
27.800,1715
27.840,1637
27.880,1469
27.920,1404
27.960,1247
28.000,1012
28.040,929
28.080,777
28.120,687
28.160,608
28.200,536
28.240,509
28.280,450
28.320,401
28.360,352
28.400,340
28.440,319
28.480,306
28.520,288
28.560,262
28.600,236
28.640,236
28.680,236
28.720,220
28.760,220
28.800,200
28.840,190
28.880,241
28.920,192
28.960,204
29.000,189
29.040,171
29.080,197
29.120,159
29.160,169
29.200,198
29.240,187
29.280,178
29.320,178
29.360,199
29.400,210
29.440,206
29.480,196
29.520,201
29.560,190
29.600,234
29.640,201
29.680,211
29.720,214
29.760,238
29.800,242
29.840,195
29.880,223
29.920,245
29.960,241
30.000,256
30.040,235
30.080,239
30.120,216
30.160,233
30.200,236
30.240,229
30.280,218
30.320,194
30.360,204
30.400,210
30.440,206
30.480,192
30.520,204
30.560,187
30.600,178
30.640,180
30.680,181
30.720,174
30.760,152
30.800,174
30.840,139
30.880,145
30.920,133
30.960,138
31.000,141
31.040,129
31.080,136
31.120,116
31.160,115
31.200,106
31.240,103
31.280,120
31.320,110
31.360,96
31.400,117
31.440,87
31.480,95
31.520,98
31.560,91
31.600,84
31.640,94
31.680,75
31.720,98
31.760,77
31.800,70
31.840,85
31.880,70
31.920,71
31.960,63
32.000,74
32.040,79
32.080,82
32.120,85
32.160,66
32.200,84
32.240,83
32.280,71
32.320,73
32.360,59
32.400,58
32.440,81
32.480,65
32.520,56
32.560,74
32.600,88
32.640,75
32.680,59
32.720,76
32.760,60
32.800,63
32.840,77
32.880,70
32.920,62
32.960,71
33.000,67
33.040,77
33.080,79
33.120,70
33.160,62
33.200,75
33.240,59
33.280,65
33.320,60
33.360,58
33.400,50
33.440,59
33.480,55
33.520,78
33.560,75
33.600,72
33.640,68
33.680,59
33.720,59
33.760,69
33.800,73
33.840,58
33.880,64
33.920,72
33.960,47
34.000,63
34.040,79
34.080,70
34.120,75
34.160,64
34.200,72
34.240,63
34.280,55
34.320,69
34.360,85
34.400,72
34.440,64
34.480,73
34.520,66
34.560,62
34.600,74
34.640,71
34.680,54
34.720,62
34.760,69
34.800,67
34.840,58
34.880,65
34.920,77
34.960,62
35.000,70
35.040,69
35.080,60
35.120,79
35.160,49
35.200,74
35.240,69
35.280,67
35.320,59
35.360,82
35.400,65
35.440,72
35.480,58
35.520,82
35.560,67
35.600,72
35.640,72
35.680,71
35.720,74
35.760,69
35.800,70
35.840,65
35.880,64
35.920,67
35.960,63
36.000,86
36.040,53
36.080,57
36.120,53
36.160,71
36.200,62
36.240,63
36.280,68
36.320,82
36.360,63
36.400,58
36.440,57
36.480,63
36.520,53
36.560,57
36.600,78
36.640,80
36.680,73
36.720,56
36.760,60
36.800,52
36.840,56
36.880,61
36.920,64
36.960,76
37.000,83
37.040,64
37.080,65
37.120,63
37.160,56
37.200,75
37.240,59
37.280,57
37.320,60
37.360,61
37.400,51
37.440,53
37.480,65
37.520,56
37.560,61
37.600,59
37.640,57
37.680,57
37.720,62
37.760,66
37.800,58
37.840,57
37.880,36
37.920,62
37.960,48
38.000,61
38.040,53
38.080,50
38.120,56
38.160,54
38.200,53
38.240,54
38.280,68
38.320,64
38.360,57
38.400,64
38.440,57
38.480,60
38.520,56
38.560,65
38.600,60
38.640,70
38.680,62
38.720,49
38.760,40
38.800,54
38.840,42
38.880,52
38.920,67
38.960,59
39.000,59
39.040,71
39.080,59
39.120,59
39.160,62
39.200,69
39.240,69
39.280,62
39.320,53
39.360,53
39.400,59
39.440,58
39.480,48
39.520,64
39.560,63
39.600,49
39.640,57
39.680,50
39.720,64
39.760,59
39.800,68
39.840,64
39.880,40
39.920,52
39.960,55
40.000,68
40.040,53
40.080,43
40.120,63
40.160,49
40.200,62
40.240,61
40.280,63
40.320,64
40.360,59
40.400,65
40.440,42
40.480,56
40.520,65
40.560,49
40.600,64
40.640,61
40.680,44
40.720,54
40.760,49
40.800,54
40.840,49
40.880,49
40.920,66
40.960,79
41.000,55
41.040,58
41.080,73
41.120,50
41.160,46
41.200,55
41.240,41
41.280,66
41.320,73
41.360,49
41.400,65
41.440,56
41.480,45
41.520,56
41.560,47
41.600,64
41.640,63
41.680,59
41.720,50
41.760,49
41.800,50
41.840,61
41.880,70
41.920,75
41.960,73
42.000,57
42.040,50
42.080,49
42.120,64
42.160,59
42.200,62
42.240,60
42.280,57
42.320,74
42.360,61
42.400,69
42.440,51
42.480,46
42.520,65
42.560,71
42.600,66
42.640,80
42.680,56
42.720,60
42.760,70
42.800,51
42.840,75
42.880,59
42.920,66
42.960,70
43.000,71
43.040,75
43.080,60
43.120,75
43.160,66
43.200,68
43.240,52
43.280,72
43.320,65
43.360,73
43.400,64
43.440,68
43.480,80
43.520,57
43.560,81
43.600,79
43.640,80
43.680,69
43.720,94
43.760,76
43.800,72
43.840,79
43.880,70
43.920,80
43.960,87
44.000,76
44.040,85
44.080,76
44.120,76
44.160,94
44.200,89
44.240,82
44.280,83
44.320,80
44.360,101
44.400,96
44.440,111
44.480,100
44.520,117
44.560,137
44.600,132
44.640,146
44.680,176
44.720,185
44.760,223
44.800,240
44.840,288
44.880,339
44.920,459
44.960,529
45.000,679
45.040,841
45.080,1028
45.120,1214
45.160,1451
45.200,1699
45.240,1916
45.280,2122
45.320,2174
45.360,2240
45.400,2158
45.440,1947
45.480,1800
45.520,1555
45.560,1256
45.600,974
45.640,870
45.680,664
45.720,546
45.760,479
45.800,398
45.840,382
45.880,242
45.920,277
45.960,230
46.000,173
46.040,149
46.080,168
46.120,146
46.160,161
46.200,145
46.240,147
46.280,147
46.320,109
46.360,126
46.400,110
46.440,112
46.480,118
46.520,126
46.560,102
46.600,133
46.640,123
46.680,107
46.720,139
46.760,100
46.800,122
46.840,111
46.880,100
46.920,116
46.960,131
47.000,110
47.040,105
47.080,95
47.120,110
47.160,118
47.200,111
47.240,115
47.280,97
47.320,98
47.360,95
47.400,95
47.440,112
47.480,128
47.520,102
47.560,110
47.600,103
47.640,126
47.680,110
47.720,92
47.760,117
47.800,116
47.840,132
47.880,114
47.920,132
47.960,142
48.000,125
48.040,119
48.080,106
48.120,139
48.160,99
48.200,147
48.240,138
48.280,109
48.320,130
48.360,125
48.400,120
48.440,120
48.480,81
48.520,109
48.560,98
48.600,100
48.640,106
48.680,93
48.720,103
48.760,103
48.800,90
48.840,95
48.880,93
48.920,81
48.960,101
49.000,87
49.040,94
49.080,85
49.120,100
49.160,102
49.200,90
49.240,98
49.280,79
49.320,76
49.360,73
49.400,92
49.440,86
49.480,77
49.520,77
49.560,81
49.600,82
49.640,73
49.680,80
49.720,89
49.760,90
49.800,94
49.840,77
49.880,99
49.920,69
49.960,88
50.000,95
50.040,77
50.080,68
50.120,92
50.160,92
50.200,88
50.240,88
50.280,86
50.320,85
50.360,90
50.400,87
50.440,80
50.480,84
50.520,72
50.560,80
50.600,83
50.640,83
50.680,85
50.720,63
50.760,81
50.800,80
50.840,85
50.880,76
50.920,87
50.960,71
51.000,76
51.040,83
51.080,73
51.120,79
51.160,61
51.200,73
51.240,74
51.280,73
51.320,70
51.360,69
51.400,74
51.440,77
51.480,75
51.520,64
51.560,79
51.600,79
51.640,71
51.680,87
51.720,80
51.760,62
51.800,71
51.840,69
51.880,68
51.920,95
51.960,79
52.000,72
52.040,53
52.080,82
52.120,84
52.160,68
52.200,77
52.240,82
52.280,91
52.320,95
52.360,67
52.400,85
52.440,80
52.480,94
52.520,116
52.560,92
52.600,110
52.640,121
52.680,130
52.720,147
52.760,136
52.800,189
52.840,174
52.880,200
52.920,215
52.960,252
53.000,266
53.040,309
53.080,287
53.120,332
53.160,367
53.200,360
53.240,409
53.280,429
53.320,412
53.360,463
53.400,409
53.440,437
53.480,434
53.520,402
53.560,374
53.600,365
53.640,376
53.680,366
53.720,329
53.760,321
53.800,320
53.840,317
53.880,266
53.920,242
53.960,270
54.000,239
54.040,233
54.080,224
54.120,233
54.160,201
54.200,176
54.240,217
54.280,182
54.320,185
54.360,178
54.400,152
54.440,175
54.480,193
54.520,182
54.560,176
54.600,172
54.640,168
54.680,162
54.720,191
54.760,199
54.800,178
54.840,184
54.880,187
54.920,190
54.960,228
55.000,233
55.040,237
55.080,224
55.120,244
55.160,228
55.200,240
55.240,254
55.280,288
55.320,272
55.360,349
55.400,286
55.440,297
55.480,313
55.520,296
55.560,318
55.600,298
55.640,299
55.680,306
55.720,307
55.760,315
55.800,334
55.840,295
55.880,323
55.920,296
55.960,291
56.000,314
56.040,278
56.080,272
56.120,248
56.160,250
56.200,239
56.240,186
56.280,184
56.320,184
56.360,177
56.400,156
56.440,153
56.480,119
56.520,113
56.560,97
56.600,96
56.640,97
56.680,97
56.720,95
56.760,86
56.800,70
56.840,85
56.880,83
56.920,91
56.960,69
57.000,69
57.040,52
57.080,62
57.120,83
57.160,66
57.200,49
57.240,67
57.280,60
57.320,60
57.360,58
57.400,50
57.440,55
57.480,46
57.520,66
57.560,59
57.600,40
57.640,48
57.680,48
57.720,49
57.760,53
57.800,49
57.840,47
57.880,66
57.920,52
57.960,56
58.000,49
58.040,43
58.080,43
58.120,52
58.160,56
58.200,48
58.240,43
58.280,42
58.320,45
58.360,41
58.400,49
58.440,41
58.480,50
58.520,56
58.560,39
58.600,44
58.640,50
58.680,45
58.720,45
58.760,37
58.800,58
58.840,33
58.880,43
58.920,43
58.960,43
59.000,38
59.040,42
59.080,26
59.120,47
59.160,41
59.200,47
59.240,33
59.280,45
59.320,39
59.360,32
59.400,44
59.440,38
59.480,46
59.520,49
59.560,49
59.600,32
59.640,49
59.680,32
59.720,48
59.760,40
59.800,38
59.840,39
59.880,31
59.920,45
59.960,35
60.000,43