File: code/data/data_source2/CuSe_AlN-150w-10min-CuSe-60w-42min.csv
[Measurement conditions]
Sample identification,
Comment - 1,"Configuration=Filmes Finos 19_1_2015, Owner=User-1, Creation date=19/01/2015 21:17:15"
Comment - 2,"Goniometer=PW3050/60 (Theta/Theta); Minimum step size 2Theta:0.001; Minimum step size Omega:0.001"
Comment - 3,"Sample stage=PW3071/xx Bracket"
Comment - 4,"Diffractometer system=XPERT-PRO"
Comment - 5,"Measurement program=C:\PANalytical\Data Collector\Programs\GrazingIncidence.xrdmp, Identifier={BC538F88-BCB7-49B1-B949-146FB158B101}"
Anode material,Cu
K-Alpha1 wavelength,1.5405980
K-Alpha2 wavelength,1.5444260
Ratio K-Alpha2/K-Alpha1,0.500
Receiving slit,0.10
Monochromator used,YES
Generator voltage, 40
Tube current, 40
File date and time,18/Apr/2016 13:26
Unit cell,
h k l, 0 0 0
Scan axis,2Theta
Scan range,20.000,72.060
Scan step size,0.0200000
No. of points, 2604
Scan type,PRE-SET COUNTS
Omega,1.500
Time per step,15.00
[Scan points]
Angle,Intensity
20.000,33
20.040,37
20.080,40
20.120,44
20.160,32
20.200,32
20.240,37
20.280,36
20.320,40
20.360,38
20.400,38
20.440,51
20.480,50
20.520,33
20.560,26
20.600,45
20.640,40
20.680,32
20.720,43
20.760,30
20.800,34
20.840,45
20.880,52
20.920,36
20.960,45
21.000,25
21.040,37
21.080,42
21.120,44
21.160,44
21.200,41
21.240,27
21.280,50
21.320,34
21.360,51
21.400,34
21.440,33
21.480,45
21.520,44
21.560,36
21.600,29
21.640,41
21.680,33
21.720,52
21.760,34
21.800,37
21.840,28
21.880,44
21.920,48
21.960,44
22.000,34
22.040,42
22.080,42
22.120,39
22.160,41
22.200,43
22.240,45
22.280,37
22.320,50
22.360,36
22.400,43
22.440,51
22.480,42
22.520,52
22.560,38
22.600,43
22.640,52
22.680,34
22.720,41
22.760,48
22.800,44
22.840,32
22.880,29
22.920,34
22.960,43
23.000,40
23.040,46
23.080,41
23.120,41
23.160,57
23.200,33
23.240,38
23.280,55
23.320,37
23.360,51
23.400,51
23.440,45
23.480,58
23.520,26
23.560,56
23.600,41
23.640,49
23.680,51
23.720,47
23.760,51
23.800,41
23.840,42
23.880,45
23.920,43
23.960,44
24.000,50
24.040,45
24.080,43
24.120,56
24.160,52
24.200,66
24.240,55
24.280,40
24.320,53
24.360,49
24.400,67
24.440,46
24.480,56
24.520,64
24.560,55
24.600,61
24.640,63
24.680,61
24.720,55
24.760,66
24.800,66
24.840,64
24.880,70
24.920,62
24.960,71
25.000,63
25.040,69
25.080,78
25.120,73
25.160,87
25.200,83
25.240,83
25.280,92
25.320,111
25.360,110
25.400,151
25.440,188
25.480,221
25.520,249
25.560,273
25.600,379
25.640,422
25.680,510
25.720,528
25.760,594
25.800,605
25.840,620
25.880,589
25.920,620
25.960,618
26.000,568
26.040,599
26.080,575
26.120,613
26.160,602
26.200,661
26.240,675
26.280,671
26.320,692
26.360,694
26.400,743
26.440,731
26.480,789
26.520,816
26.560,938
26.600,973
26.640,1104
26.680,1199
26.720,1366
26.760,1462
26.800,1716
26.840,2040
26.880,2353
26.920,2809
26.960,3059
27.000,3279
27.040,3351
27.080,3352
27.120,3070
27.160,2725
27.200,2428
27.240,2063
27.280,1751
27.320,1550
27.360,1397
27.400,1306
27.440,1197
27.480,1105
27.520,1122
27.560,1101
27.600,1044
27.640,1078
27.680,1021
27.720,1037
27.760,985
27.800,935
27.840,840
27.880,779
27.920,688
27.960,614
28.000,597
28.040,533
28.080,446
28.120,441
28.160,351
28.200,367
28.240,324
28.280,302
28.320,254
28.360,255
28.400,238
28.440,239
28.480,211
28.520,220
28.560,230
28.600,201
28.640,203
28.680,173
28.720,184
28.760,163
28.800,164
28.840,192
28.880,146
28.920,192
28.960,150
29.000,170
29.040,169
29.080,154
29.120,168
29.160,172
29.200,191
29.240,182
29.280,184
29.320,171
29.360,167
29.400,185
29.440,149
29.480,152
29.520,189
29.560,172
29.600,180
29.640,170
29.680,187
29.720,191
29.760,201
29.800,174
29.840,203
29.880,195
29.920,217
29.960,172
30.000,213
30.040,204
30.080,183
30.120,202
30.160,205
30.200,189
30.240,172
30.280,186
30.320,223
30.360,183
30.400,153
30.440,149
30.480,161
30.520,153
30.560,138
30.600,153
30.640,158
30.680,156
30.720,141
30.760,147
30.800,134
30.840,146
30.880,128
30.920,128
30.960,132
31.000,126
31.040,124
31.080,130
31.120,109
31.160,105
31.200,109
31.240,103
31.280,95
31.320,95
31.360,100
31.400,90
31.440,82
31.480,97
31.520,90
31.560,83
31.600,84
31.640,84
31.680,82
31.720,81
31.760,74
31.800,90
31.840,86
31.880,64
31.920,75
31.960,71
32.000,65
32.040,64
32.080,74
32.120,77
32.160,76
32.200,60
32.240,83
32.280,83
32.320,82
32.360,77
32.400,66
32.440,94
32.480,54
32.520,76
32.560,64
32.600,56
32.640,63
32.680,68
32.720,65
32.760,62
32.800,76
32.840,62
32.880,62
32.920,68
32.960,73
33.000,81
33.040,62
33.080,72
33.120,74
33.160,57
33.200,69
33.240,50
33.280,60
33.320,78
33.360,54
33.400,73
33.440,69
33.480,82
33.520,71
33.560,69
33.600,70
33.640,68
33.680,57
33.720,60
33.760,73
33.800,51
33.840,73
33.880,64
33.920,61
33.960,68
34.000,81
34.040,83
34.080,70
34.120,73
34.160,65
34.200,71
34.240,68
34.280,67
34.320,55
34.360,72
34.400,77
34.440,61
34.480,55
34.520,74
34.560,59
34.600,58
34.640,51
34.680,56
34.720,64
34.760,62
34.800,30
34.840,66
34.880,61
34.920,80
34.960,65
35.000,71
35.040,56
35.080,65
35.120,49
35.160,79
35.200,64
35.240,59
35.280,68
35.320,63
35.360,77
35.400,61
35.440,58
35.480,59
35.520,73
35.560,60
35.600,79
35.640,65
35.680,62
35.720,65
35.760,66
35.800,61
35.840,57
35.880,69
35.920,67
35.960,62
36.000,66
36.040,52
36.080,68
36.120,68
36.160,58
36.200,53
36.240,64
36.280,53
36.320,53
36.360,62
36.400,68
36.440,64
36.480,57
36.520,59
36.560,56
36.600,64
36.640,58
36.680,74
36.720,58
36.760,75
36.800,56
36.840,55
36.880,52
36.920,53
36.960,68
37.000,51
37.040,70
37.080,76
37.120,64
37.160,46
37.200,57
37.240,64
37.280,49
37.320,46
37.360,54
37.400,64
37.440,56
37.480,67
37.520,61
37.560,52
37.600,45
37.640,66
37.680,53
37.720,42
37.760,62
37.800,59
37.840,56
37.880,57
37.920,62
37.960,59
38.000,63
38.040,61
38.080,58
38.120,52
38.160,66
38.200,63
38.240,62
38.280,43
38.320,54
38.360,55
38.400,56
38.440,52
38.480,49
38.520,46
38.560,44
38.600,62
38.640,69
38.680,67
38.720,62
38.760,45
38.800,59
38.840,60
38.880,47
38.920,51
38.960,68
39.000,56
39.040,49
39.080,48
39.120,61
39.160,58
39.200,58
39.240,56
39.280,63
39.320,57
39.360,54
39.400,55
39.440,58
39.480,47
39.520,58
39.560,46
39.600,58
39.640,57
39.680,68
39.720,70
39.760,61
39.800,46
39.840,34
39.880,44
39.920,54
39.960,48
40.000,59
40.040,57
40.080,57
40.120,58
40.160,51
40.200,64
40.240,46
40.280,50
40.320,59
40.360,42
40.400,58
40.440,56
40.480,54
40.520,56
40.560,63
40.600,51
40.640,64
40.680,68
40.720,42
40.760,63
40.800,52
40.840,51
40.880,37
40.920,54
40.960,56
41.000,63
41.040,54
41.080,59
41.120,50
41.160,51
41.200,53
41.240,52
41.280,50
41.320,49
41.360,49
41.400,52
41.440,55
41.480,58
41.520,58
41.560,55
41.600,54
41.640,49
41.680,68
41.720,35
41.760,63
41.800,59
41.840,50
41.880,45
41.920,52
41.960,54
42.000,42
42.040,64
42.080,55
42.120,48
42.160,53
42.200,42
42.240,71
42.280,53
42.320,51
42.360,55
42.400,55
42.440,61
42.480,69
42.520,57
42.560,54
42.600,57
42.640,52
42.680,66
42.720,54
42.760,49
42.800,57
42.840,59
42.880,38
42.920,66
42.960,58
43.000,68
43.040,49
43.080,61
43.120,61
43.160,75
43.200,55
43.240,50
43.280,59
43.320,55
43.360,56
43.400,65
43.440,65
43.480,53
43.520,61
43.560,60
43.600,57
43.640,70
43.680,67
43.720,70
43.760,60
43.800,59
43.840,67
43.880,69
43.920,77
43.960,65
44.000,72
44.040,59
44.080,76
44.120,71
44.160,78
44.200,64
44.240,89
44.280,95
44.320,76
44.360,85
44.400,99
44.440,103
44.480,116
44.520,128
44.560,135
44.600,158
44.640,169
44.680,180
44.720,240
44.760,301
44.800,374
44.840,387
44.880,472
44.920,549
44.960,679
45.000,820
45.040,783
45.080,983
45.120,998
45.160,1061
45.200,1019
45.240,1058
45.280,1023
45.320,909
45.360,906
45.400,815
45.440,774
45.480,644
45.520,571
45.560,485
45.600,373
45.640,307
45.680,269
45.720,226
45.760,190
45.800,158
45.840,169
45.880,169
45.920,134
45.960,114
46.000,129
46.040,126
46.080,103
46.120,97
46.160,110
46.200,78
46.240,99
46.280,80
46.320,88
46.360,102
46.400,87
46.440,81
46.480,98
46.520,81
46.560,83
46.600,95
46.640,104
46.680,71
46.720,94
46.760,100
46.800,100
46.840,91
46.880,90
46.920,82
46.960,67
47.000,70
47.040,78
47.080,84
47.120,60
47.160,94
47.200,73
47.240,85
47.280,76
47.320,90
47.360,88
47.400,95
47.440,91
47.480,95
47.520,64
47.560,79
47.600,87
47.640,81
47.680,83
47.720,79
47.760,77
47.800,77
47.840,79
47.880,100
47.920,94
47.960,64
48.000,84
48.040,109
48.080,92
48.120,66
48.160,90
48.200,106
48.240,94
48.280,86
48.320,105
48.360,62
48.400,100
48.440,84
48.480,85
48.520,86
48.560,89
48.600,82
48.640,78
48.680,75
48.720,82
48.760,80
48.800,95
48.840,89
48.880,92
48.920,77
48.960,99
49.000,71
49.040,75
49.080,69
49.120,76
49.160,69
49.200,81
49.240,75
49.280,61
49.320,66
49.360,62
49.400,83
49.440,76
49.480,76
49.520,69
49.560,77
49.600,72
49.640,66
49.680,83
49.720,70
49.760,69
49.800,77
49.840,62
49.880,83
49.920,61
49.960,65
50.000,78
50.040,72
50.080,75
50.120,64
50.160,74
50.200,83
50.240,62
50.280,65
50.320,73
50.360,79
50.400,55
50.440,66
50.480,49
50.520,64
50.560,70
50.600,78
50.640,82
50.680,68
50.720,72
50.760,75
50.800,68
50.840,68
50.880,64
50.920,70
50.960,78
51.000,74
51.040,70
51.080,69
51.120,68
51.160,75
51.200,62
51.240,58
51.280,64
51.320,69
51.360,64
51.400,68
51.440,61
51.480,54
51.520,45
51.560,63
51.600,66
51.640,71
51.680,84
51.720,56
51.760,64
51.800,52
51.840,70
51.880,64
51.920,73
51.960,65
52.000,92
52.040,58
52.080,68
52.120,71
52.160,72
52.200,70
52.240,64
52.280,91
52.320,74
52.360,103
52.400,102
52.440,102
52.480,109
52.520,101
52.560,122
52.600,123
52.640,149
52.680,163
52.720,151
52.760,176
52.800,202
52.840,194
52.880,248
52.920,257
52.960,278
53.000,327
53.040,358
53.080,401
53.120,401
53.160,455
53.200,485
53.240,471
53.280,530
53.320,536
53.360,561
53.400,522
53.440,554
53.480,458
53.520,437
53.560,443
53.600,423
53.640,335
53.680,319
53.720,342
53.760,323
53.800,276
53.840,271
53.880,242
53.920,244
53.960,248
54.000,219
54.040,215
54.080,217
54.120,214
54.160,198
54.200,177
54.240,179
54.280,156
54.320,177
54.360,201
54.400,184
54.440,177
54.480,185
54.520,166
54.560,151
54.600,165
54.640,169
54.680,172
54.720,181
54.760,181
54.800,228
54.840,194
54.880,233
54.920,227
54.960,235
55.000,254
55.040,268
55.080,211
55.120,241
55.160,219
55.200,241
55.240,266
55.280,236
55.320,231
55.360,254
55.400,258
55.440,233
55.480,254
55.520,284
55.560,288
55.600,275
55.640,258
55.680,283
55.720,292
55.760,282
55.800,232
55.840,268
55.880,252
55.920,256
55.960,222
56.000,227
56.040,194
56.080,195
56.120,188
56.160,170
56.200,179
56.240,182
56.280,175
56.320,139
56.360,156
56.400,143
56.440,125
56.480,127
56.520,110
56.560,99
56.600,110
56.640,94
56.680,108
56.720,96
56.760,94
56.800,90
56.840,80
56.880,90
56.920,72
56.960,90
57.000,64
57.040,70
57.080,72
57.120,72
57.160,67
57.200,76
57.240,63
57.280,74
57.320,64
57.360,65
57.400,56
57.440,54
57.480,60
57.520,44
57.560,55
57.600,65
57.640,62
57.680,61
57.720,54
57.760,58
57.800,62
57.840,44
57.880,43
57.920,68
57.960,39
58.000,48
58.040,48
58.080,37
58.120,41
58.160,43
58.200,50
58.240,47
58.280,38
58.320,48
58.360,51
58.400,51
58.440,41
58.480,39
58.520,50
58.560,42
58.600,47
58.640,38
58.680,38
58.720,33
58.760,42
58.800,33
58.840,31
58.880,32
58.920,36
58.960,34
59.000,36
59.040,37
59.080,33
59.120,35
59.160,44
59.200,38
59.240,40
59.280,35
59.320,34
59.360,34
59.400,43
59.440,36
59.480,43
59.520,38
59.560,28
59.600,48
59.640,47
59.680,35
59.720,40
59.760,19
59.800,28
59.840,30
59.880,35
59.920,38
59.960,39
60.000,38
60.040,35
60.080,34
60.120,29
60.160,37
60.200,31
60.240,46
60.280,36
60.320,40
60.360,39
60.400,35
60.440,47
60.480,34
60.520,36
60.560,38
60.600,35
60.640,31
60.680,32
60.720,28
60.760,30
60.800,28
60.840,26
60.880,29
60.920,26
60.960,28
61.000,29
61.040,29
61.080,33
61.120,34
61.160,30
61.200,35
61.240,28
61.280,36
61.320,43
61.360,39
61.400,41
61.440,26
61.480,37
61.520,30
61.560,20
61.600,40
61.640,33
61.680,24
61.720,31
61.760,32
61.800,34
61.840,26
61.880,28
61.920,25
61.960,19
62.000,27
62.040,31
62.080,17
62.120,22
62.160,33
62.200,31
62.240,23
62.280,24
62.320,25
62.360,27
62.400,33
62.440,34
62.480,31
62.520,32
62.560,24
62.600,42
62.640,30
62.680,33
62.720,32
62.760,38
62.800,25
62.840,30
62.880,20
62.920,32
62.960,22
63.000,27
63.040,37
63.080,31
63.120,29
63.160,20
63.200,21
63.240,24
63.280,42
63.320,34
63.360,37
63.400,33
63.440,24
63.480,21
63.520,31
63.560,22
63.600,30
63.640,27
63.680,31
63.720,24
63.760,18
63.800,28
63.840,16
63.880,35
63.920,27
63.960,30
64.000,28
64.040,20
64.080,35
64.120,26
64.160,29
64.200,34
64.240,21
64.280,28
64.320,24
64.360,18
64.400,19
64.440,27
64.480,26
64.520,25
64.560,34
64.600,26
64.640,22
64.680,28
64.720,31
64.760,32
64.800,27
64.840,35
64.880,37
64.920,29
64.960,33
65.000,28
65.040,46
65.080,31
65.120,29
65.160,28
65.200,25
65.240,35
65.280,34
65.320,33
65.360,33
65.400,37
65.440,30
65.480,30
65.520,31
65.560,41
65.600,32
65.640,25
65.680,45
65.720,28
65.760,32
65.800,30
65.840,28
65.880,39
65.920,24
65.960,39
66.000,33
66.040,41
66.080,34
66.120,43
66.160,30
66.200,34
66.240,38
66.280,27
66.320,32
66.360,18
66.400,29
66.440,31
66.480,16
66.520,35
66.560,37
66.600,47
66.640,19
66.680,31
66.720,36
66.760,28
66.800,30
66.840,36
66.880,26
66.920,31
66.960,36
67.000,17
67.040,33
67.080,32
67.120,36
67.160,26
67.200,29
67.240,35
67.280,30
67.320,30
67.360,31
67.400,29
67.440,24
67.480,24
67.520,34
67.560,34
67.600,30
67.640,31
67.680,23
67.720,23
67.760,33
67.800,29
67.840,25
67.880,30
67.920,26
67.960,24
68.000,30
68.040,35
68.080,20
68.120,34
68.160,28
68.200,22
68.240,20
68.280,28
68.320,34
68.360,38
68.400,33
68.440,34
68.480,33
68.520,41
68.560,29
68.600,29
68.640,21
68.680,33
68.720,37
68.760,32
68.800,31
68.840,23
68.880,36
68.920,32
68.960,27
69.000,31
69.040,27
69.080,31
69.120,21
69.160,26
69.200,27
69.240,30
69.280,31
69.320,30
69.360,44
69.400,32
69.440,30
69.480,32
69.520,38
69.560,31
69.600,30
69.640,39
69.680,25
69.720,28
69.760,30
69.800,38
69.840,42
69.880,35
69.920,32
69.960,25
70.000,34
70.040,41
70.080,25
70.120,34
70.160,28
70.200,27
70.240,41
70.280,38
70.320,33
70.360,29
70.400,32
70.440,28
70.480,35
70.520,27
70.560,33
70.600,37
70.640,38
70.680,25
70.720,30
70.760,38
70.800,32
70.840,33
70.880,37
70.920,26
70.960,28
71.000,33
71.040,36
71.080,26
71.120,45
71.160,37
71.200,27
71.240,44
71.280,43
71.320,34
71.360,42
71.400,36
71.440,33
71.480,44
71.520,40
71.560,39
71.600,34
71.640,40
71.680,44
71.720,45
71.760,55
71.800,44
71.840,44
71.880,49
71.920,66
71.960,57
72.000,65
72.040,58
72.060,86