File: code/data/data_source2/CuSe_AlN-150w-10min-CuSe-50w-56min.csv
[Measurement conditions]
Sample identification,
Comment - 1,"Configuration=Filmes Finos 19_1_2015, Owner=User-1, Creation date=19/01/2015 21:17:15"
Comment - 2,"Goniometer=PW3050/60 (Theta/Theta); Minimum step size 2Theta:0.001; Minimum step size Omega:0.001"
Comment - 3,"Sample stage=PW3071/xx Bracket"
Comment - 4,"Diffractometer system=XPERT-PRO"
Comment - 5,"Measurement program=C:\PANalytical\Data Collector\Programs\GrazingIncidence.xrdmp, Identifier={8896175C-48FC-408B-8D34-A480C2183984}"
Anode material,Cu
K-Alpha1 wavelength,1.5405980
K-Alpha2 wavelength,1.5444260
Ratio K-Alpha2/K-Alpha1,0.500
Receiving slit,0.10
Monochromator used,YES
Generator voltage, 40
Tube current, 40
File date and time,16/Apr/2016 20:34
Unit cell,
h k l, 0 0 0
Scan axis,2Theta
Scan range,20.000,83.000
Scan step size,0.0200000
No. of points, 3151
Scan type,PRE-SET COUNTS
Omega,1.500
Time per step,15.00
[Scan points]
Angle,Intensity
20.000,32
20.060,37
20.120,45
20.180,26
20.240,45
20.300,26
20.360,40
20.420,38
20.480,36
20.540,27
20.600,42
20.660,47
20.720,36
20.780,36
20.840,47
20.900,36
20.960,45
21.020,31
21.080,33
21.140,38
21.200,39
21.260,38
21.320,32
21.380,42
21.440,27
21.500,37
21.560,49
21.620,36
21.680,40
21.740,32
21.800,31
21.860,42
21.920,30
21.980,40
22.040,39
22.100,32
22.160,38
22.220,50
22.280,40
22.340,27
22.400,37
22.460,44
22.520,33
22.580,35
22.640,38
22.700,30
22.760,43
22.820,42
22.880,47
22.940,36
23.000,35
23.060,33
23.120,48
23.180,36
23.240,49
23.300,46
23.360,42
23.420,45
23.480,49
23.540,39
23.600,36
23.660,42
23.720,46
23.780,44
23.840,40
23.900,43
23.960,40
24.020,53
24.080,50
24.140,37
24.200,41
24.260,64
24.320,44
24.380,49
24.440,58
24.500,53
24.560,45
24.620,52
24.680,48
24.740,50
24.800,60
24.860,53
24.920,72
24.980,68
25.040,60
25.100,72
25.160,77
25.220,92
25.280,96
25.340,121
25.400,173
25.460,240
25.520,337
25.580,499
25.640,727
25.700,851
25.760,953
25.820,982
25.880,996
25.940,930
26.000,875
26.060,865
26.120,797
26.180,848
26.240,791
26.300,848
26.360,895
26.420,977
26.480,1020
26.540,1166
26.600,1308
26.660,1413
26.720,1583
26.780,1848
26.840,2101
26.900,2299
26.960,2666
27.020,2802
27.080,2754
27.140,2517
27.200,2207
27.260,2051
27.320,1797
27.380,1632
27.440,1616
27.500,1580
27.560,1540
27.620,1474
27.680,1402
27.740,1408
27.800,1286
27.860,1090
27.920,954
27.980,809
28.040,674
28.100,527
28.160,471
28.220,353
28.280,326
28.340,298
28.400,264
28.460,254
28.520,217
28.580,230
28.640,201
28.700,174
28.760,189
28.820,162
28.880,188
28.940,136
29.000,154
29.060,155
29.120,169
29.180,137
29.240,149
29.300,178
29.360,161
29.420,139
29.480,192
29.540,161
29.600,170
29.660,160
29.720,205
29.780,198
29.840,203
29.900,178
29.960,188
30.020,173
30.080,208
30.140,204
30.200,211
30.260,182
30.320,210
30.380,175
30.440,169
30.500,175
30.560,143
30.620,147
30.680,130
30.740,134
30.800,123
30.860,127
30.920,108
30.980,107
31.040,118
31.100,95
31.160,101
31.220,99
31.280,94
31.340,93
31.400,85
31.460,71
31.520,64
31.580,93
31.640,89
31.700,81
31.760,62
31.820,63
31.880,64
31.940,58
32.000,67
32.060,62
32.120,68
32.180,61
32.240,56
32.300,67
32.360,66
32.420,69
32.480,49
32.540,50
32.600,66
32.660,54
32.720,54
32.780,63
32.840,71
32.900,71
32.960,59
33.020,62
33.080,74
33.140,51
33.200,56
33.260,58
33.320,50
33.380,44
33.440,72
33.500,67
33.560,52
33.620,73
33.680,59
33.740,65
33.800,52
33.860,61
33.920,62
33.980,55
34.040,61
34.100,56
34.160,55
34.220,71
34.280,69
34.340,69
34.400,64
34.460,59
34.520,57
34.580,56
34.640,58
34.700,50
34.760,46
34.820,64
34.880,62
34.940,57
35.000,54
35.060,45
35.120,61
35.180,75
35.240,58
35.300,47
35.360,57
35.420,57
35.480,59
35.540,58
35.600,67
35.660,53
35.720,50
35.780,52
35.840,51
35.900,69
35.960,68
36.020,57
36.080,76
36.140,53
36.200,56
36.260,56
36.320,68
36.380,60
36.440,51
36.500,67
36.560,52
36.620,63
36.680,55
36.740,57
36.800,45
36.860,65
36.920,56
36.980,60
37.040,56
37.100,65
37.160,60
37.220,56
37.280,64
37.340,73
37.400,62
37.460,59
37.520,58
37.580,59
37.640,57
37.700,56
37.760,52
37.820,49
37.880,55
37.940,58
38.000,62
38.060,69
38.120,48
38.180,51
38.240,52
38.300,59
38.360,63
38.420,61
38.480,56
38.540,62
38.600,52
38.660,51
38.720,54
38.780,56
38.840,59
38.900,54
38.960,44
39.020,53
39.080,43
39.140,43
39.200,53
39.260,66
39.320,60
39.380,57
39.440,51
39.500,42
39.560,43
39.620,53
39.680,53
39.740,64
39.800,58
39.860,53
39.920,53
39.980,58
40.040,57
40.100,56
40.160,62
40.220,64
40.280,58
40.340,54
40.400,43
40.460,48
40.520,52
40.580,39
40.640,53
40.700,56
40.760,57
40.820,68
40.880,47
40.940,49
41.000,49
41.060,55
41.120,52
41.180,53
41.240,52
41.300,52
41.360,48
41.420,48
41.480,65
41.540,44
41.600,41
41.660,48
41.720,61
41.780,50
41.840,56
41.900,60
41.960,44
42.020,52
42.080,48
42.140,57
42.200,45
42.260,65
42.320,50
42.380,43
42.440,49
42.500,56
42.560,57
42.620,68
42.680,47
42.740,67
42.800,54
42.860,69
42.920,71
42.980,70
43.040,63
43.100,60
43.160,76
43.220,65
43.280,64
43.340,63
43.400,48
43.460,67
43.520,71
43.580,59
43.640,64
43.700,76
43.760,59
43.820,66
43.880,79
43.940,62
44.000,79
44.060,85
44.120,74
44.180,92
44.240,86
44.300,77
44.360,96
44.420,94
44.480,86
44.540,124
44.600,118
44.660,159
44.720,181
44.780,224
44.840,293
44.900,404
44.960,526
45.020,673
45.080,945
45.140,1217
45.200,1525
45.260,1724
45.320,1957
45.380,1872
45.440,1782
45.500,1523
45.560,1132
45.620,850
45.680,595
45.740,441
45.800,323
45.860,276
45.920,209
45.980,199
46.040,145
46.100,122
46.160,115
46.220,119
46.280,106
46.340,100
46.400,104
46.460,81
46.520,101
46.580,114
46.640,116
46.700,103
46.760,115
46.820,99
46.880,96
46.940,85
47.000,84
47.060,112
47.120,84
47.180,85
47.240,99
47.300,82
47.360,74
47.420,106
47.480,97
47.540,105
47.600,86
47.660,83
47.720,98
47.780,84
47.840,94
47.900,103
47.960,93
48.020,104
48.080,94
48.140,105
48.200,97
48.260,102
48.320,95
48.380,108
48.440,101
48.500,79
48.560,96
48.620,90
48.680,82
48.740,70
48.800,79
48.860,79
48.920,76
48.980,67
49.040,84
49.100,87
49.160,83
49.220,80
49.280,53
49.340,83
49.400,75
49.460,68
49.520,77
49.580,81
49.640,74
49.700,65
49.760,69
49.820,75
49.880,78
49.940,78
50.000,69
50.060,87
50.120,70
50.180,73
50.240,75
50.300,73
50.360,70
50.420,62
50.480,73
50.540,76
50.600,70
50.660,80
50.720,63
50.780,62
50.840,67
50.900,64
50.960,54
51.020,70
51.080,54
51.140,72
51.200,54
51.260,69
51.320,51
51.380,54
51.440,48
51.500,61
51.560,56
51.620,58
51.680,60
51.740,66
51.800,66
51.860,61
51.920,53
51.980,72
52.040,59
52.100,62
52.160,56
52.220,66
52.280,64
52.340,71
52.400,71
52.460,90
52.520,69
52.580,79
52.640,101
52.700,114
52.760,136
52.820,160
52.880,148
52.940,180
53.000,262
53.060,239
53.120,277
53.180,346
53.240,338
53.300,347
53.360,377
53.420,380
53.480,363
53.540,400
53.600,354
53.660,323
53.720,244
53.780,221
53.840,251
53.900,241
53.960,218
54.020,193
54.080,190
54.140,165
54.200,165
54.260,194
54.320,148
54.380,148
54.440,166
54.500,163
54.560,174
54.620,172
54.680,177
54.740,216
54.800,232
54.860,222
54.920,216
54.980,189
55.040,225
55.100,208
55.160,212
55.220,213
55.280,254
55.340,264
55.400,247
55.460,275
55.520,277
55.580,285
55.640,277
55.700,284
55.760,251
55.820,263
55.880,233
55.940,247
56.000,205
56.060,192
56.120,195
56.180,188
56.240,151
56.300,141
56.360,131
56.420,129
56.480,117
56.540,101
56.600,106
56.660,119
56.720,99
56.780,85
56.840,88
56.900,81
56.960,66
57.020,64
57.080,78
57.140,70
57.200,66
57.260,68
57.320,76
57.380,52
57.440,58
57.500,60
57.560,54
57.620,57
57.680,62
57.740,47
57.800,54
57.860,33
57.920,41
57.980,44
58.040,51
58.100,42
58.160,51
58.220,42
58.280,52
58.340,43
58.400,41
58.460,37
58.520,46
58.580,41
58.640,44
58.700,43
58.760,34
58.820,47
58.880,39
58.940,34
59.000,32
59.060,36
59.120,48
59.180,41
59.240,41
59.300,38
59.360,36
59.420,29
59.480,37
59.540,40
59.600,45
59.660,37
59.720,32
59.780,44
59.840,50
59.900,33
59.960,33
60.020,30
60.080,36
60.140,37
60.200,49
60.260,45
60.320,41
60.380,36
60.440,36
60.500,27
60.560,23
60.620,35
60.680,31
60.740,34
60.800,25
60.860,28
60.920,37
60.980,32
61.040,35
61.100,35
61.160,25
61.220,38
61.280,28
61.340,22
61.400,35
61.460,30
61.520,46
61.580,31
61.640,39
61.700,35
61.760,42
61.820,27
61.880,24
61.940,36
62.000,36
62.060,23
62.120,31
62.180,32
62.240,24
62.300,33
62.360,26
62.420,31
62.480,37
62.540,27
62.600,41
62.660,38
62.720,26
62.780,29
62.840,28
62.900,38
62.960,45
63.020,33
63.080,37
63.140,29
63.200,32
63.260,32
63.320,22
63.380,30
63.440,35
63.500,29
63.560,20
63.620,25
63.680,26
63.740,23
63.800,23
63.860,33
63.920,28
63.980,28
64.040,31
64.100,37
64.160,24
64.220,40
64.280,32
64.340,30
64.400,33
64.460,28
64.520,31
64.580,31
64.640,32
64.700,32
64.760,21
64.820,28
64.880,37
64.940,32
65.000,33
65.060,29
65.120,29
65.180,32
65.240,34
65.300,32
65.360,37
65.420,38
65.480,40
65.540,34
65.600,60
65.660,44
65.720,40
65.780,39
65.840,43
65.900,42
65.960,37
66.020,28
66.080,35
66.140,40
66.200,42
66.260,35
66.320,37
66.380,30
66.440,38
66.500,29
66.560,30
66.620,34
66.680,36
66.740,39
66.800,34
66.860,40
66.920,49
66.980,40
67.040,29
67.100,28
67.160,38
67.220,38
67.280,47
67.340,32
67.400,34
67.460,29
67.520,30
67.580,33
67.640,29
67.700,25
67.760,39
67.820,35
67.880,29
67.940,31
68.000,37
68.060,35
68.120,32
68.180,32
68.240,48
68.300,37
68.360,30
68.420,35
68.480,34
68.540,37
68.600,39
68.660,34
68.720,35
68.780,34
68.840,30
68.900,35
68.960,44
69.020,36
69.080,38
69.140,35
69.200,49
69.260,44
69.320,41
69.380,45
69.440,41
69.500,45
69.560,42
69.620,50
69.680,46
69.740,49
69.800,56
69.860,50
69.920,45
69.980,54
70.040,49
70.100,52
70.160,48
70.220,37
70.280,29
70.340,46
70.400,53
70.460,47
70.520,35
70.580,36
70.640,28
70.700,37
70.760,45
70.820,32
70.880,69
70.940,38
71.000,27
71.060,48
71.120,44
71.180,30
71.240,40
71.300,30
71.360,41
71.420,41
71.480,27
71.540,46
71.600,39
71.660,52
71.720,45
71.780,74
71.840,53
71.900,62
71.960,46
72.020,52
72.080,77
72.140,68
72.200,82
72.260,68
72.320,57
72.380,107
72.440,87
72.500,98
72.560,81
72.620,90
72.680,111
72.740,88
72.800,109
72.860,96
72.920,94
72.980,75
73.040,114
73.100,101
73.160,90
73.220,89
73.280,90
73.340,67
73.400,73
73.460,76
73.520,72
73.580,70
73.640,67
73.700,62
73.760,64
73.820,70
73.880,49
73.940,67
74.000,54
74.060,39
74.120,47
74.180,39
74.240,33
74.300,46
74.360,32
74.420,56
74.480,60
74.540,47
74.600,43
74.660,61
74.720,50
74.780,42
74.840,35
74.900,40
74.960,37
75.020,41
75.080,46
75.140,43
75.200,42
75.260,32
75.320,35
75.380,34
75.440,38
75.500,41
75.560,32
75.620,37
75.680,33
75.740,39
75.800,48
75.860,39
75.920,43
75.980,42
76.040,29
76.100,36
76.160,33
76.220,39
76.280,52
76.340,37
76.400,37
76.460,42
76.520,50
76.580,38
76.640,38
76.700,33
76.760,32
76.820,28
76.880,26
76.940,33
77.000,44
77.060,45
77.120,31
77.180,55
77.240,38
77.300,42
77.360,49
77.420,32
77.480,34
77.540,38
77.600,38
77.660,47
77.720,48
77.780,33
77.840,48
77.900,39
77.960,46
78.020,41
78.080,38
78.140,46
78.200,43
78.260,45
78.320,41
78.380,41
78.440,39
78.500,39
78.560,42
78.620,39
78.680,32
78.740,42
78.800,37
78.860,35
78.920,41
78.980,33
79.040,52
79.100,37
79.160,31
79.220,47
79.280,47
79.340,39
79.400,34
79.460,42
79.520,43
79.580,44
79.640,27
79.700,31
79.760,30
79.820,41
79.880,43
79.940,45
80.000,48
80.060,43
80.120,36
80.180,44
80.240,33
80.300,45
80.360,44
80.420,55
80.480,60
80.540,33
80.600,55
80.660,44
80.720,51
80.780,49
80.840,49
80.900,40
80.960,56
81.020,48
81.080,41
81.140,48
81.200,59
81.260,31
81.320,54
81.380,48
81.440,57
81.500,43
81.560,42
81.620,33
81.680,44
81.740,35
81.800,50
81.860,47
81.920,50
81.980,35
82.040,43
82.100,35
82.160,43
82.220,40
82.280,41
82.340,43
82.400,45
82.460,54
82.520,37
82.580,41
82.640,52
82.700,52
82.760,55
82.820,57
82.880,64
82.940,54
83.000,52