File: code/data/data_source2/Ti_GIXRD - Ti-HA - 120W - 90 min - Z=30mm - TT=400C.csv
[Measurement conditions]
Sample identification,
Comment - 1,"Configuration=Filmes Finos 19_1_2015, Owner=User-1, Creation date=19/01/2015 21:17:15"
Comment - 2,"Goniometer=PW3050/60 (Theta/Theta); Minimum step size 2Theta:0.001; Minimum step size Omega:0.001"
Comment - 3,"Sample stage=PW3071/xx Bracket"
Comment - 4,"Diffractometer system=XPERT-PRO"
Comment - 5,"Measurement program=C:\PANalytical\Data Collector\Programs\GraizingIncidence.xrdmp, Identifier={915FE0EE-E051-482C-A849-DA9D0519CF47}"
Anode material,Cu
K-Alpha1 wavelength,1.5405980
K-Alpha2 wavelength,1.5444260
Ratio K-Alpha2/K-Alpha1,0.500
Divergence slit,Fixed,0.76mm
Receiving slit,0.10
Monochromator used,YES
Generator voltage, 40
Tube current, 40
File date and time,17/Mar/2015 14:58
Unit cell,
h k l, 0 0 0
Scan axis,2Theta
Scan range,8.0000,55.0000
Scan step size,0.0500000
No. of points, 940
Scan type,CONTINUOUS
Omega,2.000
Time per step,10.00
[Scan points]
Angle,Intensity
8.0250,21.0
8.0750,14.0
8.1250,21.0
8.1750,24.0
8.2250,21.0
8.2750,17.0
8.3250,14.0
8.3750,18.0
8.4250,19.0
8.4750,9.0
8.5250,17.0
8.5750,16.0
8.6250,18.0
8.6750,24.0
8.7250,12.0
8.7750,13.0
8.8250,25.0
8.8750,14.0
8.9250,13.0
8.9750,18.0
9.0250,17.0
9.0750,15.0
9.1250,17.0
9.1750,15.0
9.2250,19.0
9.2750,20.0
9.3250,21.0
9.3750,7.0
9.4250,15.0
9.4750,9.0
9.5250,10.0
9.5750,13.0
9.6250,12.0
9.6750,13.0
9.7250,14.0
9.7750,14.0
9.8250,21.0
9.8750,14.0
9.9250,9.0
9.9750,18.0
10.0250,13.0
10.0750,24.0
10.1250,8.0
10.1750,18.0
10.2250,13.0
10.2750,11.0
10.3250,12.0
10.3750,10.0
10.4250,16.0
10.4750,11.0
10.5250,15.0
10.5750,17.0
10.6250,10.0
10.6750,9.0
10.7250,15.0
10.7750,15.0
10.8250,14.0
10.8750,13.0
10.9250,21.0
10.9750,18.0
11.0250,18.0
11.0750,13.0
11.1250,12.0
11.1750,14.0
11.2250,9.0
11.2750,15.0
11.3250,15.0
11.3750,10.0
11.4250,13.0
11.4750,4.0
11.5250,14.0
11.5750,9.0
11.6250,11.0
11.6750,10.0
11.7250,10.0
11.7750,7.0
11.8250,10.0
11.8750,11.0
11.9250,9.0
11.9750,10.0
12.0250,8.0
12.0750,9.0
12.1250,11.0
12.1750,12.0
12.2250,13.0
12.2750,9.0
12.3250,12.0
12.3750,11.0
12.4250,10.0
12.4750,8.0
12.5250,11.0
12.5750,16.0
12.6250,11.0
12.6750,9.0
12.7250,11.0
12.7750,9.0
12.8250,6.0
12.8750,9.0
12.9250,5.0
12.9750,7.0
13.0250,2.0
13.0750,10.0
13.1250,10.0
13.1750,8.0
13.2250,18.0
13.2750,10.0
13.3250,9.0
13.3750,4.0
13.4250,14.0
13.4750,10.0
13.5250,17.0
13.5750,11.0
13.6250,18.0
13.6750,13.0
13.7250,8.0
13.7750,14.0
13.8250,9.0
13.8750,12.0
13.9250,6.0
13.9750,5.0
14.0250,9.0
14.0750,5.0
14.1250,7.0
14.1750,9.0
14.2250,9.0
14.2750,13.0
14.3250,14.0
14.3750,12.0
14.4250,8.0
14.4750,7.0
14.5250,5.0
14.5750,8.0
14.6250,12.0
14.6750,13.0
14.7250,17.0
14.7750,9.0
14.8250,11.0
14.8750,5.0
14.9250,3.0
14.9750,8.0
15.0250,7.0
15.0750,9.0
15.1250,8.0
15.1750,15.0
15.2250,13.0
15.2750,8.0
15.3250,11.0
15.3750,12.0
15.4250,11.0
15.4750,12.0
15.5250,9.0
15.5750,15.0
15.6250,12.0
15.6750,11.0
15.7250,4.0
15.7750,4.0
15.8250,7.0
15.8750,7.0
15.9250,5.0
15.9750,10.0
16.0250,5.0
16.0750,6.0
16.1250,12.0
16.1750,8.0
16.2250,9.0
16.2750,9.0
16.3250,5.0
16.3750,10.0
16.4250,10.0
16.4750,8.0
16.5250,10.0
16.5750,10.0
16.6250,12.0
16.6750,5.0
16.7250,7.0
16.7750,13.0
16.8250,11.0
16.8750,11.0
16.9250,15.0
16.9750,7.0
17.0250,14.0
17.0750,10.0
17.1250,8.0
17.1750,4.0
17.2250,10.0
17.2750,14.0
17.3250,8.0
17.3750,4.0
17.4250,8.0
17.4750,7.0
17.5250,8.0
17.5750,10.0
17.6250,11.0
17.6750,9.0
17.7250,10.0
17.7750,5.0
17.8250,6.0
17.8750,8.0
17.9250,7.0
17.9750,9.0
18.0250,6.0
18.0750,7.0
18.1250,11.0
18.1750,9.0
18.2250,8.0
18.2750,6.0
18.3250,6.0
18.3750,7.0
18.4250,4.0
18.4750,7.0
18.5250,10.0
18.5750,7.0
18.6250,7.0
18.6750,9.0
18.7250,11.0
18.7750,7.0
18.8250,4.0
18.8750,7.0
18.9250,6.0
18.9750,2.0
19.0250,5.0
19.0750,10.0
19.1250,11.0
19.1750,7.0
19.2250,8.0
19.2750,10.0
19.3250,6.0
19.3750,10.0
19.4250,9.0
19.4750,6.0
19.5250,4.0
19.5750,8.0
19.6250,5.0
19.6750,6.0
19.7250,5.0
19.7750,5.0
19.8250,5.0
19.8750,10.0
19.9250,9.0
19.9750,9.0
20.0250,7.0
20.0750,11.0
20.1250,9.0
20.1750,3.0
20.2250,6.0
20.2750,4.0
20.3250,4.0
20.3750,8.0
20.4250,6.0
20.4750,5.0
20.5250,4.0
20.5750,5.0
20.6250,6.0
20.6750,6.0
20.7250,4.0
20.7750,8.0
20.8250,4.0
20.8750,8.0
20.9250,9.0
20.9750,10.0
21.0250,4.0
21.0750,3.0
21.1250,5.0
21.1750,3.0
21.2250,6.0
21.2750,7.0
21.3250,8.0
21.3750,10.0
21.4250,7.0
21.4750,12.0
21.5250,8.0
21.5750,5.0
21.6250,5.0
21.6750,10.0
21.7250,4.0
21.7750,6.0
21.8250,2.0
21.8750,1.0
21.9250,8.0
21.9750,5.0
22.0250,3.0
22.0750,1.0
22.1250,6.0
22.1750,5.0
22.2250,9.0
22.2750,2.0
22.3250,1.0
22.3750,11.0
22.4250,9.0
22.4750,2.0
22.5250,8.0
22.5750,4.0
22.6250,7.0
22.6750,4.0
22.7250,5.0
22.7750,11.0
22.8250,7.0
22.8750,15.0
22.9250,9.0
22.9750,5.0
23.0250,6.0
23.0750,12.0
23.1250,7.0
23.1750,6.0
23.2250,8.0
23.2750,6.0
23.3250,3.0
23.3750,9.0
23.4250,9.0
23.4750,3.0
23.5250,12.0
23.5750,4.0
23.6250,5.0
23.6750,7.0
23.7250,3.0
23.7750,7.0
23.8250,7.0
23.8750,3.0
23.9250,3.0
23.9750,4.0
24.0250,5.0
24.0750,7.0
24.1250,3.0
24.1750,5.0
24.2250,9.0
24.2750,7.0
24.3250,7.0
24.3750,5.0
24.4250,4.0
24.4750,8.0
24.5250,9.0
24.5750,6.0
24.6250,4.0
24.6750,10.0
24.7250,6.0
24.7750,6.0
24.8250,5.0
24.8750,7.0
24.9250,7.0
24.9750,8.0
25.0250,8.0
25.0750,8.0
25.1250,8.0
25.1750,5.0
25.2250,5.0
25.2750,5.0
25.3250,15.0
25.3750,2.0
25.4250,13.0
25.4750,14.0
25.5250,11.0
25.5750,24.0
25.6250,56.0
25.6750,62.0
25.7250,129.0
25.7750,155.0
25.8250,131.0
25.8750,108.0
25.9250,88.0
25.9750,51.0
26.0250,20.0
26.0750,10.0
26.1250,13.0
26.1750,6.0
26.2250,10.0
26.2750,10.0
26.3250,7.0
26.3750,6.0
26.4250,9.0
26.4750,9.0
26.5250,4.0
26.5750,9.0
26.6250,6.0
26.6750,5.0
26.7250,4.0
26.7750,11.0
26.8250,4.0
26.8750,7.0
26.9250,9.0
26.9750,8.0
27.0250,9.0
27.0750,4.0
27.1250,5.0
27.1750,3.0
27.2250,8.0
27.2750,5.0
27.3250,3.0
27.3750,4.0
27.4250,3.0
27.4750,5.0
27.5250,5.0
27.5750,7.0
27.6250,8.0
27.6750,6.0
27.7250,11.0
27.7750,12.0
27.8250,13.0
27.8750,9.0
27.9250,14.0
27.9750,16.0
28.0250,34.0
28.0750,34.0
28.1250,19.0
28.1750,25.0
28.2250,15.0
28.2750,16.0
28.3250,7.0
28.3750,5.0
28.4250,4.0
28.4750,7.0
28.5250,7.0
28.5750,7.0
28.6250,4.0
28.6750,6.0
28.7250,4.0
28.7750,7.0
28.8250,5.0
28.8750,9.0
28.9250,7.0
28.9750,10.0
29.0250,9.0
29.0750,12.0
29.1250,2.0
29.1750,8.0
29.2250,3.0
29.2750,2.0
29.3250,8.0
29.3750,3.0
29.4250,6.0
29.4750,6.0
29.5250,7.0
29.5750,2.0
29.6250,6.0
29.6750,5.0
29.7250,2.0
29.7750,5.0
29.8250,3.0
29.8750,4.0
29.9250,1.0
29.9750,7.0
30.0250,2.0
30.0750,4.0
30.1250,4.0
30.1750,7.0
30.2250,7.0
30.2750,2.0
30.3250,7.0
30.3750,5.0
30.4250,5.0
30.4750,1.0
30.5250,7.0
30.5750,3.0
30.6250,7.0
30.6750,4.0
30.7250,5.0
30.7750,3.0
30.8250,3.0
30.8750,3.0
30.9250,3.0
30.9750,3.0
31.0250,11.0
31.0750,6.0
31.1250,8.0
31.1750,7.0
31.2250,3.0
31.2750,5.0
31.3250,2.0
31.3750,7.0
31.4250,5.0
31.4750,8.0
31.5250,10.0
31.5750,14.0
31.6250,14.0
31.6750,26.0
31.7250,26.0
31.7750,24.0
31.8250,22.0
31.8750,33.0
31.9250,31.0
31.9750,43.0
32.0250,48.0
32.0750,72.0
32.1250,84.0
32.1750,65.0
32.2250,64.0
32.2750,50.0
32.3250,32.0
32.3750,24.0
32.4250,16.0
32.4750,7.0
32.5250,14.0
32.5750,5.0
32.6250,10.0
32.6750,8.0
32.7250,6.0
32.7750,5.0
32.8250,14.0
32.8750,16.0
32.9250,17.0
32.9750,10.0
33.0250,9.0
33.0750,8.0
33.1250,14.0
33.1750,7.0
33.2250,7.0
33.2750,2.0
33.3250,8.0
33.3750,3.0
33.4250,7.0
33.4750,2.0
33.5250,4.0
33.5750,9.0
33.6250,4.0
33.6750,6.0
33.7250,6.0
33.7750,7.0
33.8250,9.0
33.8750,13.0
33.9250,17.0
33.9750,23.0
34.0250,35.0
34.0750,30.0
34.1250,18.0
34.1750,11.0
34.2250,11.0
34.2750,9.0
34.3250,6.0
34.3750,5.0
34.4250,4.0
34.4750,2.0
34.5250,7.0
34.5750,7.0
34.6250,7.0
34.6750,15.0
34.7250,6.0
34.7750,5.0
34.8250,8.0
34.8750,7.0
34.9250,11.0
34.9750,6.0
35.0250,14.0
35.0750,15.0
35.1250,12.0
35.1750,10.0
35.2250,18.0
35.2750,14.0
35.3250,7.0
35.3750,6.0
35.4250,7.0
35.4750,7.0
35.5250,10.0
35.5750,9.0
35.6250,8.0
35.6750,3.0
35.7250,5.0
35.7750,6.0
35.8250,9.0
35.8750,10.0
35.9250,2.0
35.9750,3.0
36.0250,7.0
36.0750,6.0
36.1250,9.0
36.1750,10.0
36.2250,4.0
36.2750,10.0
36.3250,8.0
36.3750,9.0
36.4250,5.0
36.4750,9.0
36.5250,14.0
36.5750,9.0
36.6250,5.0
36.6750,4.0
36.7250,10.0
36.7750,6.0
36.8250,4.0
36.8750,10.0
36.9250,11.0
36.9750,8.0
37.0250,11.0
37.0750,7.0
37.1250,13.0
37.1750,8.0
37.2250,9.0
37.2750,13.0
37.3250,16.0
37.3750,13.0
37.4250,13.0
37.4750,9.0
37.5250,19.0
37.5750,14.0
37.6250,14.0
37.6750,11.0
37.7250,17.0
37.7750,12.0
37.8250,8.0
37.8750,8.0
37.9250,18.0
37.9750,10.0
38.0250,15.0
38.0750,14.0
38.1250,16.0
38.1750,29.0
38.2250,19.0
38.2750,32.0
38.3250,30.0
38.3750,38.0
38.4250,48.0
38.4750,42.0
38.5250,36.0
38.5750,29.0
38.6250,17.0
38.6750,17.0
38.7250,10.0
38.7750,11.0
38.8250,9.0
38.8750,11.0
38.9250,7.0
38.9750,9.0
39.0250,6.0
39.0750,11.0
39.1250,17.0
39.1750,11.0
39.2250,12.0
39.2750,15.0
39.3250,18.0
39.3750,15.0
39.4250,12.0
39.4750,16.0
39.5250,13.0
39.5750,6.0
39.6250,17.0
39.6750,14.0
39.7250,10.0
39.7750,26.0
39.8250,27.0
39.8750,25.0
39.9250,18.0
39.9750,26.0
40.0250,47.0
40.0750,49.0
40.1250,74.0
40.1750,47.0
40.2250,65.0
40.2750,46.0
40.3250,43.0
40.3750,26.0
40.4250,25.0
40.4750,16.0
40.5250,13.0
40.5750,1.0
40.6250,9.0
40.6750,9.0
40.7250,6.0
40.7750,3.0
40.8250,6.0
40.8750,4.0
40.9250,11.0
40.9750,6.0
41.0250,4.0
41.0750,6.0
41.1250,3.0
41.1750,3.0
41.2250,8.0
41.2750,8.0
41.3250,7.0
41.3750,3.0
41.4250,5.0
41.4750,6.0
41.5250,6.0
41.5750,3.0
41.6250,2.0
41.6750,4.0
41.7250,4.0
41.7750,3.0
41.8250,5.0
41.8750,3.0
41.9250,6.0
41.9750,5.0
42.0250,7.0
42.0750,6.0
42.1250,6.0
42.1750,7.0
42.2250,4.0
42.2750,1.0
42.3250,4.0
42.3750,7.0
42.4250,5.0
42.4750,3.0
42.5250,4.0
42.5750,4.0
42.6250,4.0
42.6750,5.0
42.7250,4.0
42.7750,7.0
42.8250,11.0
42.8750,4.0
42.9250,5.0
42.9750,4.0
43.0250,4.0
43.0750,3.0
43.1250,3.0
43.1750,3.0
43.2250,6.0
43.2750,2.0
43.3250,6.0
43.3750,5.0
43.4250,5.0
43.4750,7.0
43.5250,3.0
43.5750,11.0
43.6250,7.0
43.6750,4.0
43.7250,12.0
43.7750,13.0
43.8250,13.0
43.8750,11.0
43.9250,8.0
43.9750,5.0
44.0250,1.0
44.0750,6.0
44.1250,4.0
44.1750,7.0
44.2250,2.0
44.2750,5.0
44.3250,2.0
44.3750,0.0
44.4250,1.0
44.4750,4.0
44.5250,5.0
44.5750,6.0
44.6250,4.0
44.6750,3.0
44.7250,1.0
44.7750,5.0
44.8250,3.0
44.8750,5.0
44.9250,5.0
44.9750,5.0
45.0250,1.0
45.0750,6.0
45.1250,7.0
45.1750,4.0
45.2250,4.0
45.2750,3.0
45.3250,10.0
45.3750,9.0
45.4250,5.0
45.4750,8.0
45.5250,6.0
45.5750,3.0
45.6250,10.0
45.6750,4.0
45.7250,6.0
45.7750,6.0
45.8250,1.0
45.8750,4.0
45.9250,3.0
45.9750,8.0
46.0250,4.0
46.0750,4.0
46.1250,6.0
46.1750,5.0
46.2250,1.0
46.2750,1.0
46.3250,6.0
46.3750,2.0
46.4250,3.0
46.4750,6.0
46.5250,11.0
46.5750,9.0
46.6250,8.0
46.6750,9.0
46.7250,15.0
46.7750,12.0
46.8250,9.0
46.8750,4.0
46.9250,5.0
46.9750,1.0
47.0250,12.0
47.0750,2.0
47.1250,4.0
47.1750,6.0
47.2250,5.0
47.2750,5.0
47.3250,4.0
47.3750,2.0
47.4250,3.0
47.4750,3.0
47.5250,7.0
47.5750,4.0
47.6250,4.0
47.6750,3.0
47.7250,3.0
47.7750,1.0
47.8250,7.0
47.8750,1.0
47.9250,5.0
47.9750,10.0
48.0250,11.0
48.0750,7.0
48.1250,8.0
48.1750,7.0
48.2250,8.0
48.2750,6.0
48.3250,3.0
48.3750,1.0
48.4250,4.0
48.4750,5.0
48.5250,4.0
48.5750,3.0
48.6250,7.0
48.6750,2.0
48.7250,4.0
48.7750,4.0
48.8250,3.0
48.8750,4.0
48.9250,12.0
48.9750,3.0
49.0250,5.0
49.0750,4.0
49.1250,7.0
49.1750,6.0
49.2250,7.0
49.2750,13.0
49.3250,24.0
49.3750,16.0
49.4250,14.0
49.4750,27.0
49.5250,19.0
49.5750,15.0
49.6250,13.0
49.6750,15.0
49.7250,13.0
49.7750,3.0
49.8250,3.0
49.8750,5.0
49.9250,0.0
49.9750,11.0
50.0250,4.0
50.0750,7.0
50.1250,1.0
50.1750,2.0
50.2250,5.0
50.2750,6.0
50.3250,4.0
50.3750,6.0
50.4250,4.0
50.4750,10.0
50.5250,3.0
50.5750,6.0
50.6250,3.0
50.6750,1.0
50.7250,3.0
50.7750,4.0
50.8250,6.0
50.8750,7.0
50.9250,8.0
50.9750,5.0
51.0250,1.0
51.0750,4.0
51.1250,4.0
51.1750,6.0
51.2250,6.0
51.2750,6.0
51.3250,5.0
51.3750,8.0
51.4250,4.0
51.4750,6.0
51.5250,2.0
51.5750,5.0
51.6250,12.0
51.6750,6.0
51.7250,6.0
51.7750,3.0
51.8250,4.0
51.8750,5.0
51.9250,6.0
51.9750,9.0
52.0250,7.0
52.0750,7.0
52.1250,9.0
52.1750,8.0
52.2250,6.0
52.2750,7.0
52.3250,7.0
52.3750,4.0
52.4250,7.0
52.4750,6.0
52.5250,5.0
52.5750,7.0
52.6250,6.0
52.6750,7.0
52.7250,5.0
52.7750,6.0
52.8250,10.0
52.8750,12.0
52.9250,19.0
52.9750,23.0
53.0250,20.0
53.0750,36.0
53.1250,28.0
53.1750,38.0
53.2250,29.0
53.2750,21.0
53.3250,15.0
53.3750,7.0
53.4250,12.0
53.4750,5.0
53.5250,3.0
53.5750,4.0
53.6250,3.0
53.6750,6.0
53.7250,2.0
53.7750,4.0
53.8250,3.0
53.8750,4.0
53.9250,6.0
53.9750,4.0
54.0250,1.0
54.0750,3.0
54.1250,6.0
54.1750,2.0
54.2250,4.0
54.2750,5.0
54.3250,5.0
54.3750,5.0
54.4250,7.0
54.4750,3.0
54.5250,4.0
54.5750,4.0
54.6250,3.0
54.6750,3.0
54.7250,1.0
54.7750,1.0
54.8250,2.0
54.8750,8.0
54.9250,4.0
54.9750,8.0