File: code/data/data_source2/Ti_GIXRD - Ti_HA-300nm-Z=29mm med.Gerk.csv
[Measurement conditions]
Sample identification,
Comment - 1,"Configuration=Filmes Finos 19_1_2015, Owner=User-1, Creation date=19/01/2015 21:17:15"
Comment - 2,"Goniometer=PW3050/60 (Theta/Theta); Minimum step size 2Theta:0.001; Minimum step size Omega:0.001"
Comment - 3,"Sample stage=PW3071/xx Bracket"
Comment - 4,"Diffractometer system=XPERT-PRO"
Comment - 5,"Measurement program=C:\PANalytical\Data Collector\Programs\GrazingIncidence.xrdmp, Identifier={FDFF3DF9-3853-4573-8C07-D24AA8EB5C47}"
Anode material,Cu
K-Alpha1 wavelength,1.5405980
K-Alpha2 wavelength,1.5444260
Ratio K-Alpha2/K-Alpha1,0.500
Divergence slit,Fixed,0.10mm
Receiving slit,0.10
Monochromator used,YES
Generator voltage, 40
Tube current, 40
File date and time,22/Jan/2018 20:51
Unit cell,
h k l, 0 0 0
Scan axis,2Theta
Scan range,8.000,60.000
Scan step size,0.0250000
No. of points, 2081
Scan type,STEP
Omega,2.000
Time per step,20.000
[Scan points]
Angle,Intensity
8.000,104
8.050,98
8.100,102
8.150,103
8.200,95
8.250,100
8.300,93
8.350,98
8.400,100
8.450,95
8.500,94
8.550,96
8.600,94
8.650,93
8.700,94
8.750,92
8.800,89
8.850,91
8.900,92
8.950,90
9.000,92
9.050,91
9.100,86
9.150,91
9.200,86
9.250,91
9.300,91
9.350,96
9.400,90
9.450,90
9.500,90
9.550,90
9.600,90
9.650,86
9.700,86
9.750,86
9.800,83
9.850,87
9.900,87
9.950,81
10.000,85
10.050,82
10.100,79
10.150,82
10.200,81
10.250,78
10.300,82
10.350,79
10.400,83
10.450,78
10.500,81
10.550,80
10.600,79
10.650,81
10.700,77
10.750,73
10.800,78
10.850,76
10.900,77
10.950,75
11.000,77
11.050,77
11.100,76
11.150,72
11.200,73
11.250,75
11.300,71
11.350,75
11.400,74
11.450,72
11.500,73
11.550,70
11.600,72
11.650,71
11.700,70
11.750,75
11.800,75
11.850,72
11.900,72
11.950,73
12.000,70
12.050,72
12.100,70
12.150,72
12.200,70
12.250,71
12.300,71
12.350,70
12.400,69
12.450,71
12.500,71
12.550,69
12.600,67
12.650,70
12.700,64
12.750,69
12.800,68
12.850,67
12.900,65
12.950,69
13.000,68
13.050,65
13.100,65
13.150,66
13.200,67
13.250,63
13.300,66
13.350,64
13.400,67
13.450,68
13.500,63
13.550,66
13.600,68
13.650,65
13.700,63
13.750,64
13.800,63
13.850,62
13.900,62
13.950,64
14.000,61
14.050,63
14.100,63
14.150,65
14.200,62
14.250,63
14.300,61
14.350,64
14.400,61
14.450,56
14.500,62
14.550,61
14.600,59
14.650,60
14.700,60
14.750,59
14.800,59
14.850,59
14.900,60
14.950,59
15.000,56
15.050,61
15.100,59
15.150,57
15.200,56
15.250,60
15.300,59
15.350,60
15.400,56
15.450,56
15.500,58
15.550,60
15.600,55
15.650,58
15.700,57
15.750,56
15.800,58
15.850,55
15.900,58
15.950,56
16.000,56
16.050,58
16.100,56
16.150,55
16.200,57
16.250,55
16.300,55
16.350,56
16.400,58
16.450,54
16.500,57
16.550,55
16.600,56
16.650,56
16.700,57
16.750,57
16.800,56
16.850,56
16.900,55
16.950,55
17.000,53
17.050,55
17.100,56
17.150,53
17.200,54
17.250,54
17.300,54
17.350,51
17.400,54
17.450,55
17.500,54
17.550,54
17.600,55
17.650,51
17.700,55
17.750,54
17.800,54
17.850,54
17.900,50
17.950,52
18.000,52
18.050,52
18.100,55
18.150,50
18.200,51
18.250,49
18.300,50
18.350,52
18.400,52
18.450,52
18.500,52
18.550,51
18.600,50
18.650,51
18.700,51
18.750,51
18.800,52
18.850,48
18.900,51
18.950,49
19.000,48
19.050,50
19.100,50
19.150,51
19.200,49
19.250,50
19.300,50
19.350,50
19.400,48
19.450,47
19.500,43
19.550,51
19.600,48
19.650,48
19.700,50
19.750,46
19.800,48
19.850,47
19.900,49
19.950,46
20.000,49
20.050,48
20.100,46
20.150,44
20.200,44
20.250,45
20.300,48
20.350,47
20.400,47
20.450,45
20.500,46
20.550,46
20.600,42
20.650,44
20.700,46
20.750,42
20.800,43
20.850,44
20.900,45
20.950,42
21.000,44
21.050,44
21.100,44
21.150,46
21.200,45
21.250,47
21.300,48
21.350,47
21.400,46
21.450,44
21.500,44
21.550,41
21.600,40
21.650,39
21.700,42
21.750,40
21.800,41
21.850,41
21.900,37
21.950,40
22.000,41
22.050,41
22.100,42
22.150,39
22.200,39
22.250,38
22.300,40
22.350,40
22.400,37
22.450,39
22.500,38
22.550,40
22.600,38
22.650,37
22.700,39
22.750,35
22.800,37
22.850,38
22.900,37
22.950,35
23.000,36
23.050,37
23.100,35
23.150,36
23.200,35
23.250,39
23.300,36
23.350,33
23.400,34
23.450,36
23.500,35
23.550,35
23.600,34
23.650,35
23.700,35
23.750,36
23.800,34
23.850,37
23.900,35
23.950,36
24.000,33
24.050,33
24.100,36
24.150,32
24.200,32
24.250,34
24.300,35
24.350,32
24.400,34
24.450,32
24.500,31
24.550,32
24.600,29
24.650,31
24.700,32
24.750,30
24.800,32
24.850,32
24.900,33
24.950,30
25.000,33
25.050,31
25.100,31
25.150,33
25.200,29
25.250,30
25.300,28
25.350,28
25.400,29
25.450,31
25.500,30
25.550,29
25.600,31
25.650,29
25.700,30
25.750,31
25.800,33
25.850,28
25.900,29
25.950,29
26.000,28
26.050,27
26.100,26
26.150,27
26.200,28
26.250,27
26.300,26
26.350,27
26.400,25
26.450,27
26.500,26
26.550,27
26.600,26
26.650,26
26.700,27
26.750,26
26.800,26
26.850,26
26.900,26
26.950,25
27.000,23
27.050,26
27.100,24
27.150,26
27.200,26
27.250,26
27.300,27
27.350,23
27.400,25
27.450,25
27.500,23
27.550,22
27.600,27
27.650,25
27.700,26
27.750,25
27.800,23
27.850,23
27.900,24
27.950,25
28.000,23
28.050,23
28.100,24
28.150,25
28.200,23
28.250,23
28.300,23
28.350,24
28.400,24
28.450,22
28.500,21
28.550,23
28.600,23
28.650,23
28.700,23
28.750,22
28.800,25
28.850,23
28.900,23
28.950,25
29.000,22
29.050,24
29.100,24
29.150,24
29.200,22
29.250,21
29.300,22
29.350,24
29.400,23
29.450,21
29.500,24
29.550,23
29.600,23
29.650,24
29.700,24
29.750,24
29.800,21
29.850,22
29.900,21
29.950,22
30.000,22
30.050,23
30.100,23
30.150,23
30.200,20
30.250,22
30.300,22
30.350,20
30.400,21
30.450,23
30.500,25
30.550,24
30.600,22
30.650,21
30.700,23
30.750,20
30.800,20
30.850,21
30.900,23
30.950,19
31.000,19
31.050,21
31.100,21
31.150,19
31.200,20
31.250,22
31.300,21
31.350,21
31.400,21
31.450,20
31.500,21
31.550,19
31.600,21
31.650,19
31.700,19
31.750,18
31.800,20
31.850,19
31.900,20
31.950,19
32.000,20
32.050,20
32.100,17
32.150,19
32.200,18
32.250,18
32.300,19
32.350,15
32.400,17
32.450,18
32.500,18
32.550,18
32.600,16
32.650,17
32.700,17
32.750,17
32.800,15
32.850,17
32.900,16
32.950,16
33.000,16
33.050,15
33.100,15
33.150,14
33.200,15
33.250,14
33.300,13
33.350,13
33.400,15
33.450,15
33.500,14
33.550,14
33.600,14
33.650,14
33.700,13
33.750,13
33.800,14
33.850,14
33.900,13
33.950,13
34.000,12
34.050,13
34.100,12
34.150,13
34.200,13
34.250,13
34.300,12
34.350,12
34.400,11
34.450,11
34.500,13
34.550,12
34.600,11
34.650,12
34.700,13
34.750,13
34.800,12
34.850,12
34.900,11
34.950,12
35.000,12
35.050,11
35.100,11
35.150,11
35.200,12
35.250,12
35.300,11
35.350,12
35.400,11
35.450,11
35.500,10
35.550,12
35.600,11
35.650,10
35.700,10
35.750,10
35.800,10
35.850,10
35.900, 9
35.950,11
36.000,10
36.050,11
36.100,10
36.150,10
36.200, 9
36.250, 9
36.300,10
36.350, 9
36.400, 8
36.450,10
36.500, 9
36.550,11
36.600,10
36.650,10
36.700,10
36.750,10
36.800,11
36.850,10
36.900,10
36.950,10
37.000, 9
37.050,10
37.100,10
37.150,10
37.200,10
37.250,11
37.300, 8
37.350,10
37.400,10
37.450,10
37.500, 9
37.550, 9
37.600, 9
37.650, 9
37.700,11
37.750,10
37.800, 9
37.850,11
37.900, 9
37.950, 9
38.000,10
38.050, 9
38.100, 9
38.150,10
38.200, 9
38.250,10
38.300,12
38.350,10
38.400, 9
38.450, 9
38.500,10
38.550, 9
38.600, 9
38.650, 8
38.700,11
38.750, 9
38.800, 9
38.850, 8
38.900, 9
38.950, 9
39.000, 9
39.050, 9
39.100, 8
39.150,10
39.200,10
39.250,10
39.300, 8
39.350, 9
39.400, 9
39.450,10
39.500, 9
39.550, 8
39.600, 9
39.650, 8
39.700, 9
39.750,10
39.800, 9
39.850, 8
39.900, 9
39.950, 9
40.000, 9
40.050, 9
40.100, 9
40.150, 9
40.200, 9
40.250, 8
40.300,10
40.350,10
40.400, 9
40.450, 8
40.500, 9
40.550, 9
40.600, 9
40.650,10
40.700, 8
40.750, 8
40.800, 9
40.850,11
40.900, 9
40.950, 9
41.000, 8
41.050, 9
41.100, 9
41.150,10
41.200, 8
41.250,10
41.300, 9
41.350,10
41.400, 8
41.450, 9
41.500, 9
41.550, 9
41.600, 8
41.650, 8
41.700, 8
41.750, 9
41.800, 9
41.850, 9
41.900, 8
41.950,10
42.000, 9
42.050, 9
42.100, 8
42.150, 8
42.200, 9
42.250, 8
42.300, 7
42.350, 9
42.400,10
42.450, 9
42.500, 8
42.550, 9
42.600, 9
42.650, 8
42.700, 9
42.750, 9
42.800, 9
42.850, 8
42.900, 8
42.950, 8
43.000, 9
43.050, 9
43.100, 8
43.150,10
43.200, 9
43.250, 9
43.300, 8
43.350, 8
43.400,10
43.450, 9
43.500, 9
43.550,10
43.600, 8
43.650, 9
43.700, 9
43.750,10
43.800,10
43.850, 9
43.900, 8
43.950,10
44.000, 9
44.050, 9
44.100,10
44.150, 9
44.200, 9
44.250, 9
44.300, 9
44.350,10
44.400, 8
44.450,10
44.500, 8
44.550, 9
44.600, 9
44.650, 7
44.700, 9
44.750, 8
44.800, 8
44.850, 9
44.900, 7
44.950, 7
45.000, 9
45.050, 9
45.100, 9
45.150, 8
45.200, 8
45.250, 8
45.300, 9
45.350, 9
45.400, 8
45.450, 8
45.500,10
45.550, 8
45.600, 8
45.650,10
45.700, 8
45.750, 8
45.800, 9
45.850, 9
45.900, 8
45.950, 9
46.000, 9
46.050, 9
46.100,10
46.150, 9
46.200,10
46.250, 9
46.300, 9
46.350, 9
46.400, 9
46.450, 8
46.500,10
46.550, 9
46.600,10
46.650, 9
46.700, 9
46.750, 9
46.800, 9
46.850, 8
46.900, 9
46.950, 8
47.000, 9
47.050, 8
47.100, 9
47.150, 8
47.200, 8
47.250, 7
47.300, 8
47.350, 9
47.400, 8
47.450,10
47.500,10
47.550,11
47.600, 8
47.650, 9
47.700,10
47.750, 8
47.800, 9
47.850, 9
47.900,10
47.950, 9
48.000, 8
48.050, 9
48.100, 9
48.150, 9
48.200, 9
48.250, 9
48.300,10
48.350, 9
48.400, 9
48.450, 8
48.500, 9
48.550, 8
48.600, 9
48.650, 8
48.700, 8
48.750, 9
48.800, 8
48.850, 8
48.900, 9
48.950, 9
49.000, 9
49.050, 9
49.100, 9
49.150, 9
49.200, 9
49.250,10
49.300, 9
49.350,10
49.400, 9
49.450, 9
49.500, 8
49.550, 8
49.600,10
49.650,10
49.700, 9
49.750, 8
49.800, 8
49.850, 9
49.900, 9
49.950, 9
50.000,10
50.050, 8
50.100, 9
50.150, 9
50.200,10
50.250, 9
50.300, 9
50.350, 8
50.400, 9
50.450, 9
50.500, 9
50.550,10
50.600,10
50.650,10
50.700, 9
50.750,10
50.800,10
50.850, 8
50.900, 9
50.950, 8
51.000, 8
51.050, 9
51.100,10
51.150, 9
51.200, 9
51.250,10
51.300,10
51.350, 9
51.400,10
51.450, 9
51.500, 9
51.550, 8
51.600, 9
51.650,10
51.700,10
51.750,10
51.800, 9
51.850,10
51.900, 9
51.950,10
52.000,11
52.050,10
52.100, 9
52.150,11
52.200, 9
52.250, 9
52.300,10
52.350, 9
52.400,11
52.450,10
52.500,10
52.550, 9
52.600,11
52.650,10
52.700,12
52.750,11
52.800,11
52.850,10
52.900,12
52.950,12
53.000,12
53.050,12
53.100,13
53.150,11
53.200,12
53.250,13
53.300,12
53.350,13
53.400,13
53.450,13
53.500,12
53.550,13
53.600,13
53.650,13
53.700,14
53.750,13
53.800,15
53.850,15
53.900,15
53.950,15
54.000,14
54.050,15
54.100,16
54.150,18
54.200,18
54.250,17
54.300,17
54.350,16
54.400,20
54.450,24
54.500,108
54.550,208
54.600,212
54.650,193
54.700,167
54.750,148
54.800,108
54.850,74
54.900,50
54.950,39
55.000,32
55.050,32
55.100,34
55.150,37
55.200,45
55.250,53
55.300,68
55.350,89
55.400,101
55.450,100
55.500,90
55.550,85
55.600,77
55.650,69
55.700,71
55.750,74
55.800,73
55.850,73
55.900,73
55.950,76
56.000,78
56.050,73
56.100,68
56.150,66
56.200,62
56.250,56
56.300,54
56.350,51
56.400,46
56.450,45
56.500,41
56.550,39
56.600,36
56.650,37
56.700,31
56.750,29
56.800,30
56.850,28
56.900,24
56.950,27
57.000,25
57.050,22
57.100,21
57.150,20
57.200,20
57.250,18
57.300,18
57.350,18
57.400,19
57.450,18
57.500,16
57.550,16
57.600,15
57.650,16
57.700,14
57.750,15
57.800,15
57.850,12
57.900,14
57.950,13
58.000,13
58.050,11
58.100,11
58.150,11
58.200,11
58.250,12
58.300,11
58.350,12
58.400,10
58.450,10
58.500,12
58.550,11
58.600,10
58.650, 9
58.700,11
58.750, 8
58.800,10
58.850,10
58.900, 9
58.950, 9
59.000,10
59.050, 9
59.100, 9
59.150, 8
59.200, 8
59.250,10
59.300, 8
59.350, 8
59.400, 8
59.450, 8
59.500, 7
59.550, 8
59.600, 7
59.650, 7
59.700, 8
59.750, 6
59.800, 8
59.850, 7
59.900, 7
59.950, 8
60.000, 8