File: code/data/data_source2/Ti_GIXRD - Ti_HA-300nm-Z=29mm.csv
[Measurement conditions]
Sample identification,
Comment - 1,"Configuration=Filmes Finos 19_1_2015, Owner=User-1, Creation date=19/01/2015 21:17:15"
Comment - 2,"Goniometer=PW3050/60 (Theta/Theta); Minimum step size 2Theta:0.001; Minimum step size Omega:0.001"
Comment - 3,"Sample stage=PW3071/xx Bracket"
Comment - 4,"Diffractometer system=XPERT-PRO"
Comment - 5,"Measurement program=C:\PANalytical\Data Collector\Programs\GrazingIncidence.xrdmp, Identifier={4F373A79-D04C-4C38-BC38-DE604BBDD19E}"
Anode material,Cu
K-Alpha1 wavelength,1.5405980
K-Alpha2 wavelength,1.5444260
Ratio K-Alpha2/K-Alpha1,0.500
Divergence slit,Fixed,0.10mm
Receiving slit,0.10
Monochromator used,YES
Generator voltage, 40
Tube current, 40
File date and time,22/Jan/2018 13:02
Unit cell,
h k l, 0 0 0
Scan axis,2Theta
Scan range,8.000,17.525
Scan step size,0.0250000
No. of points, 382
Scan type,STEP
Omega,2.000
Time per step,20.000
[Scan points]
Angle,Intensity
8.000,103
8.025,101
8.050,103
8.075,99
8.100,99
8.125,99
8.150,98
8.175,99
8.200,96
8.225,97
8.250,96
8.275,96
8.300,94
8.325,97
8.350,95
8.375,97
8.400,97
8.425,96
8.450,94
8.475,98
8.500,95
8.525,99
8.550,94
8.575,92
8.600,93
8.625,93
8.650,93
8.675,94
8.700,92
8.725,91
8.750,95
8.775,94
8.800,95
8.825,94
8.850,96
8.875,97
8.900,96
8.925,93
8.950,94
8.975,91
9.000,90
9.025,92
9.050,91
9.075,89
9.100,95
9.125,94
9.150,92
9.175,91
9.200,91
9.225,90
9.250,95
9.275,93
9.300,90
9.325,91
9.350,89
9.375,91
9.400,93
9.425,90
9.450,91
9.475,90
9.500,86
9.525,92
9.550,89
9.575,90
9.600,83
9.625,89
9.650,85
9.675,84
9.700,89
9.725,89
9.750,87
9.775,87
9.800,86
9.825,83
9.850,79
9.875,84
9.900,84
9.925,80
9.950,83
9.975,82
10.000,84
10.025,86
10.050,83
10.075,84
10.100,84
10.125,87
10.150,87
10.175,83
10.200,83
10.225,83
10.250,80
10.275,84
10.300,82
10.325,80
10.350,83
10.375,76
10.400,79
10.425,82
10.450,85
10.475,82
10.500,81
10.525,79
10.550,78
10.575,78
10.600,82
10.625,79
10.650,76
10.675,78
10.700,80
10.725,81
10.750,78
10.775,79
10.800,77
10.825,72
10.850,78
10.875,81
10.900,77
10.925,79
10.950,77
10.975,78
11.000,77
11.025,78
11.050,73
11.075,76
11.100,76
11.125,72
11.150,76
11.175,73
11.200,76
11.225,78
11.250,75
11.275,73
11.300,77
11.325,76
11.350,74
11.375,70
11.400,73
11.425,70
11.450,76
11.475,72
11.500,74
11.525,75
11.550,76
11.575,72
11.600,72
11.625,75
11.650,72
11.675,68
11.700,71
11.725,70
11.750,71
11.775,69
11.800,76
11.825,75
11.850,71
11.875,72
11.900,71
11.925,69
11.950,72
11.975,71
12.000,71
12.025,72
12.050,71
12.075,69
12.100,70
12.125,71
12.150,73
12.175,70
12.200,71
12.225,70
12.250,73
12.275,68
12.300,69
12.325,72
12.350,71
12.375,69
12.400,69
12.425,70
12.450,69
12.475,72
12.500,71
12.525,69
12.550,68
12.575,69
12.600,67
12.625,67
12.650,66
12.675,72
12.700,67
12.725,66
12.750,70
12.775,66
12.800,70
12.825,66
12.850,69
12.875,69
12.900,66
12.925,65
12.950,69
12.975,66
13.000,67
13.025,68
13.050,66
13.075,66
13.100,67
13.125,68
13.150,62
13.175,67
13.200,67
13.225,66
13.250,67
13.275,64
13.300,66
13.325,64
13.350,65
13.375,66
13.400,67
13.425,63
13.450,66
13.475,65
13.500,60
13.525,63
13.550,66
13.575,63
13.600,59
13.625,63
13.650,63
13.675,65
13.700,66
13.725,61
13.750,64
13.775,63
13.800,64
13.825,64
13.850,63
13.875,60
13.900,61
13.925,63
13.950,62
13.975,62
14.000,61
14.025,64
14.050,59
14.075,60
14.100,62
14.125,64
14.150,63
14.175,61
14.200,60
14.225,62
14.250,61
14.275,63
14.300,62
14.325,63
14.350,62
14.375,62
14.400,59
14.425,60
14.450,60
14.475,61
14.500,58
14.525,60
14.550,61
14.575,62
14.600,62
14.625,59
14.650,62
14.675,60
14.700,58
14.725,59
14.750,60
14.775,58
14.800,61
14.825,61
14.850,59
14.875,58
14.900,58
14.925,60
14.950,59
14.975,60
15.000,60
15.025,59
15.050,58
15.075,60
15.100,60
15.125,60
15.150,56
15.175,61
15.200,56
15.225,62
15.250,56
15.275,61
15.300,59
15.325,58
15.350,62
15.375,59
15.400,58
15.425,60
15.450,58
15.475,59
15.500,61
15.525,57
15.550,59
15.575,59
15.600,58
15.625,54
15.650,59
15.675,61
15.700,58
15.725,58
15.750,60
15.775,59
15.800,59
15.825,56
15.850,57
15.875,59
15.900,56
15.925,58
15.950,56
15.975,57
16.000,55
16.025,59
16.050,57
16.075,57
16.100,59
16.125,55
16.150,55
16.175,56
16.200,55
16.225,56
16.250,54
16.275,57
16.300,53
16.325,55
16.350,56
16.375,53
16.400,52
16.425,55
16.450,58
16.475,57
16.500,56
16.525,56
16.550,58
16.575,55
16.600,57
16.625,54
16.650,57
16.675,52
16.700,54
16.725,53
16.750,54
16.775,53
16.800,53
16.825,54
16.850,57
16.875,54
16.900,53
16.925,53
16.950,52
16.975,54
17.000,54
17.025,56
17.050,53
17.075,51
17.100,52
17.125,53
17.150,52
17.175,55
17.200,52
17.225,54
17.250,54
17.275,52
17.300,52
17.325,52
17.350,51
17.375,53
17.400,54
17.425,54
17.450,50
17.475,53
17.500,53
17.525,50