File: code/data/data_source2/Ti_GIXRD - Ti-HA-300nm-Z=29mm-.csv
[Measurement conditions]
Sample identification,
Comment - 1,"Configuration=Filmes Finos 19_1_2015, Owner=User-1, Creation date=19/01/2015 21:17:15"
Comment - 2,"Goniometer=PW3050/60 (Theta/Theta); Minimum step size 2Theta:0.001; Minimum step size Omega:0.001"
Comment - 3,"Sample stage=PW3071/xx Bracket"
Comment - 4,"Diffractometer system=XPERT-PRO"
Comment - 5,"Measurement program=C:\PANalytical\Data Collector\Programs\GrazingIncidence.xrdmp, Identifier={3786F9F8-4607-4502-984F-A37399FDAA2B}"
Anode material,Cu
K-Alpha1 wavelength,1.5405980
K-Alpha2 wavelength,1.5444260
Ratio K-Alpha2/K-Alpha1,0.500
Divergence slit,Fixed,0.10mm
Receiving slit,0.10
Monochromator used,YES
Generator voltage, 40
Tube current, 40
File date and time,24/Jan/2018 00:30
Unit cell,
h k l, 0 0 0
Scan axis,2Theta
Scan range,8.000,60.000
Scan step size,0.0250000
No. of points, 2081
Scan type,STEP
Omega,1.000
Time per step,20.000
[Scan points]
Angle,Intensity
8.000,105
8.050,103
8.100,103
8.150,102
8.200,98
8.250,100
8.300,97
8.350,95
8.400,98
8.450,96
8.500,94
8.550,95
8.600,96
8.650,95
8.700,95
8.750,95
8.800,98
8.850,96
8.900,98
8.950,95
9.000,93
9.050,94
9.100,93
9.150,93
9.200,95
9.250,94
9.300,97
9.350,100
9.400,99
9.450,100
9.500,97
9.550,95
9.600,91
9.650,85
9.700,86
9.750,86
9.800,81
9.850,84
9.900,84
9.950,83
10.000,83
10.050,80
10.100,80
10.150,78
10.200,80
10.250,81
10.300,81
10.350,82
10.400,79
10.450,79
10.500,80
10.550,81
10.600,80
10.650,82
10.700,79
10.750,81
10.800,79
10.850,79
10.900,74
10.950,79
11.000,71
11.050,71
11.100,75
11.150,72
11.200,70
11.250,70
11.300,67
11.350,67
11.400,70
11.450,68
11.500,68
11.550,68
11.600,69
11.650,69
11.700,69
11.750,69
11.800,69
11.850,69
11.900,64
11.950,64
12.000,67
12.050,67
12.100,66
12.150,68
12.200,64
12.250,69
12.300,69
12.350,66
12.400,67
12.450,63
12.500,67
12.550,65
12.600,61
12.650,62
12.700,63
12.750,59
12.800,62
12.850,60
12.900,61
12.950,62
13.000,58
13.050,60
13.100,58
13.150,62
13.200,58
13.250,56
13.300,57
13.350,57
13.400,61
13.450,56
13.500,55
13.550,56
13.600,57
13.650,56
13.700,59
13.750,57
13.800,55
13.850,55
13.900,55
13.950,58
14.000,54
14.050,55
14.100,50
14.150,52
14.200,54
14.250,53
14.300,53
14.350,54
14.400,54
14.450,52
14.500,52
14.550,53
14.600,51
14.650,51
14.700,50
14.750,52
14.800,52
14.850,48
14.900,50
14.950,50
15.000,50
15.050,49
15.100,49
15.150,49
15.200,49
15.250,49
15.300,50
15.350,49
15.400,49
15.450,48
15.500,48
15.550,45
15.600,49
15.650,47
15.700,44
15.750,46
15.800,45
15.850,45
15.900,46
15.950,46
16.000,47
16.050,46
16.100,46
16.150,47
16.200,45
16.250,46
16.300,44
16.350,42
16.400,43
16.450,43
16.500,42
16.550,45
16.600,45
16.650,44
16.700,46
16.750,45
16.800,42
16.850,43
16.900,42
16.950,41
17.000,44
17.050,41
17.100,41
17.150,41
17.200,41
17.250,38
17.300,37
17.350,40
17.400,42
17.450,37
17.500,41
17.550,40
17.600,38
17.650,35
17.700,40
17.750,39
17.800,39
17.850,40
17.900,36
17.950,36
18.000,35
18.050,36
18.100,37
18.150,34
18.200,37
18.250,37
18.300,35
18.350,37
18.400,36
18.450,39
18.500,37
18.550,37
18.600,36
18.650,37
18.700,36
18.750,34
18.800,37
18.850,36
18.900,37
18.950,38
19.000,34
19.050,35
19.100,37
19.150,35
19.200,31
19.250,32
19.300,33
19.350,32
19.400,35
19.450,35
19.500,35
19.550,33
19.600,32
19.650,33
19.700,33
19.750,33
19.800,31
19.850,32
19.900,30
19.950,30
20.000,34
20.050,31
20.100,33
20.150,31
20.200,32
20.250,30
20.300,32
20.350,31
20.400,30
20.450,31
20.500,30
20.550,30
20.600,31
20.650,31
20.700,28
20.750,30
20.800,29
20.850,30
20.900,28
20.950,30
21.000,30
21.050,31
21.100,29
21.150,34
21.200,34
21.250,34
21.300,33
21.350,35
21.400,33
21.450,36
21.500,35
21.550,34
21.600,33
21.650,31
21.700,32
21.750,30
21.800,30
21.850,29
21.900,28
21.950,28
22.000,27
22.050,26
22.100,27
22.150,29
22.200,28
22.250,27
22.300,27
22.350,26
22.400,25
22.450,28
22.500,26
22.550,27
22.600,28
22.650,28
22.700,29
22.750,26
22.800,25
22.850,28
22.900,26
22.950,24
23.000,27
23.050,25
23.100,24
23.150,24
23.200,24
23.250,23
23.300,24
23.350,23
23.400,25
23.450,22
23.500,23
23.550,24
23.600,23
23.650,21
23.700,24
23.750,24
23.800,23
23.850,24
23.900,24
23.950,24
24.000,22
24.050,22
24.100,21
24.150,24
24.200,23
24.250,22
24.300,22
24.350,22
24.400,22
24.450,22
24.500,22
24.550,21
24.600,21
24.650,21
24.700,20
24.750,20
24.800,21
24.850,22
24.900,22
24.950,20
25.000,20
25.050,19
25.100,21
25.150,20
25.200,21
25.250,21
25.300,21
25.350,22
25.400,22
25.450,21
25.500,24
25.550,25
25.600,29
25.650,35
25.700,33
25.750,36
25.800,34
25.850,33
25.900,31
25.950,26
26.000,24
26.050,21
26.100,20
26.150,17
26.200,20
26.250,19
26.300,19
26.350,18
26.400,18
26.450,18
26.500,19
26.550,19
26.600,18
26.650,18
26.700,17
26.750,17
26.800,18
26.850,19
26.900,18
26.950,16
27.000,18
27.050,15
27.100,17
27.150,17
27.200,16
27.250,16
27.300,17
27.350,16
27.400,16
27.450,18
27.500,16
27.550,16
27.600,18
27.650,16
27.700,16
27.750,16
27.800,16
27.850,18
27.900,17
27.950,18
28.000,19
28.050,19
28.100,19
28.150,19
28.200,17
28.250,18
28.300,16
28.350,17
28.400,18
28.450,19
28.500,18
28.550,20
28.600,22
28.650,24
28.700,22
28.750,25
28.800,23
28.850,21
28.900,20
28.950,16
29.000,18
29.050,16
29.100,16
29.150,15
29.200,16
29.250,16
29.300,17
29.350,17
29.400,16
29.450,14
29.500,14
29.550,15
29.600,15
29.650,13
29.700,14
29.750,16
29.800,15
29.850,14
29.900,14
29.950,13
30.000,15
30.050,15
30.100,14
30.150,13
30.200,14
30.250,13
30.300,13
30.350,14
30.400,14
30.450,14
30.500,15
30.550,15
30.600,14
30.650,15
30.700,13
30.750,13
30.800,13
30.850,14
30.900,16
30.950,15
31.000,14
31.050,16
31.100,17
31.150,17
31.200,19
31.250,23
31.300,29
31.350,36
31.400,43
31.450,49
31.500,53
31.550,59
31.600,57
31.650,57
31.700,45
31.750,43
31.800,38
31.850,35
31.900,34
31.950,34
32.000,34
32.050,34
32.100,32
32.150,26
32.200,23
32.250,22
32.300,23
32.350,23
32.400,26
32.450,30
32.500,35
32.550,40
32.600,46
32.650,46
32.700,48
32.750,48
32.800,42
32.850,40
32.900,30
32.950,26
33.000,18
33.050,16
33.100,16
33.150,14
33.200,14
33.250,13
33.300,13
33.350,13
33.400,12
33.450,13
33.500,12
33.550,12
33.600,13
33.650,13
33.700,14
33.750,13
33.800,15
33.850,16
33.900,15
33.950,17
34.000,17
34.050,14
34.100,12
34.150,12
34.200,10
34.250,10
34.300,10
34.350,10
34.400,11
34.450, 9
34.500,10
34.550,10
34.600,11
34.650, 9
34.700,11
34.750,10
34.800, 9
34.850,10
34.900,10
34.950,10
35.000,10
35.050,10
35.100,11
35.150,10
35.200,12
35.250,11
35.300,10
35.350,11
35.400,10
35.450,11
35.500,10
35.550, 9
35.600,10
35.650,10
35.700, 9
35.750,10
35.800, 9
35.850, 9
35.900, 9
35.950, 9
36.000, 9
36.050, 9
36.100,10
36.150, 9
36.200, 8
36.250, 9
36.300, 9
36.350, 9
36.400, 9
36.450, 9
36.500, 9
36.550, 9
36.600, 8
36.650, 9
36.700,10
36.750,10
36.800,10
36.850, 9
36.900, 9
36.950, 9
37.000, 9
37.050, 8
37.100, 9
37.150, 9
37.200,11
37.250,10
37.300,10
37.350,11
37.400,12
37.450,12
37.500,12
37.550,12
37.600,13
37.650,14
37.700,13
37.750,13
37.800,13
37.850,12
37.900,13
37.950,12
38.000,12
38.050,13
38.100,11
38.150,10
38.200,10
38.250, 9
38.300, 9
38.350, 9
38.400, 8
38.450, 8
38.500, 7
38.550, 9
38.600, 8
38.650, 8
38.700, 8
38.750, 8
38.800,10
38.850, 9
38.900,10
38.950,11
39.000,10
39.050, 8
39.100,10
39.150,11
39.200,10
39.250, 9
39.300,12
39.350,12
39.400,15
39.450,16
39.500,16
39.550,19
39.600,18
39.650,17
39.700,14
39.750,15
39.800,12
39.850,10
39.900, 9
39.950, 9
40.000, 8
40.050, 8
40.100, 8
40.150, 9
40.200, 7
40.250, 7
40.300, 6
40.350, 7
40.400, 6
40.450, 6
40.500, 7
40.550, 6
40.600, 7
40.650, 6
40.700, 6
40.750, 6
40.800, 6
40.850, 7
40.900, 6
40.950, 6
41.000, 7
41.050, 8
41.100, 6
41.150, 7
41.200, 7
41.250, 7
41.300, 7
41.350, 7
41.400, 7
41.450, 7
41.500, 8
41.550, 7
41.600, 8
41.650, 8
41.700, 9
41.750, 8
41.800, 8
41.850, 9
41.900, 8
41.950, 8
42.000, 7
42.050, 8
42.100, 7
42.150, 7
42.200, 7
42.250, 7
42.300, 7
42.350, 7
42.400, 8
42.450, 6
42.500, 7
42.550, 7
42.600, 7
42.650, 7
42.700, 8
42.750, 7
42.800, 6
42.850, 9
42.900, 7
42.950, 8
43.000, 9
43.050, 8
43.100, 9
43.150, 9
43.200, 9
43.250, 9
43.300,10
43.350,10
43.400,11
43.450,12
43.500,12
43.550,11
43.600,11
43.650,12
43.700,13
43.750,15
43.800,14
43.850,14
43.900,13
43.950,13
44.000,13
44.050,13
44.100,10
44.150,11
44.200,10
44.250,11
44.300, 9
44.350, 9
44.400,11
44.450, 9
44.500, 9
44.550, 7
44.600, 8
44.650, 8
44.700, 7
44.750, 8
44.800, 8
44.850, 8
44.900, 8
44.950, 7
45.000, 8
45.050, 8
45.100, 8
45.150, 8
45.200, 8
45.250, 7
45.300, 7
45.350, 7
45.400, 7
45.450, 7
45.500, 5
45.550, 6
45.600, 6
45.650, 7
45.700, 7
45.750, 6
45.800, 7
45.850, 7
45.900, 8
45.950, 8
46.000, 7
46.050, 8
46.100,10
46.150,10
46.200,12
46.250,13
46.300,15
46.350,14
46.400,16
46.450,15
46.500,15
46.550,14
46.600,13
46.650,12
46.700,11
46.750, 9
46.800, 9
46.850, 8
46.900, 8
46.950, 6
47.000, 7
47.050, 6
47.100, 6
47.150, 6
47.200, 7
47.250, 7
47.300, 7
47.350, 7
47.400, 8
47.450, 7
47.500, 8
47.550, 8
47.600,10
47.650, 9
47.700, 9
47.750,12
47.800,11
47.850,11
47.900,10
47.950, 9
48.000, 9
48.050, 9
48.100, 8
48.150, 9
48.200, 9
48.250, 8
48.300, 8
48.350, 8
48.400, 7
48.450, 7
48.500, 7
48.550, 7
48.600, 6
48.650, 6
48.700, 6
48.750, 6
48.800, 8
48.850, 6
48.900, 9
48.950, 9
49.000,10
49.050,13
49.100,12
49.150,11
49.200,14
49.250,14
49.300,13
49.350,12
49.400,13
49.450,10
49.500,10
49.550, 8
49.600, 9
49.650, 9
49.700, 8
49.750, 8
49.800, 9
49.850, 8
49.900, 9
49.950, 9
50.000, 9
50.050,11
50.100,11
50.150,10
50.200,11
50.250,13
50.300,11
50.350,11
50.400, 9
50.450, 9
50.500, 9
50.550, 8
50.600, 8
50.650, 8
50.700, 8
50.750, 9
50.800,10
50.850,11
50.900,10
50.950,10
51.000,11
51.050,10
51.100,11
51.150,10
51.200,10
51.250,10
51.300,10
51.350,10
51.400, 8
51.450, 8
51.500, 9
51.550,10
51.600, 9
51.650,10
51.700,10
51.750, 9
51.800, 9
51.850, 9
51.900,10
51.950, 8
52.000, 8
52.050, 9
52.100, 8
52.150, 8
52.200, 6
52.250, 7
52.300, 7
52.350, 7
52.400, 7
52.450, 7
52.500, 7
52.550, 6
52.600, 7
52.650, 7
52.700, 8
52.750, 7
52.800, 9
52.850, 9
52.900, 9
52.950,10
53.000,10
53.050,11
53.100, 9
53.150, 9
53.200, 8
53.250,10
53.300, 9
53.350, 7
53.400, 8
53.450, 8
53.500, 7
53.550, 7
53.600, 7
53.650, 7
53.700, 7
53.750, 8
53.800, 8
53.850, 9
53.900, 9
53.950, 8
54.000, 9
54.050, 8
54.100, 9
54.150, 9
54.200, 7
54.250, 8
54.300, 7
54.350, 8
54.400, 8
54.450, 8
54.500, 8
54.550, 9
54.600, 8
54.650, 9
54.700, 9
54.750,10
54.800, 9
54.850, 7
54.900, 7
54.950, 8
55.000,10
55.050, 9
55.100, 9
55.150, 9
55.200, 9
55.250, 9
55.300,10
55.350,10
55.400,10
55.450, 9
55.500,10
55.550,10
55.600,10
55.650,11
55.700,10
55.750, 9
55.800,10
55.850,10
55.900,10
55.950, 9
56.000, 8
56.050, 8
56.100, 8
56.150, 7
56.200, 7
56.250, 8
56.300, 8
56.350, 8
56.400, 7
56.450, 7
56.500, 8
56.550, 7
56.600, 8
56.650, 8
56.700, 7
56.750, 7
56.800, 8
56.850, 8
56.900, 7
56.950, 8
57.000, 7
57.050, 7
57.100, 7
57.150, 7
57.200, 7
57.250, 7
57.300, 6
57.350, 6
57.400, 7
57.450, 7
57.500, 6
57.550, 7
57.600, 6
57.650, 6
57.700, 5
57.750, 6
57.800, 5
57.850, 6
57.900, 6
57.950, 7
58.000, 7
58.050, 6
58.100, 6
58.150, 5
58.200, 6
58.250, 5
58.300, 6
58.350, 6
58.400, 5
58.450, 6
58.500, 5
58.550, 5
58.600, 5
58.650, 5
58.700, 5
58.750, 6
58.800, 5
58.850, 5
58.900, 5
58.950, 5
59.000, 5
59.050, 5
59.100, 6
59.150, 6
59.200, 5
59.250, 5
59.300, 5
59.350, 5
59.400, 5
59.450, 5
59.500, 5
59.550, 5
59.600, 6
59.650, 5
59.700, 5
59.750, 5
59.800, 6
59.850, 5
59.900, 6
59.950, 5
60.000, 6