File: code/data/data_source2/Ti_GIXRD - Ti-100nm.csv
[Measurement conditions]
Sample identification,
Comment - 1,"Configuration=Filmes Finos 19_1_2015, Owner=User-1, Creation date=19/01/2015 21:17:15"
Comment - 2,"Goniometer=PW3050/60 (Theta/Theta); Minimum step size 2Theta:0.001; Minimum step size Omega:0.001"
Comment - 3,"Sample stage=PW3071/xx Bracket"
Comment - 4,"Diffractometer system=XPERT-PRO"
Comment - 5,"Measurement program=C:\PANalytical\Data Collector\Programs\GrazingIncidence.xrdmp, Identifier={1B0B265C-F63A-42C6-ADDC-A5C5FE219C86}"
Anode material,Cu
K-Alpha1 wavelength,1.5405980
K-Alpha2 wavelength,1.5444260
Ratio K-Alpha2/K-Alpha1,0.500
Divergence slit,Fixed,0.10mm
Receiving slit,0.10
Monochromator used,YES
Generator voltage, 40
Tube current, 40
File date and time,31/Jan/2018 11:48
Unit cell,
h k l, 0 0 0
Scan axis,2Theta
Scan range,15.000,55.000
Scan step size,0.0250000
No. of points, 1601
Scan type,STEP
Omega,2.000
Time per step,10.000
[Scan points]
Angle,Intensity
15.000,44
15.050,45
15.100,43
15.150,46
15.200,47
15.250,43
15.300,45
15.350,46
15.400,42
15.450,44
15.500,44
15.550,43
15.600,45
15.650,40
15.700,46
15.750,45
15.800,43
15.850,42
15.900,42
15.950,45
16.000,42
16.050,47
16.100,46
16.150,43
16.200,37
16.250,42
16.300,40
16.350,41
16.400,40
16.450,42
16.500,39
16.550,45
16.600,44
16.650,42
16.700,42
16.750,39
16.800,39
16.850,38
16.900,40
16.950,45
17.000,42
17.050,41
17.100,39
17.150,41
17.200,37
17.250,36
17.300,40
17.350,40
17.400,41
17.450,40
17.500,38
17.550,38
17.600,39
17.650,35
17.700,39
17.750,35
17.800,34
17.850,39
17.900,39
17.950,38
18.000,39
18.050,38
18.100,36
18.150,37
18.200,39
18.250,37
18.300,35
18.350,35
18.400,37
18.450,37
18.500,34
18.550,39
18.600,35
18.650,41
18.700,36
18.750,35
18.800,39
18.850,36
18.900,37
18.950,36
19.000,38
19.050,34
19.100,36
19.150,37
19.200,36
19.250,36
19.300,36
19.350,36
19.400,33
19.450,34
19.500,33
19.550,35
19.600,35
19.650,39
19.700,32
19.750,37
19.800,37
19.850,34
19.900,35
19.950,34
20.000,34
20.050,34
20.100,31
20.150,37
20.200,35
20.250,34
20.300,34
20.350,33
20.400,32
20.450,31
20.500,35
20.550,34
20.600,31
20.650,33
20.700,33
20.750,32
20.800,31
20.850,32
20.900,32
20.950,33
21.000,33
21.050,31
21.100,32
21.150,31
21.200,31
21.250,30
21.300,34
21.350,32
21.400,28
21.450,30
21.500,27
21.550,29
21.600,29
21.650,31
21.700,31
21.750,32
21.800,29
21.850,28
21.900,32
21.950,32
22.000,29
22.050,29
22.100,31
22.150,29
22.200,32
22.250,32
22.300,29
22.350,28
22.400,31
22.450,29
22.500,27
22.550,28
22.600,28
22.650,26
22.700,28
22.750,27
22.800,26
22.850,32
22.900,29
22.950,26
23.000,26
23.050,24
23.100,24
23.150,26
23.200,24
23.250,27
23.300,25
23.350,22
23.400,27
23.450,26
23.500,27
23.550,25
23.600,21
23.650,24
23.700,22
23.750,23
23.800,24
23.850,23
23.900,23
23.950,24
24.000,22
24.050,27
24.100,22
24.150,21
24.200,21
24.250,24
24.300,23
24.350,22
24.400,20
24.450,21
24.500,21
24.550,22
24.600,21
24.650,21
24.700,21
24.750,23
24.800,20
24.850,19
24.900,19
24.950,21
25.000,19
25.050,20
25.100,21
25.150,20
25.200,22
25.250,20
25.300,20
25.350,21
25.400,22
25.450,20
25.500,21
25.550,20
25.600,20
25.650,22
25.700,17
25.750,19
25.800,17
25.850,17
25.900,19
25.950,17
26.000,18
26.050,20
26.100,15
26.150,18
26.200,17
26.250,19
26.300,19
26.350,17
26.400,18
26.450,15
26.500,16
26.550,17
26.600,17
26.650,16
26.700,14
26.750,16
26.800,16
26.850,17
26.900,15
26.950,17
27.000,17
27.050,17
27.100,20
27.150,16
27.200,17
27.250,16
27.300,15
27.350,16
27.400,16
27.450,18
27.500,16
27.550,15
27.600,13
27.650,13
27.700,14
27.750,15
27.800,15
27.850,14
27.900,15
27.950,14
28.000,14
28.050,16
28.100,14
28.150,16
28.200,13
28.250,13
28.300,14
28.350,14
28.400,13
28.450,16
28.500,16
28.550,14
28.600,13
28.650,14
28.700,13
28.750,13
28.800,15
28.850,14
28.900,12
28.950,14
29.000,12
29.050,15
29.100,13
29.150,14
29.200,12
29.250,12
29.300,14
29.350,12
29.400,13
29.450,12
29.500,10
29.550,14
29.600,14
29.650,12
29.700,11
29.750,12
29.800,13
29.850,11
29.900,14
29.950,15
30.000,13
30.050,11
30.100,13
30.150,12
30.200,11
30.250,13
30.300,12
30.350,13
30.400,12
30.450,11
30.500,12
30.550,12
30.600,10
30.650,12
30.700,12
30.750,13
30.800,11
30.850,13
30.900,11
30.950,10
31.000,11
31.050,11
31.100,14
31.150,10
31.200,11
31.250,12
31.300,12
31.350,10
31.400,10
31.450,11
31.500, 9
31.550,11
31.600,10
31.650,11
31.700,11
31.750,10
31.800,10
31.850, 9
31.900,12
31.950,11
32.000,10
32.050,11
32.100,11
32.150,10
32.200,10
32.250,10
32.300,10
32.350,10
32.400, 9
32.450,11
32.500,10
32.550, 9
32.600,10
32.650, 9
32.700,10
32.750,10
32.800,10
32.850, 8
32.900,10
32.950, 9
33.000, 9
33.050, 8
33.100, 8
33.150, 8
33.200,10
33.250, 8
33.300,10
33.350, 7
33.400, 8
33.450, 8
33.500,11
33.550,10
33.600, 9
33.650, 7
33.700, 9
33.750, 8
33.800, 7
33.850,10
33.900, 9
33.950, 8
34.000, 8
34.050, 9
34.100, 9
34.150, 8
34.200, 9
34.250, 9
34.300, 9
34.350, 8
34.400, 8
34.450, 9
34.500, 8
34.550,10
34.600, 9
34.650, 9
34.700, 9
34.750, 9
34.800, 7
34.850, 9
34.900, 7
34.950,10
35.000, 8
35.050, 8
35.100, 9
35.150, 6
35.200, 8
35.250, 7
35.300, 8
35.350,10
35.400, 6
35.450, 8
35.500, 8
35.550, 8
35.600, 7
35.650, 7
35.700, 8
35.750, 9
35.800, 7
35.850, 8
35.900, 9
35.950, 9
36.000, 8
36.050,10
36.100, 8
36.150, 8
36.200, 8
36.250, 8
36.300, 9
36.350, 8
36.400, 9
36.450, 6
36.500, 8
36.550, 9
36.600, 7
36.650,10
36.700,10
36.750,10
36.800,12
36.850,11
36.900,10
36.950,11
37.000,12
37.050,13
37.100,13
37.150,11
37.200,10
37.250,10
37.300,11
37.350,12
37.400,10
37.450, 9
37.500, 7
37.550, 8
37.600, 9
37.650, 8
37.700, 9
37.750, 7
37.800, 7
37.850, 6
37.900, 8
37.950, 6
38.000, 7
38.050, 8
38.100, 7
38.150, 6
38.200, 6
38.250, 7
38.300, 7
38.350, 8
38.400, 6
38.450, 8
38.500, 6
38.550, 6
38.600, 6
38.650, 7
38.700, 7
38.750, 7
38.800, 7
38.850, 6
38.900, 6
38.950, 6
39.000, 6
39.050, 8
39.100, 7
39.150, 7
39.200, 6
39.250, 7
39.300, 6
39.350, 7
39.400, 6
39.450, 7
39.500, 7
39.550, 7
39.600, 7
39.650, 5
39.700, 5
39.750, 6
39.800, 7
39.850, 7
39.900, 7
39.950, 7
40.000, 5
40.050, 4
40.100, 6
40.150, 7
40.200, 7
40.250, 7
40.300, 5
40.350, 6
40.400, 6
40.450, 7
40.500, 4
40.550, 6
40.600, 6
40.650, 7
40.700, 6
40.750, 7
40.800, 5
40.850, 6
40.900, 6
40.950, 7
41.000, 5
41.050, 6
41.100, 7
41.150, 7
41.200, 5
41.250, 7
41.300, 5
41.350, 6
41.400, 6
41.450, 5
41.500, 7
41.550, 8
41.600, 6
41.650, 6
41.700, 5
41.750, 6
41.800, 6
41.850, 7
41.900, 6
41.950, 7
42.000, 8
42.050, 6
42.100, 6
42.150, 8
42.200, 6
42.250, 5
42.300, 8
42.350, 7
42.400, 7
42.450, 8
42.500,10
42.550, 8
42.600, 9
42.650, 7
42.700, 9
42.750, 8
42.800, 8
42.850,11
42.900, 9
42.950,12
43.000,11
43.050,12
43.100,10
43.150,12
43.200,12
43.250,11
43.300,10
43.350,10
43.400,10
43.450,11
43.500,10
43.550,10
43.600, 8
43.650,11
43.700, 9
43.750, 8
43.800, 9
43.850, 8
43.900, 7
43.950, 9
44.000, 6
44.050, 7
44.100, 7
44.150, 7
44.200, 7
44.250, 6
44.300, 6
44.350, 7
44.400, 6
44.450, 7
44.500, 6
44.550, 7
44.600, 6
44.650, 8
44.700, 5
44.750, 7
44.800, 6
44.850, 6
44.900, 5
44.950, 7
45.000, 6
45.050, 5
45.100, 6
45.150, 5
45.200, 7
45.250, 6
45.300, 5
45.350, 5
45.400, 6
45.450, 5
45.500, 5
45.550, 6
45.600, 7
45.650, 7
45.700, 7
45.750, 5
45.800, 6
45.850, 6
45.900, 6
45.950, 6
46.000, 6
46.050, 6
46.100, 7
46.150, 5
46.200, 5
46.250, 7
46.300, 6
46.350, 7
46.400, 6
46.450, 5
46.500, 5
46.550, 5
46.600, 5
46.650, 6
46.700, 6
46.750, 6
46.800, 5
46.850, 5
46.900, 5
46.950, 6
47.000, 6
47.050, 5
47.100, 6
47.150, 5
47.200, 6
47.250, 6
47.300, 6
47.350, 5
47.400, 6
47.450, 4
47.500, 7
47.550, 6
47.600, 6
47.650, 5
47.700, 4
47.750, 5
47.800, 6
47.850, 5
47.900, 6
47.950, 5
48.000, 6
48.050, 5
48.100, 5
48.150, 7
48.200, 5
48.250, 6
48.300, 4
48.350, 6
48.400, 6
48.450, 6
48.500, 5
48.550, 6
48.600, 6
48.650, 6
48.700, 7
48.750, 6
48.800, 7
48.850, 4
48.900, 6
48.950, 5
49.000, 5
49.050, 6
49.100, 5
49.150, 5
49.200, 5
49.250, 6
49.300, 5
49.350, 5
49.400, 5
49.450, 5
49.500, 5
49.550, 6
49.600, 7
49.650, 5
49.700, 7
49.750, 6
49.800, 6
49.850, 6
49.900, 7
49.950, 6
50.000, 6
50.050, 6
50.100, 6
50.150, 6
50.200, 7
50.250, 6
50.300, 6
50.350, 6
50.400, 4
50.450, 5
50.500, 6
50.550, 5
50.600, 7
50.650, 6
50.700, 4
50.750, 6
50.800, 6
50.850, 8
50.900, 6
50.950, 6
51.000, 8
51.050, 7
51.100, 4
51.150, 6
51.200, 8
51.250, 9
51.300, 6
51.350, 7
51.400, 8
51.450, 8
51.500, 7
51.550, 8
51.600, 7
51.650, 7
51.700, 9
51.750, 8
51.800,10
51.850, 7
51.900, 7
51.950, 7
52.000, 8
52.050, 8
52.100, 8
52.150, 7
52.200, 9
52.250, 6
52.300, 8
52.350, 6
52.400, 7
52.450, 8
52.500, 8
52.550, 9
52.600, 9
52.650, 8
52.700, 9
52.750, 7
52.800, 9
52.850,10
52.900, 9
52.950, 8
53.000, 9
53.050,10
53.100,10
53.150,10
53.200,10
53.250,10
53.300,10
53.350,12
53.400,10
53.450,10
53.500,12
53.550,11
53.600,11
53.650,13
53.700,12
53.750,10
53.800,10
53.850,12
53.900,10
53.950,15
54.000,13
54.050,12
54.100,14
54.150,14
54.200,14
54.250,15
54.300,15
54.350,16
54.400,17
54.450,33
54.500,128
54.550,194
54.600,195
54.650,176
54.700,152
54.750,128
54.800,86
54.850,62
54.900,42
54.950,33
55.000,27