File: code/data/data_source2/Ti_KL305_2_T.csv
[Measurement conditions]
Sample identification,
Comment - 1,"Configuration=Filmes Finos 19_1_2015, Owner=User-1, Creation date=19/01/2015 21:17:15"
Comment - 2,"Goniometer=PW3050/60 (Theta/Theta); Minimum step size 2Theta:0.001; Minimum step size Omega:0.001"
Comment - 3,"Sample stage=PW3071/xx Bracket"
Comment - 4,"Diffractometer system=XPERT-PRO"
Comment - 5,"Measurement program=C:\PANalytical\Data Collector\Programs\GrazingIncidence.xrdmp, Identifier={1188D76C-BB31-48B4-B1BA-2C0B24B5F296}"
Anode material,Cu
K-Alpha1 wavelength,1.5405980
K-Alpha2 wavelength,1.5444260
Ratio K-Alpha2/K-Alpha1,0.500
Divergence slit,Fixed,0.76mm
Receiving slit,0.10
Monochromator used,YES
Generator voltage, 40
Tube current, 40
File date and time,12/Jun/2018 17:30
Unit cell,
h k l, 0 0 0
Scan axis,2Theta
Scan range,20.00000,71.72500
Scan step size,0.0250000
No. of points, 2069
Scan type,CONTINUOUS
Omega,5.000
Time per step,17.00
[Scan points]
Angle,Intensity
20.01250,463.0
20.06250,451.0
20.11250,490.0
20.16250,480.0
20.21250,474.0
20.26250,449.0
20.31250,455.0
20.36250,427.0
20.41250,464.0
20.46250,500.0
20.51250,443.0
20.56250,428.0
20.61250,490.0
20.66250,456.0
20.71250,435.0
20.76250,440.0
20.81250,445.0
20.86250,453.0
20.91250,402.0
20.96250,436.0
21.01250,451.0
21.06250,427.0
21.11250,434.0
21.16250,469.0
21.21250,371.0
21.26250,419.0
21.31250,408.0
21.36250,425.0
21.41250,405.0
21.46250,440.0
21.51250,438.0
21.56250,372.0
21.61250,409.0
21.66250,392.0
21.71250,374.0
21.76250,408.0
21.81250,423.0
21.86250,362.0
21.91250,387.0
21.96250,372.0
22.01250,383.0
22.06250,384.0
22.11250,403.0
22.16250,403.0
22.21250,408.0
22.26250,379.0
22.31250,400.0
22.36250,401.0
22.41250,422.0
22.46250,384.0
22.51250,416.0
22.56250,395.0
22.61250,422.0
22.66250,431.0
22.71250,389.0
22.76250,415.0
22.81250,396.0
22.86250,412.0
22.91250,391.0
22.96250,370.0
23.01250,433.0
23.06250,393.0
23.11250,377.0
23.16250,381.0
23.21250,376.0
23.26250,397.0
23.31250,349.0
23.36250,412.0
23.41250,379.0
23.46250,395.0
23.51250,380.0
23.56250,388.0
23.61250,423.0
23.66250,421.0
23.71250,419.0
23.76250,445.0
23.81250,414.0
23.86250,419.0
23.91250,439.0
23.96250,433.0
24.01250,459.0
24.06250,469.0
24.11250,436.0
24.16250,475.0
24.21250,441.0
24.26250,500.0
24.31250,456.0
24.36250,499.0
24.41250,501.0
24.46250,561.0
24.51250,580.0
24.56250,639.0
24.61250,666.0
24.66250,740.0
24.71250,861.0
24.76250,1088.0
24.81250,1346.0
24.86250,1721.0
24.91250,2505.0
24.96250,3464.0
25.01250,4928.0
25.06250,7064.0
25.11250,10120.0
25.16250,12917.0
25.21250,14810.0
25.26250,15500.0
25.31250,14346.0
25.36250,11467.0
25.41250,8046.0
25.46250,5507.0
25.51250,3461.0
25.56250,2284.0
25.61250,1536.0
25.66250,1233.0
25.71250,990.0
25.76250,832.0
25.81250,723.0
25.86250,682.0
25.91250,614.0
25.96250,560.0
26.01250,524.0
26.06250,449.0
26.11250,518.0
26.16250,451.0
26.21250,468.0
26.26250,455.0
26.31250,456.0
26.36250,474.0
26.41250,432.0
26.46250,425.0
26.51250,457.0
26.56250,425.0
26.61250,407.0
26.66250,413.0
26.71250,425.0
26.76250,443.0
26.81250,422.0
26.86250,430.0
26.91250,451.0
26.96250,476.0
27.01250,468.0
27.06250,501.0
27.11250,520.0
27.16250,531.0
27.21250,544.0
27.26250,578.0
27.31250,540.0
27.36250,584.0
27.41250,602.0
27.46250,542.0
27.51250,518.0
27.56250,475.0
27.61250,503.0
27.66250,429.0
27.71250,441.0
27.76250,442.0
27.81250,388.0
27.86250,404.0
27.91250,375.0
27.96250,374.0
28.01250,386.0
28.06250,368.0
28.11250,367.0
28.16250,353.0
28.21250,348.0
28.26250,347.0
28.31250,376.0
28.36250,294.0
28.41250,336.0
28.46250,313.0
28.51250,296.0
28.56250,334.0
28.61250,306.0
28.66250,338.0
28.71250,298.0
28.76250,325.0
28.81250,314.0
28.86250,302.0
28.91250,316.0
28.96250,316.0
29.01250,280.0
29.06250,282.0
29.11250,292.0
29.16250,284.0
29.21250,320.0
29.26250,302.0
29.31250,313.0
29.36250,290.0
29.41250,329.0
29.46250,345.0
29.51250,318.0
29.56250,285.0
29.61250,300.0
29.66250,272.0
29.71250,288.0
29.76250,287.0
29.81250,306.0
29.86250,287.0
29.91250,315.0
29.96250,274.0
30.01250,306.0
30.06250,301.0
30.11250,283.0
30.16250,301.0
30.21250,278.0
30.26250,296.0
30.31250,294.0
30.36250,295.0
30.41250,295.0
30.46250,303.0
30.51250,298.0
30.56250,286.0
30.61250,321.0
30.66250,334.0
30.71250,320.0
30.76250,319.0
30.81250,333.0
30.86250,321.0
30.91250,296.0
30.96250,294.0
31.01250,297.0
31.06250,270.0
31.11250,290.0
31.16250,295.0
31.21250,297.0
31.26250,280.0
31.31250,266.0
31.36250,267.0
31.41250,287.0
31.46250,272.0
31.51250,266.0
31.56250,263.0
31.61250,261.0
31.66250,254.0
31.71250,244.0
31.76250,296.0
31.81250,266.0
31.86250,268.0
31.91250,275.0
31.96250,256.0
32.01250,275.0
32.06250,269.0
32.11250,292.0
32.16250,214.0
32.21250,284.0
32.26250,241.0
32.31250,237.0
32.36250,247.0
32.41250,262.0
32.46250,225.0
32.51250,226.0
32.56250,283.0
32.61250,239.0
32.66250,259.0
32.71250,253.0
32.76250,261.0
32.81250,239.0
32.86250,241.0
32.91250,264.0
32.96250,285.0
33.01250,251.0
33.06250,262.0
33.11250,249.0
33.16250,262.0
33.21250,234.0
33.26250,236.0
33.31250,252.0
33.36250,275.0
33.41250,247.0
33.46250,275.0
33.51250,271.0
33.56250,247.0
33.61250,236.0
33.66250,252.0
33.71250,249.0
33.76250,242.0
33.81250,263.0
33.86250,259.0
33.91250,281.0
33.96250,300.0
34.01250,270.0
34.06250,276.0
34.11250,310.0
34.16250,260.0
34.21250,281.0
34.26250,306.0
34.31250,295.0
34.36250,359.0
34.41250,356.0
34.46250,382.0
34.51250,425.0
34.56250,478.0
34.61250,591.0
34.66250,722.0
34.71250,889.0
34.76250,1256.0
34.81250,1815.0
34.86250,2375.0
34.91250,3235.0
34.96250,3784.0
35.01250,4298.0
35.06250,4495.0
35.11250,4012.0
35.16250,3323.0
35.21250,2561.0
35.26250,1908.0
35.31250,1410.0
35.36250,1003.0
35.41250,820.0
35.46250,625.0
35.51250,538.0
35.56250,504.0
35.61250,495.0
35.66250,413.0
35.71250,443.0
35.76250,418.0
35.81250,452.0
35.86250,412.0
35.91250,443.0
35.96250,435.0
36.01250,408.0
36.06250,413.0
36.11250,447.0
36.16250,446.0
36.21250,438.0
36.26250,388.0
36.31250,410.0
36.36250,459.0
36.41250,425.0
36.46250,462.0
36.51250,433.0
36.56250,498.0
36.61250,484.0
36.66250,500.0
36.71250,584.0
36.76250,594.0
36.81250,665.0
36.86250,686.0
36.91250,661.0
36.96250,701.0
37.01250,772.0
37.06250,701.0
37.11250,716.0
37.16250,686.0
37.21250,717.0
37.26250,728.0
37.31250,811.0
37.36250,790.0
37.41250,916.0
37.46250,959.0
37.51250,1011.0
37.56250,1132.0
37.61250,1246.0
37.66250,1332.0
37.71250,1401.0
37.76250,1566.0
37.81250,1641.0
37.86250,1667.0
37.91250,1780.0
37.96250,1965.0
38.01250,2392.0
38.06250,3120.0
38.11250,4287.0
38.16250,6212.0
38.21250,8721.0
38.26250,11656.0
38.31250,13929.0
38.36250,15214.0
38.41250,14983.0
38.46250,13112.0
38.51250,10324.0
38.56250,7506.0
38.61250,5100.0
38.66250,3447.0
38.71250,2373.0
38.76250,1652.0
38.81250,1292.0
38.86250,1113.0
38.91250,968.0
38.96250,922.0
39.01250,832.0
39.06250,836.0
39.11250,860.0
39.16250,813.0
39.21250,811.0
39.26250,850.0
39.31250,879.0
39.36250,935.0
39.41250,979.0
39.46250,1088.0
39.51250,1218.0
39.56250,1380.0
39.61250,1672.0
39.66250,2001.0
39.71250,2702.0
39.76250,3663.0
39.81250,5512.0
39.86250,7865.0
39.91250,11235.0
39.96250,15291.0
40.01250,19760.0
40.06250,23456.0
40.11250,25149.0
40.16250,24040.0
40.21250,21388.0
40.26250,17229.0
40.31250,12867.0
40.36250,9280.0
40.41250,6263.0
40.46250,4243.0
40.51250,2874.0
40.56250,2030.0
40.61250,1517.0
40.66250,1137.0
40.71250,973.0
40.76250,855.0
40.81250,717.0
40.86250,638.0
40.91250,541.0
40.96250,570.0
41.01250,508.0
41.06250,469.0
41.11250,452.0
41.16250,446.0
41.21250,430.0
41.26250,401.0
41.31250,391.0
41.36250,382.0
41.41250,355.0
41.46250,348.0
41.51250,327.0
41.56250,324.0
41.61250,294.0
41.66250,295.0
41.71250,302.0
41.76250,272.0
41.81250,277.0
41.86250,303.0
41.91250,305.0
41.96250,300.0
42.01250,299.0
42.06250,255.0
42.11250,274.0
42.16250,277.0
42.21250,292.0
42.26250,248.0
42.31250,245.0
42.36250,273.0
42.41250,288.0
42.46250,258.0
42.51250,270.0
42.56250,243.0
42.61250,257.0
42.66250,254.0
42.71250,247.0
42.76250,250.0
42.81250,241.0
42.86250,253.0
42.91250,260.0
42.96250,209.0
43.01250,226.0
43.06250,256.0
43.11250,223.0
43.16250,229.0
43.21250,272.0
43.26250,233.0
43.31250,257.0
43.36250,258.0
43.41250,227.0
43.46250,251.0
43.51250,258.0
43.56250,237.0
43.61250,220.0
43.66250,208.0
43.71250,221.0
43.76250,198.0
43.81250,224.0
43.86250,225.0
43.91250,224.0
43.96250,227.0
44.01250,203.0
44.06250,203.0
44.11250,191.0
44.16250,212.0
44.21250,193.0
44.26250,170.0
44.31250,214.0
44.36250,216.0
44.41250,205.0
44.46250,188.0
44.51250,198.0
44.56250,187.0
44.61250,213.0
44.66250,187.0
44.71250,161.0
44.76250,198.0
44.81250,175.0
44.86250,182.0
44.91250,160.0
44.96250,173.0
45.01250,173.0
45.06250,181.0
45.11250,176.0
45.16250,159.0
45.21250,158.0
45.26250,175.0
45.31250,176.0
45.36250,190.0
45.41250,166.0
45.46250,158.0
45.51250,159.0
45.56250,193.0
45.61250,190.0
45.66250,188.0
45.71250,140.0
45.76250,184.0
45.81250,185.0
45.86250,173.0
45.91250,158.0
45.96250,187.0
46.01250,189.0
46.06250,170.0
46.11250,175.0
46.16250,187.0
46.21250,168.0
46.26250,146.0
46.31250,195.0
46.36250,169.0
46.41250,171.0
46.46250,174.0
46.51250,170.0
46.56250,180.0
46.61250,177.0
46.66250,160.0
46.71250,180.0
46.76250,201.0
46.81250,212.0
46.86250,170.0
46.91250,181.0
46.96250,226.0
47.01250,186.0
47.06250,239.0
47.11250,235.0
47.16250,241.0
47.21250,237.0
47.26250,235.0
47.31250,278.0
47.36250,286.0
47.41250,322.0
47.46250,328.0
47.51250,422.0
47.56250,506.0
47.61250,576.0
47.66250,817.0
47.71250,1070.0
47.76250,1535.0
47.81250,2187.0
47.86250,3026.0
47.91250,3937.0
47.96250,4452.0
48.01250,4605.0
48.06250,4258.0
48.11250,3600.0
48.16250,3005.0
48.21250,2124.0
48.26250,1505.0
48.31250,1002.0
48.36250,761.0
48.41250,556.0
48.46250,500.0
48.51250,357.0
48.56250,319.0
48.61250,277.0
48.66250,301.0
48.71250,261.0
48.76250,231.0
48.81250,192.0
48.86250,201.0
48.91250,189.0
48.96250,191.0
49.01250,194.0
49.06250,186.0
49.11250,192.0
49.16250,189.0
49.21250,135.0
49.26250,181.0
49.31250,205.0
49.36250,173.0
49.41250,168.0
49.46250,168.0
49.51250,175.0
49.56250,142.0
49.61250,139.0
49.66250,154.0
49.71250,142.0
49.76250,174.0
49.81250,150.0
49.86250,159.0
49.91250,160.0
49.96250,134.0
50.01250,156.0
50.06250,141.0
50.11250,158.0
50.16250,150.0
50.21250,146.0
50.26250,146.0
50.31250,169.0
50.36250,161.0
50.41250,163.0
50.46250,144.0
50.51250,160.0
50.56250,160.0
50.61250,160.0
50.66250,139.0
50.71250,145.0
50.76250,151.0
50.81250,164.0
50.86250,156.0
50.91250,126.0
50.96250,141.0
51.01250,169.0
51.06250,156.0
51.11250,168.0
51.16250,173.0
51.21250,150.0
51.26250,169.0
51.31250,164.0
51.36250,168.0
51.41250,183.0
51.46250,172.0
51.51250,152.0
51.56250,156.0
51.61250,177.0
51.66250,196.0
51.71250,171.0
51.76250,187.0
51.81250,190.0
51.86250,201.0
51.91250,191.0
51.96250,197.0
52.01250,208.0
52.06250,213.0
52.11250,207.0
52.16250,232.0
52.21250,254.0
52.26250,283.0
52.31250,324.0
52.36250,279.0
52.41250,393.0
52.46250,407.0
52.51250,523.0
52.56250,621.0
52.61250,833.0
52.66250,1067.0
52.71250,1524.0
52.76250,2034.0
52.81250,2546.0
52.86250,3026.0
52.91250,3532.0
52.96250,3744.0
53.01250,3603.0
53.06250,3345.0
53.11250,2784.0
53.16250,2241.0
53.21250,1757.0
53.26250,1388.0
53.31250,1138.0
53.36250,866.0
53.41250,735.0
53.46250,553.0
53.51250,590.0
53.56250,583.0
53.61250,585.0
53.66250,620.0
53.71250,694.0
53.76250,751.0
53.81250,801.0
53.86250,817.0
53.91250,802.0
53.96250,772.0
54.01250,813.0
54.06250,699.0
54.11250,667.0
54.16250,623.0
54.21250,588.0
54.26250,534.0
54.31250,483.0
54.36250,479.0
54.41250,465.0
54.46250,472.0
54.51250,456.0
54.56250,453.0
54.61250,481.0
54.66250,550.0
54.71250,622.0
54.76250,681.0
54.81250,934.0
54.86250,1134.0
54.91250,1320.0
54.96250,1385.0
55.01250,1462.0
55.06250,1469.0
55.11250,1386.0
55.16250,1143.0
55.21250,928.0
55.26250,749.0
55.31250,576.0
55.36250,470.0
55.41250,411.0
55.46250,336.0
55.51250,279.0
55.56250,254.0
55.61250,245.0
55.66250,231.0
55.71250,253.0
55.76250,215.0
55.81250,211.0
55.86250,226.0
55.91250,208.0
55.96250,200.0
56.01250,201.0
56.06250,196.0
56.11250,194.0
56.16250,240.0
56.21250,208.0
56.26250,201.0
56.31250,217.0
56.36250,192.0
56.41250,193.0
56.46250,192.0
56.51250,182.0
56.56250,178.0
56.61250,174.0
56.66250,175.0
56.71250,176.0
56.76250,168.0
56.81250,167.0
56.86250,187.0
56.91250,186.0
56.96250,179.0
57.01250,173.0
57.06250,165.0
57.11250,174.0
57.16250,158.0
57.21250,160.0
57.26250,140.0
57.31250,161.0
57.36250,169.0
57.41250,145.0
57.46250,164.0
57.51250,158.0
57.56250,155.0
57.61250,146.0
57.66250,142.0
57.71250,152.0
57.76250,162.0
57.81250,152.0
57.86250,148.0
57.91250,154.0
57.96250,145.0
58.01250,129.0
58.06250,153.0
58.11250,157.0
58.16250,153.0
58.21250,139.0
58.26250,137.0
58.31250,134.0
58.36250,147.0
58.41250,135.0
58.46250,149.0
58.51250,143.0
58.56250,153.0
58.61250,130.0
58.66250,128.0
58.71250,140.0
58.76250,162.0
58.81250,156.0
58.86250,125.0
58.91250,133.0
58.96250,147.0
59.01250,139.0
59.06250,140.0
59.11250,155.0
59.16250,135.0
59.21250,143.0
59.26250,140.0
59.31250,164.0
59.36250,162.0
59.41250,150.0
59.46250,148.0
59.51250,142.0
59.56250,162.0
59.61250,141.0
59.66250,148.0
59.71250,152.0
59.76250,146.0
59.81250,158.0
59.86250,153.0
59.91250,166.0
59.96250,184.0
60.01250,148.0
60.06250,164.0
60.11250,156.0
60.16250,165.0
60.21250,153.0
60.26250,165.0
60.31250,144.0
60.36250,163.0
60.41250,162.0
60.46250,149.0
60.51250,142.0
60.56250,155.0
60.61250,148.0
60.66250,171.0
60.71250,172.0
60.76250,140.0
60.81250,158.0
60.86250,162.0
60.91250,167.0
60.96250,177.0
61.01250,179.0
61.06250,171.0
61.11250,190.0
61.16250,174.0
61.21250,162.0
61.26250,175.0
61.31250,181.0
61.36250,179.0
61.41250,206.0
61.46250,169.0
61.51250,209.0
61.56250,225.0
61.61250,229.0
61.66250,202.0
61.71250,220.0
61.76250,273.0
61.81250,312.0
61.86250,352.0
61.91250,376.0
61.96250,430.0
62.01250,437.0
62.06250,495.0
62.11250,545.0
62.16250,532.0
62.21250,507.0
62.26250,551.0
62.31250,609.0
62.36250,609.0
62.41250,734.0
62.46250,820.0
62.51250,994.0
62.56250,1178.0
62.61250,1415.0
62.66250,1685.0
62.71250,1860.0
62.76250,2107.0
62.81250,2133.0
62.86250,2315.0
62.91250,2317.0
62.96250,2118.0
63.01250,1992.0
63.06250,1764.0
63.11250,1564.0
63.16250,1221.0
63.21250,1069.0
63.26250,838.0
63.31250,683.0
63.36250,596.0
63.41250,490.0
63.46250,400.0
63.51250,349.0
63.56250,320.0
63.61250,308.0
63.66250,275.0
63.71250,257.0
63.76250,271.0
63.81250,245.0
63.86250,255.0
63.91250,257.0
63.96250,214.0
64.01250,211.0
64.06250,201.0
64.11250,215.0
64.16250,197.0
64.21250,202.0
64.26250,196.0
64.31250,181.0
64.36250,206.0
64.41250,190.0
64.46250,194.0
64.51250,188.0
64.56250,186.0
64.61250,159.0
64.66250,178.0
64.71250,174.0
64.76250,171.0
64.81250,170.0
64.86250,197.0
64.91250,163.0
64.96250,167.0
65.01250,149.0
65.06250,149.0
65.11250,155.0
65.16250,155.0
65.21250,157.0
65.26250,160.0
65.31250,147.0
65.36250,154.0
65.41250,146.0
65.46250,163.0
65.51250,168.0
65.56250,124.0
65.61250,148.0
65.66250,148.0
65.71250,155.0
65.76250,151.0
65.81250,158.0
65.86250,134.0
65.91250,134.0
65.96250,136.0
66.01250,141.0
66.06250,146.0
66.11250,154.0
66.16250,143.0
66.21250,156.0
66.26250,141.0
66.31250,165.0
66.36250,162.0
66.41250,142.0
66.46250,131.0
66.51250,129.0
66.56250,135.0
66.61250,154.0
66.66250,163.0
66.71250,146.0
66.76250,160.0
66.81250,155.0
66.86250,171.0
66.91250,153.0
66.96250,134.0
67.01250,135.0
67.06250,130.0
67.11250,153.0
67.16250,138.0
67.21250,132.0
67.26250,134.0
67.31250,151.0
67.36250,148.0
67.41250,163.0
67.46250,159.0
67.51250,144.0
67.56250,161.0
67.61250,163.0
67.66250,149.0
67.71250,133.0
67.76250,174.0
67.81250,179.0
67.86250,167.0
67.91250,175.0
67.96250,183.0
68.01250,191.0
68.06250,194.0
68.11250,198.0
68.16250,183.0
68.21250,234.0
68.26250,200.0
68.31250,217.0
68.36250,231.0
68.41250,225.0
68.46250,261.0
68.51250,260.0
68.56250,276.0
68.61250,336.0
68.66250,330.0
68.71250,347.0
68.76250,336.0
68.81250,333.0
68.86250,327.0
68.91250,336.0
68.96250,330.0
69.01250,322.0
69.06250,312.0
69.11250,287.0
69.16250,261.0
69.21250,268.0
69.26250,283.0
69.31250,282.0
69.36250,250.0
69.41250,259.0
69.46250,284.0
69.51250,274.0
69.56250,329.0
69.61250,270.0
69.66250,288.0
69.71250,323.0
69.76250,409.0
69.81250,375.0
69.86250,417.0
69.91250,453.0
69.96250,537.0
70.01250,555.0
70.06250,718.0
70.11250,764.0
70.16250,945.0
70.21250,1082.0
70.26250,1251.0
70.31250,1476.0
70.36250,1720.0
70.41250,2138.0
70.46250,2601.0
70.51250,3150.0
70.56250,3373.0
70.61250,3669.0
70.66250,3675.0
70.71250,3504.0
70.76250,3298.0
70.81250,2764.0
70.86250,2494.0
70.91250,1986.0
70.96250,1587.0
71.01250,1300.0
71.06250,968.0
71.11250,751.0
71.16250,588.0
71.21250,520.0
71.26250,393.0
71.31250,340.0
71.36250,295.0
71.41250,324.0
71.46250,287.0
71.51250,234.0
71.56250,239.0
71.61250,235.0
71.66250,178.0
71.71250,202.0