File: code/data/data_source2/Ti_KL381A_Ti_Bragg.csv
[Measurement conditions]
Sample identification,
Comment - 1,"Configuration=Filmes Finos 19_1_2015, Owner=User-1, Creation date=19/01/2015 21:17:15"
Comment - 2,"Goniometer=PW3050/60 (Theta/Theta); Minimum step size 2Theta:0.001; Minimum step size Omega:0.001"
Comment - 3,"Sample stage=PW3071/xx Bracket"
Comment - 4,"Diffractometer system=XPERT-PRO"
Comment - 5,"Measurement program=C:\PANalytical\Data Collector\Programs\BraggBrentano.xrdmp, Identifier={FA0EF3C9-F37B-49EA-B09D-A6735D2B846F}"
Anode material,Cu
K-Alpha1 wavelength,1.5405980
K-Alpha2 wavelength,1.5444260
Ratio K-Alpha2/K-Alpha1,0.500
Divergence slit,Fixed,0.76mm
Receiving slit,0.10
Monochromator used,YES
Generator voltage, 40
Tube current, 40
File date and time,11/May/2018 13:38
Unit cell,
h k l, 0 0 0
Scan axis,Gonio
Scan range,20.00000,80.00000
Scan step size,0.0250000
No. of points, 2400
Scan type,CONTINUOUS
Time per step,3.00
[Scan points]
Angle,Intensity
20.01250,41.0
20.06250,56.0
20.11250,43.0
20.16250,40.0
20.21250,44.0
20.26250,45.0
20.31250,44.0
20.36250,50.0
20.41250,44.0
20.46250,56.0
20.51250,44.0
20.56250,49.0
20.61250,44.0
20.66250,45.0
20.71250,48.0
20.76250,47.0
20.81250,50.0
20.86250,54.0
20.91250,38.0
20.96250,46.0
21.01250,41.0
21.06250,41.0
21.11250,56.0
21.16250,32.0
21.21250,39.0
21.26250,57.0
21.31250,38.0
21.36250,43.0
21.41250,50.0
21.46250,51.0
21.51250,52.0
21.56250,49.0
21.61250,40.0
21.66250,43.0
21.71250,47.0
21.76250,44.0
21.81250,41.0
21.86250,43.0
21.91250,54.0
21.96250,51.0
22.01250,49.0
22.06250,42.0
22.11250,38.0
22.16250,43.0
22.21250,47.0
22.26250,33.0
22.31250,37.0
22.36250,54.0
22.41250,40.0
22.46250,50.0
22.51250,33.0
22.56250,43.0
22.61250,33.0
22.66250,36.0
22.71250,41.0
22.76250,33.0
22.81250,33.0
22.86250,37.0
22.91250,38.0
22.96250,45.0
23.01250,39.0
23.06250,36.0
23.11250,45.0
23.16250,43.0
23.21250,42.0
23.26250,33.0
23.31250,38.0
23.36250,39.0
23.41250,34.0
23.46250,40.0
23.51250,31.0
23.56250,49.0
23.61250,38.0
23.66250,32.0
23.71250,43.0
23.76250,44.0
23.81250,40.0
23.86250,40.0
23.91250,38.0
23.96250,34.0
24.01250,46.0
24.06250,49.0
24.11250,24.0
24.16250,32.0
24.21250,29.0
24.26250,50.0
24.31250,44.0
24.36250,32.0
24.41250,45.0
24.46250,38.0
24.51250,39.0
24.56250,38.0
24.61250,35.0
24.66250,35.0
24.71250,44.0
24.76250,47.0
24.81250,35.0
24.86250,30.0
24.91250,42.0
24.96250,52.0
25.01250,43.0
25.06250,30.0
25.11250,34.0
25.16250,44.0
25.21250,40.0
25.26250,31.0
25.31250,42.0
25.36250,24.0
25.41250,42.0
25.46250,44.0
25.51250,31.0
25.56250,41.0
25.61250,41.0
25.66250,31.0
25.71250,40.0
25.76250,39.0
25.81250,37.0
25.86250,41.0
25.91250,38.0
25.96250,41.0
26.01250,49.0
26.06250,43.0
26.11250,38.0
26.16250,42.0
26.21250,31.0
26.26250,28.0
26.31250,39.0
26.36250,31.0
26.41250,37.0
26.46250,29.0
26.51250,40.0
26.56250,34.0
26.61250,27.0
26.66250,42.0
26.71250,22.0
26.76250,36.0
26.81250,28.0
26.86250,29.0
26.91250,31.0
26.96250,41.0
27.01250,32.0
27.06250,30.0
27.11250,32.0
27.16250,24.0
27.21250,38.0
27.26250,38.0
27.31250,36.0
27.36250,42.0
27.41250,32.0
27.46250,29.0
27.51250,29.0
27.56250,40.0
27.61250,28.0
27.66250,33.0
27.71250,35.0
27.76250,27.0
27.81250,42.0
27.86250,37.0
27.91250,28.0
27.96250,34.0
28.01250,39.0
28.06250,36.0
28.11250,21.0
28.16250,56.0
28.21250,35.0
28.26250,45.0
28.31250,41.0
28.36250,28.0
28.41250,41.0
28.46250,41.0
28.51250,28.0
28.56250,37.0
28.61250,36.0
28.66250,30.0
28.71250,41.0
28.76250,43.0
28.81250,35.0
28.86250,33.0
28.91250,29.0
28.96250,38.0
29.01250,35.0
29.06250,26.0
29.11250,39.0
29.16250,34.0
29.21250,31.0
29.26250,32.0
29.31250,29.0
29.36250,31.0
29.41250,36.0
29.46250,31.0
29.51250,36.0
29.56250,34.0
29.61250,35.0
29.66250,34.0
29.71250,39.0
29.76250,32.0
29.81250,35.0
29.86250,28.0
29.91250,26.0
29.96250,31.0
30.01250,30.0
30.06250,36.0
30.11250,37.0
30.16250,34.0
30.21250,28.0
30.26250,39.0
30.31250,44.0
30.36250,29.0
30.41250,26.0
30.46250,37.0
30.51250,46.0
30.56250,33.0
30.61250,30.0
30.66250,30.0
30.71250,24.0
30.76250,37.0
30.81250,38.0
30.86250,34.0
30.91250,28.0
30.96250,32.0
31.01250,31.0
31.06250,42.0
31.11250,35.0
31.16250,34.0
31.21250,31.0
31.26250,39.0
31.31250,34.0
31.36250,27.0
31.41250,29.0
31.46250,35.0
31.51250,24.0
31.56250,37.0
31.61250,28.0
31.66250,31.0
31.71250,34.0
31.76250,28.0
31.81250,37.0
31.86250,31.0
31.91250,32.0
31.96250,31.0
32.01250,34.0
32.06250,39.0
32.11250,31.0
32.16250,33.0
32.21250,38.0
32.26250,29.0
32.31250,36.0
32.36250,39.0
32.41250,38.0
32.46250,31.0
32.51250,33.0
32.56250,38.0
32.61250,30.0
32.66250,26.0
32.71250,31.0
32.76250,34.0
32.81250,39.0
32.86250,38.0
32.91250,23.0
32.96250,38.0
33.01250,24.0
33.06250,34.0
33.11250,32.0
33.16250,45.0
33.21250,26.0
33.26250,37.0
33.31250,41.0
33.36250,36.0
33.41250,39.0
33.46250,31.0
33.51250,28.0
33.56250,35.0
33.61250,44.0
33.66250,31.0
33.71250,46.0
33.76250,45.0
33.81250,41.0
33.86250,41.0
33.91250,40.0
33.96250,59.0
34.01250,54.0
34.06250,55.0
34.11250,77.0
34.16250,75.0
34.21250,92.0
34.26250,127.0
34.31250,194.0
34.36250,358.0
34.41250,541.0
34.46250,958.0
34.51250,1508.0
34.56250,2113.0
34.61250,2635.0
34.66250,2829.0
34.71250,2600.0
34.76250,2141.0
34.81250,1628.0
34.86250,1033.0
34.91250,652.0
34.96250,412.0
35.01250,247.0
35.06250,156.0
35.11250,119.0
35.16250,71.0
35.21250,83.0
35.26250,71.0
35.31250,62.0
35.36250,64.0
35.41250,55.0
35.46250,52.0
35.51250,44.0
35.56250,45.0
35.61250,56.0
35.66250,44.0
35.71250,48.0
35.76250,47.0
35.81250,43.0
35.86250,60.0
35.91250,52.0
35.96250,63.0
36.01250,67.0
36.06250,77.0
36.11250,85.0
36.16250,85.0
36.21250,99.0
36.26250,99.0
36.31250,120.0
36.36250,121.0
36.41250,127.0
36.46250,113.0
36.51250,116.0
36.56250,126.0
36.61250,109.0
36.66250,95.0
36.71250,93.0
36.76250,93.0
36.81250,90.0
36.86250,95.0
36.91250,84.0
36.96250,92.0
37.01250,94.0
37.06250,93.0
37.11250,98.0
37.16250,92.0
37.21250,83.0
37.26250,75.0
37.31250,95.0
37.36250,96.0
37.41250,120.0
37.46250,113.0
37.51250,116.0
37.56250,138.0
37.61250,194.0
37.66250,206.0
37.71250,267.0
37.76250,375.0
37.81250,502.0
37.86250,683.0
37.91250,821.0
37.96250,900.0
38.01250,807.0
38.06250,769.0
38.11250,581.0
38.16250,438.0
38.21250,336.0
38.26250,236.0
38.31250,151.0
38.36250,133.0
38.41250,112.0
38.46250,103.0
38.51250,89.0
38.56250,116.0
38.61250,90.0
38.66250,78.0
38.71250,75.0
38.76250,71.0
38.81250,98.0
38.86250,88.0
38.91250,103.0
38.96250,92.0
39.01250,106.0
39.06250,122.0
39.11250,127.0
39.16250,158.0
39.21250,175.0
39.26250,239.0
39.31250,306.0
39.36250,382.0
39.41250,569.0
39.46250,836.0
39.51250,1275.0
39.56250,1809.0
39.61250,2476.0
39.66250,3187.0
39.71250,3607.0
39.76250,3475.0
39.81250,3154.0
39.86250,2577.0
39.91250,1965.0
39.96250,1317.0
40.01250,901.0
40.06250,601.0
40.11250,405.0
40.16250,277.0
40.21250,214.0
40.26250,170.0
40.31250,139.0
40.36250,82.0
40.41250,99.0
40.46250,64.0
40.51250,73.0
40.56250,64.0
40.61250,80.0
40.66250,50.0
40.71250,59.0
40.76250,41.0
40.81250,57.0
40.86250,44.0
40.91250,44.0
40.96250,44.0
41.01250,42.0
41.06250,41.0
41.11250,42.0
41.16250,45.0
41.21250,30.0
41.26250,42.0
41.31250,21.0
41.36250,48.0
41.41250,29.0
41.46250,46.0
41.51250,58.0
41.56250,44.0
41.61250,64.0
41.66250,66.0
41.71250,62.0
41.76250,79.0
41.81250,77.0
41.86250,95.0
41.91250,87.0
41.96250,90.0
42.01250,110.0
42.06250,105.0
42.11250,109.0
42.16250,102.0
42.21250,114.0
42.26250,111.0
42.31250,94.0
42.36250,87.0
42.41250,86.0
42.46250,87.0
42.51250,76.0
42.56250,71.0
42.61250,57.0
42.66250,56.0
42.71250,46.0
42.76250,67.0
42.81250,50.0
42.86250,46.0
42.91250,50.0
42.96250,44.0
43.01250,62.0
43.06250,44.0
43.11250,40.0
43.16250,39.0
43.21250,34.0
43.26250,44.0
43.31250,39.0
43.36250,33.0
43.41250,30.0
43.46250,35.0
43.51250,33.0
43.56250,23.0
43.61250,18.0
43.66250,32.0
43.71250,24.0
43.76250,29.0
43.81250,43.0
43.86250,28.0
43.91250,19.0
43.96250,20.0
44.01250,29.0
44.06250,26.0
44.11250,29.0
44.16250,30.0
44.21250,28.0
44.26250,24.0
44.31250,16.0
44.36250,18.0
44.41250,28.0
44.46250,27.0
44.51250,26.0
44.56250,20.0
44.61250,27.0
44.66250,20.0
44.71250,14.0
44.76250,26.0
44.81250,21.0
44.86250,23.0
44.91250,19.0
44.96250,24.0
45.01250,27.0
45.06250,26.0
45.11250,26.0
45.16250,26.0
45.21250,19.0
45.26250,37.0
45.31250,26.0
45.36250,23.0
45.41250,28.0
45.46250,22.0
45.51250,34.0
45.56250,25.0
45.61250,19.0
45.66250,15.0
45.71250,25.0
45.76250,23.0
45.81250,15.0
45.86250,20.0
45.91250,17.0
45.96250,19.0
46.01250,16.0
46.06250,25.0
46.11250,27.0
46.16250,33.0
46.21250,18.0
46.26250,20.0
46.31250,16.0
46.36250,21.0
46.41250,16.0
46.46250,17.0
46.51250,29.0
46.56250,18.0
46.61250,24.0
46.66250,23.0
46.71250,26.0
46.76250,19.0
46.81250,12.0
46.86250,22.0
46.91250,27.0
46.96250,21.0
47.01250,18.0
47.06250,21.0
47.11250,17.0
47.16250,17.0
47.21250,25.0
47.26250,26.0
47.31250,16.0
47.36250,20.0
47.41250,18.0
47.46250,15.0
47.51250,26.0
47.56250,26.0
47.61250,21.0
47.66250,9.0
47.71250,11.0
47.76250,15.0
47.81250,12.0
47.86250,23.0
47.91250,18.0
47.96250,23.0
48.01250,17.0
48.06250,13.0
48.11250,17.0
48.16250,15.0
48.21250,17.0
48.26250,15.0
48.31250,22.0
48.36250,12.0
48.41250,26.0
48.46250,14.0
48.51250,15.0
48.56250,25.0
48.61250,18.0
48.66250,16.0
48.71250,23.0
48.76250,28.0
48.81250,14.0
48.86250,23.0
48.91250,20.0
48.96250,9.0
49.01250,20.0
49.06250,26.0
49.11250,13.0
49.16250,15.0
49.21250,17.0
49.26250,23.0
49.31250,21.0
49.36250,18.0
49.41250,13.0
49.46250,13.0
49.51250,18.0
49.56250,19.0
49.61250,17.0
49.66250,18.0
49.71250,14.0
49.76250,20.0
49.81250,17.0
49.86250,25.0
49.91250,19.0
49.96250,23.0
50.01250,20.0
50.06250,22.0
50.11250,13.0
50.16250,21.0
50.21250,21.0
50.26250,15.0
50.31250,21.0
50.36250,19.0
50.41250,13.0
50.46250,22.0
50.51250,12.0
50.56250,16.0
50.61250,24.0
50.66250,19.0
50.71250,16.0
50.76250,23.0
50.81250,18.0
50.86250,17.0
50.91250,25.0
50.96250,18.0
51.01250,16.0
51.06250,20.0
51.11250,19.0
51.16250,23.0
51.21250,13.0
51.26250,23.0
51.31250,15.0
51.36250,15.0
51.41250,17.0
51.46250,22.0
51.51250,28.0
51.56250,30.0
51.61250,22.0
51.66250,22.0
51.71250,19.0
51.76250,23.0
51.81250,33.0
51.86250,29.0
51.91250,24.0
51.96250,25.0
52.01250,27.0
52.06250,28.0
52.11250,28.0
52.16250,46.0
52.21250,58.0
52.26250,66.0
52.31250,86.0
52.36250,118.0
52.41250,125.0
52.46250,190.0
52.51250,222.0
52.56250,220.0
52.61250,206.0
52.66250,208.0
52.71250,173.0
52.76250,136.0
52.81250,131.0
52.86250,102.0
52.91250,82.0
52.96250,53.0
53.01250,45.0
53.06250,48.0
53.11250,41.0
53.16250,37.0
53.21250,33.0
53.26250,36.0
53.31250,25.0
53.36250,22.0
53.41250,17.0
53.46250,26.0
53.51250,31.0
53.56250,15.0
53.61250,21.0
53.66250,26.0
53.71250,21.0
53.76250,21.0
53.81250,25.0
53.86250,12.0
53.91250,11.0
53.96250,18.0
54.01250,14.0
54.06250,20.0
54.11250,24.0
54.16250,18.0
54.21250,17.0
54.26250,17.0
54.31250,15.0
54.36250,21.0
54.41250,21.0
54.46250,13.0
54.51250,13.0
54.56250,13.0
54.61250,13.0
54.66250,17.0
54.71250,24.0
54.76250,17.0
54.81250,15.0
54.86250,23.0
54.91250,25.0
54.96250,23.0
55.01250,14.0
55.06250,23.0
55.11250,14.0
55.16250,12.0
55.21250,12.0
55.26250,20.0
55.31250,17.0
55.36250,16.0
55.41250,25.0
55.46250,24.0
55.51250,17.0
55.56250,21.0
55.61250,18.0
55.66250,27.0
55.71250,23.0
55.76250,19.0
55.81250,17.0
55.86250,19.0
55.91250,18.0
55.96250,15.0
56.01250,14.0
56.06250,19.0
56.11250,9.0
56.16250,20.0
56.21250,18.0
56.26250,18.0
56.31250,21.0
56.36250,23.0
56.41250,15.0
56.46250,17.0
56.51250,23.0
56.56250,15.0
56.61250,28.0
56.66250,18.0
56.71250,21.0
56.76250,19.0
56.81250,17.0
56.86250,17.0
56.91250,18.0
56.96250,20.0
57.01250,33.0
57.06250,24.0
57.11250,22.0
57.16250,27.0
57.21250,22.0
57.26250,25.0
57.31250,24.0
57.36250,31.0
57.41250,19.0
57.46250,22.0
57.51250,21.0
57.56250,17.0
57.61250,19.0
57.66250,22.0
57.71250,13.0
57.76250,17.0
57.81250,18.0
57.86250,24.0
57.91250,18.0
57.96250,14.0
58.01250,12.0
58.06250,21.0
58.11250,19.0
58.16250,14.0
58.21250,14.0
58.26250,18.0
58.31250,14.0
58.36250,16.0
58.41250,16.0
58.46250,19.0
58.51250,18.0
58.56250,16.0
58.61250,18.0
58.66250,20.0
58.71250,16.0
58.76250,21.0
58.81250,10.0
58.86250,14.0
58.91250,17.0
58.96250,17.0
59.01250,15.0
59.06250,17.0
59.11250,16.0
59.16250,24.0
59.21250,13.0
59.26250,13.0
59.31250,14.0
59.36250,17.0
59.41250,18.0
59.46250,20.0
59.51250,16.0
59.56250,16.0
59.61250,23.0
59.66250,19.0
59.71250,16.0
59.76250,22.0
59.81250,26.0
59.86250,18.0
59.91250,26.0
59.96250,16.0
60.01250,11.0
60.06250,15.0
60.11250,20.0
60.16250,16.0
60.21250,21.0
60.26250,19.0
60.31250,17.0
60.36250,13.0
60.41250,18.0
60.46250,25.0
60.51250,16.0
60.56250,25.0
60.61250,19.0
60.66250,24.0
60.71250,15.0
60.76250,24.0
60.81250,20.0
60.86250,23.0
60.91250,30.0
60.96250,24.0
61.01250,15.0
61.06250,22.0
61.11250,24.0
61.16250,27.0
61.21250,33.0
61.26250,36.0
61.31250,40.0
61.36250,38.0
61.41250,31.0
61.46250,34.0
61.51250,43.0
61.56250,41.0
61.61250,45.0
61.66250,41.0
61.71250,34.0
61.76250,49.0
61.81250,62.0
61.86250,41.0
61.91250,62.0
61.96250,62.0
62.01250,87.0
62.06250,89.0
62.11250,102.0
62.16250,149.0
62.21250,182.0
62.26250,261.0
62.31250,372.0
62.36250,498.0
62.41250,655.0
62.46250,813.0
62.51250,820.0
62.56250,849.0
62.61250,789.0
62.66250,701.0
62.71250,523.0
62.76250,427.0
62.81250,295.0
62.86250,223.0
62.91250,165.0
62.96250,119.0
63.01250,69.0
63.06250,67.0
63.11250,46.0
63.16250,45.0
63.21250,47.0
63.26250,41.0
63.31250,36.0
63.36250,37.0
63.41250,22.0
63.46250,30.0
63.51250,29.0
63.56250,22.0
63.61250,32.0
63.66250,25.0
63.71250,30.0
63.76250,35.0
63.81250,21.0
63.86250,30.0
63.91250,22.0
63.96250,19.0
64.01250,22.0
64.06250,23.0
64.11250,18.0
64.16250,17.0
64.21250,28.0
64.26250,18.0
64.31250,20.0
64.36250,26.0
64.41250,28.0
64.46250,20.0
64.51250,19.0
64.56250,14.0
64.61250,16.0
64.66250,18.0
64.71250,22.0
64.76250,14.0
64.81250,23.0
64.86250,15.0
64.91250,13.0
64.96250,18.0
65.01250,15.0
65.06250,22.0
65.11250,18.0
65.16250,20.0
65.21250,21.0
65.26250,19.0
65.31250,15.0
65.36250,21.0
65.41250,15.0
65.46250,22.0
65.51250,19.0
65.56250,18.0
65.61250,23.0
65.66250,11.0
65.71250,19.0
65.76250,17.0
65.81250,14.0
65.86250,17.0
65.91250,17.0
65.96250,12.0
66.01250,27.0
66.06250,12.0
66.11250,21.0
66.16250,17.0
66.21250,20.0
66.26250,11.0
66.31250,22.0
66.36250,23.0
66.41250,20.0
66.46250,22.0
66.51250,26.0
66.56250,22.0
66.61250,15.0
66.66250,16.0
66.71250,19.0
66.76250,14.0
66.81250,24.0
66.86250,24.0
66.91250,18.0
66.96250,20.0
67.01250,21.0
67.06250,13.0
67.11250,22.0
67.16250,13.0
67.21250,14.0
67.26250,13.0
67.31250,15.0
67.36250,13.0
67.41250,18.0
67.46250,12.0
67.51250,17.0
67.56250,19.0
67.61250,18.0
67.66250,17.0
67.71250,17.0
67.76250,18.0
67.81250,17.0
67.86250,21.0
67.91250,31.0
67.96250,26.0
68.01250,19.0
68.06250,15.0
68.11250,27.0
68.16250,21.0
68.21250,27.0
68.26250,22.0
68.31250,28.0
68.36250,22.0
68.41250,14.0
68.46250,22.0
68.51250,18.0
68.56250,14.0
68.61250,17.0
68.66250,21.0
68.71250,22.0
68.76250,20.0
68.81250,20.0
68.86250,21.0
68.91250,23.0
68.96250,15.0
69.01250,25.0
69.06250,34.0
69.11250,25.0
69.16250,22.0
69.21250,21.0
69.26250,17.0
69.31250,24.0
69.36250,33.0
69.41250,26.0
69.46250,29.0
69.51250,21.0
69.56250,31.0
69.61250,39.0
69.66250,29.0
69.71250,48.0
69.76250,47.0
69.81250,49.0
69.86250,53.0
69.91250,78.0
69.96250,83.0
70.01250,112.0
70.06250,115.0
70.11250,142.0
70.16250,162.0
70.21250,196.0
70.26250,177.0
70.31250,144.0
70.36250,145.0
70.41250,133.0
70.46250,123.0
70.51250,103.0
70.56250,92.0
70.61250,70.0
70.66250,65.0
70.71250,41.0
70.76250,34.0
70.81250,33.0
70.86250,34.0
70.91250,26.0
70.96250,25.0
71.01250,29.0
71.06250,23.0
71.11250,27.0
71.16250,23.0
71.21250,20.0
71.26250,17.0
71.31250,24.0
71.36250,20.0
71.41250,24.0
71.46250,18.0
71.51250,25.0
71.56250,17.0
71.61250,30.0
71.66250,22.0
71.71250,22.0
71.76250,34.0
71.81250,23.0
71.86250,27.0
71.91250,23.0
71.96250,15.0
72.01250,26.0
72.06250,29.0
72.11250,14.0
72.16250,21.0
72.21250,23.0
72.26250,21.0
72.31250,27.0
72.36250,22.0
72.41250,23.0
72.46250,16.0
72.51250,18.0
72.56250,21.0
72.61250,22.0
72.66250,16.0
72.71250,23.0
72.76250,20.0
72.81250,20.0
72.86250,22.0
72.91250,23.0
72.96250,32.0
73.01250,31.0
73.06250,42.0
73.11250,26.0
73.16250,39.0
73.21250,40.0
73.26250,45.0
73.31250,56.0
73.36250,66.0
73.41250,86.0
73.46250,104.0
73.51250,159.0
73.56250,173.0
73.61250,231.0
73.66250,277.0
73.71250,311.0
73.76250,309.0
73.81250,302.0
73.86250,276.0
73.91250,239.0
73.96250,188.0
74.01250,151.0
74.06250,135.0
74.11250,83.0
74.16250,78.0
74.21250,66.0
74.26250,42.0
74.31250,32.0
74.36250,29.0
74.41250,38.0
74.46250,22.0
74.51250,29.0
74.56250,20.0
74.61250,31.0
74.66250,23.0
74.71250,23.0
74.76250,37.0
74.81250,26.0
74.86250,41.0
74.91250,28.0
74.96250,47.0
75.01250,26.0
75.06250,31.0
75.11250,40.0
75.16250,38.0
75.21250,54.0
75.26250,66.0
75.31250,65.0
75.36250,76.0
75.41250,71.0
75.46250,116.0
75.51250,134.0
75.56250,172.0
75.61250,194.0
75.66250,212.0
75.71250,251.0
75.76250,250.0
75.81250,280.0
75.86250,255.0
75.91250,227.0
75.96250,198.0
76.01250,198.0
76.06250,149.0
76.11250,122.0
76.16250,127.0
76.21250,122.0
76.26250,106.0
76.31250,91.0
76.36250,98.0
76.41250,102.0
76.46250,101.0
76.51250,145.0
76.56250,192.0
76.61250,257.0
76.66250,322.0
76.71250,430.0
76.76250,652.0
76.81250,818.0
76.86250,918.0
76.91250,1010.0
76.96250,1008.0
77.01250,943.0
77.06250,814.0
77.11250,766.0
77.16250,663.0
77.21250,545.0
77.26250,414.0
77.31250,311.0
77.36250,233.0
77.41250,136.0
77.46250,115.0
77.51250,73.0
77.56250,71.0
77.61250,66.0
77.66250,65.0
77.71250,49.0
77.76250,59.0
77.81250,40.0
77.86250,37.0
77.91250,30.0
77.96250,35.0
78.01250,44.0
78.06250,37.0
78.11250,46.0
78.16250,33.0
78.21250,34.0
78.26250,34.0
78.31250,32.0
78.36250,28.0
78.41250,32.0
78.46250,25.0
78.51250,30.0
78.56250,20.0
78.61250,30.0
78.66250,16.0
78.71250,22.0
78.76250,28.0
78.81250,25.0
78.86250,21.0
78.91250,21.0
78.96250,22.0
79.01250,30.0
79.06250,20.0
79.11250,14.0
79.16250,21.0
79.21250,20.0
79.26250,24.0
79.31250,21.0
79.36250,20.0
79.41250,17.0
79.46250,17.0
79.51250,22.0
79.56250,22.0
79.61250,13.0
79.66250,9.0
79.71250,26.0
79.76250,18.0
79.81250,21.0
79.86250,22.0
79.91250,16.0
79.96250,13.0
79.98750,23.0