File: code/data/data_source2/Ti_KL348A_Ti_Bragg.csv
[Measurement conditions]
Sample identification,
Comment - 1,"Configuration=Filmes Finos 19_1_2015, Owner=User-1, Creation date=19/01/2015 21:17:15"
Comment - 2,"Goniometer=PW3050/60 (Theta/Theta); Minimum step size 2Theta:0.001; Minimum step size Omega:0.001"
Comment - 3,"Sample stage=PW3071/xx Bracket"
Comment - 4,"Diffractometer system=XPERT-PRO"
Comment - 5,"Measurement program=C:\PANalytical\Data Collector\Programs\BraggBrentano.xrdmp, Identifier={D6FD5039-6B00-47A4-9742-DB44022C9878}"
Anode material,Cu
K-Alpha1 wavelength,1.5405980
K-Alpha2 wavelength,1.5444260
Ratio K-Alpha2/K-Alpha1,0.500
Divergence slit,Fixed,0.76mm
Receiving slit,0.10
Monochromator used,YES
Generator voltage, 40
Tube current, 40
File date and time,25/Jun/2018 10:49
Unit cell,
h k l, 0 0 0
Scan axis,Gonio
Scan range,20.00000,80.00000
Scan step size,0.0250000
No. of points, 2400
Scan type,CONTINUOUS
Time per step,3.00
[Scan points]
Angle,Intensity
20.01250,97.0
20.06250,77.0
20.11250,87.0
20.16250,86.0
20.21250,94.0
20.26250,95.0
20.31250,102.0
20.36250,98.0
20.41250,100.0
20.46250,66.0
20.51250,90.0
20.56250,61.0
20.61250,80.0
20.66250,85.0
20.71250,90.0
20.76250,78.0
20.81250,86.0
20.86250,66.0
20.91250,77.0
20.96250,92.0
21.01250,112.0
21.06250,80.0
21.11250,80.0
21.16250,66.0
21.21250,80.0
21.26250,82.0
21.31250,71.0
21.36250,89.0
21.41250,80.0
21.46250,74.0
21.51250,66.0
21.56250,83.0
21.61250,87.0
21.66250,71.0
21.71250,81.0
21.76250,86.0
21.81250,90.0
21.86250,71.0
21.91250,77.0
21.96250,71.0
22.01250,72.0
22.06250,64.0
22.11250,73.0
22.16250,80.0
22.21250,75.0
22.26250,96.0
22.31250,85.0
22.36250,75.0
22.41250,92.0
22.46250,70.0
22.51250,94.0
22.56250,80.0
22.61250,75.0
22.66250,54.0
22.71250,73.0
22.76250,73.0
22.81250,74.0
22.86250,57.0
22.91250,83.0
22.96250,77.0
23.01250,89.0
23.06250,71.0
23.11250,71.0
23.16250,77.0
23.21250,74.0
23.26250,79.0
23.31250,81.0
23.36250,67.0
23.41250,82.0
23.46250,62.0
23.51250,62.0
23.56250,70.0
23.61250,63.0
23.66250,60.0
23.71250,69.0
23.76250,61.0
23.81250,83.0
23.86250,58.0
23.91250,78.0
23.96250,61.0
24.01250,65.0
24.06250,56.0
24.11250,68.0
24.16250,65.0
24.21250,67.0
24.26250,63.0
24.31250,65.0
24.36250,58.0
24.41250,65.0
24.46250,60.0
24.51250,65.0
24.56250,67.0
24.61250,75.0
24.66250,79.0
24.71250,69.0
24.76250,70.0
24.81250,63.0
24.86250,51.0
24.91250,85.0
24.96250,79.0
25.01250,50.0
25.06250,60.0
25.11250,60.0
25.16250,56.0
25.21250,59.0
25.26250,63.0
25.31250,66.0
25.36250,62.0
25.41250,67.0
25.46250,78.0
25.51250,61.0
25.56250,66.0
25.61250,76.0
25.66250,69.0
25.71250,64.0
25.76250,83.0
25.81250,53.0
25.86250,58.0
25.91250,76.0
25.96250,48.0
26.01250,60.0
26.06250,65.0
26.11250,54.0
26.16250,59.0
26.21250,53.0
26.26250,53.0
26.31250,73.0
26.36250,61.0
26.41250,67.0
26.46250,61.0
26.51250,56.0
26.56250,63.0
26.61250,71.0
26.66250,42.0
26.71250,64.0
26.76250,63.0
26.81250,71.0
26.86250,69.0
26.91250,66.0
26.96250,66.0
27.01250,75.0
27.06250,57.0
27.11250,75.0
27.16250,67.0
27.21250,59.0
27.26250,74.0
27.31250,62.0
27.36250,68.0
27.41250,61.0
27.46250,68.0
27.51250,64.0
27.56250,61.0
27.61250,84.0
27.66250,63.0
27.71250,57.0
27.76250,52.0
27.81250,60.0
27.86250,56.0
27.91250,59.0
27.96250,74.0
28.01250,66.0
28.06250,69.0
28.11250,56.0
28.16250,52.0
28.21250,64.0
28.26250,67.0
28.31250,63.0
28.36250,59.0
28.41250,66.0
28.46250,80.0
28.51250,61.0
28.56250,50.0
28.61250,61.0
28.66250,65.0
28.71250,59.0
28.76250,54.0
28.81250,65.0
28.86250,64.0
28.91250,77.0
28.96250,68.0
29.01250,60.0
29.06250,63.0
29.11250,65.0
29.16250,50.0
29.21250,64.0
29.26250,53.0
29.31250,71.0
29.36250,58.0
29.41250,60.0
29.46250,47.0
29.51250,49.0
29.56250,68.0
29.61250,44.0
29.66250,54.0
29.71250,62.0
29.76250,62.0
29.81250,54.0
29.86250,66.0
29.91250,45.0
29.96250,55.0
30.01250,51.0
30.06250,62.0
30.11250,62.0
30.16250,56.0
30.21250,45.0
30.26250,50.0
30.31250,59.0
30.36250,48.0
30.41250,65.0
30.46250,54.0
30.51250,51.0
30.56250,54.0
30.61250,39.0
30.66250,53.0
30.71250,43.0
30.76250,53.0
30.81250,41.0
30.86250,58.0
30.91250,50.0
30.96250,53.0
31.01250,62.0
31.06250,50.0
31.11250,41.0
31.16250,55.0
31.21250,54.0
31.26250,32.0
31.31250,48.0
31.36250,54.0
31.41250,59.0
31.46250,58.0
31.51250,56.0
31.56250,54.0
31.61250,50.0
31.66250,51.0
31.71250,56.0
31.76250,50.0
31.81250,41.0
31.86250,47.0
31.91250,45.0
31.96250,56.0
32.01250,53.0
32.06250,44.0
32.11250,39.0
32.16250,48.0
32.21250,46.0
32.26250,41.0
32.31250,48.0
32.36250,54.0
32.41250,51.0
32.46250,56.0
32.51250,47.0
32.56250,47.0
32.61250,45.0
32.66250,49.0
32.71250,53.0
32.76250,49.0
32.81250,48.0
32.86250,45.0
32.91250,39.0
32.96250,46.0
33.01250,49.0
33.06250,49.0
33.11250,36.0
33.16250,48.0
33.21250,43.0
33.26250,48.0
33.31250,52.0
33.36250,53.0
33.41250,45.0
33.46250,46.0
33.51250,45.0
33.56250,49.0
33.61250,53.0
33.66250,51.0
33.71250,48.0
33.76250,39.0
33.81250,39.0
33.86250,46.0
33.91250,34.0
33.96250,50.0
34.01250,65.0
34.06250,58.0
34.11250,72.0
34.16250,51.0
34.21250,55.0
34.26250,50.0
34.31250,68.0
34.36250,57.0
34.41250,74.0
34.46250,76.0
34.51250,63.0
34.56250,96.0
34.61250,115.0
34.66250,190.0
34.71250,298.0
34.76250,453.0
34.81250,808.0
34.86250,1125.0
34.91250,1637.0
34.96250,2047.0
35.01250,2158.0
35.06250,2128.0
35.11250,1846.0
35.16250,1358.0
35.21250,959.0
35.26250,615.0
35.31250,393.0
35.36250,248.0
35.41250,167.0
35.46250,110.0
35.51250,89.0
35.56250,82.0
35.61250,67.0
35.66250,78.0
35.71250,58.0
35.76250,70.0
35.81250,61.0
35.86250,64.0
35.91250,53.0
35.96250,62.0
36.01250,40.0
36.06250,69.0
36.11250,71.0
36.16250,58.0
36.21250,74.0
36.26250,81.0
36.31250,72.0
36.36250,71.0
36.41250,85.0
36.46250,98.0
36.51250,117.0
36.56250,126.0
36.61250,123.0
36.66250,117.0
36.71250,119.0
36.76250,131.0
36.81250,118.0
36.86250,117.0
36.91250,138.0
36.96250,146.0
37.01250,106.0
37.06250,110.0
37.11250,110.0
37.16250,80.0
37.21250,92.0
37.26250,87.0
37.31250,71.0
37.36250,92.0
37.41250,79.0
37.46250,79.0
37.51250,87.0
37.56250,87.0
37.61250,75.0
37.66250,96.0
37.71250,106.0
37.76250,137.0
37.81250,126.0
37.86250,136.0
37.91250,147.0
37.96250,160.0
38.01250,183.0
38.06250,231.0
38.11250,290.0
38.16250,395.0
38.21250,515.0
38.26250,527.0
38.31250,602.0
38.36250,584.0
38.41250,560.0
38.46250,570.0
38.51250,366.0
38.56250,300.0
38.61250,213.0
38.66250,168.0
38.71250,146.0
38.76250,92.0
38.81250,94.0
38.86250,89.0
38.91250,84.0
38.96250,91.0
39.01250,87.0
39.06250,79.0
39.11250,78.0
39.16250,73.0
39.21250,71.0
39.26250,91.0
39.31250,95.0
39.36250,97.0
39.41250,127.0
39.46250,115.0
39.51250,145.0
39.56250,191.0
39.61250,208.0
39.66250,235.0
39.71250,265.0
39.76250,377.0
39.81250,524.0
39.86250,719.0
39.91250,1055.0
39.96250,1510.0
40.01250,1878.0
40.06250,2051.0
40.11250,2139.0
40.16250,2039.0
40.21250,1793.0
40.26250,1384.0
40.31250,1050.0
40.36250,747.0
40.41250,517.0
40.46250,344.0
40.51250,266.0
40.56250,158.0
40.61250,135.0
40.66250,106.0
40.71250,98.0
40.76250,100.0
40.81250,78.0
40.86250,80.0
40.91250,72.0
40.96250,68.0
41.01250,55.0
41.06250,44.0
41.11250,55.0
41.16250,46.0
41.21250,62.0
41.26250,50.0
41.31250,57.0
41.36250,47.0
41.41250,55.0
41.46250,57.0
41.51250,72.0
41.56250,65.0
41.61250,89.0
41.66250,87.0
41.71250,108.0
41.76250,106.0
41.81250,167.0
41.86250,181.0
41.91250,254.0
41.96250,383.0
42.01250,464.0
42.06250,668.0
42.11250,831.0
42.16250,992.0
42.21250,1200.0
42.26250,1280.0
42.31250,1350.0
42.36250,1403.0
42.41250,1346.0
42.46250,1264.0
42.51250,1060.0
42.56250,962.0
42.61250,796.0
42.66250,629.0
42.71250,543.0
42.76250,423.0
42.81250,377.0
42.86250,287.0
42.91250,233.0
42.96250,217.0
43.01250,163.0
43.06250,148.0
43.11250,135.0
43.16250,129.0
43.21250,109.0
43.26250,91.0
43.31250,89.0
43.36250,86.0
43.41250,81.0
43.46250,58.0
43.51250,68.0
43.56250,82.0
43.61250,69.0
43.66250,62.0
43.71250,73.0
43.76250,48.0
43.81250,55.0
43.86250,50.0
43.91250,48.0
43.96250,67.0
44.01250,57.0
44.06250,49.0
44.11250,41.0
44.16250,38.0
44.21250,42.0
44.26250,45.0
44.31250,57.0
44.36250,61.0
44.41250,44.0
44.46250,46.0
44.51250,55.0
44.56250,47.0
44.61250,46.0
44.66250,35.0
44.71250,37.0
44.76250,34.0
44.81250,36.0
44.86250,40.0
44.91250,33.0
44.96250,43.0
45.01250,36.0
45.06250,33.0
45.11250,36.0
45.16250,39.0
45.21250,37.0
45.26250,41.0
45.31250,31.0
45.36250,34.0
45.41250,31.0
45.46250,33.0
45.51250,34.0
45.56250,34.0
45.61250,20.0
45.66250,40.0
45.71250,34.0
45.76250,31.0
45.81250,33.0
45.86250,25.0
45.91250,34.0
45.96250,41.0
46.01250,33.0
46.06250,38.0
46.11250,37.0
46.16250,34.0
46.21250,21.0
46.26250,39.0
46.31250,35.0
46.36250,25.0
46.41250,36.0
46.46250,29.0
46.51250,30.0
46.56250,31.0
46.61250,38.0
46.66250,26.0
46.71250,31.0
46.76250,41.0
46.81250,29.0
46.86250,28.0
46.91250,22.0
46.96250,26.0
47.01250,24.0
47.06250,29.0
47.11250,25.0
47.16250,33.0
47.21250,22.0
47.26250,30.0
47.31250,25.0
47.36250,21.0
47.41250,21.0
47.46250,22.0
47.51250,35.0
47.56250,30.0
47.61250,33.0
47.66250,31.0
47.71250,28.0
47.76250,33.0
47.81250,17.0
47.86250,17.0
47.91250,33.0
47.96250,18.0
48.01250,25.0
48.06250,34.0
48.11250,28.0
48.16250,25.0
48.21250,27.0
48.26250,27.0
48.31250,26.0
48.36250,28.0
48.41250,15.0
48.46250,18.0
48.51250,23.0
48.56250,26.0
48.61250,19.0
48.66250,24.0
48.71250,22.0
48.76250,25.0
48.81250,21.0
48.86250,24.0
48.91250,27.0
48.96250,28.0
49.01250,14.0
49.06250,23.0
49.11250,32.0
49.16250,25.0
49.21250,12.0
49.26250,28.0
49.31250,27.0
49.36250,28.0
49.41250,20.0
49.46250,28.0
49.51250,23.0
49.56250,24.0
49.61250,23.0
49.66250,19.0
49.71250,13.0
49.76250,16.0
49.81250,18.0
49.86250,16.0
49.91250,27.0
49.96250,23.0
50.01250,15.0
50.06250,23.0
50.11250,25.0
50.16250,25.0
50.21250,25.0
50.26250,26.0
50.31250,22.0
50.36250,28.0
50.41250,25.0
50.46250,28.0
50.51250,23.0
50.56250,19.0
50.61250,27.0
50.66250,17.0
50.71250,18.0
50.76250,24.0
50.81250,27.0
50.86250,19.0
50.91250,31.0
50.96250,21.0
51.01250,23.0
51.06250,25.0
51.11250,30.0
51.16250,29.0
51.21250,18.0
51.26250,22.0
51.31250,23.0
51.36250,25.0
51.41250,32.0
51.46250,22.0
51.51250,23.0
51.56250,27.0
51.61250,20.0
51.66250,29.0
51.71250,32.0
51.76250,15.0
51.81250,24.0
51.86250,28.0
51.91250,24.0
51.96250,28.0
52.01250,30.0
52.06250,30.0
52.11250,27.0
52.16250,21.0
52.21250,22.0
52.26250,29.0
52.31250,34.0
52.36250,34.0
52.41250,40.0
52.46250,24.0
52.51250,50.0
52.56250,47.0
52.61250,52.0
52.66250,68.0
52.71250,106.0
52.76250,116.0
52.81250,135.0
52.86250,146.0
52.91250,172.0
52.96250,177.0
53.01250,150.0
53.06250,149.0
53.11250,126.0
53.16250,104.0
53.21250,93.0
53.26250,75.0
53.31250,46.0
53.36250,48.0
53.41250,29.0
53.46250,47.0
53.51250,26.0
53.56250,23.0
53.61250,24.0
53.66250,24.0
53.71250,23.0
53.76250,24.0
53.81250,17.0
53.86250,21.0
53.91250,25.0
53.96250,18.0
54.01250,33.0
54.06250,26.0
54.11250,20.0
54.16250,18.0
54.21250,21.0
54.26250,18.0
54.31250,25.0
54.36250,34.0
54.41250,24.0
54.46250,19.0
54.51250,22.0
54.56250,21.0
54.61250,24.0
54.66250,27.0
54.71250,14.0
54.76250,20.0
54.81250,15.0
54.86250,24.0
54.91250,23.0
54.96250,19.0
55.01250,22.0
55.06250,18.0
55.11250,24.0
55.16250,16.0
55.21250,18.0
55.26250,18.0
55.31250,17.0
55.36250,20.0
55.41250,13.0
55.46250,25.0
55.51250,25.0
55.56250,20.0
55.61250,18.0
55.66250,15.0
55.71250,25.0
55.76250,19.0
55.81250,22.0
55.86250,22.0
55.91250,22.0
55.96250,16.0
56.01250,18.0
56.06250,18.0
56.11250,23.0
56.16250,20.0
56.21250,22.0
56.26250,25.0
56.31250,29.0
56.36250,16.0
56.41250,16.0
56.46250,19.0
56.51250,22.0
56.56250,27.0
56.61250,26.0
56.66250,24.0
56.71250,18.0
56.76250,19.0
56.81250,16.0
56.86250,26.0
56.91250,20.0
56.96250,26.0
57.01250,19.0
57.06250,25.0
57.11250,16.0
57.16250,18.0
57.21250,18.0
57.26250,21.0
57.31250,24.0
57.36250,27.0
57.41250,31.0
57.46250,17.0
57.51250,27.0
57.56250,24.0
57.61250,21.0
57.66250,20.0
57.71250,24.0
57.76250,23.0
57.81250,20.0
57.86250,15.0
57.91250,19.0
57.96250,21.0
58.01250,21.0
58.06250,19.0
58.11250,27.0
58.16250,18.0
58.21250,17.0
58.26250,16.0
58.31250,14.0
58.36250,25.0
58.41250,17.0
58.46250,25.0
58.51250,18.0
58.56250,25.0
58.61250,15.0
58.66250,22.0
58.71250,24.0
58.76250,18.0
58.81250,23.0
58.86250,13.0
58.91250,16.0
58.96250,18.0
59.01250,13.0
59.06250,14.0
59.11250,18.0
59.16250,16.0
59.21250,22.0
59.26250,17.0
59.31250,19.0
59.36250,21.0
59.41250,27.0
59.46250,15.0
59.51250,31.0
59.56250,18.0
59.61250,20.0
59.66250,20.0
59.71250,26.0
59.76250,20.0
59.81250,18.0
59.86250,18.0
59.91250,23.0
59.96250,16.0
60.01250,16.0
60.06250,18.0
60.11250,16.0
60.16250,17.0
60.21250,11.0
60.26250,25.0
60.31250,27.0
60.36250,27.0
60.41250,21.0
60.46250,22.0
60.51250,28.0
60.56250,16.0
60.61250,23.0
60.66250,26.0
60.71250,26.0
60.76250,23.0
60.81250,26.0
60.86250,25.0
60.91250,15.0
60.96250,15.0
61.01250,21.0
61.06250,22.0
61.11250,28.0
61.16250,21.0
61.21250,21.0
61.26250,30.0
61.31250,26.0
61.36250,32.0
61.41250,31.0
61.46250,30.0
61.51250,29.0
61.56250,24.0
61.61250,39.0
61.66250,43.0
61.71250,30.0
61.76250,43.0
61.81250,53.0
61.86250,50.0
61.91250,51.0
61.96250,59.0
62.01250,50.0
62.06250,37.0
62.11250,59.0
62.16250,52.0
62.21250,68.0
62.26250,64.0
62.31250,85.0
62.36250,80.0
62.41250,89.0
62.46250,118.0
62.51250,149.0
62.56250,226.0
62.61250,282.0
62.66250,405.0
62.71250,518.0
62.76250,646.0
62.81250,771.0
62.86250,827.0
62.91250,837.0
62.96250,828.0
63.01250,733.0
63.06250,590.0
63.11250,492.0
63.16250,409.0
63.21250,267.0
63.26250,199.0
63.31250,142.0
63.36250,114.0
63.41250,80.0
63.46250,67.0
63.51250,63.0
63.56250,46.0
63.61250,33.0
63.66250,27.0
63.71250,32.0
63.76250,21.0
63.81250,29.0
63.86250,23.0
63.91250,29.0
63.96250,29.0
64.01250,22.0
64.06250,17.0
64.11250,27.0
64.16250,20.0
64.21250,29.0
64.26250,18.0
64.31250,26.0
64.36250,24.0
64.41250,20.0
64.46250,13.0
64.51250,21.0
64.56250,30.0
64.61250,19.0
64.66250,21.0
64.71250,18.0
64.76250,23.0
64.81250,19.0
64.86250,22.0
64.91250,14.0
64.96250,26.0
65.01250,15.0
65.06250,19.0
65.11250,19.0
65.16250,19.0
65.21250,20.0
65.26250,20.0
65.31250,28.0
65.36250,24.0
65.41250,14.0
65.46250,15.0
65.51250,20.0
65.56250,16.0
65.61250,14.0
65.66250,23.0
65.71250,26.0
65.76250,17.0
65.81250,11.0
65.86250,13.0
65.91250,14.0
65.96250,10.0
66.01250,17.0
66.06250,22.0
66.11250,23.0
66.16250,17.0
66.21250,19.0
66.26250,14.0
66.31250,15.0
66.36250,12.0
66.41250,20.0
66.46250,23.0
66.51250,17.0
66.56250,17.0
66.61250,19.0
66.66250,16.0
66.71250,14.0
66.76250,11.0
66.81250,14.0
66.86250,14.0
66.91250,15.0
66.96250,19.0
67.01250,20.0
67.06250,12.0
67.11250,7.0
67.16250,14.0
67.21250,17.0
67.26250,14.0
67.31250,19.0
67.36250,15.0
67.41250,19.0
67.46250,17.0
67.51250,11.0
67.56250,28.0
67.61250,18.0
67.66250,21.0
67.71250,20.0
67.76250,24.0
67.81250,21.0
67.86250,23.0
67.91250,16.0
67.96250,21.0
68.01250,10.0
68.06250,12.0
68.11250,18.0
68.16250,20.0
68.21250,24.0
68.26250,14.0
68.31250,9.0
68.36250,16.0
68.41250,19.0
68.46250,28.0
68.51250,14.0
68.56250,20.0
68.61250,26.0
68.66250,25.0
68.71250,12.0
68.76250,14.0
68.81250,18.0
68.86250,19.0
68.91250,17.0
68.96250,11.0
69.01250,15.0
69.06250,19.0
69.11250,25.0
69.16250,21.0
69.21250,15.0
69.26250,12.0
69.31250,18.0
69.36250,16.0
69.41250,16.0
69.46250,25.0
69.51250,23.0
69.56250,29.0
69.61250,20.0
69.66250,28.0
69.71250,19.0
69.76250,23.0
69.81250,22.0
69.86250,33.0
69.91250,29.0
69.96250,27.0
70.01250,34.0
70.06250,50.0
70.11250,49.0
70.16250,42.0
70.21250,46.0
70.26250,61.0
70.31250,74.0
70.36250,85.0
70.41250,120.0
70.46250,115.0
70.51250,131.0
70.56250,155.0
70.61250,136.0
70.66250,130.0
70.71250,114.0
70.76250,106.0
70.81250,107.0
70.86250,83.0
70.91250,76.0
70.96250,53.0
71.01250,59.0
71.06250,40.0
71.11250,35.0
71.16250,37.0
71.21250,29.0
71.26250,32.0
71.31250,13.0
71.36250,33.0
71.41250,27.0
71.46250,26.0
71.51250,20.0
71.56250,19.0
71.61250,20.0
71.66250,18.0
71.71250,29.0
71.76250,25.0
71.81250,32.0
71.86250,16.0
71.91250,18.0
71.96250,14.0
72.01250,25.0
72.06250,22.0
72.11250,33.0
72.16250,18.0
72.21250,23.0
72.26250,24.0
72.31250,24.0
72.36250,18.0
72.41250,18.0
72.46250,25.0
72.51250,22.0
72.56250,15.0
72.61250,19.0
72.66250,26.0
72.71250,18.0
72.76250,33.0
72.81250,22.0
72.86250,34.0
72.91250,21.0
72.96250,26.0
73.01250,34.0
73.06250,33.0
73.11250,27.0
73.16250,31.0
73.21250,47.0
73.26250,60.0
73.31250,46.0
73.36250,65.0
73.41250,63.0
73.46250,65.0
73.51250,88.0
73.56250,110.0
73.61250,112.0
73.66250,141.0
73.71250,152.0
73.76250,148.0
73.81250,202.0
73.86250,223.0
73.91250,285.0
73.96250,289.0
74.01250,314.0
74.06250,317.0
74.11250,358.0
74.16250,329.0
74.21250,324.0
74.26250,253.0
74.31250,263.0
74.36250,203.0
74.41250,192.0
74.46250,146.0
74.51250,119.0
74.56250,84.0
74.61250,73.0
74.66250,65.0
74.71250,66.0
74.76250,41.0
74.81250,51.0
74.86250,47.0
74.91250,36.0
74.96250,25.0
75.01250,45.0
75.06250,34.0
75.11250,42.0
75.16250,36.0
75.21250,32.0
75.26250,36.0
75.31250,41.0
75.36250,32.0
75.41250,46.0
75.46250,32.0
75.51250,35.0
75.56250,41.0
75.61250,41.0
75.66250,53.0
75.71250,73.0
75.76250,79.0
75.81250,76.0
75.86250,106.0
75.91250,113.0
75.96250,168.0
76.01250,184.0
76.06250,218.0
76.11250,198.0
76.16250,233.0
76.21250,174.0
76.26250,193.0
76.31250,189.0
76.36250,146.0
76.41250,161.0
76.46250,160.0
76.51250,102.0
76.56250,98.0
76.61250,93.0
76.66250,97.0
76.71250,93.0
76.76250,90.0
76.81250,84.0
76.86250,126.0
76.91250,141.0
76.96250,204.0
77.01250,256.0
77.06250,362.0
77.11250,477.0
77.16250,528.0
77.21250,653.0
77.26250,737.0
77.31250,757.0
77.36250,645.0
77.41250,693.0
77.46250,592.0
77.51250,488.0
77.56250,437.0
77.61250,367.0
77.66250,258.0
77.71250,215.0
77.76250,169.0
77.81250,131.0
77.86250,88.0
77.91250,72.0
77.96250,65.0
78.01250,54.0
78.06250,61.0
78.11250,36.0
78.16250,45.0
78.21250,48.0
78.26250,39.0
78.31250,42.0
78.36250,39.0
78.41250,40.0
78.46250,35.0
78.51250,34.0
78.56250,28.0
78.61250,24.0
78.66250,32.0
78.71250,26.0
78.76250,38.0
78.81250,15.0
78.86250,32.0
78.91250,27.0
78.96250,31.0
79.01250,17.0
79.06250,28.0
79.11250,20.0
79.16250,21.0
79.21250,27.0
79.26250,17.0
79.31250,38.0
79.36250,18.0
79.41250,24.0
79.46250,29.0
79.51250,17.0
79.56250,20.0
79.61250,23.0
79.66250,15.0
79.71250,19.0
79.76250,20.0
79.81250,19.0
79.86250,21.0
79.91250,20.0
79.96250,25.0
79.98750,16.0