File: code/data/data_source2/Ti_KL305_2_T_1.csv
[Measurement conditions]
Sample identification,
Comment - 1,"Configuration=Filmes Finos 19_1_2015, Owner=User-1, Creation date=19/01/2015 21:17:15"
Comment - 2,"Goniometer=PW3050/60 (Theta/Theta); Minimum step size 2Theta:0.001; Minimum step size Omega:0.001"
Comment - 3,"Sample stage=PW3071/xx Bracket"
Comment - 4,"Diffractometer system=XPERT-PRO"
Comment - 5,"Measurement program=C:\PANalytical\Data Collector\Programs\GrazingIncidence.xrdmp, Identifier={07D6FCFD-48B5-4C05-A893-001347146203}"
Anode material,Cu
K-Alpha1 wavelength,1.5405980
K-Alpha2 wavelength,1.5444260
Ratio K-Alpha2/K-Alpha1,0.500
Divergence slit,Fixed,0.76mm
Receiving slit,0.10
Monochromator used,YES
Generator voltage, 40
Tube current, 40
File date and time,13/Jun/2018 17:44
Unit cell,
h k l, 0 0 0
Scan axis,2Theta
Scan range,19.99600,99.99600
Scan step size,0.0250000
No. of points, 3200
Scan type,CONTINUOUS
Omega,5.000
Time per step,17.00
[Scan points]
Angle,Intensity
20.00850,446.0
20.08350,471.0
20.15850,483.0
20.23350,440.0
20.30850,391.0
20.38350,424.0
20.45850,426.0
20.53350,408.0
20.60850,463.0
20.68350,425.0
20.75850,439.0
20.83350,400.0
20.90850,422.0
20.98350,408.0
21.05850,390.0
21.13350,454.0
21.20850,446.0
21.28350,405.0
21.35850,429.0
21.43350,450.0
21.50850,427.0
21.58350,407.0
21.65850,389.0
21.73350,425.0
21.80850,443.0
21.88350,414.0
21.95850,383.0
22.03350,433.0
22.10850,403.0
22.18350,393.0
22.25850,376.0
22.33350,406.0
22.40850,425.0
22.48350,395.0
22.55850,403.0
22.63350,369.0
22.70850,369.0
22.78350,362.0
22.85850,373.0
22.93350,354.0
23.00850,365.0
23.08350,353.0
23.15850,414.0
23.23350,396.0
23.30850,382.0
23.38350,394.0
23.45850,382.0
23.53350,385.0
23.60850,373.0
23.68350,389.0
23.75850,360.0
23.83350,390.0
23.90850,391.0
23.98350,417.0
24.05850,416.0
24.13350,407.0
24.20850,401.0
24.28350,454.0
24.35850,481.0
24.43350,498.0
24.50850,630.0
24.58350,612.0
24.65850,724.0
24.73350,874.0
24.80850,1247.0
24.88350,1842.0
24.95850,3133.0
25.03350,5372.0
25.10850,8725.0
25.18350,12301.0
25.25850,13717.0
25.33350,11706.0
25.40850,7625.0
25.48350,4171.0
25.55850,2214.0
25.63350,1275.0
25.70850,913.0
25.78350,704.0
25.85850,632.0
25.93350,545.0
26.00850,496.0
26.08350,480.0
26.15850,446.0
26.23350,413.0
26.30850,459.0
26.38350,414.0
26.45850,444.0
26.53350,437.0
26.60850,396.0
26.68350,394.0
26.75850,417.0
26.83350,414.0
26.90850,416.0
26.98350,448.0
27.05850,457.0
27.13350,494.0
27.20850,523.0
27.28350,531.0
27.35850,527.0
27.43350,524.0
27.50850,477.0
27.58350,432.0
27.65850,417.0
27.73350,416.0
27.80850,388.0
27.88350,395.0
27.95850,356.0
28.03350,389.0
28.10850,350.0
28.18350,343.0
28.25850,322.0
28.33350,359.0
28.40850,303.0
28.48350,326.0
28.55850,311.0
28.63350,308.0
28.70850,313.0
28.78350,330.0
28.85850,296.0
28.93350,329.0
29.00850,310.0
29.08350,328.0
29.15850,316.0
29.23350,302.0
29.30850,295.0
29.38350,319.0
29.45850,288.0
29.53350,307.0
29.60850,304.0
29.68350,290.0
29.75850,324.0
29.83350,283.0
29.90850,285.0
29.98350,277.0
30.05850,269.0
30.13350,269.0
30.20850,287.0
30.28350,280.0
30.35850,260.0
30.43350,295.0
30.50850,296.0
30.58350,311.0
30.65850,303.0
30.73350,337.0
30.80850,305.0
30.88350,324.0
30.95850,326.0
31.03350,303.0
31.10850,294.0
31.18350,250.0
31.25850,267.0
31.33350,256.0
31.40850,275.0
31.48350,276.0
31.55850,244.0
31.63350,268.0
31.70850,292.0
31.78350,245.0
31.85850,272.0
31.93350,263.0
32.00850,262.0
32.08350,250.0
32.15850,261.0
32.23350,232.0
32.30850,245.0
32.38350,262.0
32.45850,222.0
32.53350,223.0
32.60850,225.0
32.68350,240.0
32.75850,234.0
32.83350,266.0
32.90850,254.0
32.98350,252.0
33.05850,266.0
33.13350,237.0
33.20850,249.0
33.28350,247.0
33.35850,229.0
33.43350,246.0
33.50850,261.0
33.58350,267.0
33.65850,239.0
33.73350,262.0
33.80850,268.0
33.88350,251.0
33.95850,292.0
34.03350,288.0
34.10850,263.0
34.18350,290.0
34.25850,322.0
34.33350,348.0
34.40850,383.0
34.48350,401.0
34.55850,461.0
34.63350,576.0
34.70850,920.0
34.78350,1537.0
34.85850,2516.0
34.93350,3714.0
35.00850,4607.0
35.08350,4468.0
35.15850,3492.0
35.23350,2344.0
35.30850,1369.0
35.38350,906.0
35.45850,620.0
35.53350,516.0
35.60850,478.0
35.68350,480.0
35.75850,429.0
35.83350,402.0
35.90850,410.0
35.98350,413.0
36.05850,404.0
36.13350,428.0
36.20850,425.0
36.28350,414.0
36.35850,465.0
36.43350,403.0
36.50850,470.0
36.58350,480.0
36.65850,524.0
36.73350,577.0
36.80850,598.0
36.88350,687.0
36.95850,648.0
37.03350,636.0
37.10850,687.0
37.18350,646.0
37.25850,762.0
37.33350,770.0
37.40850,881.0
37.48350,942.0
37.55850,1103.0
37.63350,1152.0
37.70850,1303.0
37.78350,1503.0
37.85850,1549.0
37.93350,1689.0
38.00850,2213.0
38.08350,3402.0
38.15850,5902.0
38.23350,9912.0
38.30850,13249.0
38.38350,14447.0
38.45850,12211.0
38.53350,8427.0
38.60850,4838.0
38.68350,2604.0
38.75850,1573.0
38.83350,1124.0
38.90850,906.0
38.98350,867.0
39.05850,809.0
39.13350,767.0
39.20850,822.0
39.28350,841.0
39.35850,927.0
39.43350,1064.0
39.50850,1197.0
39.58350,1600.0
39.65850,2203.0
39.73350,3307.0
39.80850,5739.0
39.88350,10135.0
39.95850,17134.0
40.03350,24057.0
40.10850,27576.0
40.18350,25310.0
40.25850,18821.0
40.33350,11755.0
40.40850,6737.0
40.48350,3620.0
40.55850,2117.0
40.63350,1369.0
40.70850,1046.0
40.78350,811.0
40.85850,642.0
40.93350,594.0
41.00850,522.0
41.08350,463.0
41.15850,468.0
41.23350,403.0
41.30850,439.0
41.38350,370.0
41.45850,330.0
41.53350,261.0
41.60850,316.0
41.68350,274.0
41.75850,279.0
41.83350,279.0
41.90850,281.0
41.98350,267.0
42.05850,269.0
42.13350,253.0
42.20850,267.0
42.28350,286.0
42.35850,260.0
42.43350,272.0
42.50850,271.0
42.58350,233.0
42.65850,247.0
42.73350,202.0
42.80850,262.0
42.88350,260.0
42.95850,238.0
43.03350,261.0
43.10850,212.0
43.18350,232.0
43.25850,226.0
43.33350,236.0
43.40850,237.0
43.48350,219.0
43.55850,230.0
43.63350,235.0
43.70850,231.0
43.78350,223.0
43.85850,207.0
43.93350,208.0
44.00850,177.0
44.08350,191.0
44.15850,203.0
44.23350,191.0
44.30850,193.0
44.38350,190.0
44.45850,199.0
44.53350,184.0
44.60850,184.0
44.68350,183.0
44.75850,178.0
44.83350,193.0
44.90850,172.0
44.98350,197.0
45.05850,169.0
45.13350,180.0
45.20850,180.0
45.28350,184.0
45.35850,150.0
45.43350,180.0
45.50850,163.0
45.58350,158.0
45.65850,157.0
45.73350,174.0
45.80850,150.0
45.88350,176.0
45.95850,171.0
46.03350,167.0
46.10850,172.0
46.18350,156.0
46.25850,158.0
46.33350,158.0
46.40850,158.0
46.48350,166.0
46.55850,180.0
46.63350,175.0
46.70850,183.0
46.78350,201.0
46.85850,196.0
46.93350,195.0
47.00850,190.0
47.08350,220.0
47.15850,234.0
47.23350,232.0
47.30850,278.0
47.38350,310.0
47.45850,365.0
47.53350,437.0
47.60850,578.0
47.68350,887.0
47.75850,1463.0
47.83350,2383.0
47.90850,3590.0
47.98350,4128.0
48.05850,4077.0
48.13350,3130.0
48.20850,2041.0
48.28350,1221.0
48.35850,736.0
48.43350,508.0
48.50850,369.0
48.58350,312.0
48.65850,268.0
48.73350,224.0
48.80850,189.0
48.88350,189.0
48.95850,201.0
49.03350,202.0
49.10850,169.0
49.18350,198.0
49.25850,162.0
49.33350,162.0
49.40850,168.0
49.48350,165.0
49.55850,147.0
49.63350,162.0
49.70850,172.0
49.78350,158.0
49.85850,147.0
49.93350,150.0
50.00850,147.0
50.08350,134.0
50.15850,159.0
50.23350,133.0
50.30850,148.0
50.38350,157.0
50.45850,146.0
50.53350,154.0
50.60850,150.0
50.68350,134.0
50.75850,135.0
50.83350,153.0
50.90850,150.0
50.98350,146.0
51.05850,154.0
51.13350,153.0
51.20850,159.0
51.28350,167.0
51.35850,152.0
51.43350,179.0
51.50850,170.0
51.58350,160.0
51.65850,173.0
51.73350,189.0
51.80850,169.0
51.88350,190.0
51.95850,198.0
52.03350,217.0
52.10850,205.0
52.18350,259.0
52.25850,264.0
52.33350,283.0
52.40850,366.0
52.48350,482.0
52.55850,647.0
52.63350,953.0
52.70850,1574.0
52.78350,2355.0
52.85850,3326.0
52.93350,3987.0
53.00850,3853.0
53.08350,3128.0
53.15850,2411.0
53.23350,1655.0
53.30850,1089.0
53.38350,738.0
53.45850,650.0
53.53350,516.0
53.60850,615.0
53.68350,563.0
53.75850,658.0
53.83350,762.0
53.90850,707.0
53.98350,745.0
54.05850,650.0
54.13350,603.0
54.20850,537.0
54.28350,552.0
54.35850,444.0
54.43350,439.0
54.50850,428.0
54.58350,501.0
54.65850,523.0
54.73350,639.0
54.80850,849.0
54.88350,1048.0
54.95850,1260.0
55.03350,1312.0
55.10850,1177.0
55.18350,982.0
55.25850,680.0
55.33350,480.0
55.40850,350.0
55.48350,261.0
55.55850,230.0
55.63350,236.0
55.70850,204.0
55.78350,181.0
55.85850,202.0
55.93350,201.0
56.00850,193.0
56.08350,176.0
56.15850,187.0
56.23350,180.0
56.30850,178.0
56.38350,176.0
56.45850,183.0
56.53350,185.0
56.60850,204.0
56.68350,191.0
56.75850,165.0
56.83350,165.0
56.90850,166.0
56.98350,172.0
57.05850,162.0
57.13350,151.0
57.20850,159.0
57.28350,151.0
57.35850,153.0
57.43350,156.0
57.50850,165.0
57.58350,158.0
57.65850,159.0
57.73350,151.0
57.80850,149.0
57.88350,132.0
57.95850,128.0
58.03350,131.0
58.10850,134.0
58.18350,144.0
58.25850,147.0
58.33350,123.0
58.40850,149.0
58.48350,153.0
58.55850,128.0
58.63350,128.0
58.70850,131.0
58.78350,142.0
58.85850,129.0
58.93350,140.0
59.00850,168.0
59.08350,137.0
59.15850,131.0
59.23350,138.0
59.30850,145.0
59.38350,129.0
59.45850,162.0
59.53350,135.0
59.60850,157.0
59.68350,144.0
59.75850,146.0
59.83350,156.0
59.90850,148.0
59.98350,148.0
60.05850,128.0
60.13350,150.0
60.20850,129.0
60.28350,136.0
60.35850,154.0
60.43350,128.0
60.50850,151.0
60.58350,152.0
60.65850,135.0
60.73350,151.0
60.80850,151.0
60.88350,150.0
60.95850,178.0
61.03350,150.0
61.10850,173.0
61.18350,162.0
61.25850,166.0
61.33350,174.0
61.40850,184.0
61.48350,183.0
61.55850,192.0
61.63350,240.0
61.70850,209.0
61.78350,265.0
61.85850,299.0
61.93350,352.0
62.00850,419.0
62.08350,473.0
62.15850,475.0
62.23350,514.0
62.30850,551.0
62.38350,620.0
62.45850,800.0
62.53350,1094.0
62.60850,1356.0
62.68350,1764.0
62.75850,2059.0
62.83350,2284.0
62.90850,2397.0
62.98350,2140.0
63.05850,1795.0
63.13350,1440.0
63.20850,1029.0
63.28350,762.0
63.35850,561.0
63.43350,424.0
63.50850,374.0
63.58350,301.0
63.65850,291.0
63.73350,271.0
63.80850,252.0
63.88350,228.0
63.95850,194.0
64.03350,195.0
64.10850,202.0
64.18350,195.0
64.25850,202.0
64.33350,191.0
64.40850,171.0
64.48350,176.0
64.55850,193.0
64.63350,182.0
64.70850,165.0
64.78350,166.0
64.85850,167.0
64.93350,158.0
65.00850,166.0
65.08350,149.0
65.15850,173.0
65.23350,144.0
65.30850,132.0
65.38350,157.0
65.45850,137.0
65.53350,163.0
65.60850,142.0
65.68350,131.0
65.75850,149.0
65.83350,138.0
65.90850,131.0
65.98350,157.0
66.05850,147.0
66.13350,145.0
66.20850,144.0
66.28350,137.0
66.35850,138.0
66.43350,147.0
66.50850,134.0
66.58350,154.0
66.65850,141.0
66.73350,156.0
66.80850,141.0
66.88350,132.0
66.95850,138.0
67.03350,154.0
67.10850,153.0
67.18350,154.0
67.25850,152.0
67.33350,164.0
67.40850,157.0
67.48350,171.0
67.55850,138.0
67.63350,159.0
67.70850,154.0
67.78350,153.0
67.85850,151.0
67.93350,174.0
68.00850,185.0
68.08350,184.0
68.15850,179.0
68.23350,188.0
68.30850,192.0
68.38350,240.0
68.45850,267.0
68.53350,250.0
68.60850,290.0
68.68350,319.0
68.75850,305.0
68.83350,324.0
68.90850,302.0
68.98350,252.0
69.05850,296.0
69.13350,255.0
69.20850,245.0
69.28350,263.0
69.35850,265.0
69.43350,250.0
69.50850,275.0
69.58350,268.0
69.65850,276.0
69.73350,287.0
69.80850,344.0
69.88350,405.0
69.95850,487.0
70.03350,572.0
70.10850,806.0
70.18350,928.0
70.25850,1201.0
70.33350,1559.0
70.40850,2218.0
70.48350,2870.0
70.55850,3376.0
70.63350,3664.0
70.70850,3378.0
70.78350,2917.0
70.85850,2288.0
70.93350,1710.0
71.00850,1190.0
71.08350,859.0
71.15850,556.0
71.23350,466.0
71.30850,319.0
71.38350,270.0
71.45850,239.0
71.53350,264.0
71.60850,211.0
71.68350,194.0
71.75850,199.0
71.83350,181.0
71.90850,187.0
71.98350,198.0
72.05850,186.0
72.13350,165.0
72.20850,161.0
72.28350,149.0
72.35850,148.0
72.43350,191.0
72.50850,171.0
72.58350,173.0
72.65850,154.0
72.73350,154.0
72.80850,172.0
72.88350,158.0
72.95850,161.0
73.03350,166.0
73.10850,161.0
73.18350,144.0
73.25850,184.0
73.33350,171.0
73.40850,145.0
73.48350,194.0
73.55850,201.0
73.63350,234.0
73.70850,224.0
73.78350,283.0
73.85850,352.0
73.93350,423.0
74.00850,490.0
74.08350,552.0
74.15850,552.0
74.23350,514.0
74.30850,488.0
74.38350,410.0
74.45850,410.0
74.53350,363.0
74.60850,318.0
74.68350,364.0
74.75850,397.0
74.83350,411.0
74.90850,462.0
74.98350,522.0
75.05850,495.0
75.13350,516.0
75.20850,509.0
75.28350,435.0
75.35850,480.0
75.43350,409.0
75.50850,418.0
75.58350,472.0
75.65850,554.0
75.73350,694.0
75.80850,930.0
75.88350,1250.0
75.95850,1649.0
76.03350,2140.0
76.10850,2528.0
76.18350,2688.0
76.25850,2491.0
76.33350,2348.0
76.40850,2005.0
76.48350,1620.0
76.55850,1232.0
76.63350,968.0
76.70850,790.0
76.78350,726.0
76.85850,623.0
76.93350,751.0
77.00850,992.0
77.08350,1131.0
77.15850,1541.0
77.23350,1893.0
77.30850,1974.0
77.38350,1906.0
77.45850,1758.0
77.53350,1520.0
77.60850,1281.0
77.68350,1004.0
77.75850,755.0
77.83350,582.0
77.90850,463.0
77.98350,388.0
78.05850,300.0
78.13350,246.0
78.20850,248.0
78.28350,215.0
78.35850,185.0
78.43350,159.0
78.50850,187.0
78.58350,172.0
78.65850,153.0
78.73350,168.0
78.80850,127.0
78.88350,142.0
78.95850,137.0
79.03350,116.0
79.10850,112.0
79.18350,131.0
79.25850,124.0
79.33350,118.0
79.40850,108.0
79.48350,134.0
79.55850,135.0
79.63350,135.0
79.70850,133.0
79.78350,122.0
79.85850,141.0
79.93350,160.0
80.00850,117.0
80.08350,121.0
80.15850,120.0
80.23350,140.0
80.30850,127.0
80.38350,120.0
80.45850,132.0
80.53350,155.0
80.60850,128.0
80.68350,127.0
80.75850,119.0
80.83350,144.0
80.90850,139.0
80.98350,172.0
81.05850,134.0
81.13350,147.0
81.20850,150.0
81.28350,164.0
81.35850,144.0
81.43350,169.0
81.50850,175.0
81.58350,175.0
81.65850,204.0
81.73350,230.0
81.80850,308.0
81.88350,366.0
81.95850,517.0
82.03350,753.0
82.10850,1098.0
82.18350,1426.0
82.25850,1680.0
82.33350,1554.0
82.40850,1415.0
82.48350,1327.0
82.55850,1128.0
82.63350,918.0
82.70850,677.0
82.78350,564.0
82.85850,446.0
82.93350,408.0
83.00850,352.0
83.08350,335.0
83.15850,285.0
83.23350,292.0
83.30850,206.0
83.38350,211.0
83.45850,200.0
83.53350,165.0
83.60850,144.0
83.68350,137.0
83.75850,153.0
83.83350,127.0
83.90850,131.0
83.98350,113.0
84.05850,135.0
84.13350,129.0
84.20850,122.0
84.28350,134.0
84.35850,127.0
84.43350,115.0
84.50850,127.0
84.58350,111.0
84.65850,114.0
84.73350,105.0
84.80850,113.0
84.88350,123.0
84.95850,89.0
85.03350,123.0
85.10850,107.0
85.18350,101.0
85.25850,105.0
85.33350,97.0
85.40850,100.0
85.48350,102.0
85.55850,116.0
85.63350,115.0
85.70850,124.0
85.78350,118.0
85.85850,118.0
85.93350,127.0
86.00850,137.0
86.08350,157.0
86.15850,161.0
86.23350,168.0
86.30850,189.0
86.38350,234.0
86.45850,278.0
86.53350,337.0
86.60850,411.0
86.68350,424.0
86.75850,450.0
86.83350,404.0
86.90850,364.0
86.98350,324.0
87.05850,313.0
87.13350,257.0
87.20850,192.0
87.28350,181.0
87.35850,153.0
87.43350,168.0
87.50850,113.0
87.58350,129.0
87.65850,99.0
87.73350,106.0
87.80850,112.0
87.88350,104.0
87.95850,98.0
88.03350,96.0
88.10850,101.0
88.18350,99.0
88.25850,97.0
88.33350,93.0
88.40850,95.0
88.48350,76.0
88.55850,94.0
88.63350,92.0
88.70850,104.0
88.78350,99.0
88.85850,93.0
88.93350,99.0
89.00850,96.0
89.08350,87.0
89.15850,93.0
89.23350,91.0
89.30850,95.0
89.38350,92.0
89.45850,90.0
89.53350,103.0
89.60850,94.0
89.68350,104.0
89.75850,94.0
89.83350,94.0
89.90850,104.0
89.98350,117.0
90.05850,111.0
90.13350,105.0
90.20850,105.0
90.28350,108.0
90.35850,78.0
90.43350,71.0
90.50850,87.0
90.58350,79.0
90.65850,90.0
90.73350,94.0
90.80850,93.0
90.88350,95.0
90.95850,94.0
91.03350,80.0
91.10850,107.0
91.18350,92.0
91.25850,107.0
91.33350,102.0
91.40850,102.0
91.48350,97.0
91.55850,95.0
91.63350,103.0
91.70850,96.0
91.78350,108.0
91.85850,120.0
91.93350,106.0
92.00850,123.0
92.08350,134.0
92.15850,141.0
92.23350,176.0
92.30850,213.0
92.38350,250.0
92.45850,332.0
92.53350,424.0
92.60850,506.0
92.68350,640.0
92.75850,560.0
92.83350,514.0
92.90850,485.0
92.98350,444.0
93.05850,384.0
93.13350,305.0
93.20850,258.0
93.28350,213.0
93.35850,177.0
93.43350,210.0
93.50850,149.0
93.58350,165.0
93.65850,137.0
93.73350,135.0
93.80850,145.0
93.88350,141.0
93.95850,167.0
94.03350,169.0
94.10850,167.0
94.18350,160.0
94.25850,196.0
94.33350,203.0
94.40850,144.0
94.48350,186.0
94.55850,168.0
94.63350,168.0
94.70850,169.0
94.78350,180.0
94.85850,170.0
94.93350,214.0
95.00850,214.0
95.08350,208.0
95.15850,217.0
95.23350,226.0
95.30850,217.0
95.38350,241.0
95.45850,207.0
95.53350,152.0
95.60850,128.0
95.68350,143.0
95.75850,136.0
95.83350,131.0
95.90850,118.0
95.98350,101.0
96.05850,98.0
96.13350,114.0
96.20850,79.0
96.28350,99.0
96.35850,87.0
96.43350,97.0
96.50850,106.0
96.58350,91.0
96.65850,116.0
96.73350,113.0
96.80850,130.0
96.88350,97.0
96.95850,94.0
97.03350,106.0
97.10850,98.0
97.18350,91.0
97.25850,95.0
97.33350,118.0
97.40850,98.0
97.48350,108.0
97.55850,95.0
97.63350,106.0
97.70850,106.0
97.78350,104.0
97.85850,103.0
97.93350,95.0
98.00850,115.0
98.08350,121.0
98.15850,124.0
98.23350,122.0
98.30850,144.0
98.38350,144.0
98.45850,136.0
98.53350,143.0
98.60850,131.0
98.68350,113.0
98.75850,140.0
98.83350,102.0
98.90850,150.0
98.98350,136.0
99.05850,102.0
99.13350,123.0
99.20850,119.0
99.28350,114.0
99.35850,137.0
99.43350,114.0
99.50850,116.0
99.58350,107.0
99.65850,142.0
99.73350,120.0
99.80850,126.0
99.88350,124.0
99.95850,141.0
99.98350,127.0