File: code/data/data_source2/TiNb_KL381D_Ti40Nb_1_Grazing.csv
[Measurement conditions]
Sample identification,
Comment - 1,"Configuration=Filmes Finos 19_1_2015, Owner=User-1, Creation date=19/01/2015 21:17:15"
Comment - 2,"Goniometer=PW3050/60 (Theta/Theta); Minimum step size 2Theta:0.001; Minimum step size Omega:0.001"
Comment - 3,"Sample stage=PW3071/xx Bracket"
Comment - 4,"Diffractometer system=XPERT-PRO"
Comment - 5,"Measurement program=C:\PANalytical\Data Collector\Programs\GrazingIncidence.xrdmp, Identifier={B582B90F-1D45-47AE-98F5-4C15691F6AD6}"
Anode material,Cu
K-Alpha1 wavelength,1.5405980
K-Alpha2 wavelength,1.5444260
Ratio K-Alpha2/K-Alpha1,0.500
Divergence slit,Fixed,0.76mm
Receiving slit,0.10
Monochromator used,YES
Generator voltage, 40
Tube current, 40
File date and time,13/Jun/2018 13:19
Unit cell,
h k l, 0 0 0
Scan axis,2Theta
Scan range,20.00000,80.00000
Scan step size,0.0120000
No. of points, 5000
Scan type,CONTINUOUS
Omega,5.000
Time per step,1.50
[Scan points]
Angle,Intensity
20.00600,32.0
20.05400,37.0
20.10200,26.0
20.15000,16.0
20.19800,33.0
20.24600,20.0
20.29400,29.0
20.34200,35.0
20.39000,21.0
20.43800,20.0
20.48600,22.0
20.53400,18.0
20.58200,25.0
20.63000,32.0
20.67800,25.0
20.72600,22.0
20.77400,27.0
20.82200,18.0
20.87000,12.0
20.91800,31.0
20.96600,37.0
21.01400,30.0
21.06200,26.0
21.11000,31.0
21.15800,43.0
21.20600,30.0
21.25400,24.0
21.30200,30.0
21.35000,23.0
21.39800,28.0
21.44600,32.0
21.49400,24.0
21.54200,21.0
21.59000,24.0
21.63800,21.0
21.68600,23.0
21.73400,24.0
21.78200,19.0
21.83000,31.0
21.87800,24.0
21.92600,28.0
21.97400,24.0
22.02200,21.0
22.07000,23.0
22.11800,27.0
22.16600,15.0
22.21400,19.0
22.26200,13.0
22.31000,27.0
22.35800,26.0
22.40600,18.0
22.45400,19.0
22.50200,24.0
22.55000,22.0
22.59800,24.0
22.64600,18.0
22.69400,23.0
22.74200,24.0
22.79000,15.0
22.83800,17.0
22.88600,29.0
22.93400,24.0
22.98200,14.0
23.03000,18.0
23.07800,16.0
23.12600,28.0
23.17400,19.0
23.22200,13.0
23.27000,20.0
23.31800,21.0
23.36600,20.0
23.41400,22.0
23.46200,21.0
23.51000,25.0
23.55800,16.0
23.60600,12.0
23.65400,17.0
23.70200,21.0
23.75000,17.0
23.79800,17.0
23.84600,15.0
23.89400,18.0
23.94200,18.0
23.99000,25.0
24.03800,20.0
24.08600,16.0
24.13400,22.0
24.18200,18.0
24.23000,15.0
24.27800,17.0
24.32600,18.0
24.37400,21.0
24.42200,21.0
24.47000,21.0
24.51800,19.0
24.56600,12.0
24.61400,16.0
24.66200,15.0
24.71000,27.0
24.75800,22.0
24.80600,15.0
24.85400,26.0
24.90200,19.0
24.95000,14.0
24.99800,12.0
25.04600,15.0
25.09400,20.0
25.14200,24.0
25.19000,29.0
25.23800,19.0
25.28600,23.0
25.33400,15.0
25.38200,9.0
25.43000,21.0
25.47800,23.0
25.52600,16.0
25.57400,15.0
25.62200,16.0
25.67000,15.0
25.71800,16.0
25.76600,15.0
25.81400,23.0
25.86200,13.0
25.91000,19.0
25.95800,18.0
26.00600,19.0
26.05400,22.0
26.10200,12.0
26.15000,14.0
26.19800,19.0
26.24600,16.0
26.29400,14.0
26.34200,15.0
26.39000,15.0
26.43800,16.0
26.48600,10.0
26.53400,15.0
26.58200,10.0
26.63000,15.0
26.67800,11.0
26.72600,14.0
26.77400,13.0
26.82200,18.0
26.87000,15.0
26.91800,18.0
26.96600,10.0
27.01400,18.0
27.06200,21.0
27.11000,17.0
27.15800,8.0
27.20600,19.0
27.25400,14.0
27.30200,15.0
27.35000,12.0
27.39800,12.0
27.44600,16.0
27.49400,14.0
27.54200,18.0
27.59000,16.0
27.63800,13.0
27.68600,18.0
27.73400,8.0
27.78200,16.0
27.83000,15.0
27.87800,14.0
27.92600,11.0
27.97400,18.0
28.02200,20.0
28.07000,18.0
28.11800,14.0
28.16600,19.0
28.21400,16.0
28.26200,15.0
28.31000,15.0
28.35800,12.0
28.40600,20.0
28.45400,19.0
28.50200,14.0
28.55000,18.0
28.59800,14.0
28.64600,14.0
28.69400,9.0
28.74200,9.0
28.79000,12.0
28.83800,23.0
28.88600,13.0
28.93400,18.0
28.98200,13.0
29.03000,15.0
29.07800,8.0
29.12600,17.0
29.17400,21.0
29.22200,16.0
29.27000,14.0
29.31800,9.0
29.36600,14.0
29.41400,8.0
29.46200,12.0
29.51000,9.0
29.55800,10.0
29.60600,13.0
29.65400,18.0
29.70200,12.0
29.75000,5.0
29.79800,10.0
29.84600,17.0
29.89400,10.0
29.94200,13.0
29.99000,11.0
30.03800,18.0
30.08600,12.0
30.13400,10.0
30.18200,20.0
30.23000,12.0
30.27800,17.0
30.32600,14.0
30.37400,10.0
30.42200,17.0
30.47000,18.0
30.51800,24.0
30.56600,20.0
30.61400,12.0
30.66200,15.0
30.71000,14.0
30.75800,16.0
30.80600,16.0
30.85400,13.0
30.90200,14.0
30.95000,15.0
30.99800,10.0
31.04600,14.0
31.09400,14.0
31.14200,12.0
31.19000,11.0
31.23800,8.0
31.28600,16.0
31.33400,16.0
31.38200,17.0
31.43000,20.0
31.47800,15.0
31.52600,12.0
31.57400,9.0
31.62200,11.0
31.67000,16.0
31.71800,12.0
31.76600,11.0
31.81400,5.0
31.86200,9.0
31.91000,8.0
31.95800,12.0
32.00600,11.0
32.05400,17.0
32.10200,15.0
32.15000,13.0
32.19800,15.0
32.24600,12.0
32.29400,16.0
32.34200,15.0
32.39000,10.0
32.43800,15.0
32.48600,9.0
32.53400,4.0
32.58200,17.0
32.63000,12.0
32.67800,16.0
32.72600,11.0
32.77400,7.0
32.82200,15.0
32.87000,13.0
32.91800,7.0
32.96600,18.0
33.01400,5.0
33.06200,11.0
33.11000,15.0
33.15800,11.0
33.20600,10.0
33.25400,15.0
33.30200,8.0
33.35000,11.0
33.39800,13.0
33.44600,9.0
33.49400,14.0
33.54200,7.0
33.59000,13.0
33.63800,10.0
33.68600,15.0
33.73400,7.0
33.78200,21.0
33.83000,13.0
33.87800,19.0
33.92600,13.0
33.97400,11.0
34.02200,17.0
34.07000,14.0
34.11800,17.0
34.16600,15.0
34.21400,19.0
34.26200,13.0
34.31000,13.0
34.35800,19.0
34.40600,14.0
34.45400,22.0
34.50200,26.0
34.55000,27.0
34.59800,37.0
34.64600,41.0
34.69400,67.0
34.74200,76.0
34.79000,116.0
34.83800,123.0
34.88600,135.0
34.93400,164.0
34.98200,173.0
35.03000,146.0
35.07800,140.0
35.12600,120.0
35.17400,77.0
35.22200,57.0
35.27000,52.0
35.31800,38.0
35.36600,26.0
35.41400,28.0
35.46200,27.0
35.51000,19.0
35.55800,17.0
35.60600,16.0
35.65400,13.0
35.70200,20.0
35.75000,14.0
35.79800,15.0
35.84600,17.0
35.89400,14.0
35.94200,9.0
35.99000,5.0
36.03800,18.0
36.08600,16.0
36.13400,10.0
36.18200,13.0
36.23000,17.0
36.27800,9.0
36.32600,16.0
36.37400,18.0
36.42200,17.0
36.47000,27.0
36.51800,20.0
36.56600,27.0
36.61400,27.0
36.66200,39.0
36.71000,42.0
36.75800,37.0
36.80600,38.0
36.85400,36.0
36.90200,31.0
36.95000,31.0
36.99800,20.0
37.04600,28.0
37.09400,27.0
37.14200,28.0
37.19000,19.0
37.23800,19.0
37.28600,16.0
37.33400,11.0
37.38200,18.0
37.43000,21.0
37.47800,25.0
37.52600,15.0
37.57400,14.0
37.62200,22.0
37.67000,16.0
37.71800,15.0
37.76600,25.0
37.81400,14.0
37.86200,23.0
37.91000,29.0
37.95800,34.0
38.00600,36.0
38.05400,34.0
38.10200,57.0
38.15000,43.0
38.19800,55.0
38.24600,57.0
38.29400,50.0
38.34200,49.0
38.39000,53.0
38.43800,73.0
38.48600,59.0
38.53400,69.0
38.58200,92.0
38.63000,74.0
38.67800,86.0
38.72600,82.0
38.77400,95.0
38.82200,77.0
38.87000,64.0
38.91800,71.0
38.96600,58.0
39.01400,43.0
39.06200,50.0
39.11000,41.0
39.15800,35.0
39.20600,35.0
39.25400,29.0
39.30200,32.0
39.35000,33.0
39.39800,42.0
39.44600,32.0
39.49400,32.0
39.54200,43.0
39.59000,44.0
39.63800,51.0
39.68600,56.0
39.73400,114.0
39.78200,124.0
39.83000,175.0
39.87800,174.0
39.92600,211.0
39.97400,234.0
40.02200,274.0
40.07000,232.0
40.11800,224.0
40.16600,206.0
40.21400,121.0
40.26200,123.0
40.31000,96.0
40.35800,73.0
40.40600,65.0
40.45400,42.0
40.50200,46.0
40.55000,26.0
40.59800,30.0
40.64600,30.0
40.69400,17.0
40.74200,18.0
40.79000,19.0
40.83800,13.0
40.88600,9.0
40.93400,17.0
40.98200,15.0
41.03000,15.0
41.07800,16.0
41.12600,7.0
41.17400,9.0
41.22200,12.0
41.27000,18.0
41.31800,12.0
41.36600,13.0
41.41400,10.0
41.46200,10.0
41.51000,15.0
41.55800,14.0
41.60600,14.0
41.65400,16.0
41.70200,15.0
41.75000,10.0
41.79800,12.0
41.84600,10.0
41.89400,16.0
41.94200,13.0
41.99000,13.0
42.03800,13.0
42.08600,21.0
42.13400,18.0
42.18200,39.0
42.23000,40.0
42.27800,50.0
42.32600,42.0
42.37400,46.0
42.42200,64.0
42.47000,64.0
42.51800,64.0
42.56600,74.0
42.61400,77.0
42.66200,42.0
42.71000,61.0
42.75800,41.0
42.80600,34.0
42.85400,33.0
42.90200,37.0
42.95000,25.0
42.99800,25.0
43.04600,20.0
43.09400,11.0
43.14200,19.0
43.19000,20.0
43.23800,14.0
43.28600,15.0
43.33400,10.0
43.38200,7.0
43.43000,19.0
43.47800,4.0
43.52600,11.0
43.57400,11.0
43.62200,9.0
43.67000,8.0
43.71800,9.0
43.76600,9.0
43.81400,12.0
43.86200,8.0
43.91000,4.0
43.95800,4.0
44.00600,4.0
44.05400,14.0
44.10200,5.0
44.15000,8.0
44.19800,9.0
44.24600,6.0
44.29400,10.0
44.34200,5.0
44.39000,8.0
44.43800,4.0
44.48600,7.0
44.53400,5.0
44.58200,9.0
44.63000,10.0
44.67800,9.0
44.72600,4.0
44.77400,3.0
44.82200,9.0
44.87000,9.0
44.91800,10.0
44.96600,3.0
45.01400,9.0
45.06200,14.0
45.11000,9.0
45.15800,6.0
45.20600,2.0
45.25400,8.0
45.30200,6.0
45.35000,4.0
45.39800,6.0
45.44600,10.0
45.49400,7.0
45.54200,7.0
45.59000,6.0
45.63800,9.0
45.68600,9.0
45.73400,4.0
45.78200,9.0
45.83000,7.0
45.87800,8.0
45.92600,7.0
45.97400,11.0
46.02200,10.0
46.07000,6.0
46.11800,12.0
46.16600,5.0
46.21400,8.0
46.26200,9.0
46.31000,4.0
46.35800,4.0
46.40600,7.0
46.45400,5.0
46.50200,6.0
46.55000,14.0
46.59800,2.0
46.64600,5.0
46.69400,2.0
46.74200,6.0
46.79000,3.0
46.83800,5.0
46.88600,4.0
46.93400,6.0
46.98200,6.0
47.03000,5.0
47.07800,7.0
47.12600,4.0
47.17400,7.0
47.22200,7.0
47.27000,3.0
47.31800,7.0
47.36600,1.0
47.41400,6.0
47.46200,5.0
47.51000,4.0
47.55800,4.0
47.60600,5.0
47.65400,6.0
47.70200,5.0
47.75000,0.0
47.79800,8.0
47.84600,3.0
47.89400,4.0
47.94200,1.0
47.99000,2.0
48.03800,9.0
48.08600,4.0
48.13400,5.0
48.18200,6.0
48.23000,5.0
48.27800,7.0
48.32600,7.0
48.37400,6.0
48.42200,5.0
48.47000,7.0
48.51800,3.0
48.56600,7.0
48.61400,9.0
48.66200,7.0
48.71000,6.0
48.75800,5.0
48.80600,9.0
48.85400,6.0
48.90200,1.0
48.95000,11.0
48.99800,2.0
49.04600,6.0
49.09400,6.0
49.14200,7.0
49.19000,7.0
49.23800,10.0
49.28600,10.0
49.33400,5.0
49.38200,6.0
49.43000,1.0
49.47800,6.0
49.52600,4.0
49.57400,4.0
49.62200,9.0
49.67000,7.0
49.71800,7.0
49.76600,9.0
49.81400,3.0
49.86200,5.0
49.91000,5.0
49.95800,8.0
50.00600,6.0
50.05400,3.0
50.10200,11.0
50.15000,8.0
50.19800,3.0
50.24600,9.0
50.29400,8.0
50.34200,4.0
50.39000,7.0
50.43800,8.0
50.48600,9.0
50.53400,7.0
50.58200,6.0
50.63000,7.0
50.67800,10.0
50.72600,4.0
50.77400,5.0
50.82200,5.0
50.87000,5.0
50.91800,13.0
50.96600,8.0
51.01400,9.0
51.06200,5.0
51.11000,14.0
51.15800,2.0
51.20600,10.0
51.25400,8.0
51.30200,8.0
51.35000,14.0
51.39800,6.0
51.44600,7.0
51.49400,5.0
51.54200,7.0
51.59000,8.0
51.63800,6.0
51.68600,5.0
51.73400,5.0
51.78200,3.0
51.83000,8.0
51.87800,6.0
51.92600,9.0
51.97400,9.0
52.02200,9.0
52.07000,7.0
52.11800,6.0
52.16600,5.0
52.21400,13.0
52.26200,11.0
52.31000,10.0
52.35800,12.0
52.40600,17.0
52.45400,21.0
52.50200,41.0
52.55000,38.0
52.59800,58.0
52.64600,69.0
52.69400,86.0
52.74200,92.0
52.79000,97.0
52.83800,82.0
52.88600,85.0
52.93400,78.0
52.98200,62.0
53.03000,61.0
53.07800,63.0
53.12600,31.0
53.17400,34.0
53.22200,21.0
53.27000,14.0
53.31800,18.0
53.36600,19.0
53.41400,21.0
53.46200,13.0
53.51000,13.0
53.55800,13.0
53.60600,13.0
53.65400,15.0
53.70200,12.0
53.75000,8.0
53.79800,10.0
53.84600,3.0
53.89400,8.0
53.94200,5.0
53.99000,17.0
54.03800,14.0
54.08600,6.0
54.13400,12.0
54.18200,19.0
54.23000,6.0
54.27800,15.0
54.32600,16.0
54.37400,7.0
54.42200,6.0
54.47000,14.0
54.51800,6.0
54.56600,10.0
54.61400,13.0
54.66200,14.0
54.71000,9.0
54.75800,13.0
54.80600,10.0
54.85400,16.0
54.90200,10.0
54.95000,12.0
54.99800,15.0
55.04600,13.0
55.09400,15.0
55.14200,17.0
55.19000,15.0
55.23800,21.0
55.28600,21.0
55.33400,20.0
55.38200,24.0
55.43000,28.0
55.47800,22.0
55.52600,20.0
55.57400,28.0
55.62200,30.0
55.67000,26.0
55.71800,35.0
55.76600,24.0
55.81400,39.0
55.86200,38.0
55.91000,45.0
55.95800,29.0
56.00600,32.0
56.05400,43.0
56.10200,40.0
56.15000,28.0
56.19800,39.0
56.24600,29.0
56.29400,21.0
56.34200,29.0
56.39000,19.0
56.43800,22.0
56.48600,16.0
56.53400,14.0
56.58200,14.0
56.63000,18.0
56.67800,15.0
56.72600,13.0
56.77400,11.0
56.82200,8.0
56.87000,15.0
56.91800,9.0
56.96600,13.0
57.01400,6.0
57.06200,9.0
57.11000,11.0
57.15800,9.0
57.20600,7.0
57.25400,4.0
57.30200,3.0
57.35000,2.0
57.39800,8.0
57.44600,12.0
57.49400,9.0
57.54200,9.0
57.59000,6.0
57.63800,6.0
57.68600,8.0
57.73400,4.0
57.78200,8.0
57.83000,9.0
57.87800,8.0
57.92600,7.0
57.97400,4.0
58.02200,11.0
58.07000,0.0
58.11800,9.0
58.16600,8.0
58.21400,6.0
58.26200,5.0
58.31000,8.0
58.35800,8.0
58.40600,3.0
58.45400,4.0
58.50200,10.0
58.55000,6.0
58.59800,6.0
58.64600,10.0
58.69400,3.0
58.74200,6.0
58.79000,3.0
58.83800,5.0
58.88600,8.0
58.93400,4.0
58.98200,2.0
59.03000,7.0
59.07800,7.0
59.12600,1.0
59.17400,8.0
59.22200,8.0
59.27000,6.0
59.31800,6.0
59.36600,4.0
59.41400,9.0
59.46200,4.0
59.51000,9.0
59.55800,5.0
59.60600,9.0
59.65400,6.0
59.70200,5.0
59.75000,8.0
59.79800,6.0
59.84600,7.0
59.89400,8.0
59.94200,8.0
59.99000,6.0
60.03800,8.0
60.08600,7.0
60.13400,3.0
60.18200,10.0
60.23000,10.0
60.27800,5.0
60.32600,5.0
60.37400,6.0
60.42200,3.0
60.47000,7.0
60.51800,6.0
60.56600,3.0
60.61400,9.0
60.66200,7.0
60.71000,8.0
60.75800,10.0
60.80600,7.0
60.85400,9.0
60.90200,8.0
60.95000,11.0
60.99800,11.0
61.04600,8.0
61.09400,9.0
61.14200,8.0
61.19000,9.0
61.23800,11.0
61.28600,6.0
61.33400,11.0
61.38200,15.0
61.43000,12.0
61.47800,19.0
61.52600,14.0
61.57400,16.0
61.62200,23.0
61.67000,22.0
61.71800,25.0
61.76600,27.0
61.81400,26.0
61.86200,26.0
61.91000,45.0
61.95800,43.0
62.00600,45.0
62.05400,42.0
62.10200,42.0
62.15000,34.0
62.19800,48.0
62.24600,39.0
62.29400,51.0
62.34200,41.0
62.39000,53.0
62.43800,49.0
62.48600,46.0
62.53400,40.0
62.58200,77.0
62.63000,91.0
62.67800,63.0
62.72600,114.0
62.77400,114.0
62.82200,101.0
62.87000,96.0
62.91800,103.0
62.96600,82.0
63.01400,81.0
63.06200,79.0
63.11000,78.0
63.15800,44.0
63.20600,46.0
63.25400,37.0
63.30200,33.0
63.35000,31.0
63.39800,28.0
63.44600,29.0
63.49400,23.0
63.54200,13.0
63.59000,13.0
63.63800,8.0
63.68600,13.0
63.73400,10.0
63.78200,14.0
63.83000,13.0
63.87800,7.0
63.92600,11.0
63.97400,11.0
64.02200,4.0
64.07000,13.0
64.11800,6.0
64.16600,5.0
64.21400,5.0
64.26200,4.0
64.31000,7.0
64.35800,9.0
64.40600,8.0
64.45400,10.0
64.50200,8.0
64.55000,11.0
64.59800,6.0
64.64600,7.0
64.69400,7.0
64.74200,7.0
64.79000,6.0
64.83800,7.0
64.88600,3.0
64.93400,4.0
64.98200,7.0
65.03000,11.0
65.07800,3.0
65.12600,1.0
65.17400,5.0
65.22200,7.0
65.27000,5.0
65.31800,4.0
65.36600,7.0
65.41400,3.0
65.46200,14.0
65.51000,11.0
65.55800,6.0
65.60600,4.0
65.65400,11.0
65.70200,4.0
65.75000,12.0
65.79800,5.0
65.84600,6.0
65.89400,9.0
65.94200,8.0
65.99000,7.0
66.03800,5.0
66.08600,3.0
66.13400,9.0
66.18200,9.0
66.23000,3.0
66.27800,5.0
66.32600,3.0
66.37400,7.0
66.42200,8.0
66.47000,6.0
66.51800,6.0
66.56600,4.0
66.61400,6.0
66.66200,11.0
66.71000,4.0
66.75800,8.0
66.80600,5.0
66.85400,4.0
66.90200,5.0
66.95000,6.0
66.99800,8.0
67.04600,7.0
67.09400,6.0
67.14200,2.0
67.19000,2.0
67.23800,6.0
67.28600,4.0
67.33400,3.0
67.38200,6.0
67.43000,3.0
67.47800,6.0
67.52600,6.0
67.57400,8.0
67.62200,8.0
67.67000,2.0
67.71800,3.0
67.76600,2.0
67.81400,3.0
67.86200,3.0
67.91000,9.0
67.95800,5.0
68.00600,6.0
68.05400,5.0
68.10200,8.0
68.15000,7.0
68.19800,6.0
68.24600,6.0
68.29400,5.0
68.34200,10.0
68.39000,8.0
68.43800,4.0
68.48600,1.0
68.53400,7.0
68.58200,8.0
68.63000,8.0
68.67800,5.0
68.72600,11.0
68.77400,4.0
68.82200,9.0
68.87000,5.0
68.91800,4.0
68.96600,11.0
69.01400,11.0
69.06200,11.0
69.11000,13.0
69.15800,10.0
69.20600,11.0
69.25400,12.0
69.30200,10.0
69.35000,14.0
69.39800,11.0
69.44600,10.0
69.49400,11.0
69.54200,12.0
69.59000,11.0
69.63800,18.0
69.68600,29.0
69.73400,21.0
69.78200,20.0
69.83000,25.0
69.87800,25.0
69.92600,41.0
69.97400,39.0
70.02200,44.0
70.07000,55.0
70.11800,59.0
70.16600,50.0
70.21400,62.0
70.26200,96.0
70.31000,85.0
70.35800,71.0
70.40600,76.0
70.45400,80.0
70.50200,69.0
70.55000,77.0
70.59800,48.0
70.64600,46.0
70.69400,31.0
70.74200,35.0
70.79000,30.0
70.83800,34.0
70.88600,23.0
70.93400,21.0
70.98200,16.0
71.03000,16.0
71.07800,18.0
71.12600,14.0
71.17400,10.0
71.22200,9.0
71.27000,13.0
71.31800,5.0
71.36600,12.0
71.41400,5.0
71.46200,15.0
71.51000,5.0
71.55800,5.0
71.60600,9.0
71.65400,6.0
71.70200,6.0
71.75000,7.0
71.79800,5.0
71.84600,8.0
71.89400,4.0
71.94200,5.0
71.99000,6.0
72.03800,5.0
72.08600,5.0
72.13400,11.0
72.18200,4.0
72.23000,10.0
72.27800,15.0
72.32600,11.0
72.37400,4.0
72.42200,6.0
72.47000,8.0
72.51800,9.0
72.56600,6.0
72.61400,5.0
72.66200,8.0
72.71000,4.0
72.75800,5.0
72.80600,3.0
72.85400,3.0
72.90200,6.0
72.95000,12.0
72.99800,9.0
73.04600,10.0
73.09400,3.0
73.14200,4.0
73.19000,6.0
73.23800,7.0
73.28600,2.0
73.33400,7.0
73.38200,6.0
73.43000,7.0
73.47800,3.0
73.52600,6.0
73.57400,8.0
73.62200,3.0
73.67000,8.0
73.71800,7.0
73.76600,10.0
73.81400,7.0
73.86200,11.0
73.91000,6.0
73.95800,7.0
74.00600,11.0
74.05400,5.0
74.10200,8.0
74.15000,8.0
74.19800,10.0
74.24600,3.0
74.29400,13.0
74.34200,11.0
74.39000,11.0
74.43800,10.0
74.48600,9.0
74.53400,9.0
74.58200,9.0
74.63000,5.0
74.67800,8.0
74.72600,9.0
74.77400,7.0
74.82200,7.0
74.87000,9.0
74.91800,4.0
74.96600,4.0
75.01400,8.0
75.06200,13.0
75.11000,11.0
75.15800,12.0
75.20600,4.0
75.25400,8.0
75.30200,11.0
75.35000,8.0
75.39800,17.0
75.44600,13.0
75.49400,11.0
75.54200,12.0
75.59000,16.0
75.63800,18.0
75.68600,17.0
75.73400,16.0
75.78200,19.0
75.83000,28.0
75.87800,24.0
75.92600,31.0
75.97400,44.0
76.02200,30.0
76.07000,30.0
76.11800,32.0
76.16600,30.0
76.21400,27.0
76.26200,38.0
76.31000,25.0
76.35800,27.0
76.40600,23.0
76.45400,16.0
76.50200,20.0
76.55000,19.0
76.59800,14.0
76.64600,20.0
76.69400,18.0
76.74200,12.0
76.79000,19.0
76.83800,20.0
76.88600,18.0
76.93400,15.0
76.98200,29.0
77.03000,19.0
77.07800,24.0
77.12600,25.0
77.17400,25.0
77.22200,26.0
77.27000,20.0
77.31800,30.0
77.36600,23.0
77.41400,29.0
77.46200,26.0
77.51000,36.0
77.55800,21.0
77.60600,21.0
77.65400,23.0
77.70200,10.0
77.75000,19.0
77.79800,11.0
77.84600,15.0
77.89400,12.0
77.94200,13.0
77.99000,14.0
78.03800,8.0
78.08600,10.0
78.13400,6.0
78.18200,9.0
78.23000,11.0
78.27800,12.0
78.32600,13.0
78.37400,15.0
78.42200,18.0
78.47000,9.0
78.51800,11.0
78.56600,9.0
78.61400,7.0
78.66200,9.0
78.71000,8.0
78.75800,19.0
78.80600,7.0
78.85400,8.0
78.90200,7.0
78.95000,9.0
78.99800,15.0
79.04600,8.0
79.09400,11.0
79.14200,9.0
79.19000,6.0
79.23800,11.0
79.28600,6.0
79.33400,9.0
79.38200,9.0
79.43000,4.0
79.47800,5.0
79.52600,5.0
79.57400,4.0
79.62200,7.0
79.67000,3.0
79.71800,5.0
79.76600,5.0
79.81400,4.0
79.86200,7.0
79.91000,14.0
79.95800,5.0
79.99400,10.0