File: code/data/data_source2/TiNb_KL387E_Ti15Nb_Bragg.csv
[Measurement conditions]
Sample identification,
Comment - 1,"Configuration=Filmes Finos 19_1_2015, Owner=User-1, Creation date=19/01/2015 21:17:15"
Comment - 2,"Goniometer=PW3050/60 (Theta/Theta); Minimum step size 2Theta:0.001; Minimum step size Omega:0.001"
Comment - 3,"Sample stage=PW3071/xx Bracket"
Comment - 4,"Diffractometer system=XPERT-PRO"
Comment - 5,"Measurement program=C:\PANalytical\Data Collector\Programs\BraggBrentano.xrdmp, Identifier={E0FB4A26-42FE-4201-BB41-2325C246ED82}"
Anode material,Cu
K-Alpha1 wavelength,1.5405980
K-Alpha2 wavelength,1.5444260
Ratio K-Alpha2/K-Alpha1,0.500
Divergence slit,Fixed,0.76mm
Receiving slit,0.10
Monochromator used,YES
Generator voltage, 40
Tube current, 40
File date and time,15/Jun/2018 15:43
Unit cell,
h k l, 0 0 0
Scan axis,Gonio
Scan range,20.00000,80.00000
Scan step size,0.0120000
No. of points, 5000
Scan type,CONTINUOUS
Time per step,1.50
[Scan points]
Angle,Intensity
20.00600,38.0
20.05400,40.0
20.10200,32.0
20.15000,28.0
20.19800,31.0
20.24600,36.0
20.29400,35.0
20.34200,27.0
20.39000,32.0
20.43800,24.0
20.48600,24.0
20.53400,25.0
20.58200,27.0
20.63000,32.0
20.67800,24.0
20.72600,29.0
20.77400,20.0
20.82200,36.0
20.87000,22.0
20.91800,30.0
20.96600,30.0
21.01400,19.0
21.06200,24.0
21.11000,26.0
21.15800,23.0
21.20600,27.0
21.25400,31.0
21.30200,27.0
21.35000,44.0
21.39800,22.0
21.44600,29.0
21.49400,23.0
21.54200,26.0
21.59000,19.0
21.63800,23.0
21.68600,31.0
21.73400,33.0
21.78200,24.0
21.83000,21.0
21.87800,35.0
21.92600,22.0
21.97400,25.0
22.02200,21.0
22.07000,31.0
22.11800,34.0
22.16600,28.0
22.21400,18.0
22.26200,25.0
22.31000,28.0
22.35800,23.0
22.40600,27.0
22.45400,26.0
22.50200,29.0
22.55000,29.0
22.59800,23.0
22.64600,30.0
22.69400,25.0
22.74200,37.0
22.79000,27.0
22.83800,27.0
22.88600,25.0
22.93400,24.0
22.98200,21.0
23.03000,19.0
23.07800,25.0
23.12600,27.0
23.17400,26.0
23.22200,26.0
23.27000,28.0
23.31800,22.0
23.36600,17.0
23.41400,28.0
23.46200,25.0
23.51000,20.0
23.55800,29.0
23.60600,23.0
23.65400,30.0
23.70200,28.0
23.75000,20.0
23.79800,29.0
23.84600,29.0
23.89400,27.0
23.94200,25.0
23.99000,20.0
24.03800,25.0
24.08600,24.0
24.13400,29.0
24.18200,27.0
24.23000,31.0
24.27800,27.0
24.32600,24.0
24.37400,22.0
24.42200,29.0
24.47000,21.0
24.51800,30.0
24.56600,29.0
24.61400,21.0
24.66200,22.0
24.71000,18.0
24.75800,31.0
24.80600,23.0
24.85400,21.0
24.90200,37.0
24.95000,26.0
24.99800,22.0
25.04600,23.0
25.09400,29.0
25.14200,26.0
25.19000,40.0
25.23800,26.0
25.28600,22.0
25.33400,23.0
25.38200,25.0
25.43000,30.0
25.47800,33.0
25.52600,16.0
25.57400,25.0
25.62200,27.0
25.67000,23.0
25.71800,22.0
25.76600,25.0
25.81400,24.0
25.86200,31.0
25.91000,24.0
25.95800,29.0
26.00600,30.0
26.05400,25.0
26.10200,22.0
26.15000,33.0
26.19800,25.0
26.24600,20.0
26.29400,28.0
26.34200,21.0
26.39000,27.0
26.43800,20.0
26.48600,23.0
26.53400,26.0
26.58200,42.0
26.63000,17.0
26.67800,24.0
26.72600,17.0
26.77400,24.0
26.82200,17.0
26.87000,26.0
26.91800,27.0
26.96600,25.0
27.01400,26.0
27.06200,18.0
27.11000,19.0
27.15800,29.0
27.20600,26.0
27.25400,19.0
27.30200,27.0
27.35000,19.0
27.39800,22.0
27.44600,15.0
27.49400,24.0
27.54200,26.0
27.59000,16.0
27.63800,27.0
27.68600,25.0
27.73400,19.0
27.78200,25.0
27.83000,24.0
27.87800,25.0
27.92600,26.0
27.97400,27.0
28.02200,23.0
28.07000,26.0
28.11800,18.0
28.16600,29.0
28.21400,16.0
28.26200,23.0
28.31000,25.0
28.35800,21.0
28.40600,23.0
28.45400,21.0
28.50200,26.0
28.55000,22.0
28.59800,21.0
28.64600,17.0
28.69400,18.0
28.74200,21.0
28.79000,31.0
28.83800,18.0
28.88600,31.0
28.93400,27.0
28.98200,22.0
29.03000,23.0
29.07800,20.0
29.12600,26.0
29.17400,23.0
29.22200,25.0
29.27000,18.0
29.31800,15.0
29.36600,26.0
29.41400,26.0
29.46200,20.0
29.51000,31.0
29.55800,24.0
29.60600,22.0
29.65400,23.0
29.70200,20.0
29.75000,26.0
29.79800,20.0
29.84600,18.0
29.89400,17.0
29.94200,16.0
29.99000,25.0
30.03800,18.0
30.08600,30.0
30.13400,25.0
30.18200,30.0
30.23000,21.0
30.27800,15.0
30.32600,13.0
30.37400,22.0
30.42200,30.0
30.47000,19.0
30.51800,20.0
30.56600,18.0
30.61400,21.0
30.66200,32.0
30.71000,19.0
30.75800,20.0
30.80600,21.0
30.85400,18.0
30.90200,22.0
30.95000,18.0
30.99800,20.0
31.04600,35.0
31.09400,27.0
31.14200,21.0
31.19000,23.0
31.23800,20.0
31.28600,21.0
31.33400,26.0
31.38200,20.0
31.43000,23.0
31.47800,33.0
31.52600,27.0
31.57400,19.0
31.62200,22.0
31.67000,14.0
31.71800,24.0
31.76600,11.0
31.81400,15.0
31.86200,28.0
31.91000,21.0
31.95800,24.0
32.00600,19.0
32.05400,22.0
32.10200,22.0
32.15000,30.0
32.19800,34.0
32.24600,30.0
32.29400,22.0
32.34200,34.0
32.39000,17.0
32.43800,26.0
32.48600,27.0
32.53400,22.0
32.58200,20.0
32.63000,20.0
32.67800,15.0
32.72600,19.0
32.77400,23.0
32.82200,25.0
32.87000,16.0
32.91800,23.0
32.96600,23.0
33.01400,24.0
33.06200,23.0
33.11000,27.0
33.15800,24.0
33.20600,24.0
33.25400,22.0
33.30200,19.0
33.35000,23.0
33.39800,15.0
33.44600,20.0
33.49400,28.0
33.54200,17.0
33.59000,20.0
33.63800,23.0
33.68600,27.0
33.73400,30.0
33.78200,18.0
33.83000,28.0
33.87800,19.0
33.92600,26.0
33.97400,27.0
34.02200,24.0
34.07000,26.0
34.11800,33.0
34.16600,19.0
34.21400,19.0
34.26200,30.0
34.31000,29.0
34.35800,37.0
34.40600,33.0
34.45400,47.0
34.50200,47.0
34.55000,55.0
34.59800,71.0
34.64600,80.0
34.69400,100.0
34.74200,166.0
34.79000,239.0
34.83800,287.0
34.88600,348.0
34.93400,453.0
34.98200,478.0
35.03000,467.0
35.07800,451.0
35.12600,362.0
35.17400,273.0
35.22200,215.0
35.27000,150.0
35.31800,109.0
35.36600,89.0
35.41400,82.0
35.46200,52.0
35.51000,52.0
35.55800,54.0
35.60600,50.0
35.65400,38.0
35.70200,43.0
35.75000,33.0
35.79800,35.0
35.84600,29.0
35.89400,44.0
35.94200,45.0
35.99000,46.0
36.03800,36.0
36.08600,64.0
36.13400,38.0
36.18200,47.0
36.23000,50.0
36.27800,53.0
36.32600,49.0
36.37400,52.0
36.42200,35.0
36.47000,57.0
36.51800,39.0
36.56600,44.0
36.61400,47.0
36.66200,38.0
36.71000,34.0
36.75800,35.0
36.80600,35.0
36.85400,30.0
36.90200,37.0
36.95000,40.0
36.99800,36.0
37.04600,36.0
37.09400,44.0
37.14200,28.0
37.19000,40.0
37.23800,39.0
37.28600,41.0
37.33400,41.0
37.38200,32.0
37.43000,41.0
37.47800,37.0
37.52600,33.0
37.57400,44.0
37.62200,50.0
37.67000,46.0
37.71800,61.0
37.76600,58.0
37.81400,62.0
37.86200,64.0
37.91000,77.0
37.95800,113.0
38.00600,130.0
38.05400,157.0
38.10200,227.0
38.15000,282.0
38.19800,324.0
38.24600,348.0
38.29400,326.0
38.34200,345.0
38.39000,367.0
38.43800,339.0
38.48600,353.0
38.53400,368.0
38.58200,432.0
38.63000,486.0
38.67800,495.0
38.72600,560.0
38.77400,582.0
38.82200,541.0
38.87000,501.0
38.91800,436.0
38.96600,373.0
39.01400,267.0
39.06200,250.0
39.11000,183.0
39.15800,151.0
39.20600,127.0
39.25400,137.0
39.30200,115.0
39.35000,108.0
39.39800,110.0
39.44600,114.0
39.49400,103.0
39.54200,98.0
39.59000,110.0
39.63800,139.0
39.68600,206.0
39.73400,238.0
39.78200,326.0
39.83000,515.0
39.87800,611.0
39.92600,803.0
39.97400,953.0
40.02200,1052.0
40.07000,1161.0
40.11800,1063.0
40.16600,919.0
40.21400,726.0
40.26200,517.0
40.31000,413.0
40.35800,291.0
40.40600,188.0
40.45400,155.0
40.50200,128.0
40.55000,97.0
40.59800,75.0
40.64600,57.0
40.69400,63.0
40.74200,57.0
40.79000,50.0
40.83800,48.0
40.88600,51.0
40.93400,29.0
40.98200,35.0
41.03000,42.0
41.07800,36.0
41.12600,47.0
41.17400,44.0
41.22200,32.0
41.27000,45.0
41.31800,34.0
41.36600,44.0
41.41400,34.0
41.46200,27.0
41.51000,38.0
41.55800,32.0
41.60600,36.0
41.65400,32.0
41.70200,38.0
41.75000,35.0
41.79800,30.0
41.84600,37.0
41.89400,38.0
41.94200,40.0
41.99000,29.0
42.03800,37.0
42.08600,23.0
42.13400,50.0
42.18200,37.0
42.23000,33.0
42.27800,34.0
42.32600,39.0
42.37400,35.0
42.42200,34.0
42.47000,29.0
42.51800,35.0
42.56600,22.0
42.61400,32.0
42.66200,31.0
42.71000,25.0
42.75800,24.0
42.80600,22.0
42.85400,21.0
42.90200,30.0
42.95000,27.0
42.99800,16.0
43.04600,29.0
43.09400,30.0
43.14200,30.0
43.19000,28.0
43.23800,34.0
43.28600,29.0
43.33400,22.0
43.38200,29.0
43.43000,29.0
43.47800,29.0
43.52600,28.0
43.57400,23.0
43.62200,22.0
43.67000,26.0
43.71800,23.0
43.76600,33.0
43.81400,24.0
43.86200,21.0
43.91000,28.0
43.95800,27.0
44.00600,11.0
44.05400,28.0
44.10200,27.0
44.15000,21.0
44.19800,25.0
44.24600,26.0
44.29400,25.0
44.34200,20.0
44.39000,25.0
44.43800,27.0
44.48600,19.0
44.53400,17.0
44.58200,30.0
44.63000,34.0
44.67800,17.0
44.72600,26.0
44.77400,25.0
44.82200,24.0
44.87000,17.0
44.91800,26.0
44.96600,21.0
45.01400,22.0
45.06200,25.0
45.11000,25.0
45.15800,18.0
45.20600,20.0
45.25400,35.0
45.30200,20.0
45.35000,31.0
45.39800,24.0
45.44600,17.0
45.49400,22.0
45.54200,26.0
45.59000,21.0
45.63800,30.0
45.68600,28.0
45.73400,20.0
45.78200,22.0
45.83000,21.0
45.87800,26.0
45.92600,14.0
45.97400,25.0
46.02200,30.0
46.07000,18.0
46.11800,19.0
46.16600,21.0
46.21400,18.0
46.26200,14.0
46.31000,36.0
46.35800,25.0
46.40600,20.0
46.45400,24.0
46.50200,28.0
46.55000,19.0
46.59800,19.0
46.64600,22.0
46.69400,18.0
46.74200,20.0
46.79000,26.0
46.83800,17.0
46.88600,30.0
46.93400,20.0
46.98200,23.0
47.03000,26.0
47.07800,24.0
47.12600,14.0
47.17400,19.0
47.22200,20.0
47.27000,18.0
47.31800,17.0
47.36600,27.0
47.41400,30.0
47.46200,16.0
47.51000,22.0
47.55800,23.0
47.60600,25.0
47.65400,21.0
47.70200,17.0
47.75000,23.0
47.79800,19.0
47.84600,22.0
47.89400,20.0
47.94200,30.0
47.99000,17.0
48.03800,11.0
48.08600,18.0
48.13400,26.0
48.18200,24.0
48.23000,14.0
48.27800,11.0
48.32600,26.0
48.37400,23.0
48.42200,21.0
48.47000,23.0
48.51800,12.0
48.56600,23.0
48.61400,18.0
48.66200,26.0
48.71000,14.0
48.75800,27.0
48.80600,19.0
48.85400,11.0
48.90200,16.0
48.95000,19.0
48.99800,14.0
49.04600,23.0
49.09400,23.0
49.14200,23.0
49.19000,19.0
49.23800,22.0
49.28600,23.0
49.33400,25.0
49.38200,24.0
49.43000,20.0
49.47800,27.0
49.52600,30.0
49.57400,22.0
49.62200,19.0
49.67000,16.0
49.71800,26.0
49.76600,24.0
49.81400,9.0
49.86200,26.0
49.91000,16.0
49.95800,22.0
50.00600,16.0
50.05400,23.0
50.10200,16.0
50.15000,25.0
50.19800,21.0
50.24600,21.0
50.29400,24.0
50.34200,26.0
50.39000,26.0
50.43800,15.0
50.48600,22.0
50.53400,17.0
50.58200,19.0
50.63000,28.0
50.67800,21.0
50.72600,16.0
50.77400,24.0
50.82200,23.0
50.87000,21.0
50.91800,35.0
50.96600,24.0
51.01400,20.0
51.06200,18.0
51.11000,22.0
51.15800,10.0
51.20600,23.0
51.25400,19.0
51.30200,28.0
51.35000,17.0
51.39800,16.0
51.44600,18.0
51.49400,27.0
51.54200,16.0
51.59000,26.0
51.63800,23.0
51.68600,23.0
51.73400,16.0
51.78200,20.0
51.83000,28.0
51.87800,26.0
51.92600,12.0
51.97400,27.0
52.02200,25.0
52.07000,24.0
52.11800,21.0
52.16600,19.0
52.21400,24.0
52.26200,29.0
52.31000,31.0
52.35800,22.0
52.40600,36.0
52.45400,31.0
52.50200,56.0
52.55000,64.0
52.59800,89.0
52.64600,129.0
52.69400,182.0
52.74200,213.0
52.79000,237.0
52.83800,247.0
52.88600,210.0
52.93400,238.0
52.98200,185.0
53.03000,167.0
53.07800,132.0
53.12600,95.0
53.17400,72.0
53.22200,70.0
53.27000,56.0
53.31800,36.0
53.36600,35.0
53.41400,29.0
53.46200,31.0
53.51000,22.0
53.55800,31.0
53.60600,26.0
53.65400,22.0
53.70200,25.0
53.75000,31.0
53.79800,19.0
53.84600,26.0
53.89400,22.0
53.94200,26.0
53.99000,24.0
54.03800,29.0
54.08600,29.0
54.13400,26.0
54.18200,23.0
54.23000,21.0
54.27800,25.0
54.32600,21.0
54.37400,27.0
54.42200,21.0
54.47000,17.0
54.51800,29.0
54.56600,27.0
54.61400,24.0
54.66200,25.0
54.71000,27.0
54.75800,23.0
54.80600,29.0
54.85400,35.0
54.90200,19.0
54.95000,40.0
54.99800,35.0
55.04600,26.0
55.09400,21.0
55.14200,34.0
55.19000,28.0
55.23800,30.0
55.28600,36.0
55.33400,32.0
55.38200,60.0
55.43000,41.0
55.47800,58.0
55.52600,40.0
55.57400,62.0
55.62200,68.0
55.67000,76.0
55.71800,71.0
55.76600,86.0
55.81400,85.0
55.86200,109.0
55.91000,106.0
55.95800,109.0
56.00600,120.0
56.05400,145.0
56.10200,145.0
56.15000,124.0
56.19800,94.0
56.24600,104.0
56.29400,82.0
56.34200,69.0
56.39000,67.0
56.43800,49.0
56.48600,42.0
56.53400,44.0
56.58200,51.0
56.63000,36.0
56.67800,30.0
56.72600,31.0
56.77400,24.0
56.82200,16.0
56.87000,20.0
56.91800,33.0
56.96600,26.0
57.01400,24.0
57.06200,18.0
57.11000,19.0
57.15800,33.0
57.20600,16.0
57.25400,25.0
57.30200,18.0
57.35000,25.0
57.39800,25.0
57.44600,23.0
57.49400,15.0
57.54200,17.0
57.59000,19.0
57.63800,15.0
57.68600,17.0
57.73400,23.0
57.78200,19.0
57.83000,14.0
57.87800,16.0
57.92600,15.0
57.97400,19.0
58.02200,14.0
58.07000,17.0
58.11800,22.0
58.16600,16.0
58.21400,18.0
58.26200,18.0
58.31000,13.0
58.35800,16.0
58.40600,18.0
58.45400,22.0
58.50200,18.0
58.55000,16.0
58.59800,18.0
58.64600,22.0
58.69400,21.0
58.74200,16.0
58.79000,26.0
58.83800,17.0
58.88600,18.0
58.93400,13.0
58.98200,17.0
59.03000,18.0
59.07800,20.0
59.12600,21.0
59.17400,14.0
59.22200,14.0
59.27000,22.0
59.31800,17.0
59.36600,24.0
59.41400,19.0
59.46200,22.0
59.51000,20.0
59.55800,26.0
59.60600,20.0
59.65400,26.0
59.70200,14.0
59.75000,10.0
59.79800,16.0
59.84600,20.0
59.89400,11.0
59.94200,13.0
59.99000,21.0
60.03800,19.0
60.08600,22.0
60.13400,18.0
60.18200,12.0
60.23000,14.0
60.27800,23.0
60.32600,15.0
60.37400,23.0
60.42200,23.0
60.47000,21.0
60.51800,23.0
60.56600,23.0
60.61400,25.0
60.66200,27.0
60.71000,25.0
60.75800,23.0
60.80600,19.0
60.85400,26.0
60.90200,19.0
60.95000,33.0
60.99800,23.0
61.04600,23.0
61.09400,14.0
61.14200,23.0
61.19000,18.0
61.23800,18.0
61.28600,22.0
61.33400,22.0
61.38200,19.0
61.43000,24.0
61.47800,13.0
61.52600,22.0
61.57400,20.0
61.62200,20.0
61.67000,19.0
61.71800,19.0
61.76600,22.0
61.81400,23.0
61.86200,26.0
61.91000,17.0
61.95800,16.0
62.00600,35.0
62.05400,24.0
62.10200,34.0
62.15000,28.0
62.19800,37.0
62.24600,33.0
62.29400,44.0
62.34200,64.0
62.39000,50.0
62.43800,76.0
62.48600,93.0
62.53400,120.0
62.58200,127.0
62.63000,163.0
62.67800,193.0
62.72600,231.0
62.77400,238.0
62.82200,225.0
62.87000,217.0
62.91800,230.0
62.96600,217.0
63.01400,195.0
63.06200,169.0
63.11000,137.0
63.15800,107.0
63.20600,85.0
63.25400,60.0
63.30200,59.0
63.35000,40.0
63.39800,45.0
63.44600,32.0
63.49400,38.0
63.54200,31.0
63.59000,25.0
63.63800,26.0
63.68600,26.0
63.73400,21.0
63.78200,17.0
63.83000,18.0
63.87800,15.0
63.92600,20.0
63.97400,22.0
64.02200,28.0
64.07000,18.0
64.11800,19.0
64.16600,12.0
64.21400,20.0
64.26200,16.0
64.31000,20.0
64.35800,17.0
64.40600,15.0
64.45400,12.0
64.50200,16.0
64.55000,19.0
64.59800,13.0
64.64600,26.0
64.69400,10.0
64.74200,13.0
64.79000,7.0
64.83800,18.0
64.88600,23.0
64.93400,15.0
64.98200,18.0
65.03000,22.0
65.07800,22.0
65.12600,23.0
65.17400,21.0
65.22200,19.0
65.27000,16.0
65.31800,19.0
65.36600,15.0
65.41400,24.0
65.46200,22.0
65.51000,27.0
65.55800,11.0
65.60600,19.0
65.65400,15.0
65.70200,32.0
65.75000,17.0
65.79800,26.0
65.84600,22.0
65.89400,17.0
65.94200,21.0
65.99000,23.0
66.03800,21.0
66.08600,25.0
66.13400,15.0
66.18200,16.0
66.23000,21.0
66.27800,11.0
66.32600,17.0
66.37400,26.0
66.42200,29.0
66.47000,20.0
66.51800,14.0
66.56600,16.0
66.61400,23.0
66.66200,16.0
66.71000,16.0
66.75800,15.0
66.80600,8.0
66.85400,20.0
66.90200,16.0
66.95000,15.0
66.99800,16.0
67.04600,27.0
67.09400,14.0
67.14200,26.0
67.19000,24.0
67.23800,22.0
67.28600,15.0
67.33400,22.0
67.38200,20.0
67.43000,21.0
67.47800,12.0
67.52600,23.0
67.57400,14.0
67.62200,15.0
67.67000,17.0
67.71800,19.0
67.76600,17.0
67.81400,24.0
67.86200,21.0
67.91000,23.0
67.95800,26.0
68.00600,20.0
68.05400,15.0
68.10200,20.0
68.15000,16.0
68.19800,22.0
68.24600,21.0
68.29400,14.0
68.34200,23.0
68.39000,24.0
68.43800,24.0
68.48600,24.0
68.53400,20.0
68.58200,27.0
68.63000,25.0
68.67800,15.0
68.72600,14.0
68.77400,18.0
68.82200,27.0
68.87000,15.0
68.91800,32.0
68.96600,26.0
69.01400,18.0
69.06200,33.0
69.11000,27.0
69.15800,34.0
69.20600,37.0
69.25400,30.0
69.30200,34.0
69.35000,39.0
69.39800,42.0
69.44600,40.0
69.49400,43.0
69.54200,50.0
69.59000,47.0
69.63800,68.0
69.68600,67.0
69.73400,72.0
69.78200,77.0
69.83000,87.0
69.87800,97.0
69.92600,114.0
69.97400,120.0
70.02200,160.0
70.07000,172.0
70.11800,219.0
70.16600,246.0
70.21400,274.0
70.26200,291.0
70.31000,302.0
70.35800,332.0
70.40600,345.0
70.45400,355.0
70.50200,277.0
70.55000,300.0
70.59800,279.0
70.64600,219.0
70.69400,201.0
70.74200,153.0
70.79000,112.0
70.83800,85.0
70.88600,85.0
70.93400,84.0
70.98200,64.0
71.03000,50.0
71.07800,62.0
71.12600,44.0
71.17400,30.0
71.22200,39.0
71.27000,36.0
71.31800,31.0
71.36600,26.0
71.41400,38.0
71.46200,28.0
71.51000,27.0
71.55800,34.0
71.60600,20.0
71.65400,24.0
71.70200,21.0
71.75000,26.0
71.79800,15.0
71.84600,23.0
71.89400,18.0
71.94200,20.0
71.99000,28.0
72.03800,21.0
72.08600,22.0
72.13400,22.0
72.18200,14.0
72.23000,22.0
72.27800,29.0
72.32600,24.0
72.37400,22.0
72.42200,21.0
72.47000,19.0
72.51800,23.0
72.56600,26.0
72.61400,21.0
72.66200,24.0
72.71000,26.0
72.75800,24.0
72.80600,16.0
72.85400,27.0
72.90200,14.0
72.95000,19.0
72.99800,23.0
73.04600,26.0
73.09400,19.0
73.14200,22.0
73.19000,23.0
73.23800,22.0
73.28600,19.0
73.33400,20.0
73.38200,27.0
73.43000,19.0
73.47800,29.0
73.52600,29.0
73.57400,35.0
73.62200,17.0
73.67000,24.0
73.71800,31.0
73.76600,29.0
73.81400,30.0
73.86200,28.0
73.91000,33.0
73.95800,41.0
74.00600,41.0
74.05400,36.0
74.10200,36.0
74.15000,36.0
74.19800,35.0
74.24600,30.0
74.29400,29.0
74.34200,31.0
74.39000,25.0
74.43800,30.0
74.48600,27.0
74.53400,27.0
74.58200,20.0
74.63000,29.0
74.67800,15.0
74.72600,16.0
74.77400,19.0
74.82200,15.0
74.87000,24.0
74.91800,21.0
74.96600,27.0
75.01400,20.0
75.06200,27.0
75.11000,18.0
75.15800,30.0
75.20600,16.0
75.25400,25.0
75.30200,24.0
75.35000,23.0
75.39800,22.0
75.44600,23.0
75.49400,30.0
75.54200,39.0
75.59000,51.0
75.63800,51.0
75.68600,43.0
75.73400,67.0
75.78200,89.0
75.83000,115.0
75.87800,113.0
75.92600,143.0
75.97400,147.0
76.02200,161.0
76.07000,138.0
76.11800,121.0
76.16600,145.0
76.21400,112.0
76.26200,112.0
76.31000,96.0
76.35800,79.0
76.40600,71.0
76.45400,55.0
76.50200,57.0
76.55000,47.0
76.59800,43.0
76.64600,36.0
76.69400,43.0
76.74200,39.0
76.79000,34.0
76.83800,51.0
76.88600,52.0
76.93400,45.0
76.98200,60.0
77.03000,76.0
77.07800,93.0
77.12600,93.0
77.17400,94.0
77.22200,103.0
77.27000,109.0
77.31800,98.0
77.36600,84.0
77.41400,63.0
77.46200,82.0
77.51000,70.0
77.55800,40.0
77.60600,56.0
77.65400,38.0
77.70200,40.0
77.75000,32.0
77.79800,34.0
77.84600,28.0
77.89400,32.0
77.94200,21.0
77.99000,18.0
78.03800,20.0
78.08600,24.0
78.13400,17.0
78.18200,23.0
78.23000,16.0
78.27800,26.0
78.32600,15.0
78.37400,15.0
78.42200,34.0
78.47000,25.0
78.51800,24.0
78.56600,22.0
78.61400,27.0
78.66200,24.0
78.71000,24.0
78.75800,23.0
78.80600,23.0
78.85400,24.0
78.90200,23.0
78.95000,16.0
78.99800,23.0
79.04600,22.0
79.09400,23.0
79.14200,33.0
79.19000,27.0
79.23800,23.0
79.28600,19.0
79.33400,25.0
79.38200,25.0
79.43000,16.0
79.47800,19.0
79.52600,20.0
79.57400,30.0
79.62200,21.0
79.67000,20.0
79.71800,21.0
79.76600,19.0
79.81400,19.0
79.86200,22.0
79.91000,15.0
79.95800,16.0
79.99400,19.0