File: code/data/data_source2/TiNb_KL388H_Ti40Nb_Bragg.csv
[Measurement conditions]
Sample identification,
Comment - 1,"Configuration=Filmes Finos 19_1_2015, Owner=User-1, Creation date=19/01/2015 21:17:15"
Comment - 2,"Goniometer=PW3050/60 (Theta/Theta); Minimum step size 2Theta:0.001; Minimum step size Omega:0.001"
Comment - 3,"Sample stage=PW3071/xx Bracket"
Comment - 4,"Diffractometer system=XPERT-PRO"
Comment - 5,"Measurement program=C:\PANalytical\Data Collector\Programs\BraggBrentano.xrdmp, Identifier={E0FB4A26-42FE-4201-BB41-2325C246ED82}"
Anode material,Cu
K-Alpha1 wavelength,1.5405980
K-Alpha2 wavelength,1.5444260
Ratio K-Alpha2/K-Alpha1,0.500
Divergence slit,Fixed,0.76mm
Receiving slit,0.10
Monochromator used,YES
Generator voltage, 40
Tube current, 40
File date and time,15/Jun/2018 13:33
Unit cell,
h k l, 0 0 0
Scan axis,Gonio
Scan range,20.00000,80.00000
Scan step size,0.0120000
No. of points, 5000
Scan type,CONTINUOUS
Time per step,1.50
[Scan points]
Angle,Intensity
20.00600,49.0
20.05400,48.0
20.10200,26.0
20.15000,49.0
20.19800,47.0
20.24600,54.0
20.29400,48.0
20.34200,39.0
20.39000,49.0
20.43800,36.0
20.48600,43.0
20.53400,46.0
20.58200,42.0
20.63000,45.0
20.67800,47.0
20.72600,36.0
20.77400,53.0
20.82200,41.0
20.87000,43.0
20.91800,42.0
20.96600,36.0
21.01400,42.0
21.06200,31.0
21.11000,49.0
21.15800,48.0
21.20600,36.0
21.25400,37.0
21.30200,44.0
21.35000,57.0
21.39800,37.0
21.44600,46.0
21.49400,36.0
21.54200,28.0
21.59000,42.0
21.63800,44.0
21.68600,40.0
21.73400,47.0
21.78200,46.0
21.83000,36.0
21.87800,47.0
21.92600,36.0
21.97400,33.0
22.02200,42.0
22.07000,42.0
22.11800,36.0
22.16600,36.0
22.21400,44.0
22.26200,38.0
22.31000,39.0
22.35800,35.0
22.40600,48.0
22.45400,30.0
22.50200,50.0
22.55000,42.0
22.59800,38.0
22.64600,55.0
22.69400,48.0
22.74200,38.0
22.79000,51.0
22.83800,34.0
22.88600,33.0
22.93400,37.0
22.98200,41.0
23.03000,27.0
23.07800,26.0
23.12600,33.0
23.17400,39.0
23.22200,37.0
23.27000,37.0
23.31800,51.0
23.36600,32.0
23.41400,55.0
23.46200,35.0
23.51000,38.0
23.55800,33.0
23.60600,31.0
23.65400,47.0
23.70200,27.0
23.75000,28.0
23.79800,39.0
23.84600,32.0
23.89400,39.0
23.94200,33.0
23.99000,44.0
24.03800,40.0
24.08600,27.0
24.13400,30.0
24.18200,46.0
24.23000,44.0
24.27800,47.0
24.32600,39.0
24.37400,22.0
24.42200,31.0
24.47000,38.0
24.51800,36.0
24.56600,46.0
24.61400,32.0
24.66200,38.0
24.71000,35.0
24.75800,40.0
24.80600,41.0
24.85400,51.0
24.90200,25.0
24.95000,35.0
24.99800,36.0
25.04600,25.0
25.09400,32.0
25.14200,33.0
25.19000,44.0
25.23800,34.0
25.28600,40.0
25.33400,44.0
25.38200,41.0
25.43000,32.0
25.47800,39.0
25.52600,31.0
25.57400,25.0
25.62200,33.0
25.67000,48.0
25.71800,27.0
25.76600,29.0
25.81400,32.0
25.86200,44.0
25.91000,36.0
25.95800,34.0
26.00600,41.0
26.05400,25.0
26.10200,30.0
26.15000,37.0
26.19800,29.0
26.24600,34.0
26.29400,39.0
26.34200,38.0
26.39000,35.0
26.43800,47.0
26.48600,36.0
26.53400,38.0
26.58200,33.0
26.63000,35.0
26.67800,40.0
26.72600,29.0
26.77400,34.0
26.82200,36.0
26.87000,35.0
26.91800,30.0
26.96600,28.0
27.01400,24.0
27.06200,32.0
27.11000,27.0
27.15800,30.0
27.20600,32.0
27.25400,33.0
27.30200,31.0
27.35000,30.0
27.39800,29.0
27.44600,26.0
27.49400,33.0
27.54200,28.0
27.59000,45.0
27.63800,35.0
27.68600,33.0
27.73400,26.0
27.78200,28.0
27.83000,21.0
27.87800,31.0
27.92600,38.0
27.97400,35.0
28.02200,30.0
28.07000,34.0
28.11800,29.0
28.16600,30.0
28.21400,33.0
28.26200,31.0
28.31000,30.0
28.35800,35.0
28.40600,31.0
28.45400,37.0
28.50200,20.0
28.55000,25.0
28.59800,32.0
28.64600,24.0
28.69400,35.0
28.74200,20.0
28.79000,24.0
28.83800,36.0
28.88600,36.0
28.93400,32.0
28.98200,29.0
29.03000,41.0
29.07800,25.0
29.12600,36.0
29.17400,36.0
29.22200,28.0
29.27000,38.0
29.31800,35.0
29.36600,27.0
29.41400,30.0
29.46200,30.0
29.51000,29.0
29.55800,23.0
29.60600,25.0
29.65400,29.0
29.70200,27.0
29.75000,34.0
29.79800,23.0
29.84600,30.0
29.89400,34.0
29.94200,29.0
29.99000,27.0
30.03800,28.0
30.08600,35.0
30.13400,44.0
30.18200,27.0
30.23000,28.0
30.27800,33.0
30.32600,31.0
30.37400,41.0
30.42200,25.0
30.47000,26.0
30.51800,21.0
30.56600,29.0
30.61400,38.0
30.66200,25.0
30.71000,34.0
30.75800,36.0
30.80600,27.0
30.85400,35.0
30.90200,29.0
30.95000,25.0
30.99800,31.0
31.04600,42.0
31.09400,42.0
31.14200,39.0
31.19000,33.0
31.23800,53.0
31.28600,36.0
31.33400,47.0
31.38200,55.0
31.43000,56.0
31.47800,58.0
31.52600,35.0
31.57400,45.0
31.62200,45.0
31.67000,53.0
31.71800,43.0
31.76600,39.0
31.81400,30.0
31.86200,35.0
31.91000,32.0
31.95800,31.0
32.00600,42.0
32.05400,27.0
32.10200,35.0
32.15000,32.0
32.19800,26.0
32.24600,29.0
32.29400,42.0
32.34200,28.0
32.39000,43.0
32.43800,27.0
32.48600,27.0
32.53400,35.0
32.58200,31.0
32.63000,26.0
32.67800,36.0
32.72600,23.0
32.77400,32.0
32.82200,28.0
32.87000,26.0
32.91800,33.0
32.96600,37.0
33.01400,26.0
33.06200,37.0
33.11000,36.0
33.15800,41.0
33.20600,30.0
33.25400,38.0
33.30200,31.0
33.35000,33.0
33.39800,31.0
33.44600,38.0
33.49400,24.0
33.54200,26.0
33.59000,30.0
33.63800,34.0
33.68600,36.0
33.73400,27.0
33.78200,41.0
33.83000,35.0
33.87800,39.0
33.92600,33.0
33.97400,33.0
34.02200,33.0
34.07000,38.0
34.11800,32.0
34.16600,31.0
34.21400,24.0
34.26200,33.0
34.31000,32.0
34.35800,24.0
34.40600,26.0
34.45400,43.0
34.50200,37.0
34.55000,31.0
34.59800,36.0
34.64600,39.0
34.69400,40.0
34.74200,37.0
34.79000,38.0
34.83800,27.0
34.88600,21.0
34.93400,38.0
34.98200,28.0
35.03000,36.0
35.07800,37.0
35.12600,31.0
35.17400,33.0
35.22200,37.0
35.27000,37.0
35.31800,38.0
35.36600,35.0
35.41400,34.0
35.46200,39.0
35.51000,37.0
35.55800,36.0
35.60600,28.0
35.65400,30.0
35.70200,35.0
35.75000,44.0
35.79800,36.0
35.84600,42.0
35.89400,49.0
35.94200,33.0
35.99000,42.0
36.03800,34.0
36.08600,35.0
36.13400,35.0
36.18200,47.0
36.23000,34.0
36.27800,44.0
36.32600,37.0
36.37400,47.0
36.42200,42.0
36.47000,41.0
36.51800,53.0
36.56600,45.0
36.61400,37.0
36.66200,57.0
36.71000,45.0
36.75800,49.0
36.80600,59.0
36.85400,50.0
36.90200,50.0
36.95000,59.0
36.99800,39.0
37.04600,42.0
37.09400,47.0
37.14200,49.0
37.19000,51.0
37.23800,55.0
37.28600,62.0
37.33400,46.0
37.38200,52.0
37.43000,64.0
37.47800,55.0
37.52600,65.0
37.57400,53.0
37.62200,55.0
37.67000,67.0
37.71800,72.0
37.76600,70.0
37.81400,75.0
37.86200,99.0
37.91000,116.0
37.95800,105.0
38.00600,127.0
38.05400,148.0
38.10200,150.0
38.15000,161.0
38.19800,220.0
38.24600,253.0
38.29400,319.0
38.34200,416.0
38.39000,546.0
38.43800,659.0
38.48600,989.0
38.53400,1405.0
38.58200,1845.0
38.63000,2604.0
38.67800,3155.0
38.72600,3487.0
38.77400,3277.0
38.82200,2858.0
38.87000,2206.0
38.91800,1607.0
38.96600,984.0
39.01400,551.0
39.06200,363.0
39.11000,216.0
39.15800,183.0
39.20600,156.0
39.25400,134.0
39.30200,111.0
39.35000,102.0
39.39800,92.0
39.44600,84.0
39.49400,87.0
39.54200,49.0
39.59000,65.0
39.63800,59.0
39.68600,64.0
39.73400,70.0
39.78200,53.0
39.83000,48.0
39.87800,46.0
39.92600,56.0
39.97400,49.0
40.02200,29.0
40.07000,32.0
40.11800,44.0
40.16600,46.0
40.21400,36.0
40.26200,40.0
40.31000,45.0
40.35800,48.0
40.40600,39.0
40.45400,34.0
40.50200,33.0
40.55000,35.0
40.59800,37.0
40.64600,36.0
40.69400,38.0
40.74200,42.0
40.79000,35.0
40.83800,39.0
40.88600,34.0
40.93400,42.0
40.98200,41.0
41.03000,33.0
41.07800,40.0
41.12600,33.0
41.17400,40.0
41.22200,49.0
41.27000,37.0
41.31800,39.0
41.36600,34.0
41.41400,40.0
41.46200,38.0
41.51000,21.0
41.55800,26.0
41.60600,34.0
41.65400,39.0
41.70200,29.0
41.75000,31.0
41.79800,36.0
41.84600,31.0
41.89400,32.0
41.94200,25.0
41.99000,37.0
42.03800,42.0
42.08600,46.0
42.13400,51.0
42.18200,30.0
42.23000,53.0
42.27800,53.0
42.32600,63.0
42.37400,50.0
42.42200,56.0
42.47000,58.0
42.51800,68.0
42.56600,86.0
42.61400,63.0
42.66200,86.0
42.71000,72.0
42.75800,72.0
42.80600,54.0
42.85400,52.0
42.90200,58.0
42.95000,42.0
42.99800,42.0
43.04600,27.0
43.09400,40.0
43.14200,37.0
43.19000,27.0
43.23800,29.0
43.28600,26.0
43.33400,36.0
43.38200,24.0
43.43000,33.0
43.47800,29.0
43.52600,36.0
43.57400,38.0
43.62200,27.0
43.67000,33.0
43.71800,33.0
43.76600,36.0
43.81400,41.0
43.86200,28.0
43.91000,36.0
43.95800,26.0
44.00600,28.0
44.05400,29.0
44.10200,30.0
44.15000,29.0
44.19800,23.0
44.24600,29.0
44.29400,18.0
44.34200,32.0
44.39000,29.0
44.43800,26.0
44.48600,31.0
44.53400,21.0
44.58200,25.0
44.63000,36.0
44.67800,34.0
44.72600,22.0
44.77400,19.0
44.82200,25.0
44.87000,33.0
44.91800,18.0
44.96600,34.0
45.01400,44.0
45.06200,17.0
45.11000,25.0
45.15800,29.0
45.20600,42.0
45.25400,27.0
45.30200,38.0
45.35000,31.0
45.39800,33.0
45.44600,30.0
45.49400,30.0
45.54200,28.0
45.59000,13.0
45.63800,26.0
45.68600,24.0
45.73400,26.0
45.78200,30.0
45.83000,26.0
45.87800,20.0
45.92600,31.0
45.97400,34.0
46.02200,29.0
46.07000,33.0
46.11800,35.0
46.16600,32.0
46.21400,27.0
46.26200,30.0
46.31000,24.0
46.35800,23.0
46.40600,31.0
46.45400,35.0
46.50200,24.0
46.55000,35.0
46.59800,21.0
46.64600,25.0
46.69400,24.0
46.74200,24.0
46.79000,26.0
46.83800,34.0
46.88600,33.0
46.93400,22.0
46.98200,33.0
47.03000,29.0
47.07800,31.0
47.12600,25.0
47.17400,22.0
47.22200,22.0
47.27000,24.0
47.31800,27.0
47.36600,29.0
47.41400,31.0
47.46200,34.0
47.51000,29.0
47.55800,24.0
47.60600,22.0
47.65400,25.0
47.70200,33.0
47.75000,26.0
47.79800,31.0
47.84600,45.0
47.89400,37.0
47.94200,38.0
47.99000,29.0
48.03800,25.0
48.08600,17.0
48.13400,31.0
48.18200,19.0
48.23000,26.0
48.27800,27.0
48.32600,21.0
48.37400,14.0
48.42200,24.0
48.47000,24.0
48.51800,31.0
48.56600,27.0
48.61400,20.0
48.66200,31.0
48.71000,21.0
48.75800,23.0
48.80600,24.0
48.85400,20.0
48.90200,27.0
48.95000,27.0
48.99800,24.0
49.04600,23.0
49.09400,26.0
49.14200,20.0
49.19000,30.0
49.23800,18.0
49.28600,25.0
49.33400,21.0
49.38200,26.0
49.43000,26.0
49.47800,24.0
49.52600,24.0
49.57400,33.0
49.62200,27.0
49.67000,42.0
49.71800,28.0
49.76600,31.0
49.81400,32.0
49.86200,39.0
49.91000,23.0
49.95800,25.0
50.00600,30.0
50.05400,34.0
50.10200,29.0
50.15000,36.0
50.19800,36.0
50.24600,36.0
50.29400,44.0
50.34200,41.0
50.39000,35.0
50.43800,35.0
50.48600,35.0
50.53400,35.0
50.58200,34.0
50.63000,59.0
50.67800,46.0
50.72600,53.0
50.77400,46.0
50.82200,48.0
50.87000,40.0
50.91800,42.0
50.96600,43.0
51.01400,48.0
51.06200,36.0
51.11000,40.0
51.15800,45.0
51.20600,29.0
51.25400,34.0
51.30200,36.0
51.35000,40.0
51.39800,21.0
51.44600,33.0
51.49400,40.0
51.54200,41.0
51.59000,33.0
51.63800,17.0
51.68600,19.0
51.73400,22.0
51.78200,24.0
51.83000,25.0
51.87800,22.0
51.92600,32.0
51.97400,31.0
52.02200,28.0
52.07000,29.0
52.11800,20.0
52.16600,21.0
52.21400,26.0
52.26200,23.0
52.31000,30.0
52.35800,36.0
52.40600,24.0
52.45400,26.0
52.50200,20.0
52.55000,16.0
52.59800,28.0
52.64600,35.0
52.69400,26.0
52.74200,26.0
52.79000,22.0
52.83800,20.0
52.88600,25.0
52.93400,20.0
52.98200,32.0
53.03000,25.0
53.07800,16.0
53.12600,21.0
53.17400,16.0
53.22200,20.0
53.27000,29.0
53.31800,29.0
53.36600,17.0
53.41400,21.0
53.46200,24.0
53.51000,29.0
53.55800,23.0
53.60600,24.0
53.65400,32.0
53.70200,23.0
53.75000,25.0
53.79800,22.0
53.84600,35.0
53.89400,24.0
53.94200,34.0
53.99000,27.0
54.03800,27.0
54.08600,24.0
54.13400,20.0
54.18200,19.0
54.23000,25.0
54.27800,24.0
54.32600,19.0
54.37400,26.0
54.42200,25.0
54.47000,25.0
54.51800,31.0
54.56600,30.0
54.61400,28.0
54.66200,25.0
54.71000,30.0
54.75800,32.0
54.80600,38.0
54.85400,38.0
54.90200,33.0
54.95000,24.0
54.99800,36.0
55.04600,34.0
55.09400,47.0
55.14200,35.0
55.19000,35.0
55.23800,36.0
55.28600,51.0
55.33400,43.0
55.38200,60.0
55.43000,60.0
55.47800,54.0
55.52600,67.0
55.57400,72.0
55.62200,75.0
55.67000,100.0
55.71800,79.0
55.76600,82.0
55.81400,135.0
55.86200,181.0
55.91000,219.0
55.95800,222.0
56.00600,230.0
56.05400,242.0
56.10200,178.0
56.15000,154.0
56.19800,117.0
56.24600,124.0
56.29400,77.0
56.34200,72.0
56.39000,65.0
56.43800,34.0
56.48600,50.0
56.53400,46.0
56.58200,40.0
56.63000,31.0
56.67800,43.0
56.72600,26.0
56.77400,28.0
56.82200,34.0
56.87000,37.0
56.91800,31.0
56.96600,22.0
57.01400,37.0
57.06200,32.0
57.11000,26.0
57.15800,29.0
57.20600,16.0
57.25400,22.0
57.30200,26.0
57.35000,26.0
57.39800,20.0
57.44600,26.0
57.49400,24.0
57.54200,19.0
57.59000,18.0
57.63800,24.0
57.68600,17.0
57.73400,24.0
57.78200,30.0
57.83000,26.0
57.87800,21.0
57.92600,20.0
57.97400,19.0
58.02200,19.0
58.07000,26.0
58.11800,25.0
58.16600,14.0
58.21400,15.0
58.26200,24.0
58.31000,26.0
58.35800,16.0
58.40600,22.0
58.45400,21.0
58.50200,23.0
58.55000,22.0
58.59800,29.0
58.64600,23.0
58.69400,18.0
58.74200,29.0
58.79000,23.0
58.83800,25.0
58.88600,20.0
58.93400,17.0
58.98200,23.0
59.03000,15.0
59.07800,24.0
59.12600,21.0
59.17400,28.0
59.22200,28.0
59.27000,19.0
59.31800,19.0
59.36600,30.0
59.41400,25.0
59.46200,20.0
59.51000,27.0
59.55800,20.0
59.60600,18.0
59.65400,26.0
59.70200,18.0
59.75000,21.0
59.79800,12.0
59.84600,15.0
59.89400,31.0
59.94200,21.0
59.99000,16.0
60.03800,32.0
60.08600,20.0
60.13400,15.0
60.18200,22.0
60.23000,28.0
60.27800,29.0
60.32600,14.0
60.37400,21.0
60.42200,16.0
60.47000,14.0
60.51800,14.0
60.56600,21.0
60.61400,19.0
60.66200,20.0
60.71000,29.0
60.75800,17.0
60.80600,23.0
60.85400,15.0
60.90200,20.0
60.95000,24.0
60.99800,29.0
61.04600,18.0
61.09400,29.0
61.14200,25.0
61.19000,16.0
61.23800,19.0
61.28600,23.0
61.33400,18.0
61.38200,28.0
61.43000,20.0
61.47800,19.0
61.52600,34.0
61.57400,26.0
61.62200,36.0
61.67000,22.0
61.71800,21.0
61.76600,17.0
61.81400,24.0
61.86200,32.0
61.91000,27.0
61.95800,26.0
62.00600,28.0
62.05400,23.0
62.10200,23.0
62.15000,20.0
62.19800,25.0
62.24600,20.0
62.29400,18.0
62.34200,22.0
62.39000,21.0
62.43800,19.0
62.48600,16.0
62.53400,18.0
62.58200,22.0
62.63000,23.0
62.67800,28.0
62.72600,21.0
62.77400,17.0
62.82200,17.0
62.87000,18.0
62.91800,21.0
62.96600,16.0
63.01400,27.0
63.06200,23.0
63.11000,15.0
63.15800,24.0
63.20600,15.0
63.25400,9.0
63.30200,16.0
63.35000,19.0
63.39800,18.0
63.44600,19.0
63.49400,12.0
63.54200,20.0
63.59000,20.0
63.63800,18.0
63.68600,16.0
63.73400,25.0
63.78200,23.0
63.83000,30.0
63.87800,21.0
63.92600,23.0
63.97400,20.0
64.02200,22.0
64.07000,21.0
64.11800,14.0
64.16600,17.0
64.21400,24.0
64.26200,18.0
64.31000,27.0
64.35800,18.0
64.40600,17.0
64.45400,30.0
64.50200,19.0
64.55000,18.0
64.59800,18.0
64.64600,22.0
64.69400,21.0
64.74200,26.0
64.79000,24.0
64.83800,31.0
64.88600,27.0
64.93400,13.0
64.98200,20.0
65.03000,16.0
65.07800,16.0
65.12600,30.0
65.17400,25.0
65.22200,25.0
65.27000,15.0
65.31800,22.0
65.36600,21.0
65.41400,30.0
65.46200,26.0
65.51000,34.0
65.55800,31.0
65.60600,41.0
65.65400,28.0
65.70200,30.0
65.75000,41.0
65.79800,41.0
65.84600,38.0
65.89400,46.0
65.94200,32.0
65.99000,34.0
66.03800,33.0
66.08600,25.0
66.13400,28.0
66.18200,34.0
66.23000,23.0
66.27800,24.0
66.32600,28.0
66.37400,36.0
66.42200,22.0
66.47000,16.0
66.51800,31.0
66.56600,21.0
66.61400,26.0
66.66200,19.0
66.71000,22.0
66.75800,29.0
66.80600,22.0
66.85400,16.0
66.90200,31.0
66.95000,13.0
66.99800,22.0
67.04600,28.0
67.09400,22.0
67.14200,24.0
67.19000,18.0
67.23800,21.0
67.28600,25.0
67.33400,23.0
67.38200,26.0
67.43000,23.0
67.47800,28.0
67.52600,22.0
67.57400,30.0
67.62200,20.0
67.67000,21.0
67.71800,24.0
67.76600,26.0
67.81400,27.0
67.86200,31.0
67.91000,23.0
67.95800,22.0
68.00600,22.0
68.05400,27.0
68.10200,27.0
68.15000,20.0
68.19800,33.0
68.24600,20.0
68.29400,28.0
68.34200,26.0
68.39000,33.0
68.43800,27.0
68.48600,22.0
68.53400,32.0
68.58200,29.0
68.63000,40.0
68.67800,28.0
68.72600,28.0
68.77400,34.0
68.82200,34.0
68.87000,32.0
68.91800,33.0
68.96600,32.0
69.01400,33.0
69.06200,26.0
69.11000,31.0
69.15800,31.0
69.20600,33.0
69.25400,57.0
69.30200,50.0
69.35000,44.0
69.39800,63.0
69.44600,60.0
69.49400,62.0
69.54200,62.0
69.59000,71.0
69.63800,85.0
69.68600,84.0
69.73400,104.0
69.78200,99.0
69.83000,111.0
69.87800,139.0
69.92600,129.0
69.97400,164.0
70.02200,237.0
70.07000,284.0
70.11800,371.0
70.16600,441.0
70.21400,430.0
70.26200,419.0
70.31000,344.0
70.35800,313.0
70.40600,318.0
70.45400,236.0
70.50200,188.0
70.55000,148.0
70.59800,128.0
70.64600,86.0
70.69400,71.0
70.74200,68.0
70.79000,45.0
70.83800,54.0
70.88600,47.0
70.93400,41.0
70.98200,47.0
71.03000,46.0
71.07800,35.0
71.12600,33.0
71.17400,31.0
71.22200,35.0
71.27000,27.0
71.31800,33.0
71.36600,35.0
71.41400,35.0
71.46200,22.0
71.51000,22.0
71.55800,37.0
71.60600,34.0
71.65400,33.0
71.70200,28.0
71.75000,25.0
71.79800,25.0
71.84600,22.0
71.89400,22.0
71.94200,25.0
71.99000,32.0
72.03800,22.0
72.08600,17.0
72.13400,31.0
72.18200,21.0
72.23000,17.0
72.27800,30.0
72.32600,26.0
72.37400,16.0
72.42200,16.0
72.47000,24.0
72.51800,22.0
72.56600,30.0
72.61400,24.0
72.66200,23.0
72.71000,17.0
72.75800,29.0
72.80600,16.0
72.85400,29.0
72.90200,29.0
72.95000,20.0
72.99800,22.0
73.04600,29.0
73.09400,28.0
73.14200,34.0
73.19000,17.0
73.23800,24.0
73.28600,25.0
73.33400,23.0
73.38200,19.0
73.43000,23.0
73.47800,15.0
73.52600,16.0
73.57400,23.0
73.62200,26.0
73.67000,22.0
73.71800,21.0
73.76600,17.0
73.81400,23.0
73.86200,28.0
73.91000,30.0
73.95800,28.0
74.00600,23.0
74.05400,29.0
74.10200,21.0
74.15000,24.0
74.19800,27.0
74.24600,22.0
74.29400,22.0
74.34200,30.0
74.39000,29.0
74.43800,27.0
74.48600,22.0
74.53400,23.0
74.58200,31.0
74.63000,21.0
74.67800,24.0
74.72600,24.0
74.77400,31.0
74.82200,18.0
74.87000,17.0
74.91800,22.0
74.96600,21.0
75.01400,20.0
75.06200,22.0
75.11000,25.0
75.15800,19.0
75.20600,17.0
75.25400,27.0
75.30200,17.0
75.35000,16.0
75.39800,22.0
75.44600,18.0
75.49400,33.0
75.54200,31.0
75.59000,16.0
75.63800,20.0
75.68600,21.0
75.73400,28.0
75.78200,16.0
75.83000,22.0
75.87800,24.0
75.92600,17.0
75.97400,14.0
76.02200,12.0
76.07000,21.0
76.11800,20.0
76.16600,15.0
76.21400,26.0
76.26200,26.0
76.31000,21.0
76.35800,22.0
76.40600,27.0
76.45400,27.0
76.50200,29.0
76.55000,24.0
76.59800,24.0
76.64600,24.0
76.69400,26.0
76.74200,16.0
76.79000,20.0
76.83800,15.0
76.88600,18.0
76.93400,31.0
76.98200,16.0
77.03000,21.0
77.07800,18.0
77.12600,21.0
77.17400,17.0
77.22200,18.0
77.27000,22.0
77.31800,26.0
77.36600,22.0
77.41400,24.0
77.46200,24.0
77.51000,26.0
77.55800,23.0
77.60600,27.0
77.65400,14.0
77.70200,31.0
77.75000,27.0
77.79800,31.0
77.84600,24.0
77.89400,23.0
77.94200,27.0
77.99000,26.0
78.03800,24.0
78.08600,29.0
78.13400,31.0
78.18200,31.0
78.23000,38.0
78.27800,35.0
78.32600,38.0
78.37400,30.0
78.42200,33.0
78.47000,46.0
78.51800,45.0
78.56600,35.0
78.61400,60.0
78.66200,55.0
78.71000,65.0
78.75800,73.0
78.80600,62.0
78.85400,69.0
78.90200,75.0
78.95000,86.0
78.99800,87.0
79.04600,72.0
79.09400,76.0
79.14200,84.0
79.19000,88.0
79.23800,62.0
79.28600,84.0
79.33400,83.0
79.38200,77.0
79.43000,66.0
79.47800,57.0
79.52600,60.0
79.57400,63.0
79.62200,60.0
79.67000,41.0
79.71800,30.0
79.76600,46.0
79.81400,40.0
79.86200,46.0
79.91000,38.0
79.95800,39.0
79.99400,32.0