File: code/data/data_source2/TiNb_KL387A_Ti15Nb_1_Grazing.csv
[Measurement conditions]
Sample identification,
Comment - 1,"Configuration=Filmes Finos 19_1_2015, Owner=User-1, Creation date=19/01/2015 21:17:15"
Comment - 2,"Goniometer=PW3050/60 (Theta/Theta); Minimum step size 2Theta:0.001; Minimum step size Omega:0.001"
Comment - 3,"Sample stage=PW3071/xx Bracket"
Comment - 4,"Diffractometer system=XPERT-PRO"
Comment - 5,"Measurement program=C:\PANalytical\Data Collector\Programs\GrazingIncidence.xrdmp, Identifier={916340AE-147D-4DBE-80CC-FF5A2212E1FD}"
Anode material,Cu
K-Alpha1 wavelength,1.5405980
K-Alpha2 wavelength,1.5444260
Ratio K-Alpha2/K-Alpha1,0.500
Divergence slit,Fixed,0.76mm
Receiving slit,0.10
Monochromator used,YES
Generator voltage, 40
Tube current, 40
File date and time,14/Jun/2018 14:58
Unit cell,
h k l, 0 0 0
Scan axis,2Theta
Scan range,20.00000,46.55600
Scan step size,0.0120000
No. of points, 2213
Scan type,CONTINUOUS
Omega,5.000
Time per step,1.50
[Scan points]
Angle,Intensity
20.00600,26.0
20.03000,37.0
20.05400,31.0
20.07800,36.0
20.10200,26.0
20.12600,28.0
20.15000,25.0
20.17400,36.0
20.19800,31.0
20.22200,20.0
20.24600,21.0
20.27000,29.0
20.29400,21.0
20.31800,27.0
20.34200,22.0
20.36600,21.0
20.39000,19.0
20.41400,19.0
20.43800,17.0
20.46200,13.0
20.48600,22.0
20.51000,21.0
20.53400,32.0
20.55800,26.0
20.58200,29.0
20.60600,17.0
20.63000,18.0
20.65400,17.0
20.67800,13.0
20.70200,26.0
20.72600,23.0
20.75000,13.0
20.77400,16.0
20.79800,21.0
20.82200,21.0
20.84600,14.0
20.87000,14.0
20.89400,20.0
20.91800,18.0
20.94200,20.0
20.96600,14.0
20.99000,12.0
21.01400,14.0
21.03800,18.0
21.06200,15.0
21.08600,16.0
21.11000,13.0
21.13400,7.0
21.15800,24.0
21.18200,20.0
21.20600,22.0
21.23000,14.0
21.25400,14.0
21.27800,16.0
21.30200,16.0
21.32600,17.0
21.35000,19.0
21.37400,11.0
21.39800,13.0
21.42200,15.0
21.44600,16.0
21.47000,24.0
21.49400,17.0
21.51800,17.0
21.54200,22.0
21.56600,10.0
21.59000,15.0
21.61400,10.0
21.63800,18.0
21.66200,11.0
21.68600,13.0
21.71000,14.0
21.73400,13.0
21.75800,18.0
21.78200,18.0
21.80600,16.0
21.83000,19.0
21.85400,11.0
21.87800,14.0
21.90200,10.0
21.92600,23.0
21.95000,21.0
21.97400,8.0
21.99800,11.0
22.02200,13.0
22.04600,10.0
22.07000,14.0
22.09400,19.0
22.11800,16.0
22.14200,17.0
22.16600,16.0
22.19000,12.0
22.21400,19.0
22.23800,12.0
22.26200,14.0
22.28600,13.0
22.31000,11.0
22.33400,16.0
22.35800,17.0
22.38200,11.0
22.40600,7.0
22.43000,17.0
22.45400,9.0
22.47800,12.0
22.50200,21.0
22.52600,13.0
22.55000,12.0
22.57400,10.0
22.59800,11.0
22.62200,16.0
22.64600,15.0
22.67000,8.0
22.69400,11.0
22.71800,13.0
22.74200,11.0
22.76600,14.0
22.79000,19.0
22.81400,9.0
22.83800,12.0
22.86200,7.0
22.88600,8.0
22.91000,13.0
22.93400,18.0
22.95800,17.0
22.98200,7.0
23.00600,12.0
23.03000,11.0
23.05400,14.0
23.07800,17.0
23.10200,22.0
23.12600,11.0
23.15000,11.0
23.17400,15.0
23.19800,17.0
23.22200,8.0
23.24600,6.0
23.27000,15.0
23.29400,10.0
23.31800,12.0
23.34200,12.0
23.36600,8.0
23.39000,10.0
23.41400,14.0
23.43800,11.0
23.46200,11.0
23.48600,11.0
23.51000,14.0
23.53400,13.0
23.55800,18.0
23.58200,13.0
23.60600,8.0
23.63000,9.0
23.65400,13.0
23.67800,16.0
23.70200,10.0
23.72600,12.0
23.75000,4.0
23.77400,18.0
23.79800,9.0
23.82200,7.0
23.84600,6.0
23.87000,8.0
23.89400,13.0
23.91800,11.0
23.94200,10.0
23.96600,12.0
23.99000,8.0
24.01400,10.0
24.03800,9.0
24.06200,11.0
24.08600,9.0
24.11000,19.0
24.13400,9.0
24.15800,8.0
24.18200,8.0
24.20600,14.0
24.23000,9.0
24.25400,10.0
24.27800,10.0
24.30200,13.0
24.32600,10.0
24.35000,4.0
24.37400,8.0
24.39800,13.0
24.42200,8.0
24.44600,14.0
24.47000,8.0
24.49400,8.0
24.51800,18.0
24.54200,14.0
24.56600,10.0
24.59000,9.0
24.61400,7.0
24.63800,18.0
24.66200,14.0
24.68600,7.0
24.71000,12.0
24.73400,8.0
24.75800,8.0
24.78200,9.0
24.80600,14.0
24.83000,15.0
24.85400,15.0
24.87800,11.0
24.90200,9.0
24.92600,10.0
24.95000,8.0
24.97400,10.0
24.99800,16.0
25.02200,11.0
25.04600,16.0
25.07000,9.0
25.09400,9.0
25.11800,7.0
25.14200,12.0
25.16600,15.0
25.19000,8.0
25.21400,11.0
25.23800,12.0
25.26200,7.0
25.28600,9.0
25.31000,6.0
25.33400,9.0
25.35800,15.0
25.38200,4.0
25.40600,8.0
25.43000,9.0
25.45400,5.0
25.47800,9.0
25.50200,9.0
25.52600,6.0
25.55000,12.0
25.57400,3.0
25.59800,12.0
25.62200,10.0
25.64600,4.0
25.67000,15.0
25.69400,9.0
25.71800,14.0
25.74200,11.0
25.76600,10.0
25.79000,12.0
25.81400,8.0
25.83800,5.0
25.86200,12.0
25.88600,8.0
25.91000,13.0
25.93400,6.0
25.95800,8.0
25.98200,7.0
26.00600,11.0
26.03000,14.0
26.05400,10.0
26.07800,9.0
26.10200,5.0
26.12600,5.0
26.15000,7.0
26.17400,14.0
26.19800,6.0
26.22200,2.0
26.24600,5.0
26.27000,10.0
26.29400,7.0
26.31800,8.0
26.34200,12.0
26.36600,6.0
26.39000,4.0
26.41400,10.0
26.43800,6.0
26.46200,13.0
26.48600,11.0
26.51000,6.0
26.53400,9.0
26.55800,9.0
26.58200,10.0
26.60600,11.0
26.63000,6.0
26.65400,9.0
26.67800,13.0
26.70200,6.0
26.72600,12.0
26.75000,5.0
26.77400,9.0
26.79800,12.0
26.82200,8.0
26.84600,4.0
26.87000,11.0
26.89400,4.0
26.91800,14.0
26.94200,3.0
26.96600,7.0
26.99000,6.0
27.01400,8.0
27.03800,6.0
27.06200,13.0
27.08600,8.0
27.11000,9.0
27.13400,4.0
27.15800,4.0
27.18200,6.0
27.20600,3.0
27.23000,9.0
27.25400,3.0
27.27800,6.0
27.30200,13.0
27.32600,7.0
27.35000,10.0
27.37400,10.0
27.39800,4.0
27.42200,10.0
27.44600,8.0
27.47000,8.0
27.49400,11.0
27.51800,8.0
27.54200,6.0
27.56600,9.0
27.59000,9.0
27.61400,10.0
27.63800,11.0
27.66200,7.0
27.68600,8.0
27.71000,9.0
27.73400,9.0
27.75800,10.0
27.78200,12.0
27.80600,6.0
27.83000,8.0
27.85400,7.0
27.87800,8.0
27.90200,8.0
27.92600,13.0
27.95000,8.0
27.97400,11.0
27.99800,3.0
28.02200,3.0
28.04600,3.0
28.07000,1.0
28.09400,7.0
28.11800,6.0
28.14200,4.0
28.16600,5.0
28.19000,7.0
28.21400,13.0
28.23800,7.0
28.26200,11.0
28.28600,8.0
28.31000,10.0
28.33400,5.0
28.35800,8.0
28.38200,8.0
28.40600,9.0
28.43000,5.0
28.45400,12.0
28.47800,9.0
28.50200,5.0
28.52600,8.0
28.55000,2.0
28.57400,6.0
28.59800,5.0
28.62200,5.0
28.64600,6.0
28.67000,11.0
28.69400,6.0
28.71800,3.0
28.74200,4.0
28.76600,2.0
28.79000,9.0
28.81400,3.0
28.83800,7.0
28.86200,5.0
28.88600,4.0
28.91000,10.0
28.93400,8.0
28.95800,6.0
28.98200,11.0
29.00600,8.0
29.03000,4.0
29.05400,6.0
29.07800,7.0
29.10200,6.0
29.12600,7.0
29.15000,7.0
29.17400,8.0
29.19800,6.0
29.22200,8.0
29.24600,4.0
29.27000,7.0
29.29400,6.0
29.31800,5.0
29.34200,4.0
29.36600,6.0
29.39000,6.0
29.41400,12.0
29.43800,10.0
29.46200,2.0
29.48600,5.0
29.51000,6.0
29.53400,3.0
29.55800,8.0
29.58200,5.0
29.60600,7.0
29.63000,5.0
29.65400,6.0
29.67800,8.0
29.70200,8.0
29.72600,10.0
29.75000,5.0
29.77400,4.0
29.79800,8.0
29.82200,8.0
29.84600,7.0
29.87000,8.0
29.89400,6.0
29.91800,7.0
29.94200,2.0
29.96600,2.0
29.99000,6.0
30.01400,4.0
30.03800,2.0
30.06200,5.0
30.08600,12.0
30.11000,9.0
30.13400,7.0
30.15800,3.0
30.18200,6.0
30.20600,12.0
30.23000,5.0
30.25400,6.0
30.27800,6.0
30.30200,4.0
30.32600,6.0
30.35000,5.0
30.37400,4.0
30.39800,6.0
30.42200,6.0
30.44600,3.0
30.47000,7.0
30.49400,5.0
30.51800,2.0
30.54200,2.0
30.56600,4.0
30.59000,9.0
30.61400,6.0
30.63800,8.0
30.66200,4.0
30.68600,7.0
30.71000,4.0
30.73400,6.0
30.75800,2.0
30.78200,7.0
30.80600,5.0
30.83000,2.0
30.85400,3.0
30.87800,4.0
30.90200,6.0
30.92600,2.0
30.95000,3.0
30.97400,4.0
30.99800,5.0
31.02200,5.0
31.04600,2.0
31.07000,5.0
31.09400,3.0
31.11800,9.0
31.14200,6.0
31.16600,4.0
31.19000,0.0
31.21400,3.0
31.23800,5.0
31.26200,6.0
31.28600,4.0
31.31000,5.0
31.33400,3.0
31.35800,5.0
31.38200,7.0
31.40600,2.0
31.43000,6.0
31.45400,1.0
31.47800,3.0
31.50200,1.0
31.52600,4.0
31.55000,6.0
31.57400,3.0
31.59800,3.0
31.62200,0.0
31.64600,9.0
31.67000,0.0
31.69400,3.0
31.71800,5.0
31.74200,3.0
31.76600,8.0
31.79000,10.0
31.81400,3.0
31.83800,4.0
31.86200,3.0
31.88600,2.0
31.91000,5.0
31.93400,3.0
31.95800,1.0
31.98200,4.0
32.00600,4.0
32.03000,3.0
32.05400,4.0
32.07800,8.0
32.10200,6.0
32.12600,4.0
32.15000,5.0
32.17400,5.0
32.19800,2.0
32.22200,2.0
32.24600,1.0
32.27000,9.0
32.29400,5.0
32.31800,3.0
32.34200,0.0
32.36600,3.0
32.39000,4.0
32.41400,2.0
32.43800,8.0
32.46200,3.0
32.48600,4.0
32.51000,4.0
32.53400,7.0
32.55800,5.0
32.58200,2.0
32.60600,4.0
32.63000,2.0
32.65400,4.0
32.67800,4.0
32.70200,5.0
32.72600,3.0
32.75000,4.0
32.77400,4.0
32.79800,6.0
32.82200,5.0
32.84600,4.0
32.87000,4.0
32.89400,2.0
32.91800,5.0
32.94200,6.0
32.96600,4.0
32.99000,0.0
33.01400,6.0
33.03800,7.0
33.06200,4.0
33.08600,3.0
33.11000,3.0
33.13400,1.0
33.15800,7.0
33.18200,7.0
33.20600,4.0
33.23000,7.0
33.25400,3.0
33.27800,3.0
33.30200,3.0
33.32600,3.0
33.35000,5.0
33.37400,3.0
33.39800,6.0
33.42200,4.0
33.44600,3.0
33.47000,2.0
33.49400,6.0
33.51800,5.0
33.54200,5.0
33.56600,1.0
33.59000,1.0
33.61400,1.0
33.63800,3.0
33.66200,2.0
33.68600,5.0
33.71000,3.0
33.73400,6.0
33.75800,4.0
33.78200,3.0
33.80600,4.0
33.83000,4.0
33.85400,1.0
33.87800,4.0
33.90200,5.0
33.92600,6.0
33.95000,3.0
33.97400,3.0
33.99800,6.0
34.02200,6.0
34.04600,5.0
34.07000,4.0
34.09400,2.0
34.11800,1.0
34.14200,4.0
34.16600,2.0
34.19000,1.0
34.21400,1.0
34.23800,3.0
34.26200,6.0
34.28600,3.0
34.31000,4.0
34.33400,3.0
34.35800,2.0
34.38200,1.0
34.40600,1.0
34.43000,4.0
34.45400,2.0
34.47800,4.0
34.50200,2.0
34.52600,4.0
34.55000,7.0
34.57400,4.0
34.59800,5.0
34.62200,4.0
34.64600,4.0
34.67000,2.0
34.69400,5.0
34.71800,4.0
34.74200,3.0
34.76600,1.0
34.79000,5.0
34.81400,2.0
34.83800,5.0
34.86200,1.0
34.88600,3.0
34.91000,3.0
34.93400,1.0
34.95800,4.0
34.98200,5.0
35.00600,3.0
35.03000,3.0
35.05400,1.0
35.07800,7.0
35.10200,7.0
35.12600,4.0
35.15000,0.0
35.17400,2.0
35.19800,4.0
35.22200,2.0
35.24600,4.0
35.27000,1.0
35.29400,3.0
35.31800,5.0
35.34200,4.0
35.36600,3.0
35.39000,2.0
35.41400,4.0
35.43800,4.0
35.46200,4.0
35.48600,1.0
35.51000,2.0
35.53400,2.0
35.55800,3.0
35.58200,4.0
35.60600,4.0
35.63000,3.0
35.65400,1.0
35.67800,2.0
35.70200,3.0
35.72600,7.0
35.75000,5.0
35.77400,3.0
35.79800,2.0
35.82200,1.0
35.84600,3.0
35.87000,3.0
35.89400,2.0
35.91800,3.0
35.94200,6.0
35.96600,1.0
35.99000,3.0
36.01400,1.0
36.03800,1.0
36.06200,2.0
36.08600,2.0
36.11000,1.0
36.13400,1.0
36.15800,1.0
36.18200,2.0
36.20600,2.0
36.23000,0.0
36.25400,3.0
36.27800,2.0
36.30200,2.0
36.32600,1.0
36.35000,6.0
36.37400,2.0
36.39800,1.0
36.42200,3.0
36.44600,2.0
36.47000,1.0
36.49400,1.0
36.51800,2.0
36.54200,2.0
36.56600,3.0
36.59000,4.0
36.61400,2.0
36.63800,2.0
36.66200,4.0
36.68600,1.0
36.71000,3.0
36.73400,1.0
36.75800,1.0
36.78200,2.0
36.80600,3.0
36.83000,3.0
36.85400,3.0
36.87800,3.0
36.90200,2.0
36.92600,6.0
36.95000,0.0
36.97400,2.0
36.99800,3.0
37.02200,4.0
37.04600,1.0
37.07000,3.0
37.09400,3.0
37.11800,2.0
37.14200,4.0
37.16600,1.0
37.19000,3.0
37.21400,3.0
37.23800,3.0
37.26200,4.0
37.28600,3.0
37.31000,2.0
37.33400,2.0
37.35800,5.0
37.38200,3.0
37.40600,0.0
37.43000,5.0
37.45400,3.0
37.47800,2.0
37.50200,3.0
37.52600,4.0
37.55000,2.0
37.57400,4.0
37.59800,5.0
37.62200,4.0
37.64600,3.0
37.67000,2.0
37.69400,4.0
37.71800,2.0
37.74200,3.0
37.76600,3.0
37.79000,4.0
37.81400,2.0
37.83800,3.0
37.86200,0.0
37.88600,2.0
37.91000,3.0
37.93400,2.0
37.95800,1.0
37.98200,3.0
38.00600,0.0
38.03000,3.0
38.05400,4.0
38.07800,1.0
38.10200,1.0
38.12600,2.0
38.15000,4.0
38.17400,1.0
38.19800,5.0
38.22200,4.0
38.24600,2.0
38.27000,2.0
38.29400,2.0
38.31800,1.0
38.34200,2.0
38.36600,3.0
38.39000,2.0
38.41400,2.0
38.43800,5.0
38.46200,3.0
38.48600,1.0
38.51000,4.0
38.53400,3.0
38.55800,2.0
38.58200,4.0
38.60600,3.0
38.63000,4.0
38.65400,0.0
38.67800,1.0
38.70200,0.0
38.72600,2.0
38.75000,3.0
38.77400,1.0
38.79800,5.0
38.82200,2.0
38.84600,3.0
38.87000,1.0
38.89400,3.0
38.91800,3.0
38.94200,1.0
38.96600,4.0
38.99000,0.0
39.01400,7.0
39.03800,4.0
39.06200,1.0
39.08600,5.0
39.11000,4.0
39.13400,1.0
39.15800,2.0
39.18200,5.0
39.20600,3.0
39.23000,1.0
39.25400,1.0
39.27800,3.0
39.30200,5.0
39.32600,2.0
39.35000,1.0
39.37400,4.0
39.39800,1.0
39.42200,0.0
39.44600,2.0
39.47000,4.0
39.49400,0.0
39.51800,1.0
39.54200,1.0
39.56600,2.0
39.59000,5.0
39.61400,1.0
39.63800,0.0
39.66200,1.0
39.68600,0.0
39.71000,2.0
39.73400,3.0
39.75800,1.0
39.78200,2.0
39.80600,8.0
39.83000,1.0
39.85400,6.0
39.87800,2.0
39.90200,6.0
39.92600,1.0
39.95000,4.0
39.97400,3.0
39.99800,2.0
40.02200,2.0
40.04600,3.0
40.07000,3.0
40.09400,4.0
40.11800,8.0
40.14200,4.0
40.16600,3.0
40.19000,4.0
40.21400,3.0
40.23800,1.0
40.26200,1.0
40.28600,4.0
40.31000,2.0
40.33400,5.0
40.35800,0.0
40.38200,1.0
40.40600,0.0
40.43000,4.0
40.45400,3.0
40.47800,1.0
40.50200,2.0
40.52600,1.0
40.55000,3.0
40.57400,2.0
40.59800,1.0
40.62200,3.0
40.64600,2.0
40.67000,1.0
40.69400,4.0
40.71800,2.0
40.74200,4.0
40.76600,3.0
40.79000,2.0
40.81400,3.0
40.83800,2.0
40.86200,1.0
40.88600,1.0
40.91000,1.0
40.93400,1.0
40.95800,2.0
40.98200,2.0
41.00600,0.0
41.03000,0.0
41.05400,3.0
41.07800,2.0
41.10200,3.0
41.12600,4.0
41.15000,0.0
41.17400,0.0
41.19800,3.0
41.22200,0.0
41.24600,0.0
41.27000,3.0
41.29400,1.0
41.31800,1.0
41.34200,0.0
41.36600,2.0
41.39000,0.0
41.41400,4.0
41.43800,3.0
41.46200,2.0
41.48600,1.0
41.51000,2.0
41.53400,0.0
41.55800,3.0
41.58200,2.0
41.60600,1.0
41.63000,2.0
41.65400,2.0
41.67800,0.0
41.70200,0.0
41.72600,2.0
41.75000,0.0
41.77400,0.0
41.79800,0.0
41.82200,2.0
41.84600,3.0
41.87000,3.0
41.89400,0.0
41.91800,0.0
41.94200,1.0
41.96600,0.0
41.99000,2.0
42.01400,1.0
42.03800,1.0
42.06200,0.0
42.08600,1.0
42.11000,4.0
42.13400,2.0
42.15800,3.0
42.18200,2.0
42.20600,1.0
42.23000,3.0
42.25400,2.0
42.27800,1.0
42.30200,3.0
42.32600,0.0
42.35000,1.0
42.37400,1.0
42.39800,1.0
42.42200,2.0
42.44600,2.0
42.47000,1.0
42.49400,0.0
42.51800,3.0
42.54200,2.0
42.56600,1.0
42.59000,1.0
42.61400,0.0
42.63800,0.0
42.66200,2.0
42.68600,0.0
42.71000,3.0
42.73400,2.0
42.75800,0.0
42.78200,1.0
42.80600,1.0
42.83000,0.0
42.85400,0.0
42.87800,2.0
42.90200,5.0
42.92600,2.0
42.95000,1.0
42.97400,4.0
42.99800,0.0
43.02200,0.0
43.04600,1.0
43.07000,1.0
43.09400,0.0
43.11800,1.0
43.14200,1.0
43.16600,1.0
43.19000,2.0
43.21400,2.0
43.23800,0.0
43.26200,2.0
43.28600,2.0
43.31000,0.0
43.33400,0.0
43.35800,1.0
43.38200,1.0
43.40600,0.0
43.43000,1.0
43.45400,1.0
43.47800,0.0
43.50200,1.0
43.52600,1.0
43.55000,0.0
43.57400,1.0
43.59800,1.0
43.62200,1.0
43.64600,1.0
43.67000,0.0
43.69400,2.0
43.71800,0.0
43.74200,1.0
43.76600,2.0
43.79000,3.0
43.81400,0.0
43.83800,3.0
43.86200,0.0
43.88600,1.0
43.91000,2.0
43.93400,1.0
43.95800,2.0
43.98200,1.0
44.00600,2.0
44.03000,3.0
44.05400,0.0
44.07800,0.0
44.10200,0.0
44.12600,1.0
44.15000,2.0
44.17400,0.0
44.19800,1.0
44.22200,2.0
44.24600,0.0
44.27000,1.0
44.29400,2.0
44.31800,0.0
44.34200,2.0
44.36600,2.0
44.39000,0.0
44.41400,1.0
44.43800,3.0
44.46200,3.0
44.48600,1.0
44.51000,0.0
44.53400,0.0
44.55800,1.0
44.58200,0.0
44.60600,0.0
44.63000,3.0
44.65400,0.0
44.67800,4.0
44.70200,1.0
44.72600,2.0
44.75000,2.0
44.77400,1.0
44.79800,1.0
44.82200,2.0
44.84600,2.0
44.87000,2.0
44.89400,1.0
44.91800,0.0
44.94200,3.0
44.96600,0.0
44.99000,1.0
45.01400,2.0
45.03800,1.0
45.06200,0.0
45.08600,3.0
45.11000,0.0
45.13400,1.0
45.15800,1.0
45.18200,0.0
45.20600,3.0
45.23000,3.0
45.25400,3.0
45.27800,0.0
45.30200,3.0
45.32600,2.0
45.35000,2.0
45.37400,0.0
45.39800,1.0
45.42200,4.0
45.44600,2.0
45.47000,0.0
45.49400,1.0
45.51800,1.0
45.54200,1.0
45.56600,1.0
45.59000,3.0
45.61400,0.0
45.63800,1.0
45.66200,0.0
45.68600,3.0
45.71000,1.0
45.73400,3.0
45.75800,0.0
45.78200,0.0
45.80600,2.0
45.83000,1.0
45.85400,1.0
45.87800,1.0
45.90200,0.0
45.92600,1.0
45.95000,1.0
45.97400,2.0
45.99800,1.0
46.02200,2.0
46.04600,0.0
46.07000,0.0
46.09400,1.0
46.11800,0.0
46.14200,1.0
46.16600,0.0
46.19000,0.0
46.21400,1.0
46.23800,3.0
46.26200,0.0
46.28600,2.0
46.31000,0.0
46.33400,1.0
46.35800,1.0
46.38200,0.0
46.40600,3.0
46.43000,1.0
46.45400,0.0
46.47800,0.0
46.50200,2.0
46.52600,2.0
46.55000,0.0