File: code/data/data_source2/TiNb_KL381D_Ti40Nb_1_Bragg.csv
[Measurement conditions]
Sample identification,
Comment - 1,"Configuration=Filmes Finos 19_1_2015, Owner=User-1, Creation date=19/01/2015 21:17:15"
Comment - 2,"Goniometer=PW3050/60 (Theta/Theta); Minimum step size 2Theta:0.001; Minimum step size Omega:0.001"
Comment - 3,"Sample stage=PW3071/xx Bracket"
Comment - 4,"Diffractometer system=XPERT-PRO"
Comment - 5,"Measurement program=C:\PANalytical\Data Collector\Programs\BraggBrentano.xrdmp, Identifier={1069A1B4-F515-4840-9AC8-848F644ED6C5}"
Anode material,Cu
K-Alpha1 wavelength,1.5405980
K-Alpha2 wavelength,1.5444260
Ratio K-Alpha2/K-Alpha1,0.500
Divergence slit,Fixed,0.76mm
Receiving slit,0.10
Monochromator used,YES
Generator voltage, 40
Tube current, 40
File date and time,13/Jun/2018 11:02
Unit cell,
h k l, 0 0 0
Scan axis,Gonio
Scan range,20.00000,80.00000
Scan step size,0.0120000
No. of points, 5000
Scan type,CONTINUOUS
Time per step,1.50
[Scan points]
Angle,Intensity
20.00600,34.0
20.05400,35.0
20.10200,42.0
20.15000,35.0
20.19800,30.0
20.24600,35.0
20.29400,34.0
20.34200,31.0
20.39000,29.0
20.43800,36.0
20.48600,38.0
20.53400,40.0
20.58200,38.0
20.63000,40.0
20.67800,32.0
20.72600,44.0
20.77400,49.0
20.82200,39.0
20.87000,32.0
20.91800,32.0
20.96600,35.0
21.01400,35.0
21.06200,35.0
21.11000,33.0
21.15800,24.0
21.20600,39.0
21.25400,31.0
21.30200,37.0
21.35000,38.0
21.39800,37.0
21.44600,27.0
21.49400,25.0
21.54200,31.0
21.59000,30.0
21.63800,36.0
21.68600,34.0
21.73400,39.0
21.78200,24.0
21.83000,32.0
21.87800,32.0
21.92600,31.0
21.97400,49.0
22.02200,30.0
22.07000,29.0
22.11800,34.0
22.16600,37.0
22.21400,33.0
22.26200,27.0
22.31000,32.0
22.35800,25.0
22.40600,38.0
22.45400,26.0
22.50200,29.0
22.55000,33.0
22.59800,26.0
22.64600,26.0
22.69400,28.0
22.74200,39.0
22.79000,30.0
22.83800,27.0
22.88600,30.0
22.93400,29.0
22.98200,35.0
23.03000,36.0
23.07800,29.0
23.12600,39.0
23.17400,24.0
23.22200,22.0
23.27000,25.0
23.31800,19.0
23.36600,30.0
23.41400,34.0
23.46200,31.0
23.51000,34.0
23.55800,33.0
23.60600,22.0
23.65400,27.0
23.70200,26.0
23.75000,29.0
23.79800,27.0
23.84600,26.0
23.89400,34.0
23.94200,31.0
23.99000,21.0
24.03800,20.0
24.08600,40.0
24.13400,34.0
24.18200,30.0
24.23000,26.0
24.27800,30.0
24.32600,31.0
24.37400,26.0
24.42200,31.0
24.47000,25.0
24.51800,34.0
24.56600,33.0
24.61400,29.0
24.66200,28.0
24.71000,27.0
24.75800,24.0
24.80600,29.0
24.85400,28.0
24.90200,31.0
24.95000,32.0
24.99800,33.0
25.04600,24.0
25.09400,29.0
25.14200,28.0
25.19000,27.0
25.23800,31.0
25.28600,22.0
25.33400,19.0
25.38200,23.0
25.43000,30.0
25.47800,29.0
25.52600,24.0
25.57400,22.0
25.62200,18.0
25.67000,28.0
25.71800,18.0
25.76600,27.0
25.81400,25.0
25.86200,30.0
25.91000,21.0
25.95800,26.0
26.00600,30.0
26.05400,35.0
26.10200,37.0
26.15000,23.0
26.19800,22.0
26.24600,27.0
26.29400,23.0
26.34200,24.0
26.39000,19.0
26.43800,31.0
26.48600,19.0
26.53400,18.0
26.58200,25.0
26.63000,29.0
26.67800,26.0
26.72600,26.0
26.77400,30.0
26.82200,24.0
26.87000,16.0
26.91800,24.0
26.96600,23.0
27.01400,28.0
27.06200,21.0
27.11000,14.0
27.15800,19.0
27.20600,24.0
27.25400,27.0
27.30200,20.0
27.35000,27.0
27.39800,32.0
27.44600,24.0
27.49400,19.0
27.54200,30.0
27.59000,21.0
27.63800,26.0
27.68600,26.0
27.73400,21.0
27.78200,30.0
27.83000,20.0
27.87800,28.0
27.92600,27.0
27.97400,19.0
28.02200,30.0
28.07000,29.0
28.11800,24.0
28.16600,33.0
28.21400,28.0
28.26200,19.0
28.31000,30.0
28.35800,23.0
28.40600,25.0
28.45400,32.0
28.50200,23.0
28.55000,27.0
28.59800,17.0
28.64600,25.0
28.69400,30.0
28.74200,20.0
28.79000,26.0
28.83800,21.0
28.88600,28.0
28.93400,29.0
28.98200,23.0
29.03000,22.0
29.07800,42.0
29.12600,26.0
29.17400,20.0
29.22200,37.0
29.27000,23.0
29.31800,27.0
29.36600,21.0
29.41400,24.0
29.46200,25.0
29.51000,36.0
29.55800,24.0
29.60600,20.0
29.65400,26.0
29.70200,27.0
29.75000,27.0
29.79800,26.0
29.84600,21.0
29.89400,21.0
29.94200,21.0
29.99000,19.0
30.03800,29.0
30.08600,24.0
30.13400,21.0
30.18200,19.0
30.23000,29.0
30.27800,28.0
30.32600,23.0
30.37400,23.0
30.42200,26.0
30.47000,20.0
30.51800,24.0
30.56600,22.0
30.61400,21.0
30.66200,33.0
30.71000,23.0
30.75800,28.0
30.80600,26.0
30.85400,30.0
30.90200,17.0
30.95000,26.0
30.99800,30.0
31.04600,25.0
31.09400,16.0
31.14200,25.0
31.19000,26.0
31.23800,35.0
31.28600,35.0
31.33400,26.0
31.38200,33.0
31.43000,28.0
31.47800,28.0
31.52600,32.0
31.57400,32.0
31.62200,27.0
31.67000,34.0
31.71800,23.0
31.76600,23.0
31.81400,23.0
31.86200,22.0
31.91000,27.0
31.95800,26.0
32.00600,25.0
32.05400,18.0
32.10200,28.0
32.15000,28.0
32.19800,22.0
32.24600,24.0
32.29400,24.0
32.34200,31.0
32.39000,18.0
32.43800,19.0
32.48600,17.0
32.53400,15.0
32.58200,17.0
32.63000,31.0
32.67800,31.0
32.72600,29.0
32.77400,18.0
32.82200,21.0
32.87000,22.0
32.91800,26.0
32.96600,22.0
33.01400,21.0
33.06200,14.0
33.11000,19.0
33.15800,26.0
33.20600,22.0
33.25400,15.0
33.30200,16.0
33.35000,22.0
33.39800,21.0
33.44600,16.0
33.49400,18.0
33.54200,25.0
33.59000,25.0
33.63800,28.0
33.68600,31.0
33.73400,17.0
33.78200,27.0
33.83000,25.0
33.87800,19.0
33.92600,24.0
33.97400,28.0
34.02200,22.0
34.07000,28.0
34.11800,23.0
34.16600,39.0
34.21400,29.0
34.26200,31.0
34.31000,37.0
34.35800,38.0
34.40600,43.0
34.45400,43.0
34.50200,41.0
34.55000,60.0
34.59800,69.0
34.64600,95.0
34.69400,131.0
34.74200,173.0
34.79000,248.0
34.83800,297.0
34.88600,377.0
34.93400,416.0
34.98200,438.0
35.03000,422.0
35.07800,364.0
35.12600,329.0
35.17400,257.0
35.22200,196.0
35.27000,154.0
35.31800,86.0
35.36600,73.0
35.41400,68.0
35.46200,54.0
35.51000,56.0
35.55800,47.0
35.60600,43.0
35.65400,39.0
35.70200,20.0
35.75000,34.0
35.79800,37.0
35.84600,25.0
35.89400,19.0
35.94200,28.0
35.99000,25.0
36.03800,34.0
36.08600,31.0
36.13400,38.0
36.18200,32.0
36.23000,30.0
36.27800,28.0
36.32600,32.0
36.37400,31.0
36.42200,29.0
36.47000,31.0
36.51800,34.0
36.56600,35.0
36.61400,55.0
36.66200,48.0
36.71000,56.0
36.75800,47.0
36.80600,65.0
36.85400,61.0
36.90200,47.0
36.95000,50.0
36.99800,56.0
37.04600,50.0
37.09400,39.0
37.14200,59.0
37.19000,58.0
37.23800,38.0
37.28600,51.0
37.33400,35.0
37.38200,48.0
37.43000,44.0
37.47800,41.0
37.52600,49.0
37.57400,52.0
37.62200,40.0
37.67000,41.0
37.71800,55.0
37.76600,65.0
37.81400,75.0
37.86200,93.0
37.91000,98.0
37.95800,125.0
38.00600,144.0
38.05400,167.0
38.10200,211.0
38.15000,220.0
38.19800,256.0
38.24600,240.0
38.29400,242.0
38.34200,249.0
38.39000,256.0
38.43800,244.0
38.48600,283.0
38.53400,337.0
38.58200,386.0
38.63000,466.0
38.67800,436.0
38.72600,428.0
38.77400,421.0
38.82200,426.0
38.87000,405.0
38.91800,337.0
38.96600,305.0
39.01400,234.0
39.06200,169.0
39.11000,176.0
39.15800,152.0
39.20600,127.0
39.25400,118.0
39.30200,113.0
39.35000,103.0
39.39800,75.0
39.44600,105.0
39.49400,119.0
39.54200,135.0
39.59000,138.0
39.63800,184.0
39.68600,233.0
39.73400,285.0
39.78200,427.0
39.83000,549.0
39.87800,718.0
39.92600,874.0
39.97400,1052.0
40.02200,1134.0
40.07000,1114.0
40.11800,1072.0
40.16600,864.0
40.21400,766.0
40.26200,517.0
40.31000,411.0
40.35800,305.0
40.40600,226.0
40.45400,185.0
40.50200,136.0
40.55000,127.0
40.59800,92.0
40.64600,80.0
40.69400,72.0
40.74200,48.0
40.79000,41.0
40.83800,42.0
40.88600,36.0
40.93400,56.0
40.98200,38.0
41.03000,35.0
41.07800,44.0
41.12600,33.0
41.17400,25.0
41.22200,27.0
41.27000,29.0
41.31800,32.0
41.36600,32.0
41.41400,34.0
41.46200,27.0
41.51000,24.0
41.55800,32.0
41.60600,26.0
41.65400,27.0
41.70200,23.0
41.75000,36.0
41.79800,23.0
41.84600,23.0
41.89400,42.0
41.94200,27.0
41.99000,24.0
42.03800,25.0
42.08600,37.0
42.13400,33.0
42.18200,49.0
42.23000,50.0
42.27800,64.0
42.32600,67.0
42.37400,73.0
42.42200,66.0
42.47000,62.0
42.51800,54.0
42.56600,57.0
42.61400,47.0
42.66200,54.0
42.71000,48.0
42.75800,42.0
42.80600,46.0
42.85400,29.0
42.90200,47.0
42.95000,33.0
42.99800,29.0
43.04600,30.0
43.09400,13.0
43.14200,24.0
43.19000,31.0
43.23800,22.0
43.28600,19.0
43.33400,25.0
43.38200,19.0
43.43000,21.0
43.47800,17.0
43.52600,19.0
43.57400,17.0
43.62200,14.0
43.67000,19.0
43.71800,21.0
43.76600,20.0
43.81400,22.0
43.86200,18.0
43.91000,12.0
43.95800,17.0
44.00600,16.0
44.05400,15.0
44.10200,15.0
44.15000,17.0
44.19800,14.0
44.24600,15.0
44.29400,14.0
44.34200,19.0
44.39000,23.0
44.43800,24.0
44.48600,20.0
44.53400,19.0
44.58200,23.0
44.63000,14.0
44.67800,12.0
44.72600,16.0
44.77400,19.0
44.82200,22.0
44.87000,15.0
44.91800,10.0
44.96600,19.0
45.01400,10.0
45.06200,17.0
45.11000,9.0
45.15800,17.0
45.20600,20.0
45.25400,12.0
45.30200,23.0
45.35000,18.0
45.39800,14.0
45.44600,8.0
45.49400,18.0
45.54200,14.0
45.59000,12.0
45.63800,17.0
45.68600,17.0
45.73400,21.0
45.78200,13.0
45.83000,16.0
45.87800,13.0
45.92600,18.0
45.97400,13.0
46.02200,11.0
46.07000,15.0
46.11800,12.0
46.16600,14.0
46.21400,20.0
46.26200,20.0
46.31000,16.0
46.35800,19.0
46.40600,14.0
46.45400,14.0
46.50200,17.0
46.55000,13.0
46.59800,13.0
46.64600,22.0
46.69400,18.0
46.74200,12.0
46.79000,12.0
46.83800,16.0
46.88600,10.0
46.93400,10.0
46.98200,19.0
47.03000,22.0
47.07800,16.0
47.12600,16.0
47.17400,17.0
47.22200,12.0
47.27000,8.0
47.31800,15.0
47.36600,18.0
47.41400,10.0
47.46200,17.0
47.51000,11.0
47.55800,11.0
47.60600,14.0
47.65400,17.0
47.70200,19.0
47.75000,9.0
47.79800,14.0
47.84600,11.0
47.89400,10.0
47.94200,10.0
47.99000,14.0
48.03800,18.0
48.08600,12.0
48.13400,14.0
48.18200,12.0
48.23000,14.0
48.27800,17.0
48.32600,6.0
48.37400,12.0
48.42200,17.0
48.47000,10.0
48.51800,10.0
48.56600,9.0
48.61400,17.0
48.66200,7.0
48.71000,18.0
48.75800,19.0
48.80600,6.0
48.85400,13.0
48.90200,15.0
48.95000,15.0
48.99800,11.0
49.04600,20.0
49.09400,11.0
49.14200,12.0
49.19000,23.0
49.23800,12.0
49.28600,8.0
49.33400,15.0
49.38200,11.0
49.43000,12.0
49.47800,6.0
49.52600,8.0
49.57400,15.0
49.62200,15.0
49.67000,15.0
49.71800,11.0
49.76600,9.0
49.81400,9.0
49.86200,8.0
49.91000,18.0
49.95800,18.0
50.00600,14.0
50.05400,15.0
50.10200,17.0
50.15000,17.0
50.19800,16.0
50.24600,15.0
50.29400,14.0
50.34200,16.0
50.39000,8.0
50.43800,19.0
50.48600,22.0
50.53400,14.0
50.58200,15.0
50.63000,10.0
50.67800,20.0
50.72600,13.0
50.77400,19.0
50.82200,12.0
50.87000,18.0
50.91800,18.0
50.96600,13.0
51.01400,10.0
51.06200,13.0
51.11000,22.0
51.15800,18.0
51.20600,20.0
51.25400,14.0
51.30200,10.0
51.35000,12.0
51.39800,14.0
51.44600,16.0
51.49400,15.0
51.54200,16.0
51.59000,11.0
51.63800,19.0
51.68600,11.0
51.73400,13.0
51.78200,11.0
51.83000,14.0
51.87800,7.0
51.92600,15.0
51.97400,10.0
52.02200,23.0
52.07000,24.0
52.11800,16.0
52.16600,16.0
52.21400,18.0
52.26200,22.0
52.31000,31.0
52.35800,26.0
52.40600,31.0
52.45400,33.0
52.50200,48.0
52.55000,70.0
52.59800,94.0
52.64600,93.0
52.69400,129.0
52.74200,154.0
52.79000,157.0
52.83800,181.0
52.88600,175.0
52.93400,137.0
52.98200,116.0
53.03000,124.0
53.07800,84.0
53.12600,89.0
53.17400,73.0
53.22200,48.0
53.27000,49.0
53.31800,22.0
53.36600,39.0
53.41400,32.0
53.46200,34.0
53.51000,18.0
53.55800,27.0
53.60600,19.0
53.65400,20.0
53.70200,26.0
53.75000,18.0
53.79800,16.0
53.84600,16.0
53.89400,23.0
53.94200,14.0
53.99000,12.0
54.03800,28.0
54.08600,19.0
54.13400,21.0
54.18200,25.0
54.23000,28.0
54.27800,16.0
54.32600,14.0
54.37400,16.0
54.42200,22.0
54.47000,24.0
54.51800,16.0
54.56600,21.0
54.61400,23.0
54.66200,31.0
54.71000,26.0
54.75800,23.0
54.80600,20.0
54.85400,28.0
54.90200,24.0
54.95000,36.0
54.99800,32.0
55.04600,20.0
55.09400,23.0
55.14200,26.0
55.19000,22.0
55.23800,23.0
55.28600,30.0
55.33400,31.0
55.38200,38.0
55.43000,40.0
55.47800,47.0
55.52600,55.0
55.57400,61.0
55.62200,44.0
55.67000,66.0
55.71800,62.0
55.76600,54.0
55.81400,74.0
55.86200,95.0
55.91000,98.0
55.95800,104.0
56.00600,96.0
56.05400,100.0
56.10200,85.0
56.15000,92.0
56.19800,76.0
56.24600,72.0
56.29400,62.0
56.34200,56.0
56.39000,49.0
56.43800,42.0
56.48600,54.0
56.53400,33.0
56.58200,43.0
56.63000,31.0
56.67800,22.0
56.72600,26.0
56.77400,26.0
56.82200,21.0
56.87000,30.0
56.91800,18.0
56.96600,20.0
57.01400,12.0
57.06200,17.0
57.11000,20.0
57.15800,22.0
57.20600,16.0
57.25400,17.0
57.30200,7.0
57.35000,10.0
57.39800,11.0
57.44600,8.0
57.49400,13.0
57.54200,22.0
57.59000,15.0
57.63800,7.0
57.68600,20.0
57.73400,13.0
57.78200,19.0
57.83000,10.0
57.87800,8.0
57.92600,13.0
57.97400,11.0
58.02200,16.0
58.07000,15.0
58.11800,12.0
58.16600,17.0
58.21400,17.0
58.26200,15.0
58.31000,12.0
58.35800,13.0
58.40600,17.0
58.45400,8.0
58.50200,14.0
58.55000,16.0
58.59800,12.0
58.64600,15.0
58.69400,9.0
58.74200,13.0
58.79000,17.0
58.83800,16.0
58.88600,14.0
58.93400,9.0
58.98200,16.0
59.03000,10.0
59.07800,15.0
59.12600,10.0
59.17400,7.0
59.22200,17.0
59.27000,13.0
59.31800,18.0
59.36600,9.0
59.41400,14.0
59.46200,16.0
59.51000,15.0
59.55800,11.0
59.60600,8.0
59.65400,14.0
59.70200,6.0
59.75000,11.0
59.79800,11.0
59.84600,10.0
59.89400,11.0
59.94200,11.0
59.99000,17.0
60.03800,13.0
60.08600,13.0
60.13400,16.0
60.18200,11.0
60.23000,17.0
60.27800,17.0
60.32600,23.0
60.37400,15.0
60.42200,15.0
60.47000,11.0
60.51800,15.0
60.56600,14.0
60.61400,16.0
60.66200,13.0
60.71000,10.0
60.75800,16.0
60.80600,17.0
60.85400,10.0
60.90200,14.0
60.95000,16.0
60.99800,14.0
61.04600,12.0
61.09400,18.0
61.14200,13.0
61.19000,19.0
61.23800,13.0
61.28600,8.0
61.33400,21.0
61.38200,9.0
61.43000,12.0
61.47800,24.0
61.52600,16.0
61.57400,19.0
61.62200,22.0
61.67000,17.0
61.71800,25.0
61.76600,19.0
61.81400,22.0
61.86200,23.0
61.91000,19.0
61.95800,25.0
62.00600,32.0
62.05400,35.0
62.10200,42.0
62.15000,28.0
62.19800,43.0
62.24600,39.0
62.29400,55.0
62.34200,56.0
62.39000,61.0
62.43800,70.0
62.48600,107.0
62.53400,117.0
62.58200,134.0
62.63000,160.0
62.67800,171.0
62.72600,186.0
62.77400,181.0
62.82200,186.0
62.87000,212.0
62.91800,213.0
62.96600,204.0
63.01400,160.0
63.06200,151.0
63.11000,153.0
63.15800,114.0
63.20600,99.0
63.25400,70.0
63.30200,66.0
63.35000,78.0
63.39800,61.0
63.44600,42.0
63.49400,31.0
63.54200,31.0
63.59000,27.0
63.63800,25.0
63.68600,27.0
63.73400,25.0
63.78200,13.0
63.83000,20.0
63.87800,22.0
63.92600,20.0
63.97400,19.0
64.02200,18.0
64.07000,20.0
64.11800,20.0
64.16600,16.0
64.21400,8.0
64.26200,22.0
64.31000,21.0
64.35800,24.0
64.40600,18.0
64.45400,21.0
64.50200,12.0
64.55000,13.0
64.59800,10.0
64.64600,12.0
64.69400,19.0
64.74200,15.0
64.79000,13.0
64.83800,18.0
64.88600,13.0
64.93400,19.0
64.98200,13.0
65.03000,14.0
65.07800,10.0
65.12600,4.0
65.17400,16.0
65.22200,14.0
65.27000,25.0
65.31800,15.0
65.36600,15.0
65.41400,10.0
65.46200,22.0
65.51000,21.0
65.55800,16.0
65.60600,12.0
65.65400,24.0
65.70200,10.0
65.75000,22.0
65.79800,13.0
65.84600,18.0
65.89400,17.0
65.94200,18.0
65.99000,11.0
66.03800,16.0
66.08600,20.0
66.13400,18.0
66.18200,13.0
66.23000,12.0
66.27800,16.0
66.32600,19.0
66.37400,18.0
66.42200,10.0
66.47000,12.0
66.51800,16.0
66.56600,11.0
66.61400,18.0
66.66200,18.0
66.71000,11.0
66.75800,10.0
66.80600,7.0
66.85400,23.0
66.90200,12.0
66.95000,14.0
66.99800,15.0
67.04600,13.0
67.09400,15.0
67.14200,12.0
67.19000,18.0
67.23800,12.0
67.28600,10.0
67.33400,17.0
67.38200,11.0
67.43000,15.0
67.47800,22.0
67.52600,18.0
67.57400,10.0
67.62200,12.0
67.67000,20.0
67.71800,15.0
67.76600,12.0
67.81400,17.0
67.86200,18.0
67.91000,17.0
67.95800,18.0
68.00600,20.0
68.05400,18.0
68.10200,21.0
68.15000,13.0
68.19800,16.0
68.24600,15.0
68.29400,23.0
68.34200,18.0
68.39000,14.0
68.43800,23.0
68.48600,17.0
68.53400,20.0
68.58200,21.0
68.63000,18.0
68.67800,17.0
68.72600,19.0
68.77400,20.0
68.82200,23.0
68.87000,27.0
68.91800,24.0
68.96600,23.0
69.01400,30.0
69.06200,36.0
69.11000,32.0
69.15800,32.0
69.20600,25.0
69.25400,31.0
69.30200,36.0
69.35000,29.0
69.39800,45.0
69.44600,48.0
69.49400,37.0
69.54200,47.0
69.59000,56.0
69.63800,65.0
69.68600,56.0
69.73400,74.0
69.78200,90.0
69.83000,90.0
69.87800,105.0
69.92600,117.0
69.97400,122.0
70.02200,148.0
70.07000,183.0
70.11800,187.0
70.16600,231.0
70.21400,242.0
70.26200,315.0
70.31000,249.0
70.35800,281.0
70.40600,271.0
70.45400,299.0
70.50200,242.0
70.55000,229.0
70.59800,232.0
70.64600,186.0
70.69400,158.0
70.74200,151.0
70.79000,109.0
70.83800,118.0
70.88600,93.0
70.93400,61.0
70.98200,58.0
71.03000,56.0
71.07800,36.0
71.12600,50.0
71.17400,34.0
71.22200,39.0
71.27000,41.0
71.31800,22.0
71.36600,37.0
71.41400,30.0
71.46200,27.0
71.51000,31.0
71.55800,24.0
71.60600,23.0
71.65400,23.0
71.70200,18.0
71.75000,19.0
71.79800,25.0
71.84600,12.0
71.89400,27.0
71.94200,23.0
71.99000,24.0
72.03800,19.0
72.08600,22.0
72.13400,22.0
72.18200,26.0
72.23000,25.0
72.27800,23.0
72.32600,22.0
72.37400,14.0
72.42200,18.0
72.47000,18.0
72.51800,18.0
72.56600,19.0
72.61400,20.0
72.66200,22.0
72.71000,16.0
72.75800,14.0
72.80600,21.0
72.85400,18.0
72.90200,19.0
72.95000,17.0
72.99800,18.0
73.04600,22.0
73.09400,15.0
73.14200,9.0
73.19000,25.0
73.23800,12.0
73.28600,23.0
73.33400,26.0
73.38200,15.0
73.43000,26.0
73.47800,26.0
73.52600,25.0
73.57400,28.0
73.62200,16.0
73.67000,22.0
73.71800,31.0
73.76600,33.0
73.81400,51.0
73.86200,35.0
73.91000,49.0
73.95800,43.0
74.00600,63.0
74.05400,41.0
74.10200,43.0
74.15000,60.0
74.19800,44.0
74.24600,38.0
74.29400,47.0
74.34200,35.0
74.39000,37.0
74.43800,41.0
74.48600,26.0
74.53400,30.0
74.58200,29.0
74.63000,26.0
74.67800,28.0
74.72600,20.0
74.77400,23.0
74.82200,22.0
74.87000,29.0
74.91800,31.0
74.96600,27.0
75.01400,38.0
75.06200,16.0
75.11000,22.0
75.15800,19.0
75.20600,25.0
75.25400,24.0
75.30200,28.0
75.35000,28.0
75.39800,34.0
75.44600,47.0
75.49400,38.0
75.54200,44.0
75.59000,46.0
75.63800,56.0
75.68600,74.0
75.73400,93.0
75.78200,91.0
75.83000,127.0
75.87800,122.0
75.92600,133.0
75.97400,134.0
76.02200,138.0
76.07000,134.0
76.11800,138.0
76.16600,130.0
76.21400,154.0
76.26200,116.0
76.31000,109.0
76.35800,92.0
76.40600,69.0
76.45400,78.0
76.50200,66.0
76.55000,60.0
76.59800,51.0
76.64600,61.0
76.69400,60.0
76.74200,63.0
76.79000,65.0
76.83800,56.0
76.88600,62.0
76.93400,67.0
76.98200,80.0
77.03000,77.0
77.07800,92.0
77.12600,94.0
77.17400,97.0
77.22200,93.0
77.27000,118.0
77.31800,112.0
77.36600,92.0
77.41400,117.0
77.46200,93.0
77.51000,92.0
77.55800,80.0
77.60600,59.0
77.65400,41.0
77.70200,47.0
77.75000,49.0
77.79800,39.0
77.84600,37.0
77.89400,35.0
77.94200,31.0
77.99000,32.0
78.03800,23.0
78.08600,28.0
78.13400,25.0
78.18200,24.0
78.23000,22.0
78.27800,24.0
78.32600,15.0
78.37400,24.0
78.42200,19.0
78.47000,21.0
78.51800,37.0
78.56600,19.0
78.61400,17.0
78.66200,21.0
78.71000,26.0
78.75800,19.0
78.80600,25.0
78.85400,25.0
78.90200,30.0
78.95000,19.0
78.99800,18.0
79.04600,19.0
79.09400,23.0
79.14200,17.0
79.19000,17.0
79.23800,18.0
79.28600,11.0
79.33400,19.0
79.38200,14.0
79.43000,13.0
79.47800,18.0
79.52600,21.0
79.57400,11.0
79.62200,16.0
79.67000,16.0
79.71800,14.0
79.76600,17.0
79.81400,21.0
79.86200,16.0
79.91000,15.0
79.95800,8.0
79.99400,20.0