File: code/data/data_source2/TiNb_KL388E_Ti40Nb_1_Bragg.csv
[Measurement conditions]
Sample identification,
Comment - 1,"Configuration=Filmes Finos 19_1_2015, Owner=User-1, Creation date=19/01/2015 21:17:15"
Comment - 2,"Goniometer=PW3050/60 (Theta/Theta); Minimum step size 2Theta:0.001; Minimum step size Omega:0.001"
Comment - 3,"Sample stage=PW3071/xx Bracket"
Comment - 4,"Diffractometer system=XPERT-PRO"
Comment - 5,"Measurement program=C:\PANalytical\Data Collector\Programs\BraggBrentano.xrdmp, Identifier={1069A1B4-F515-4840-9AC8-848F644ED6C5}"
Anode material,Cu
K-Alpha1 wavelength,1.5405980
K-Alpha2 wavelength,1.5444260
Ratio K-Alpha2/K-Alpha1,0.500
Divergence slit,Fixed,0.76mm
Receiving slit,0.10
Monochromator used,YES
Generator voltage, 40
Tube current, 40
File date and time,14/Jun/2018 16:13
Unit cell,
h k l, 0 0 0
Scan axis,Gonio
Scan range,20.00000,80.00000
Scan step size,0.0120000
No. of points, 5000
Scan type,CONTINUOUS
Time per step,1.50
[Scan points]
Angle,Intensity
20.00600,41.0
20.05400,41.0
20.10200,35.0
20.15000,35.0
20.19800,54.0
20.24600,47.0
20.29400,37.0
20.34200,38.0
20.39000,40.0
20.43800,34.0
20.48600,49.0
20.53400,42.0
20.58200,36.0
20.63000,43.0
20.67800,38.0
20.72600,41.0
20.77400,36.0
20.82200,40.0
20.87000,33.0
20.91800,48.0
20.96600,51.0
21.01400,47.0
21.06200,39.0
21.11000,31.0
21.15800,38.0
21.20600,38.0
21.25400,53.0
21.30200,37.0
21.35000,43.0
21.39800,36.0
21.44600,30.0
21.49400,31.0
21.54200,52.0
21.59000,41.0
21.63800,33.0
21.68600,40.0
21.73400,48.0
21.78200,39.0
21.83000,38.0
21.87800,32.0
21.92600,47.0
21.97400,45.0
22.02200,34.0
22.07000,33.0
22.11800,46.0
22.16600,39.0
22.21400,31.0
22.26200,34.0
22.31000,39.0
22.35800,36.0
22.40600,39.0
22.45400,37.0
22.50200,38.0
22.55000,33.0
22.59800,37.0
22.64600,49.0
22.69400,33.0
22.74200,43.0
22.79000,30.0
22.83800,29.0
22.88600,31.0
22.93400,37.0
22.98200,37.0
23.03000,46.0
23.07800,48.0
23.12600,45.0
23.17400,29.0
23.22200,26.0
23.27000,34.0
23.31800,49.0
23.36600,22.0
23.41400,38.0
23.46200,38.0
23.51000,38.0
23.55800,32.0
23.60600,40.0
23.65400,22.0
23.70200,46.0
23.75000,34.0
23.79800,47.0
23.84600,39.0
23.89400,42.0
23.94200,32.0
23.99000,38.0
24.03800,26.0
24.08600,38.0
24.13400,33.0
24.18200,36.0
24.23000,29.0
24.27800,33.0
24.32600,29.0
24.37400,24.0
24.42200,39.0
24.47000,30.0
24.51800,32.0
24.56600,28.0
24.61400,25.0
24.66200,32.0
24.71000,29.0
24.75800,28.0
24.80600,36.0
24.85400,24.0
24.90200,28.0
24.95000,36.0
24.99800,37.0
25.04600,26.0
25.09400,31.0
25.14200,30.0
25.19000,28.0
25.23800,30.0
25.28600,40.0
25.33400,35.0
25.38200,31.0
25.43000,36.0
25.47800,29.0
25.52600,40.0
25.57400,36.0
25.62200,35.0
25.67000,30.0
25.71800,36.0
25.76600,40.0
25.81400,30.0
25.86200,38.0
25.91000,27.0
25.95800,33.0
26.00600,27.0
26.05400,39.0
26.10200,39.0
26.15000,26.0
26.19800,29.0
26.24600,40.0
26.29400,24.0
26.34200,33.0
26.39000,30.0
26.43800,34.0
26.48600,34.0
26.53400,30.0
26.58200,39.0
26.63000,32.0
26.67800,44.0
26.72600,39.0
26.77400,34.0
26.82200,38.0
26.87000,31.0
26.91800,28.0
26.96600,27.0
27.01400,31.0
27.06200,26.0
27.11000,33.0
27.15800,23.0
27.20600,30.0
27.25400,28.0
27.30200,37.0
27.35000,25.0
27.39800,27.0
27.44600,32.0
27.49400,34.0
27.54200,22.0
27.59000,37.0
27.63800,41.0
27.68600,31.0
27.73400,30.0
27.78200,29.0
27.83000,42.0
27.87800,38.0
27.92600,24.0
27.97400,29.0
28.02200,45.0
28.07000,29.0
28.11800,33.0
28.16600,29.0
28.21400,37.0
28.26200,36.0
28.31000,30.0
28.35800,33.0
28.40600,33.0
28.45400,28.0
28.50200,34.0
28.55000,40.0
28.59800,30.0
28.64600,32.0
28.69400,40.0
28.74200,29.0
28.79000,30.0
28.83800,40.0
28.88600,32.0
28.93400,32.0
28.98200,28.0
29.03000,26.0
29.07800,30.0
29.12600,26.0
29.17400,26.0
29.22200,25.0
29.27000,31.0
29.31800,29.0
29.36600,30.0
29.41400,28.0
29.46200,32.0
29.51000,36.0
29.55800,26.0
29.60600,24.0
29.65400,36.0
29.70200,24.0
29.75000,32.0
29.79800,28.0
29.84600,28.0
29.89400,34.0
29.94200,35.0
29.99000,40.0
30.03800,18.0
30.08600,27.0
30.13400,28.0
30.18200,30.0
30.23000,22.0
30.27800,40.0
30.32600,31.0
30.37400,37.0
30.42200,27.0
30.47000,26.0
30.51800,26.0
30.56600,42.0
30.61400,36.0
30.66200,32.0
30.71000,24.0
30.75800,27.0
30.80600,42.0
30.85400,30.0
30.90200,30.0
30.95000,35.0
30.99800,41.0
31.04600,50.0
31.09400,41.0
31.14200,42.0
31.19000,32.0
31.23800,42.0
31.28600,48.0
31.33400,52.0
31.38200,56.0
31.43000,57.0
31.47800,54.0
31.52600,65.0
31.57400,57.0
31.62200,48.0
31.67000,45.0
31.71800,34.0
31.76600,49.0
31.81400,38.0
31.86200,35.0
31.91000,39.0
31.95800,41.0
32.00600,31.0
32.05400,29.0
32.10200,33.0
32.15000,38.0
32.19800,27.0
32.24600,28.0
32.29400,37.0
32.34200,33.0
32.39000,31.0
32.43800,30.0
32.48600,32.0
32.53400,24.0
32.58200,21.0
32.63000,26.0
32.67800,18.0
32.72600,40.0
32.77400,25.0
32.82200,43.0
32.87000,32.0
32.91800,30.0
32.96600,22.0
33.01400,22.0
33.06200,24.0
33.11000,29.0
33.15800,27.0
33.20600,27.0
33.25400,33.0
33.30200,31.0
33.35000,28.0
33.39800,32.0
33.44600,28.0
33.49400,26.0
33.54200,34.0
33.59000,41.0
33.63800,24.0
33.68600,19.0
33.73400,28.0
33.78200,37.0
33.83000,34.0
33.87800,28.0
33.92600,37.0
33.97400,31.0
34.02200,36.0
34.07000,23.0
34.11800,29.0
34.16600,28.0
34.21400,34.0
34.26200,24.0
34.31000,35.0
34.35800,36.0
34.40600,28.0
34.45400,34.0
34.50200,38.0
34.55000,32.0
34.59800,26.0
34.64600,36.0
34.69400,28.0
34.74200,37.0
34.79000,30.0
34.83800,34.0
34.88600,35.0
34.93400,40.0
34.98200,41.0
35.03000,28.0
35.07800,36.0
35.12600,30.0
35.17400,34.0
35.22200,33.0
35.27000,31.0
35.31800,37.0
35.36600,19.0
35.41400,33.0
35.46200,46.0
35.51000,37.0
35.55800,47.0
35.60600,44.0
35.65400,41.0
35.70200,39.0
35.75000,37.0
35.79800,36.0
35.84600,38.0
35.89400,41.0
35.94200,32.0
35.99000,51.0
36.03800,42.0
36.08600,44.0
36.13400,50.0
36.18200,60.0
36.23000,62.0
36.27800,68.0
36.32600,78.0
36.37400,77.0
36.42200,94.0
36.47000,93.0
36.51800,107.0
36.56600,94.0
36.61400,110.0
36.66200,93.0
36.71000,81.0
36.75800,79.0
36.80600,67.0
36.85400,65.0
36.90200,72.0
36.95000,49.0
36.99800,70.0
37.04600,71.0
37.09400,77.0
37.14200,77.0
37.19000,92.0
37.23800,81.0
37.28600,105.0
37.33400,108.0
37.38200,105.0
37.43000,123.0
37.47800,128.0
37.52600,172.0
37.57400,190.0
37.62200,212.0
37.67000,240.0
37.71800,273.0
37.76600,345.0
37.81400,400.0
37.86200,428.0
37.91000,523.0
37.95800,581.0
38.00600,623.0
38.05400,709.0
38.10200,716.0
38.15000,763.0
38.19800,805.0
38.24600,854.0
38.29400,904.0
38.34200,1030.0
38.39000,1154.0
38.43800,1405.0
38.48600,1749.0
38.53400,2295.0
38.58200,3208.0
38.63000,4277.0
38.67800,5423.0
38.72600,6356.0
38.77400,6396.0
38.82200,5716.0
38.87000,4878.0
38.91800,3408.0
38.96600,2283.0
39.01400,1315.0
39.06200,738.0
39.11000,421.0
39.15800,275.0
39.20600,205.0
39.25400,176.0
39.30200,169.0
39.35000,144.0
39.39800,140.0
39.44600,135.0
39.49400,96.0
39.54200,90.0
39.59000,80.0
39.63800,63.0
39.68600,64.0
39.73400,65.0
39.78200,51.0
39.83000,58.0
39.87800,66.0
39.92600,60.0
39.97400,44.0
40.02200,38.0
40.07000,42.0
40.11800,49.0
40.16600,55.0
40.21400,40.0
40.26200,58.0
40.31000,50.0
40.35800,42.0
40.40600,28.0
40.45400,36.0
40.50200,42.0
40.55000,36.0
40.59800,33.0
40.64600,39.0
40.69400,28.0
40.74200,45.0
40.79000,35.0
40.83800,39.0
40.88600,32.0
40.93400,31.0
40.98200,38.0
41.03000,32.0
41.07800,34.0
41.12600,39.0
41.17400,29.0
41.22200,31.0
41.27000,31.0
41.31800,44.0
41.36600,26.0
41.41400,39.0
41.46200,21.0
41.51000,28.0
41.55800,36.0
41.60600,33.0
41.65400,34.0
41.70200,37.0
41.75000,40.0
41.79800,34.0
41.84600,27.0
41.89400,41.0
41.94200,39.0
41.99000,47.0
42.03800,46.0
42.08600,53.0
42.13400,51.0
42.18200,53.0
42.23000,60.0
42.27800,59.0
42.32600,75.0
42.37400,57.0
42.42200,66.0
42.47000,42.0
42.51800,40.0
42.56600,44.0
42.61400,45.0
42.66200,35.0
42.71000,35.0
42.75800,36.0
42.80600,36.0
42.85400,39.0
42.90200,40.0
42.95000,22.0
42.99800,29.0
43.04600,34.0
43.09400,33.0
43.14200,24.0
43.19000,18.0
43.23800,26.0
43.28600,21.0
43.33400,19.0
43.38200,27.0
43.43000,27.0
43.47800,25.0
43.52600,19.0
43.57400,17.0
43.62200,23.0
43.67000,34.0
43.71800,27.0
43.76600,28.0
43.81400,33.0
43.86200,23.0
43.91000,18.0
43.95800,25.0
44.00600,33.0
44.05400,29.0
44.10200,29.0
44.15000,22.0
44.19800,29.0
44.24600,26.0
44.29400,18.0
44.34200,23.0
44.39000,28.0
44.43800,23.0
44.48600,21.0
44.53400,19.0
44.58200,20.0
44.63000,14.0
44.67800,28.0
44.72600,22.0
44.77400,19.0
44.82200,29.0
44.87000,22.0
44.91800,20.0
44.96600,19.0
45.01400,22.0
45.06200,20.0
45.11000,20.0
45.15800,23.0
45.20600,23.0
45.25400,22.0
45.30200,24.0
45.35000,19.0
45.39800,23.0
45.44600,27.0
45.49400,23.0
45.54200,25.0
45.59000,27.0
45.63800,22.0
45.68600,17.0
45.73400,12.0
45.78200,32.0
45.83000,23.0
45.87800,20.0
45.92600,21.0
45.97400,27.0
46.02200,23.0
46.07000,14.0
46.11800,17.0
46.16600,14.0
46.21400,24.0
46.26200,18.0
46.31000,25.0
46.35800,26.0
46.40600,18.0
46.45400,13.0
46.50200,27.0
46.55000,15.0
46.59800,27.0
46.64600,19.0
46.69400,24.0
46.74200,19.0
46.79000,20.0
46.83800,23.0
46.88600,19.0
46.93400,23.0
46.98200,21.0
47.03000,18.0
47.07800,17.0
47.12600,20.0
47.17400,16.0
47.22200,22.0
47.27000,17.0
47.31800,18.0
47.36600,30.0
47.41400,20.0
47.46200,19.0
47.51000,21.0
47.55800,24.0
47.60600,16.0
47.65400,28.0
47.70200,19.0
47.75000,10.0
47.79800,23.0
47.84600,25.0
47.89400,26.0
47.94200,15.0
47.99000,17.0
48.03800,25.0
48.08600,28.0
48.13400,14.0
48.18200,31.0
48.23000,9.0
48.27800,13.0
48.32600,13.0
48.37400,13.0
48.42200,22.0
48.47000,18.0
48.51800,17.0
48.56600,14.0
48.61400,26.0
48.66200,17.0
48.71000,18.0
48.75800,12.0
48.80600,34.0
48.85400,29.0
48.90200,33.0
48.95000,16.0
48.99800,18.0
49.04600,18.0
49.09400,21.0
49.14200,24.0
49.19000,23.0
49.23800,28.0
49.28600,26.0
49.33400,24.0
49.38200,19.0
49.43000,21.0
49.47800,29.0
49.52600,24.0
49.57400,23.0
49.62200,26.0
49.67000,26.0
49.71800,18.0
49.76600,19.0
49.81400,16.0
49.86200,25.0
49.91000,26.0
49.95800,27.0
50.00600,20.0
50.05400,27.0
50.10200,19.0
50.15000,22.0
50.19800,30.0
50.24600,26.0
50.29400,35.0
50.34200,36.0
50.39000,29.0
50.43800,32.0
50.48600,33.0
50.53400,48.0
50.58200,39.0
50.63000,48.0
50.67800,46.0
50.72600,32.0
50.77400,36.0
50.82200,45.0
50.87000,46.0
50.91800,40.0
50.96600,54.0
51.01400,49.0
51.06200,40.0
51.11000,30.0
51.15800,27.0
51.20600,30.0
51.25400,37.0
51.30200,22.0
51.35000,24.0
51.39800,24.0
51.44600,37.0
51.49400,29.0
51.54200,24.0
51.59000,21.0
51.63800,18.0
51.68600,22.0
51.73400,17.0
51.78200,29.0
51.83000,16.0
51.87800,22.0
51.92600,20.0
51.97400,14.0
52.02200,14.0
52.07000,19.0
52.11800,22.0
52.16600,27.0
52.21400,22.0
52.26200,21.0
52.31000,26.0
52.35800,20.0
52.40600,22.0
52.45400,22.0
52.50200,14.0
52.55000,19.0
52.59800,20.0
52.64600,20.0
52.69400,20.0
52.74200,24.0
52.79000,21.0
52.83800,16.0
52.88600,21.0
52.93400,23.0
52.98200,19.0
53.03000,24.0
53.07800,20.0
53.12600,24.0
53.17400,26.0
53.22200,30.0
53.27000,31.0
53.31800,14.0
53.36600,35.0
53.41400,27.0
53.46200,35.0
53.51000,25.0
53.55800,31.0
53.60600,28.0
53.65400,21.0
53.70200,34.0
53.75000,31.0
53.79800,31.0
53.84600,39.0
53.89400,36.0
53.94200,27.0
53.99000,54.0
54.03800,42.0
54.08600,39.0
54.13400,48.0
54.18200,48.0
54.23000,41.0
54.27800,43.0
54.32600,33.0
54.37400,53.0
54.42200,48.0
54.47000,43.0
54.51800,52.0
54.56600,54.0
54.61400,63.0
54.66200,59.0
54.71000,54.0
54.75800,48.0
54.80600,43.0
54.85400,49.0
54.90200,59.0
54.95000,64.0
54.99800,78.0
55.04600,83.0
55.09400,57.0
55.14200,68.0
55.19000,78.0
55.23800,72.0
55.28600,53.0
55.33400,81.0
55.38200,90.0
55.43000,108.0
55.47800,103.0
55.52600,124.0
55.57400,129.0
55.62200,136.0
55.67000,172.0
55.71800,188.0
55.76600,230.0
55.81400,303.0
55.86200,450.0
55.91000,608.0
55.95800,622.0
56.00600,704.0
56.05400,778.0
56.10200,592.0
56.15000,514.0
56.19800,433.0
56.24600,302.0
56.29400,221.0
56.34200,161.0
56.39000,102.0
56.43800,92.0
56.48600,77.0
56.53400,63.0
56.58200,62.0
56.63000,55.0
56.67800,52.0
56.72600,37.0
56.77400,39.0
56.82200,32.0
56.87000,28.0
56.91800,33.0
56.96600,21.0
57.01400,37.0
57.06200,24.0
57.11000,22.0
57.15800,19.0
57.20600,14.0
57.25400,20.0
57.30200,20.0
57.35000,23.0
57.39800,25.0
57.44600,22.0
57.49400,18.0
57.54200,19.0
57.59000,26.0
57.63800,18.0
57.68600,17.0
57.73400,14.0
57.78200,22.0
57.83000,14.0
57.87800,28.0
57.92600,14.0
57.97400,20.0
58.02200,22.0
58.07000,21.0
58.11800,21.0
58.16600,24.0
58.21400,16.0
58.26200,15.0
58.31000,22.0
58.35800,26.0
58.40600,19.0
58.45400,13.0
58.50200,14.0
58.55000,15.0
58.59800,15.0
58.64600,20.0
58.69400,13.0
58.74200,25.0
58.79000,12.0
58.83800,23.0
58.88600,17.0
58.93400,24.0
58.98200,12.0
59.03000,17.0
59.07800,13.0
59.12600,23.0
59.17400,20.0
59.22200,6.0
59.27000,22.0
59.31800,15.0
59.36600,20.0
59.41400,13.0
59.46200,15.0
59.51000,13.0
59.55800,12.0
59.60600,19.0
59.65400,18.0
59.70200,12.0
59.75000,15.0
59.79800,14.0
59.84600,20.0
59.89400,12.0
59.94200,13.0
59.99000,12.0
60.03800,17.0
60.08600,12.0
60.13400,18.0
60.18200,15.0
60.23000,18.0
60.27800,11.0
60.32600,20.0
60.37400,25.0
60.42200,19.0
60.47000,15.0
60.51800,15.0
60.56600,12.0
60.61400,26.0
60.66200,13.0
60.71000,5.0
60.75800,12.0
60.80600,21.0
60.85400,16.0
60.90200,22.0
60.95000,18.0
60.99800,27.0
61.04600,7.0
61.09400,23.0
61.14200,19.0
61.19000,20.0
61.23800,25.0
61.28600,18.0
61.33400,33.0
61.38200,42.0
61.43000,51.0
61.47800,41.0
61.52600,41.0
61.57400,40.0
61.62200,58.0
61.67000,64.0
61.71800,45.0
61.76600,41.0
61.81400,29.0
61.86200,36.0
61.91000,36.0
61.95800,26.0
62.00600,38.0
62.05400,24.0
62.10200,19.0
62.15000,23.0
62.19800,22.0
62.24600,21.0
62.29400,16.0
62.34200,24.0
62.39000,19.0
62.43800,14.0
62.48600,15.0
62.53400,27.0
62.58200,22.0
62.63000,8.0
62.67800,19.0
62.72600,21.0
62.77400,14.0
62.82200,20.0
62.87000,19.0
62.91800,10.0
62.96600,14.0
63.01400,17.0
63.06200,12.0
63.11000,21.0
63.15800,19.0
63.20600,14.0
63.25400,17.0
63.30200,19.0
63.35000,14.0
63.39800,19.0
63.44600,19.0
63.49400,22.0
63.54200,21.0
63.59000,24.0
63.63800,14.0
63.68600,20.0
63.73400,15.0
63.78200,18.0
63.83000,15.0
63.87800,17.0
63.92600,19.0
63.97400,20.0
64.02200,17.0
64.07000,19.0
64.11800,14.0
64.16600,16.0
64.21400,13.0
64.26200,16.0
64.31000,24.0
64.35800,14.0
64.40600,16.0
64.45400,15.0
64.50200,25.0
64.55000,19.0
64.59800,22.0
64.64600,20.0
64.69400,24.0
64.74200,20.0
64.79000,23.0
64.83800,17.0
64.88600,16.0
64.93400,15.0
64.98200,19.0
65.03000,22.0
65.07800,23.0
65.12600,17.0
65.17400,17.0
65.22200,17.0
65.27000,21.0
65.31800,23.0
65.36600,24.0
65.41400,19.0
65.46200,31.0
65.51000,23.0
65.55800,27.0
65.60600,30.0
65.65400,30.0
65.70200,24.0
65.75000,32.0
65.79800,37.0
65.84600,40.0
65.89400,47.0
65.94200,32.0
65.99000,28.0
66.03800,28.0
66.08600,27.0
66.13400,29.0
66.18200,20.0
66.23000,20.0
66.27800,29.0
66.32600,27.0
66.37400,15.0
66.42200,21.0
66.47000,16.0
66.51800,25.0
66.56600,17.0
66.61400,22.0
66.66200,31.0
66.71000,24.0
66.75800,25.0
66.80600,26.0
66.85400,20.0
66.90200,30.0
66.95000,23.0
66.99800,20.0
67.04600,22.0
67.09400,21.0
67.14200,17.0
67.19000,20.0
67.23800,19.0
67.28600,27.0
67.33400,27.0
67.38200,25.0
67.43000,29.0
67.47800,29.0
67.52600,23.0
67.57400,27.0
67.62200,28.0
67.67000,28.0
67.71800,37.0
67.76600,40.0
67.81400,24.0
67.86200,29.0
67.91000,30.0
67.95800,45.0
68.00600,36.0
68.05400,36.0
68.10200,31.0
68.15000,34.0
68.19800,45.0
68.24600,32.0
68.29400,37.0
68.34200,40.0
68.39000,46.0
68.43800,41.0
68.48600,44.0
68.53400,64.0
68.58200,41.0
68.63000,52.0
68.67800,52.0
68.72600,54.0
68.77400,55.0
68.82200,66.0
68.87000,60.0
68.91800,56.0
68.96600,70.0
69.01400,53.0
69.06200,70.0
69.11000,59.0
69.15800,55.0
69.20600,80.0
69.25400,94.0
69.30200,77.0
69.35000,71.0
69.39800,83.0
69.44600,88.0
69.49400,92.0
69.54200,113.0
69.59000,120.0
69.63800,126.0
69.68600,133.0
69.73400,152.0
69.78200,140.0
69.83000,163.0
69.87800,196.0
69.92600,205.0
69.97400,253.0
70.02200,292.0
70.07000,416.0
70.11800,558.0
70.16600,657.0
70.21400,750.0
70.26200,798.0
70.31000,718.0
70.35800,615.0
70.40600,561.0
70.45400,482.0
70.50200,394.0
70.55000,293.0
70.59800,237.0
70.64600,162.0
70.69400,100.0
70.74200,93.0
70.79000,66.0
70.83800,71.0
70.88600,73.0
70.93400,39.0
70.98200,49.0
71.03000,44.0
71.07800,49.0
71.12600,36.0
71.17400,43.0
71.22200,44.0
71.27000,32.0
71.31800,26.0
71.36600,33.0
71.41400,28.0
71.46200,22.0
71.51000,29.0
71.55800,30.0
71.60600,31.0
71.65400,28.0
71.70200,33.0
71.75000,21.0
71.79800,24.0
71.84600,34.0
71.89400,22.0
71.94200,32.0
71.99000,24.0
72.03800,32.0
72.08600,19.0
72.13400,19.0
72.18200,14.0
72.23000,26.0
72.27800,35.0
72.32600,19.0
72.37400,13.0
72.42200,25.0
72.47000,20.0
72.51800,16.0
72.56600,22.0
72.61400,17.0
72.66200,22.0
72.71000,20.0
72.75800,22.0
72.80600,19.0
72.85400,21.0
72.90200,19.0
72.95000,21.0
72.99800,14.0
73.04600,18.0
73.09400,20.0
73.14200,20.0
73.19000,17.0
73.23800,21.0
73.28600,17.0
73.33400,18.0
73.38200,19.0
73.43000,12.0
73.47800,20.0
73.52600,20.0
73.57400,11.0
73.62200,25.0
73.67000,26.0
73.71800,10.0
73.76600,15.0
73.81400,26.0
73.86200,27.0
73.91000,19.0
73.95800,14.0
74.00600,16.0
74.05400,23.0
74.10200,21.0
74.15000,14.0
74.19800,24.0
74.24600,20.0
74.29400,32.0
74.34200,16.0
74.39000,17.0
74.43800,12.0
74.48600,28.0
74.53400,15.0
74.58200,15.0
74.63000,17.0
74.67800,19.0
74.72600,18.0
74.77400,16.0
74.82200,18.0
74.87000,22.0
74.91800,14.0
74.96600,28.0
75.01400,26.0
75.06200,24.0
75.11000,22.0
75.15800,17.0
75.20600,14.0
75.25400,15.0
75.30200,29.0
75.35000,25.0
75.39800,18.0
75.44600,15.0
75.49400,18.0
75.54200,11.0
75.59000,19.0
75.63800,21.0
75.68600,12.0
75.73400,26.0
75.78200,19.0
75.83000,20.0
75.87800,24.0
75.92600,20.0
75.97400,13.0
76.02200,23.0
76.07000,17.0
76.11800,17.0
76.16600,20.0
76.21400,16.0
76.26200,14.0
76.31000,17.0
76.35800,19.0
76.40600,14.0
76.45400,19.0
76.50200,24.0
76.55000,18.0
76.59800,26.0
76.64600,19.0
76.69400,11.0
76.74200,28.0
76.79000,22.0
76.83800,21.0
76.88600,18.0
76.93400,21.0
76.98200,17.0
77.03000,20.0
77.07800,17.0
77.12600,14.0
77.17400,21.0
77.22200,20.0
77.27000,21.0
77.31800,21.0
77.36600,20.0
77.41400,18.0
77.46200,29.0
77.51000,17.0
77.55800,21.0
77.60600,25.0
77.65400,29.0
77.70200,23.0
77.75000,29.0
77.79800,21.0
77.84600,26.0
77.89400,23.0
77.94200,22.0
77.99000,24.0
78.03800,34.0
78.08600,30.0
78.13400,19.0
78.18200,24.0
78.23000,30.0
78.27800,31.0
78.32600,27.0
78.37400,32.0
78.42200,28.0
78.47000,40.0
78.51800,38.0
78.56600,40.0
78.61400,44.0
78.66200,34.0
78.71000,38.0
78.75800,46.0
78.80600,60.0
78.85400,66.0
78.90200,64.0
78.95000,62.0
78.99800,60.0
79.04600,87.0
79.09400,75.0
79.14200,66.0
79.19000,74.0
79.23800,67.0
79.28600,75.0
79.33400,67.0
79.38200,64.0
79.43000,78.0
79.47800,65.0
79.52600,53.0
79.57400,47.0
79.62200,34.0
79.67000,39.0
79.71800,36.0
79.76600,45.0
79.81400,33.0
79.86200,25.0
79.91000,25.0
79.95800,31.0
79.99400,24.0