File: code/data/data_source2/TiNb_KL381C_Ti15Nb_Bragg.csv
[Measurement conditions]
Sample identification,
Comment - 1,"Configuration=Filmes Finos 19_1_2015, Owner=User-1, Creation date=19/01/2015 21:17:15"
Comment - 2,"Goniometer=PW3050/60 (Theta/Theta); Minimum step size 2Theta:0.001; Minimum step size Omega:0.001"
Comment - 3,"Sample stage=PW3071/xx Bracket"
Comment - 4,"Diffractometer system=XPERT-PRO"
Comment - 5,"Measurement program=C:\PANalytical\Data Collector\Programs\BraggBrentano.xrdmp, Identifier={19FB9B06-E004-4D40-A94B-5B35F08DCC27}"
Comment - 6,"Fine Calibration Offset for 2Theta = 1.522 deg"
Comment - 7,"Fine Calibration Offset for Omega = 1.140 deg"
Anode material,Cu
K-Alpha1 wavelength,1.5405980
K-Alpha2 wavelength,1.5444260
Ratio K-Alpha2/K-Alpha1,0.500
Divergence slit,Fixed,0.10mm
Receiving slit,0.10
Monochromator used,YES
Generator voltage, 40
Tube current, 40
File date and time,02/May/2018 10:50
Unit cell,
h k l, 0 0 0
Scan axis,Gonio
Scan range,20.00000,80.00000
Scan step size,0.0250000
No. of points, 2400
Scan type,CONTINUOUS
Time per step,3.00
[Scan points]
Angle,Intensity
20.01250,97.0
20.06250,84.0
20.11250,89.0
20.16250,86.0
20.21250,93.0
20.26250,84.0
20.31250,71.0
20.36250,93.0
20.41250,70.0
20.46250,71.0
20.51250,87.0
20.56250,99.0
20.61250,106.0
20.66250,105.0
20.71250,86.0
20.76250,79.0
20.81250,101.0
20.86250,85.0
20.91250,80.0
20.96250,75.0
21.01250,84.0
21.06250,78.0
21.11250,63.0
21.16250,87.0
21.21250,93.0
21.26250,78.0
21.31250,76.0
21.36250,80.0
21.41250,80.0
21.46250,75.0
21.51250,92.0
21.56250,84.0
21.61250,85.0
21.66250,93.0
21.71250,73.0
21.76250,91.0
21.81250,74.0
21.86250,88.0
21.91250,74.0
21.96250,66.0
22.01250,96.0
22.06250,80.0
22.11250,86.0
22.16250,76.0
22.21250,77.0
22.26250,66.0
22.31250,62.0
22.36250,73.0
22.41250,69.0
22.46250,72.0
22.51250,86.0
22.56250,71.0
22.61250,72.0
22.66250,88.0
22.71250,80.0
22.76250,76.0
22.81250,65.0
22.86250,54.0
22.91250,74.0
22.96250,76.0
23.01250,70.0
23.06250,81.0
23.11250,77.0
23.16250,69.0
23.21250,74.0
23.26250,63.0
23.31250,62.0
23.36250,71.0
23.41250,82.0
23.46250,69.0
23.51250,85.0
23.56250,67.0
23.61250,82.0
23.66250,69.0
23.71250,74.0
23.76250,74.0
23.81250,71.0
23.86250,63.0
23.91250,73.0
23.96250,75.0
24.01250,73.0
24.06250,67.0
24.11250,64.0
24.16250,57.0
24.21250,68.0
24.26250,78.0
24.31250,72.0
24.36250,72.0
24.41250,83.0
24.46250,66.0
24.51250,72.0
24.56250,77.0
24.61250,68.0
24.66250,61.0
24.71250,56.0
24.76250,85.0
24.81250,63.0
24.86250,55.0
24.91250,65.0
24.96250,73.0
25.01250,65.0
25.06250,69.0
25.11250,56.0
25.16250,63.0
25.21250,52.0
25.26250,53.0
25.31250,51.0
25.36250,66.0
25.41250,62.0
25.46250,68.0
25.51250,63.0
25.56250,60.0
25.61250,63.0
25.66250,57.0
25.71250,61.0
25.76250,63.0
25.81250,74.0
25.86250,63.0
25.91250,74.0
25.96250,64.0
26.01250,75.0
26.06250,72.0
26.11250,72.0
26.16250,58.0
26.21250,60.0
26.26250,81.0
26.31250,64.0
26.36250,62.0
26.41250,80.0
26.46250,64.0
26.51250,67.0
26.56250,69.0
26.61250,56.0
26.66250,76.0
26.71250,57.0
26.76250,67.0
26.81250,70.0
26.86250,62.0
26.91250,76.0
26.96250,59.0
27.01250,66.0
27.06250,74.0
27.11250,61.0
27.16250,68.0
27.21250,54.0
27.26250,70.0
27.31250,68.0
27.36250,62.0
27.41250,62.0
27.46250,64.0
27.51250,64.0
27.56250,68.0
27.61250,75.0
27.66250,76.0
27.71250,67.0
27.76250,64.0
27.81250,58.0
27.86250,74.0
27.91250,60.0
27.96250,49.0
28.01250,71.0
28.06250,77.0
28.11250,76.0
28.16250,76.0
28.21250,68.0
28.26250,55.0
28.31250,68.0
28.36250,66.0
28.41250,70.0
28.46250,60.0
28.51250,66.0
28.56250,68.0
28.61250,67.0
28.66250,47.0
28.71250,56.0
28.76250,66.0
28.81250,66.0
28.86250,70.0
28.91250,71.0
28.96250,75.0
29.01250,52.0
29.06250,56.0
29.11250,50.0
29.16250,52.0
29.21250,62.0
29.26250,57.0
29.31250,60.0
29.36250,63.0
29.41250,75.0
29.46250,62.0
29.51250,65.0
29.56250,62.0
29.61250,62.0
29.66250,69.0
29.71250,70.0
29.76250,69.0
29.81250,59.0
29.86250,60.0
29.91250,62.0
29.96250,56.0
30.01250,71.0
30.06250,56.0
30.11250,74.0
30.16250,58.0
30.21250,76.0
30.26250,64.0
30.31250,63.0
30.36250,59.0
30.41250,84.0
30.46250,81.0
30.51250,71.0
30.56250,80.0
30.61250,60.0
30.66250,67.0
30.71250,65.0
30.76250,70.0
30.81250,82.0
30.86250,72.0
30.91250,83.0
30.96250,84.0
31.01250,61.0
31.06250,67.0
31.11250,60.0
31.16250,66.0
31.21250,64.0
31.26250,57.0
31.31250,53.0
31.36250,62.0
31.41250,72.0
31.46250,53.0
31.51250,75.0
31.56250,79.0
31.61250,63.0
31.66250,61.0
31.71250,58.0
31.76250,64.0
31.81250,73.0
31.86250,80.0
31.91250,66.0
31.96250,89.0
32.01250,74.0
32.06250,89.0
32.11250,75.0
32.16250,92.0
32.21250,75.0
32.26250,72.0
32.31250,84.0
32.36250,79.0
32.41250,92.0
32.46250,79.0
32.51250,93.0
32.56250,86.0
32.61250,93.0
32.66250,91.0
32.71250,91.0
32.76250,92.0
32.81250,89.0
32.86250,80.0
32.91250,83.0
32.96250,71.0
33.01250,75.0
33.06250,78.0
33.11250,75.0
33.16250,83.0
33.21250,62.0
33.26250,73.0
33.31250,62.0
33.36250,71.0
33.41250,89.0
33.46250,85.0
33.51250,76.0
33.56250,78.0
33.61250,72.0
33.66250,86.0
33.71250,77.0
33.76250,87.0
33.81250,78.0
33.86250,65.0
33.91250,64.0
33.96250,76.0
34.01250,74.0
34.06250,69.0
34.11250,69.0
34.16250,56.0
34.21250,65.0
34.26250,66.0
34.31250,66.0
34.36250,86.0
34.41250,69.0
34.46250,67.0
34.51250,80.0
34.56250,58.0
34.61250,84.0
34.66250,67.0
34.71250,79.0
34.76250,86.0
34.81250,81.0
34.86250,73.0
34.91250,83.0
34.96250,65.0
35.01250,75.0
35.06250,86.0
35.11250,70.0
35.16250,68.0
35.21250,70.0
35.26250,70.0
35.31250,79.0
35.36250,74.0
35.41250,68.0
35.46250,62.0
35.51250,79.0
35.56250,82.0
35.61250,77.0
35.66250,70.0
35.71250,80.0
35.76250,88.0
35.81250,77.0
35.86250,85.0
35.91250,96.0
35.96250,90.0
36.01250,79.0
36.06250,80.0
36.11250,71.0
36.16250,65.0
36.21250,85.0
36.26250,88.0
36.31250,76.0
36.36250,82.0
36.41250,102.0
36.46250,87.0
36.51250,99.0
36.56250,119.0
36.61250,92.0
36.66250,90.0
36.71250,85.0
36.76250,90.0
36.81250,95.0
36.86250,109.0
36.91250,97.0
36.96250,92.0
37.01250,112.0
37.06250,114.0
37.11250,94.0
37.16250,110.0
37.21250,116.0
37.26250,111.0
37.31250,110.0
37.36250,139.0
37.41250,134.0
37.46250,158.0
37.51250,153.0
37.56250,167.0
37.61250,184.0
37.66250,173.0
37.71250,212.0
37.76250,240.0
37.81250,280.0
37.86250,283.0
37.91250,292.0
37.96250,339.0
38.01250,424.0
38.06250,434.0
38.11250,505.0
38.16250,585.0
38.21250,635.0
38.26250,669.0
38.31250,727.0
38.36250,761.0
38.41250,799.0
38.46250,800.0
38.51250,735.0
38.56250,708.0
38.61250,743.0
38.66250,676.0
38.71250,674.0
38.76250,618.0
38.81250,605.0
38.86250,589.0
38.91250,607.0
38.96250,606.0
39.01250,555.0
39.06250,557.0
39.11250,591.0
39.16250,644.0
39.21250,618.0
39.26250,670.0
39.31250,694.0
39.36250,828.0
39.41250,918.0
39.46250,1120.0
39.51250,1431.0
39.56250,1805.0
39.61250,2575.0
39.66250,3396.0
39.71250,4592.0
39.76250,5986.0
39.81250,7150.0
39.86250,7682.0
39.91250,7655.0
39.96250,6932.0
40.01250,5586.0
40.06250,4021.0
40.11250,2925.0
40.16250,1946.0
40.21250,1459.0
40.26250,993.0
40.31250,740.0
40.36250,606.0
40.41250,515.0
40.46250,425.0
40.51250,391.0
40.56250,334.0
40.61250,331.0
40.66250,262.0
40.71250,282.0
40.76250,244.0
40.81250,247.0
40.86250,221.0
40.91250,204.0
40.96250,181.0
41.01250,165.0
41.06250,159.0
41.11250,161.0
41.16250,143.0
41.21250,146.0
41.26250,160.0
41.31250,123.0
41.36250,131.0
41.41250,115.0
41.46250,108.0
41.51250,128.0
41.56250,120.0
41.61250,112.0
41.66250,114.0
41.71250,109.0
41.76250,116.0
41.81250,110.0
41.86250,101.0
41.91250,103.0
41.96250,84.0
42.01250,100.0
42.06250,110.0
42.11250,109.0
42.16250,101.0
42.21250,96.0
42.26250,102.0
42.31250,107.0
42.36250,86.0
42.41250,104.0
42.46250,94.0
42.51250,107.0
42.56250,106.0
42.61250,116.0
42.66250,118.0
42.71250,102.0
42.76250,125.0
42.81250,116.0
42.86250,111.0
42.91250,130.0
42.96250,140.0
43.01250,162.0
43.06250,161.0
43.11250,168.0
43.16250,144.0
43.21250,156.0
43.26250,147.0
43.31250,153.0
43.36250,167.0
43.41250,174.0
43.46250,167.0
43.51250,181.0
43.56250,164.0
43.61250,179.0
43.66250,194.0
43.71250,154.0
43.76250,194.0
43.81250,152.0
43.86250,159.0
43.91250,126.0
43.96250,138.0
44.01250,133.0
44.06250,96.0
44.11250,98.0
44.16250,88.0
44.21250,89.0
44.26250,103.0
44.31250,101.0
44.36250,93.0
44.41250,65.0
44.46250,73.0
44.51250,84.0
44.56250,55.0
44.61250,73.0
44.66250,65.0
44.71250,69.0
44.76250,67.0
44.81250,73.0
44.86250,59.0
44.91250,58.0
44.96250,58.0
45.01250,66.0
45.06250,58.0
45.11250,46.0
45.16250,48.0
45.21250,61.0
45.26250,61.0
45.31250,60.0
45.36250,77.0
45.41250,46.0
45.46250,65.0
45.51250,53.0
45.56250,44.0
45.61250,68.0
45.66250,54.0
45.71250,59.0
45.76250,55.0
45.81250,58.0
45.86250,63.0
45.91250,58.0
45.96250,54.0
46.01250,50.0
46.06250,52.0
46.11250,40.0
46.16250,39.0
46.21250,46.0
46.26250,53.0
46.31250,49.0
46.36250,45.0
46.41250,49.0
46.46250,51.0
46.51250,54.0
46.56250,61.0
46.61250,49.0
46.66250,53.0
46.71250,46.0
46.76250,44.0
46.81250,49.0
46.86250,49.0
46.91250,62.0
46.96250,41.0
47.01250,48.0
47.06250,53.0
47.11250,58.0
47.16250,39.0
47.21250,50.0
47.26250,61.0
47.31250,46.0
47.36250,51.0
47.41250,48.0
47.46250,36.0
47.51250,52.0
47.56250,52.0
47.61250,41.0
47.66250,45.0
47.71250,43.0
47.76250,45.0
47.81250,48.0
47.86250,52.0
47.91250,56.0
47.96250,47.0
48.01250,57.0
48.06250,56.0
48.11250,50.0
48.16250,49.0
48.21250,42.0
48.26250,46.0
48.31250,49.0
48.36250,45.0
48.41250,56.0
48.46250,35.0
48.51250,30.0
48.56250,43.0
48.61250,54.0
48.66250,52.0
48.71250,53.0
48.76250,50.0
48.81250,50.0
48.86250,51.0
48.91250,43.0
48.96250,47.0
49.01250,45.0
49.06250,48.0
49.11250,39.0
49.16250,53.0
49.21250,38.0
49.26250,38.0
49.31250,40.0
49.36250,48.0
49.41250,36.0
49.46250,52.0
49.51250,47.0
49.56250,49.0
49.61250,37.0
49.66250,57.0
49.71250,37.0
49.76250,51.0
49.81250,41.0
49.86250,40.0
49.91250,43.0
49.96250,49.0
50.01250,42.0
50.06250,39.0
50.11250,50.0
50.16250,54.0
50.21250,36.0
50.26250,47.0
50.31250,36.0
50.36250,46.0
50.41250,45.0
50.46250,47.0
50.51250,49.0
50.56250,43.0
50.61250,62.0
50.66250,48.0
50.71250,35.0
50.76250,60.0
50.81250,40.0
50.86250,51.0
50.91250,46.0
50.96250,60.0
51.01250,46.0
51.06250,45.0
51.11250,60.0
51.16250,57.0
51.21250,45.0
51.26250,62.0
51.31250,46.0
51.36250,58.0
51.41250,72.0
51.46250,59.0
51.51250,45.0
51.56250,58.0
51.61250,53.0
51.66250,70.0
51.71250,59.0
51.76250,56.0
51.81250,49.0
51.86250,69.0
51.91250,57.0
51.96250,59.0
52.01250,45.0
52.06250,61.0
52.11250,58.0
52.16250,57.0
52.21250,53.0
52.26250,71.0
52.31250,51.0
52.36250,42.0
52.41250,42.0
52.46250,50.0
52.51250,54.0
52.56250,55.0
52.61250,39.0
52.66250,60.0
52.71250,51.0
52.76250,51.0
52.81250,41.0
52.86250,47.0
52.91250,60.0
52.96250,43.0
53.01250,45.0
53.06250,49.0
53.11250,52.0
53.16250,40.0
53.21250,42.0
53.26250,47.0
53.31250,56.0
53.36250,56.0
53.41250,47.0
53.46250,57.0
53.51250,45.0
53.56250,46.0
53.61250,41.0
53.66250,54.0
53.71250,40.0
53.76250,47.0
53.81250,40.0
53.86250,48.0
53.91250,45.0
53.96250,45.0
54.01250,51.0
54.06250,42.0
54.11250,32.0
54.16250,37.0
54.21250,48.0
54.26250,47.0
54.31250,51.0
54.36250,44.0
54.41250,44.0
54.46250,36.0
54.51250,54.0
54.56250,63.0
54.61250,39.0
54.66250,40.0
54.71250,56.0
54.76250,34.0
54.81250,50.0
54.86250,45.0
54.91250,40.0
54.96250,51.0
55.01250,55.0
55.06250,59.0
55.11250,56.0
55.16250,54.0
55.21250,61.0
55.26250,60.0
55.31250,62.0
55.36250,70.0
55.41250,68.0
55.46250,68.0
55.51250,71.0
55.56250,67.0
55.61250,81.0
55.66250,80.0
55.71250,81.0
55.76250,100.0
55.81250,80.0
55.86250,102.0
55.91250,104.0
55.96250,106.0
56.01250,90.0
56.06250,109.0
56.11250,116.0
56.16250,109.0
56.21250,92.0
56.26250,91.0
56.31250,99.0
56.36250,102.0
56.41250,103.0
56.46250,113.0
56.51250,147.0
56.56250,120.0
56.61250,144.0
56.66250,131.0
56.71250,135.0
56.76250,140.0
56.81250,151.0
56.86250,132.0
56.91250,151.0
56.96250,155.0
57.01250,163.0
57.06250,177.0
57.11250,179.0
57.16250,161.0
57.21250,215.0
57.26250,188.0
57.31250,169.0
57.36250,157.0
57.41250,135.0
57.46250,125.0
57.51250,114.0
57.56250,97.0
57.61250,94.0
57.66250,87.0
57.71250,75.0
57.76250,81.0
57.81250,49.0
57.86250,72.0
57.91250,89.0
57.96250,68.0
58.01250,62.0
58.06250,68.0
58.11250,51.0
58.16250,69.0
58.21250,70.0
58.26250,65.0
58.31250,59.0
58.36250,55.0
58.41250,58.0
58.46250,49.0
58.51250,49.0
58.56250,44.0
58.61250,47.0
58.66250,48.0
58.71250,40.0
58.76250,49.0
58.81250,41.0
58.86250,52.0
58.91250,46.0
58.96250,49.0
59.01250,30.0
59.06250,54.0
59.11250,32.0
59.16250,46.0
59.21250,41.0
59.26250,30.0
59.31250,39.0
59.36250,37.0
59.41250,41.0
59.46250,35.0
59.51250,36.0
59.56250,42.0
59.61250,45.0
59.66250,41.0
59.71250,38.0
59.76250,48.0
59.81250,34.0
59.86250,40.0
59.91250,47.0
59.96250,31.0
60.01250,33.0
60.06250,43.0
60.11250,33.0
60.16250,39.0
60.21250,38.0
60.26250,47.0
60.31250,49.0
60.36250,45.0
60.41250,46.0
60.46250,31.0
60.51250,40.0
60.56250,26.0
60.61250,34.0
60.66250,26.0
60.71250,30.0
60.76250,35.0
60.81250,42.0
60.86250,48.0
60.91250,26.0
60.96250,38.0
61.01250,30.0
61.06250,30.0
61.11250,52.0
61.16250,38.0
61.21250,37.0
61.26250,31.0
61.31250,32.0
61.36250,32.0
61.41250,37.0
61.46250,42.0
61.51250,31.0
61.56250,30.0
61.61250,37.0
61.66250,45.0
61.71250,42.0
61.76250,33.0
61.81250,41.0
61.86250,42.0
61.91250,40.0
61.96250,34.0
62.01250,41.0
62.06250,35.0
62.11250,28.0
62.16250,29.0
62.21250,39.0
62.26250,35.0
62.31250,41.0
62.36250,42.0
62.41250,41.0
62.46250,29.0
62.51250,44.0
62.56250,39.0
62.61250,34.0
62.66250,27.0
62.71250,35.0
62.76250,30.0
62.81250,33.0
62.86250,29.0
62.91250,41.0
62.96250,50.0
63.01250,38.0
63.06250,46.0
63.11250,46.0
63.16250,59.0
63.21250,41.0
63.26250,42.0
63.31250,36.0
63.36250,40.0
63.41250,45.0
63.46250,49.0
63.51250,39.0
63.56250,45.0
63.61250,41.0
63.66250,33.0
63.71250,38.0
63.76250,48.0
63.81250,56.0
63.86250,34.0
63.91250,42.0
63.96250,37.0
64.01250,38.0
64.06250,45.0
64.11250,44.0
64.16250,32.0
64.21250,57.0
64.26250,45.0
64.31250,34.0
64.36250,36.0
64.41250,39.0
64.46250,41.0
64.51250,40.0
64.56250,48.0
64.61250,53.0
64.66250,42.0
64.71250,41.0
64.76250,37.0
64.81250,40.0
64.86250,36.0
64.91250,66.0
64.96250,47.0
65.01250,48.0
65.06250,49.0
65.11250,51.0
65.16250,55.0
65.21250,46.0
65.26250,67.0
65.31250,52.0
65.36250,60.0
65.41250,56.0
65.46250,54.0
65.51250,74.0
65.56250,68.0
65.61250,68.0
65.66250,62.0
65.71250,58.0
65.76250,67.0
65.81250,67.0
65.86250,77.0
65.91250,80.0
65.96250,65.0
66.01250,69.0
66.06250,89.0
66.11250,79.0
66.16250,73.0
66.21250,66.0
66.26250,58.0
66.31250,105.0
66.36250,82.0
66.41250,76.0
66.46250,95.0
66.51250,87.0
66.56250,81.0
66.61250,83.0
66.66250,88.0
66.71250,82.0
66.76250,73.0
66.81250,83.0
66.86250,78.0
66.91250,88.0
66.96250,78.0
67.01250,77.0
67.06250,68.0
67.11250,76.0
67.16250,85.0
67.21250,55.0
67.26250,52.0
67.31250,80.0
67.36250,67.0
67.41250,76.0
67.46250,70.0
67.51250,61.0
67.56250,52.0
67.61250,56.0
67.66250,52.0
67.71250,45.0
67.76250,59.0
67.81250,65.0
67.86250,55.0
67.91250,56.0
67.96250,58.0
68.01250,55.0
68.06250,58.0
68.11250,47.0
68.16250,55.0
68.21250,54.0
68.26250,53.0
68.31250,51.0
68.36250,55.0
68.41250,64.0
68.46250,45.0
68.51250,53.0
68.56250,80.0
68.61250,63.0
68.66250,73.0
68.71250,63.0
68.76250,62.0
68.81250,82.0
68.86250,63.0
68.91250,76.0
68.96250,75.0
69.01250,75.0
69.06250,84.0
69.11250,81.0
69.16250,76.0
69.21250,89.0
69.26250,101.0
69.31250,99.0
69.36250,117.0
69.41250,97.0
69.46250,115.0
69.51250,101.0
69.56250,124.0
69.61250,136.0
69.66250,135.0
69.71250,120.0
69.76250,143.0
69.81250,113.0
69.86250,125.0
69.91250,139.0
69.96250,130.0
70.01250,136.0
70.06250,142.0
70.11250,157.0
70.16250,142.0
70.21250,142.0
70.26250,139.0
70.31250,153.0
70.36250,138.0
70.41250,146.0
70.46250,153.0
70.51250,163.0
70.56250,157.0
70.61250,196.0
70.66250,190.0
70.71250,224.0
70.76250,228.0
70.81250,257.0
70.86250,305.0
70.91250,358.0
70.96250,445.0
71.01250,509.0
71.06250,615.0
71.11250,673.0
71.16250,735.0
71.21250,913.0
71.26250,1096.0
71.31250,1285.0
71.36250,1416.0
71.41250,1483.0
71.46250,1444.0
71.51250,1301.0
71.56250,1129.0
71.61250,979.0
71.66250,834.0
71.71250,648.0
71.76250,455.0
71.81250,346.0
71.86250,267.0
71.91250,201.0
71.96250,158.0
72.01250,127.0
72.06250,144.0
72.11250,141.0
72.16250,107.0
72.21250,124.0
72.26250,88.0
72.31250,109.0
72.36250,84.0
72.41250,104.0
72.46250,95.0
72.51250,86.0
72.56250,91.0
72.61250,74.0
72.66250,72.0
72.71250,78.0
72.76250,78.0
72.81250,61.0
72.86250,81.0
72.91250,61.0
72.96250,52.0
73.01250,59.0
73.06250,62.0
73.11250,64.0
73.16250,55.0
73.21250,54.0
73.26250,54.0
73.31250,68.0
73.36250,51.0
73.41250,61.0
73.46250,52.0
73.51250,44.0
73.56250,56.0
73.61250,49.0
73.66250,60.0
73.71250,66.0
73.76250,44.0
73.81250,60.0
73.86250,44.0
73.91250,45.0
73.96250,56.0
74.01250,46.0
74.06250,47.0
74.11250,48.0
74.16250,53.0
74.21250,41.0
74.26250,36.0
74.31250,51.0
74.36250,48.0
74.41250,46.0
74.46250,39.0
74.51250,36.0
74.56250,47.0
74.61250,53.0
74.66250,41.0
74.71250,44.0
74.76250,46.0
74.81250,55.0
74.86250,60.0
74.91250,51.0
74.96250,48.0
75.01250,52.0
75.06250,47.0
75.11250,50.0
75.16250,55.0
75.21250,53.0
75.26250,60.0
75.31250,56.0
75.36250,59.0
75.41250,61.0
75.46250,68.0
75.51250,48.0
75.56250,60.0
75.61250,57.0
75.66250,56.0
75.71250,50.0
75.76250,55.0
75.81250,52.0
75.86250,58.0
75.91250,48.0
75.96250,49.0
76.01250,53.0
76.06250,43.0
76.11250,46.0
76.16250,47.0
76.21250,35.0
76.26250,39.0
76.31250,36.0
76.36250,42.0
76.41250,41.0
76.46250,41.0
76.51250,42.0
76.56250,34.0
76.61250,45.0
76.66250,45.0
76.71250,45.0
76.76250,39.0
76.81250,34.0
76.86250,43.0
76.91250,43.0
76.96250,43.0
77.01250,51.0
77.06250,50.0
77.11250,45.0
77.16250,39.0
77.21250,42.0
77.26250,56.0
77.31250,38.0
77.36250,39.0
77.41250,41.0
77.46250,34.0
77.51250,42.0
77.56250,28.0
77.61250,46.0
77.66250,46.0
77.71250,44.0
77.76250,46.0
77.81250,40.0
77.86250,43.0
77.91250,43.0
77.96250,47.0
78.01250,52.0
78.06250,54.0
78.11250,39.0
78.16250,53.0
78.21250,41.0
78.26250,59.0
78.31250,53.0
78.36250,46.0
78.41250,56.0
78.46250,62.0
78.51250,67.0
78.56250,46.0
78.61250,41.0
78.66250,48.0
78.71250,58.0
78.76250,58.0
78.81250,58.0
78.86250,71.0
78.91250,54.0
78.96250,68.0
79.01250,65.0
79.06250,77.0
79.11250,67.0
79.16250,70.0
79.21250,64.0
79.26250,77.0
79.31250,84.0
79.36250,81.0
79.41250,80.0
79.46250,80.0
79.51250,84.0
79.56250,85.0
79.61250,92.0
79.66250,96.0
79.71250,87.0
79.76250,91.0
79.81250,117.0
79.86250,115.0
79.91250,101.0
79.96250,94.0
79.98750,94.0