File: code/data/data_source2/TiNb_KL388A_Ti40Nb_1_Bragg.csv
[Measurement conditions]
Sample identification,
Comment - 1,"Configuration=Filmes Finos 19_1_2015, Owner=User-1, Creation date=19/01/2015 21:17:15"
Comment - 2,"Goniometer=PW3050/60 (Theta/Theta); Minimum step size 2Theta:0.001; Minimum step size Omega:0.001"
Comment - 3,"Sample stage=PW3071/xx Bracket"
Comment - 4,"Diffractometer system=XPERT-PRO"
Comment - 5,"Measurement program=C:\PANalytical\Data Collector\Programs\BraggBrentano.xrdmp, Identifier={1069A1B4-F515-4840-9AC8-848F644ED6C5}"
Anode material,Cu
K-Alpha1 wavelength,1.5405980
K-Alpha2 wavelength,1.5444260
Ratio K-Alpha2/K-Alpha1,0.500
Divergence slit,Fixed,0.76mm
Receiving slit,0.10
Monochromator used,YES
Generator voltage, 40
Tube current, 40
File date and time,13/Jun/2018 15:32
Unit cell,
h k l, 0 0 0
Scan axis,Gonio
Scan range,20.00000,80.00000
Scan step size,0.0120000
No. of points, 5000
Scan type,CONTINUOUS
Time per step,1.50
[Scan points]
Angle,Intensity
20.00600,33.0
20.05400,32.0
20.10200,43.0
20.15000,36.0
20.19800,28.0
20.24600,22.0
20.29400,35.0
20.34200,31.0
20.39000,23.0
20.43800,32.0
20.48600,22.0
20.53400,25.0
20.58200,22.0
20.63000,28.0
20.67800,28.0
20.72600,30.0
20.77400,28.0
20.82200,33.0
20.87000,29.0
20.91800,33.0
20.96600,23.0
21.01400,19.0
21.06200,41.0
21.11000,27.0
21.15800,32.0
21.20600,26.0
21.25400,29.0
21.30200,32.0
21.35000,34.0
21.39800,32.0
21.44600,22.0
21.49400,29.0
21.54200,24.0
21.59000,28.0
21.63800,33.0
21.68600,28.0
21.73400,38.0
21.78200,29.0
21.83000,33.0
21.87800,26.0
21.92600,25.0
21.97400,28.0
22.02200,13.0
22.07000,21.0
22.11800,33.0
22.16600,17.0
22.21400,25.0
22.26200,37.0
22.31000,29.0
22.35800,25.0
22.40600,33.0
22.45400,24.0
22.50200,35.0
22.55000,25.0
22.59800,24.0
22.64600,31.0
22.69400,18.0
22.74200,25.0
22.79000,32.0
22.83800,30.0
22.88600,17.0
22.93400,22.0
22.98200,22.0
23.03000,21.0
23.07800,29.0
23.12600,26.0
23.17400,26.0
23.22200,31.0
23.27000,30.0
23.31800,31.0
23.36600,38.0
23.41400,16.0
23.46200,33.0
23.51000,27.0
23.55800,32.0
23.60600,25.0
23.65400,26.0
23.70200,28.0
23.75000,31.0
23.79800,17.0
23.84600,25.0
23.89400,27.0
23.94200,18.0
23.99000,20.0
24.03800,20.0
24.08600,26.0
24.13400,31.0
24.18200,22.0
24.23000,17.0
24.27800,21.0
24.32600,29.0
24.37400,22.0
24.42200,17.0
24.47000,24.0
24.51800,25.0
24.56600,27.0
24.61400,20.0
24.66200,32.0
24.71000,20.0
24.75800,19.0
24.80600,35.0
24.85400,23.0
24.90200,21.0
24.95000,16.0
24.99800,18.0
25.04600,19.0
25.09400,25.0
25.14200,28.0
25.19000,24.0
25.23800,22.0
25.28600,20.0
25.33400,30.0
25.38200,21.0
25.43000,25.0
25.47800,32.0
25.52600,25.0
25.57400,16.0
25.62200,33.0
25.67000,27.0
25.71800,24.0
25.76600,20.0
25.81400,23.0
25.86200,24.0
25.91000,21.0
25.95800,24.0
26.00600,30.0
26.05400,22.0
26.10200,31.0
26.15000,21.0
26.19800,22.0
26.24600,29.0
26.29400,20.0
26.34200,24.0
26.39000,27.0
26.43800,22.0
26.48600,29.0
26.53400,31.0
26.58200,29.0
26.63000,25.0
26.67800,21.0
26.72600,22.0
26.77400,25.0
26.82200,24.0
26.87000,25.0
26.91800,22.0
26.96600,30.0
27.01400,26.0
27.06200,23.0
27.11000,19.0
27.15800,32.0
27.20600,21.0
27.25400,23.0
27.30200,17.0
27.35000,24.0
27.39800,23.0
27.44600,29.0
27.49400,22.0
27.54200,27.0
27.59000,22.0
27.63800,20.0
27.68600,20.0
27.73400,23.0
27.78200,18.0
27.83000,18.0
27.87800,25.0
27.92600,28.0
27.97400,21.0
28.02200,15.0
28.07000,16.0
28.11800,21.0
28.16600,26.0
28.21400,27.0
28.26200,22.0
28.31000,26.0
28.35800,16.0
28.40600,22.0
28.45400,21.0
28.50200,21.0
28.55000,20.0
28.59800,14.0
28.64600,20.0
28.69400,17.0
28.74200,21.0
28.79000,31.0
28.83800,21.0
28.88600,30.0
28.93400,20.0
28.98200,27.0
29.03000,15.0
29.07800,22.0
29.12600,27.0
29.17400,21.0
29.22200,22.0
29.27000,31.0
29.31800,20.0
29.36600,24.0
29.41400,33.0
29.46200,30.0
29.51000,28.0
29.55800,21.0
29.60600,25.0
29.65400,27.0
29.70200,34.0
29.75000,26.0
29.79800,35.0
29.84600,18.0
29.89400,20.0
29.94200,22.0
29.99000,32.0
30.03800,16.0
30.08600,26.0
30.13400,27.0
30.18200,30.0
30.23000,23.0
30.27800,16.0
30.32600,19.0
30.37400,22.0
30.42200,22.0
30.47000,25.0
30.51800,22.0
30.56600,22.0
30.61400,28.0
30.66200,21.0
30.71000,25.0
30.75800,22.0
30.80600,32.0
30.85400,31.0
30.90200,22.0
30.95000,27.0
30.99800,23.0
31.04600,26.0
31.09400,32.0
31.14200,39.0
31.19000,22.0
31.23800,34.0
31.28600,51.0
31.33400,34.0
31.38200,41.0
31.43000,55.0
31.47800,50.0
31.52600,27.0
31.57400,48.0
31.62200,24.0
31.67000,30.0
31.71800,27.0
31.76600,29.0
31.81400,26.0
31.86200,27.0
31.91000,29.0
31.95800,27.0
32.00600,29.0
32.05400,30.0
32.10200,25.0
32.15000,26.0
32.19800,18.0
32.24600,25.0
32.29400,30.0
32.34200,27.0
32.39000,15.0
32.43800,19.0
32.48600,18.0
32.53400,25.0
32.58200,26.0
32.63000,30.0
32.67800,20.0
32.72600,16.0
32.77400,31.0
32.82200,24.0
32.87000,24.0
32.91800,28.0
32.96600,17.0
33.01400,30.0
33.06200,24.0
33.11000,29.0
33.15800,30.0
33.20600,23.0
33.25400,28.0
33.30200,28.0
33.35000,33.0
33.39800,31.0
33.44600,35.0
33.49400,15.0
33.54200,28.0
33.59000,28.0
33.63800,26.0
33.68600,26.0
33.73400,25.0
33.78200,28.0
33.83000,24.0
33.87800,25.0
33.92600,27.0
33.97400,37.0
34.02200,25.0
34.07000,33.0
34.11800,22.0
34.16600,24.0
34.21400,25.0
34.26200,25.0
34.31000,17.0
34.35800,24.0
34.40600,23.0
34.45400,25.0
34.50200,36.0
34.55000,22.0
34.59800,26.0
34.64600,36.0
34.69400,28.0
34.74200,32.0
34.79000,23.0
34.83800,29.0
34.88600,27.0
34.93400,31.0
34.98200,30.0
35.03000,32.0
35.07800,24.0
35.12600,19.0
35.17400,35.0
35.22200,42.0
35.27000,32.0
35.31800,43.0
35.36600,32.0
35.41400,21.0
35.46200,37.0
35.51000,25.0
35.55800,29.0
35.60600,42.0
35.65400,39.0
35.70200,24.0
35.75000,46.0
35.79800,35.0
35.84600,45.0
35.89400,34.0
35.94200,32.0
35.99000,53.0
36.03800,53.0
36.08600,40.0
36.13400,51.0
36.18200,51.0
36.23000,51.0
36.27800,55.0
36.32600,67.0
36.37400,50.0
36.42200,48.0
36.47000,85.0
36.51800,66.0
36.56600,73.0
36.61400,77.0
36.66200,100.0
36.71000,102.0
36.75800,118.0
36.80600,90.0
36.85400,143.0
36.90200,134.0
36.95000,136.0
36.99800,151.0
37.04600,167.0
37.09400,185.0
37.14200,184.0
37.19000,201.0
37.23800,189.0
37.28600,192.0
37.33400,178.0
37.38200,192.0
37.43000,152.0
37.47800,150.0
37.52600,157.0
37.57400,148.0
37.62200,135.0
37.67000,160.0
37.71800,137.0
37.76600,146.0
37.81400,159.0
37.86200,149.0
37.91000,150.0
37.95800,168.0
38.00600,182.0
38.05400,236.0
38.10200,213.0
38.15000,259.0
38.19800,310.0
38.24600,359.0
38.29400,426.0
38.34200,529.0
38.39000,681.0
38.43800,972.0
38.48600,1311.0
38.53400,1898.0
38.58200,2563.0
38.63000,3358.0
38.67800,3842.0
38.72600,3681.0
38.77400,3439.0
38.82200,2699.0
38.87000,1950.0
38.91800,1260.0
38.96600,818.0
39.01400,428.0
39.06200,290.0
39.11000,241.0
39.15800,200.0
39.20600,160.0
39.25400,134.0
39.30200,133.0
39.35000,130.0
39.39800,107.0
39.44600,101.0
39.49400,103.0
39.54200,89.0
39.59000,85.0
39.63800,80.0
39.68600,56.0
39.73400,74.0
39.78200,61.0
39.83000,66.0
39.87800,68.0
39.92600,58.0
39.97400,41.0
40.02200,42.0
40.07000,44.0
40.11800,39.0
40.16600,52.0
40.21400,51.0
40.26200,60.0
40.31000,49.0
40.35800,52.0
40.40600,48.0
40.45400,42.0
40.50200,46.0
40.55000,43.0
40.59800,45.0
40.64600,53.0
40.69400,49.0
40.74200,51.0
40.79000,39.0
40.83800,40.0
40.88600,49.0
40.93400,42.0
40.98200,48.0
41.03000,60.0
41.07800,45.0
41.12600,38.0
41.17400,44.0
41.22200,66.0
41.27000,60.0
41.31800,55.0
41.36600,42.0
41.41400,51.0
41.46200,52.0
41.51000,50.0
41.55800,55.0
41.60600,62.0
41.65400,49.0
41.70200,55.0
41.75000,46.0
41.79800,60.0
41.84600,52.0
41.89400,57.0
41.94200,40.0
41.99000,48.0
42.03800,43.0
42.08600,53.0
42.13400,50.0
42.18200,49.0
42.23000,51.0
42.27800,46.0
42.32600,50.0
42.37400,36.0
42.42200,40.0
42.47000,39.0
42.51800,52.0
42.56600,43.0
42.61400,54.0
42.66200,59.0
42.71000,64.0
42.75800,50.0
42.80600,44.0
42.85400,77.0
42.90200,45.0
42.95000,51.0
42.99800,32.0
43.04600,36.0
43.09400,36.0
43.14200,47.0
43.19000,37.0
43.23800,32.0
43.28600,31.0
43.33400,42.0
43.38200,27.0
43.43000,43.0
43.47800,26.0
43.52600,35.0
43.57400,39.0
43.62200,25.0
43.67000,32.0
43.71800,29.0
43.76600,38.0
43.81400,32.0
43.86200,27.0
43.91000,37.0
43.95800,29.0
44.00600,26.0
44.05400,34.0
44.10200,27.0
44.15000,41.0
44.19800,34.0
44.24600,37.0
44.29400,32.0
44.34200,24.0
44.39000,17.0
44.43800,27.0
44.48600,33.0
44.53400,27.0
44.58200,32.0
44.63000,20.0
44.67800,26.0
44.72600,27.0
44.77400,29.0
44.82200,22.0
44.87000,29.0
44.91800,26.0
44.96600,29.0
45.01400,29.0
45.06200,28.0
45.11000,19.0
45.15800,21.0
45.20600,24.0
45.25400,28.0
45.30200,28.0
45.35000,30.0
45.39800,27.0
45.44600,21.0
45.49400,26.0
45.54200,23.0
45.59000,29.0
45.63800,21.0
45.68600,30.0
45.73400,31.0
45.78200,18.0
45.83000,25.0
45.87800,19.0
45.92600,30.0
45.97400,24.0
46.02200,35.0
46.07000,21.0
46.11800,29.0
46.16600,24.0
46.21400,25.0
46.26200,25.0
46.31000,31.0
46.35800,28.0
46.40600,25.0
46.45400,24.0
46.50200,27.0
46.55000,15.0
46.59800,28.0
46.64600,25.0
46.69400,25.0
46.74200,21.0
46.79000,32.0
46.83800,30.0
46.88600,32.0
46.93400,32.0
46.98200,18.0
47.03000,31.0
47.07800,36.0
47.12600,24.0
47.17400,24.0
47.22200,24.0
47.27000,25.0
47.31800,31.0
47.36600,22.0
47.41400,28.0
47.46200,31.0
47.51000,20.0
47.55800,24.0
47.60600,20.0
47.65400,13.0
47.70200,26.0
47.75000,28.0
47.79800,30.0
47.84600,23.0
47.89400,25.0
47.94200,29.0
47.99000,27.0
48.03800,26.0
48.08600,25.0
48.13400,19.0
48.18200,25.0
48.23000,20.0
48.27800,28.0
48.32600,27.0
48.37400,28.0
48.42200,30.0
48.47000,22.0
48.51800,25.0
48.56600,24.0
48.61400,17.0
48.66200,21.0
48.71000,21.0
48.75800,22.0
48.80600,33.0
48.85400,20.0
48.90200,27.0
48.95000,29.0
48.99800,23.0
49.04600,29.0
49.09400,27.0
49.14200,21.0
49.19000,24.0
49.23800,17.0
49.28600,29.0
49.33400,22.0
49.38200,20.0
49.43000,23.0
49.47800,23.0
49.52600,23.0
49.57400,24.0
49.62200,37.0
49.67000,26.0
49.71800,26.0
49.76600,41.0
49.81400,25.0
49.86200,35.0
49.91000,34.0
49.95800,31.0
50.00600,31.0
50.05400,27.0
50.10200,30.0
50.15000,35.0
50.19800,36.0
50.24600,29.0
50.29400,36.0
50.34200,35.0
50.39000,38.0
50.43800,39.0
50.48600,41.0
50.53400,48.0
50.58200,44.0
50.63000,46.0
50.67800,39.0
50.72600,52.0
50.77400,32.0
50.82200,38.0
50.87000,41.0
50.91800,45.0
50.96600,49.0
51.01400,36.0
51.06200,25.0
51.11000,32.0
51.15800,51.0
51.20600,38.0
51.25400,27.0
51.30200,32.0
51.35000,39.0
51.39800,36.0
51.44600,27.0
51.49400,36.0
51.54200,28.0
51.59000,34.0
51.63800,22.0
51.68600,23.0
51.73400,31.0
51.78200,27.0
51.83000,13.0
51.87800,28.0
51.92600,18.0
51.97400,34.0
52.02200,19.0
52.07000,28.0
52.11800,19.0
52.16600,27.0
52.21400,20.0
52.26200,24.0
52.31000,24.0
52.35800,24.0
52.40600,29.0
52.45400,23.0
52.50200,22.0
52.55000,22.0
52.59800,20.0
52.64600,23.0
52.69400,21.0
52.74200,21.0
52.79000,23.0
52.83800,19.0
52.88600,24.0
52.93400,19.0
52.98200,21.0
53.03000,33.0
53.07800,33.0
53.12600,22.0
53.17400,30.0
53.22200,30.0
53.27000,24.0
53.31800,22.0
53.36600,24.0
53.41400,31.0
53.46200,26.0
53.51000,29.0
53.55800,26.0
53.60600,18.0
53.65400,21.0
53.70200,32.0
53.75000,23.0
53.79800,32.0
53.84600,31.0
53.89400,41.0
53.94200,24.0
53.99000,31.0
54.03800,32.0
54.08600,35.0
54.13400,40.0
54.18200,37.0
54.23000,33.0
54.27800,35.0
54.32600,35.0
54.37400,42.0
54.42200,32.0
54.47000,34.0
54.51800,34.0
54.56600,42.0
54.61400,47.0
54.66200,35.0
54.71000,41.0
54.75800,46.0
54.80600,37.0
54.85400,42.0
54.90200,42.0
54.95000,46.0
54.99800,52.0
55.04600,53.0
55.09400,60.0
55.14200,62.0
55.19000,52.0
55.23800,63.0
55.28600,62.0
55.33400,61.0
55.38200,74.0
55.43000,77.0
55.47800,63.0
55.52600,102.0
55.57400,109.0
55.62200,86.0
55.67000,140.0
55.71800,148.0
55.76600,213.0
55.81400,283.0
55.86200,338.0
55.91000,491.0
55.95800,568.0
56.00600,458.0
56.05400,430.0
56.10200,388.0
56.15000,260.0
56.19800,155.0
56.24600,125.0
56.29400,114.0
56.34200,58.0
56.39000,48.0
56.43800,58.0
56.48600,37.0
56.53400,45.0
56.58200,28.0
56.63000,34.0
56.67800,31.0
56.72600,49.0
56.77400,29.0
56.82200,27.0
56.87000,24.0
56.91800,28.0
56.96600,35.0
57.01400,40.0
57.06200,25.0
57.11000,20.0
57.15800,38.0
57.20600,36.0
57.25400,20.0
57.30200,24.0
57.35000,26.0
57.39800,21.0
57.44600,18.0
57.49400,27.0
57.54200,19.0
57.59000,17.0
57.63800,25.0
57.68600,27.0
57.73400,13.0
57.78200,17.0
57.83000,20.0
57.87800,16.0
57.92600,25.0
57.97400,21.0
58.02200,14.0
58.07000,21.0
58.11800,15.0
58.16600,30.0
58.21400,20.0
58.26200,16.0
58.31000,18.0
58.35800,19.0
58.40600,15.0
58.45400,13.0
58.50200,20.0
58.55000,22.0
58.59800,23.0
58.64600,20.0
58.69400,23.0
58.74200,20.0
58.79000,20.0
58.83800,14.0
58.88600,20.0
58.93400,21.0
58.98200,17.0
59.03000,19.0
59.07800,18.0
59.12600,16.0
59.17400,23.0
59.22200,37.0
59.27000,20.0
59.31800,16.0
59.36600,20.0
59.41400,16.0
59.46200,23.0
59.51000,16.0
59.55800,19.0
59.60600,15.0
59.65400,17.0
59.70200,24.0
59.75000,23.0
59.79800,17.0
59.84600,20.0
59.89400,15.0
59.94200,26.0
59.99000,15.0
60.03800,12.0
60.08600,18.0
60.13400,19.0
60.18200,16.0
60.23000,14.0
60.27800,18.0
60.32600,21.0
60.37400,15.0
60.42200,22.0
60.47000,16.0
60.51800,12.0
60.56600,17.0
60.61400,17.0
60.66200,14.0
60.71000,13.0
60.75800,16.0
60.80600,20.0
60.85400,20.0
60.90200,17.0
60.95000,14.0
60.99800,15.0
61.04600,17.0
61.09400,14.0
61.14200,20.0
61.19000,23.0
61.23800,18.0
61.28600,21.0
61.33400,12.0
61.38200,19.0
61.43000,16.0
61.47800,19.0
61.52600,21.0
61.57400,19.0
61.62200,27.0
61.67000,18.0
61.71800,38.0
61.76600,32.0
61.81400,27.0
61.86200,32.0
61.91000,41.0
61.95800,36.0
62.00600,24.0
62.05400,40.0
62.10200,29.0
62.15000,26.0
62.19800,24.0
62.24600,25.0
62.29400,18.0
62.34200,22.0
62.39000,29.0
62.43800,28.0
62.48600,29.0
62.53400,24.0
62.58200,14.0
62.63000,30.0
62.67800,20.0
62.72600,16.0
62.77400,18.0
62.82200,22.0
62.87000,15.0
62.91800,23.0
62.96600,20.0
63.01400,24.0
63.06200,20.0
63.11000,12.0
63.15800,24.0
63.20600,22.0
63.25400,15.0
63.30200,13.0
63.35000,21.0
63.39800,19.0
63.44600,24.0
63.49400,21.0
63.54200,24.0
63.59000,24.0
63.63800,26.0
63.68600,16.0
63.73400,14.0
63.78200,14.0
63.83000,28.0
63.87800,24.0
63.92600,25.0
63.97400,27.0
64.02200,22.0
64.07000,18.0
64.11800,17.0
64.16600,19.0
64.21400,28.0
64.26200,28.0
64.31000,15.0
64.35800,26.0
64.40600,34.0
64.45400,20.0
64.50200,17.0
64.55000,29.0
64.59800,22.0
64.64600,21.0
64.69400,17.0
64.74200,19.0
64.79000,36.0
64.83800,23.0
64.88600,16.0
64.93400,28.0
64.98200,20.0
65.03000,26.0
65.07800,25.0
65.12600,33.0
65.17400,25.0
65.22200,26.0
65.27000,22.0
65.31800,27.0
65.36600,23.0
65.41400,31.0
65.46200,28.0
65.51000,36.0
65.55800,27.0
65.60600,20.0
65.65400,45.0
65.70200,27.0
65.75000,36.0
65.79800,35.0
65.84600,32.0
65.89400,42.0
65.94200,43.0
65.99000,35.0
66.03800,31.0
66.08600,27.0
66.13400,23.0
66.18200,23.0
66.23000,22.0
66.27800,18.0
66.32600,29.0
66.37400,26.0
66.42200,28.0
66.47000,20.0
66.51800,23.0
66.56600,25.0
66.61400,24.0
66.66200,21.0
66.71000,20.0
66.75800,19.0
66.80600,19.0
66.85400,25.0
66.90200,29.0
66.95000,27.0
66.99800,20.0
67.04600,29.0
67.09400,26.0
67.14200,19.0
67.19000,33.0
67.23800,25.0
67.28600,29.0
67.33400,30.0
67.38200,35.0
67.43000,24.0
67.47800,33.0
67.52600,20.0
67.57400,33.0
67.62200,25.0
67.67000,37.0
67.71800,43.0
67.76600,28.0
67.81400,28.0
67.86200,36.0
67.91000,44.0
67.95800,33.0
68.00600,47.0
68.05400,31.0
68.10200,42.0
68.15000,43.0
68.19800,52.0
68.24600,41.0
68.29400,37.0
68.34200,43.0
68.39000,39.0
68.43800,44.0
68.48600,51.0
68.53400,43.0
68.58200,52.0
68.63000,44.0
68.67800,51.0
68.72600,65.0
68.77400,55.0
68.82200,57.0
68.87000,63.0
68.91800,61.0
68.96600,61.0
69.01400,76.0
69.06200,86.0
69.11000,78.0
69.15800,54.0
69.20600,98.0
69.25400,123.0
69.30200,91.0
69.35000,122.0
69.39800,123.0
69.44600,103.0
69.49400,114.0
69.54200,130.0
69.59000,163.0
69.63800,174.0
69.68600,193.0
69.73400,203.0
69.78200,237.0
69.83000,270.0
69.87800,326.0
69.92600,375.0
69.97400,539.0
70.02200,683.0
70.07000,811.0
70.11800,1003.0
70.16600,1036.0
70.21400,929.0
70.26200,754.0
70.31000,618.0
70.35800,601.0
70.40600,472.0
70.45400,332.0
70.50200,260.0
70.55000,171.0
70.59800,130.0
70.64600,118.0
70.69400,78.0
70.74200,88.0
70.79000,73.0
70.83800,67.0
70.88600,61.0
70.93400,62.0
70.98200,63.0
71.03000,38.0
71.07800,48.0
71.12600,53.0
71.17400,60.0
71.22200,49.0
71.27000,45.0
71.31800,38.0
71.36600,42.0
71.41400,43.0
71.46200,32.0
71.51000,26.0
71.55800,28.0
71.60600,24.0
71.65400,36.0
71.70200,30.0
71.75000,39.0
71.79800,34.0
71.84600,20.0
71.89400,32.0
71.94200,25.0
71.99000,19.0
72.03800,27.0
72.08600,26.0
72.13400,25.0
72.18200,18.0
72.23000,22.0
72.27800,22.0
72.32600,17.0
72.37400,18.0
72.42200,16.0
72.47000,21.0
72.51800,37.0
72.56600,23.0
72.61400,22.0
72.66200,26.0
72.71000,24.0
72.75800,17.0
72.80600,18.0
72.85400,24.0
72.90200,25.0
72.95000,18.0
72.99800,13.0
73.04600,24.0
73.09400,24.0
73.14200,17.0
73.19000,20.0
73.23800,25.0
73.28600,30.0
73.33400,21.0
73.38200,31.0
73.43000,15.0
73.47800,23.0
73.52600,17.0
73.57400,20.0
73.62200,27.0
73.67000,19.0
73.71800,21.0
73.76600,20.0
73.81400,25.0
73.86200,16.0
73.91000,34.0
73.95800,34.0
74.00600,30.0
74.05400,17.0
74.10200,20.0
74.15000,23.0
74.19800,22.0
74.24600,26.0
74.29400,30.0
74.34200,25.0
74.39000,18.0
74.43800,18.0
74.48600,24.0
74.53400,23.0
74.58200,30.0
74.63000,22.0
74.67800,24.0
74.72600,28.0
74.77400,21.0
74.82200,27.0
74.87000,24.0
74.91800,24.0
74.96600,19.0
75.01400,21.0
75.06200,22.0
75.11000,24.0
75.15800,27.0
75.20600,29.0
75.25400,17.0
75.30200,21.0
75.35000,15.0
75.39800,21.0
75.44600,21.0
75.49400,16.0
75.54200,16.0
75.59000,20.0
75.63800,14.0
75.68600,20.0
75.73400,16.0
75.78200,21.0
75.83000,10.0
75.87800,21.0
75.92600,23.0
75.97400,19.0
76.02200,26.0
76.07000,14.0
76.11800,29.0
76.16600,22.0
76.21400,18.0
76.26200,18.0
76.31000,17.0
76.35800,13.0
76.40600,20.0
76.45400,24.0
76.50200,22.0
76.55000,18.0
76.59800,31.0
76.64600,20.0
76.69400,26.0
76.74200,27.0
76.79000,21.0
76.83800,27.0
76.88600,26.0
76.93400,24.0
76.98200,22.0
77.03000,25.0
77.07800,26.0
77.12600,28.0
77.17400,19.0
77.22200,26.0
77.27000,19.0
77.31800,25.0
77.36600,25.0
77.41400,22.0
77.46200,32.0
77.51000,27.0
77.55800,25.0
77.60600,21.0
77.65400,27.0
77.70200,24.0
77.75000,28.0
77.79800,25.0
77.84600,30.0
77.89400,30.0
77.94200,29.0
77.99000,26.0
78.03800,22.0
78.08600,35.0
78.13400,30.0
78.18200,32.0
78.23000,29.0
78.27800,40.0
78.32600,53.0
78.37400,47.0
78.42200,35.0
78.47000,43.0
78.51800,38.0
78.56600,44.0
78.61400,40.0
78.66200,42.0
78.71000,60.0
78.75800,58.0
78.80600,48.0
78.85400,70.0
78.90200,52.0
78.95000,51.0
78.99800,53.0
79.04600,54.0
79.09400,56.0
79.14200,80.0
79.19000,50.0
79.23800,44.0
79.28600,56.0
79.33400,44.0
79.38200,53.0
79.43000,48.0
79.47800,40.0
79.52600,42.0
79.57400,42.0
79.62200,33.0
79.67000,33.0
79.71800,38.0
79.76600,39.0
79.81400,28.0
79.86200,26.0
79.91000,35.0
79.95800,25.0
79.99400,27.0