File: code/data/data_source2/TiNb_KL387A_Ti15Nb_1_Bragg.csv
[Measurement conditions]
Sample identification,
Comment - 1,"Configuration=Filmes Finos 19_1_2015, Owner=User-1, Creation date=19/01/2015 21:17:15"
Comment - 2,"Goniometer=PW3050/60 (Theta/Theta); Minimum step size 2Theta:0.001; Minimum step size Omega:0.001"
Comment - 3,"Sample stage=PW3071/xx Bracket"
Comment - 4,"Diffractometer system=XPERT-PRO"
Comment - 5,"Measurement program=C:\PANalytical\Data Collector\Programs\BraggBrentano.xrdmp, Identifier={1069A1B4-F515-4840-9AC8-848F644ED6C5}"
Anode material,Cu
K-Alpha1 wavelength,1.5405980
K-Alpha2 wavelength,1.5444260
Ratio K-Alpha2/K-Alpha1,0.500
Divergence slit,Fixed,0.76mm
Receiving slit,0.10
Monochromator used,YES
Generator voltage, 40
Tube current, 40
File date and time,14/Jun/2018 12:44
Unit cell,
h k l, 0 0 0
Scan axis,Gonio
Scan range,20.00000,80.00000
Scan step size,0.0120000
No. of points, 5000
Scan type,CONTINUOUS
Time per step,1.50
[Scan points]
Angle,Intensity
20.00600,27.0
20.05400,27.0
20.10200,16.0
20.15000,27.0
20.19800,26.0
20.24600,25.0
20.29400,28.0
20.34200,24.0
20.39000,25.0
20.43800,25.0
20.48600,20.0
20.53400,21.0
20.58200,25.0
20.63000,36.0
20.67800,23.0
20.72600,25.0
20.77400,28.0
20.82200,30.0
20.87000,22.0
20.91800,31.0
20.96600,33.0
21.01400,24.0
21.06200,26.0
21.11000,24.0
21.15800,17.0
21.20600,25.0
21.25400,20.0
21.30200,25.0
21.35000,16.0
21.39800,23.0
21.44600,28.0
21.49400,20.0
21.54200,18.0
21.59000,15.0
21.63800,21.0
21.68600,21.0
21.73400,24.0
21.78200,15.0
21.83000,25.0
21.87800,19.0
21.92600,26.0
21.97400,21.0
22.02200,21.0
22.07000,23.0
22.11800,17.0
22.16600,17.0
22.21400,26.0
22.26200,20.0
22.31000,31.0
22.35800,16.0
22.40600,29.0
22.45400,25.0
22.50200,29.0
22.55000,21.0
22.59800,17.0
22.64600,12.0
22.69400,18.0
22.74200,14.0
22.79000,25.0
22.83800,22.0
22.88600,23.0
22.93400,19.0
22.98200,19.0
23.03000,20.0
23.07800,20.0
23.12600,15.0
23.17400,16.0
23.22200,24.0
23.27000,17.0
23.31800,23.0
23.36600,24.0
23.41400,19.0
23.46200,25.0
23.51000,20.0
23.55800,24.0
23.60600,23.0
23.65400,18.0
23.70200,22.0
23.75000,32.0
23.79800,17.0
23.84600,21.0
23.89400,12.0
23.94200,30.0
23.99000,16.0
24.03800,29.0
24.08600,15.0
24.13400,20.0
24.18200,24.0
24.23000,21.0
24.27800,22.0
24.32600,31.0
24.37400,19.0
24.42200,26.0
24.47000,21.0
24.51800,18.0
24.56600,19.0
24.61400,26.0
24.66200,28.0
24.71000,16.0
24.75800,26.0
24.80600,26.0
24.85400,24.0
24.90200,20.0
24.95000,27.0
24.99800,13.0
25.04600,17.0
25.09400,30.0
25.14200,21.0
25.19000,30.0
25.23800,25.0
25.28600,26.0
25.33400,21.0
25.38200,20.0
25.43000,26.0
25.47800,23.0
25.52600,24.0
25.57400,22.0
25.62200,14.0
25.67000,19.0
25.71800,21.0
25.76600,25.0
25.81400,21.0
25.86200,20.0
25.91000,21.0
25.95800,23.0
26.00600,21.0
26.05400,19.0
26.10200,15.0
26.15000,15.0
26.19800,11.0
26.24600,23.0
26.29400,18.0
26.34200,23.0
26.39000,21.0
26.43800,19.0
26.48600,21.0
26.53400,22.0
26.58200,20.0
26.63000,22.0
26.67800,16.0
26.72600,18.0
26.77400,16.0
26.82200,15.0
26.87000,18.0
26.91800,14.0
26.96600,20.0
27.01400,13.0
27.06200,18.0
27.11000,19.0
27.15800,15.0
27.20600,24.0
27.25400,27.0
27.30200,19.0
27.35000,19.0
27.39800,13.0
27.44600,22.0
27.49400,18.0
27.54200,16.0
27.59000,16.0
27.63800,14.0
27.68600,16.0
27.73400,18.0
27.78200,16.0
27.83000,11.0
27.87800,17.0
27.92600,20.0
27.97400,18.0
28.02200,17.0
28.07000,17.0
28.11800,11.0
28.16600,15.0
28.21400,15.0
28.26200,21.0
28.31000,14.0
28.35800,14.0
28.40600,26.0
28.45400,21.0
28.50200,19.0
28.55000,20.0
28.59800,21.0
28.64600,24.0
28.69400,22.0
28.74200,17.0
28.79000,21.0
28.83800,22.0
28.88600,15.0
28.93400,16.0
28.98200,16.0
29.03000,16.0
29.07800,16.0
29.12600,16.0
29.17400,19.0
29.22200,14.0
29.27000,18.0
29.31800,17.0
29.36600,10.0
29.41400,23.0
29.46200,21.0
29.51000,16.0
29.55800,23.0
29.60600,13.0
29.65400,18.0
29.70200,16.0
29.75000,13.0
29.79800,27.0
29.84600,21.0
29.89400,19.0
29.94200,20.0
29.99000,8.0
30.03800,19.0
30.08600,22.0
30.13400,14.0
30.18200,23.0
30.23000,24.0
30.27800,21.0
30.32600,16.0
30.37400,15.0
30.42200,12.0
30.47000,9.0
30.51800,24.0
30.56600,20.0
30.61400,17.0
30.66200,14.0
30.71000,15.0
30.75800,21.0
30.80600,20.0
30.85400,20.0
30.90200,12.0
30.95000,20.0
30.99800,21.0
31.04600,18.0
31.09400,16.0
31.14200,23.0
31.19000,16.0
31.23800,11.0
31.28600,23.0
31.33400,16.0
31.38200,27.0
31.43000,21.0
31.47800,28.0
31.52600,16.0
31.57400,22.0
31.62200,19.0
31.67000,27.0
31.71800,22.0
31.76600,19.0
31.81400,15.0
31.86200,15.0
31.91000,26.0
31.95800,19.0
32.00600,26.0
32.05400,19.0
32.10200,16.0
32.15000,24.0
32.19800,27.0
32.24600,23.0
32.29400,19.0
32.34200,26.0
32.39000,29.0
32.43800,21.0
32.48600,18.0
32.53400,29.0
32.58200,16.0
32.63000,16.0
32.67800,18.0
32.72600,19.0
32.77400,19.0
32.82200,24.0
32.87000,20.0
32.91800,19.0
32.96600,24.0
33.01400,30.0
33.06200,24.0
33.11000,15.0
33.15800,21.0
33.20600,19.0
33.25400,15.0
33.30200,26.0
33.35000,15.0
33.39800,19.0
33.44600,17.0
33.49400,22.0
33.54200,23.0
33.59000,21.0
33.63800,18.0
33.68600,18.0
33.73400,28.0
33.78200,24.0
33.83000,17.0
33.87800,22.0
33.92600,32.0
33.97400,17.0
34.02200,24.0
34.07000,29.0
34.11800,26.0
34.16600,20.0
34.21400,31.0
34.26200,38.0
34.31000,29.0
34.35800,48.0
34.40600,38.0
34.45400,44.0
34.50200,58.0
34.55000,68.0
34.59800,105.0
34.64600,117.0
34.69400,122.0
34.74200,150.0
34.79000,180.0
34.83800,228.0
34.88600,242.0
34.93400,244.0
34.98200,238.0
35.03000,229.0
35.07800,233.0
35.12600,224.0
35.17400,189.0
35.22200,167.0
35.27000,143.0
35.31800,104.0
35.36600,89.0
35.41400,86.0
35.46200,65.0
35.51000,69.0
35.55800,57.0
35.60600,41.0
35.65400,41.0
35.70200,33.0
35.75000,42.0
35.79800,28.0
35.84600,39.0
35.89400,31.0
35.94200,38.0
35.99000,29.0
36.03800,41.0
36.08600,33.0
36.13400,44.0
36.18200,43.0
36.23000,46.0
36.27800,52.0
36.32600,38.0
36.37400,35.0
36.42200,35.0
36.47000,28.0
36.51800,37.0
36.56600,29.0
36.61400,43.0
36.66200,49.0
36.71000,36.0
36.75800,37.0
36.80600,41.0
36.85400,32.0
36.90200,30.0
36.95000,34.0
36.99800,36.0
37.04600,49.0
37.09400,37.0
37.14200,42.0
37.19000,38.0
37.23800,37.0
37.28600,40.0
37.33400,48.0
37.38200,52.0
37.43000,43.0
37.47800,40.0
37.52600,43.0
37.57400,55.0
37.62200,42.0
37.67000,59.0
37.71800,68.0
37.76600,53.0
37.81400,70.0
37.86200,100.0
37.91000,125.0
37.95800,158.0
38.00600,194.0
38.05400,261.0
38.10200,293.0
38.15000,331.0
38.19800,380.0
38.24600,448.0
38.29400,427.0
38.34200,402.0
38.39000,459.0
38.43800,438.0
38.48600,421.0
38.53400,393.0
38.58200,460.0
38.63000,465.0
38.67800,489.0
38.72600,498.0
38.77400,427.0
38.82200,439.0
38.87000,410.0
38.91800,364.0
38.96600,341.0
39.01400,299.0
39.06200,241.0
39.11000,247.0
39.15800,218.0
39.20600,185.0
39.25400,181.0
39.30200,179.0
39.35000,171.0
39.39800,187.0
39.44600,181.0
39.49400,186.0
39.54200,224.0
39.59000,266.0
39.63800,337.0
39.68600,409.0
39.73400,533.0
39.78200,625.0
39.83000,782.0
39.87800,924.0
39.92600,1044.0
39.97400,1125.0
40.02200,1217.0
40.07000,1090.0
40.11800,1112.0
40.16600,952.0
40.21400,846.0
40.26200,707.0
40.31000,572.0
40.35800,500.0
40.40600,385.0
40.45400,269.0
40.50200,241.0
40.55000,200.0
40.59800,168.0
40.64600,121.0
40.69400,105.0
40.74200,77.0
40.79000,60.0
40.83800,56.0
40.88600,55.0
40.93400,44.0
40.98200,46.0
41.03000,50.0
41.07800,44.0
41.12600,38.0
41.17400,34.0
41.22200,43.0
41.27000,39.0
41.31800,32.0
41.36600,34.0
41.41400,32.0
41.46200,41.0
41.51000,32.0
41.55800,33.0
41.60600,34.0
41.65400,32.0
41.70200,37.0
41.75000,35.0
41.79800,35.0
41.84600,44.0
41.89400,30.0
41.94200,36.0
41.99000,45.0
42.03800,37.0
42.08600,40.0
42.13400,39.0
42.18200,46.0
42.23000,37.0
42.27800,46.0
42.32600,34.0
42.37400,41.0
42.42200,32.0
42.47000,33.0
42.51800,31.0
42.56600,36.0
42.61400,26.0
42.66200,33.0
42.71000,35.0
42.75800,24.0
42.80600,45.0
42.85400,35.0
42.90200,24.0
42.95000,28.0
42.99800,34.0
43.04600,24.0
43.09400,30.0
43.14200,31.0
43.19000,27.0
43.23800,27.0
43.28600,22.0
43.33400,29.0
43.38200,17.0
43.43000,30.0
43.47800,21.0
43.52600,35.0
43.57400,23.0
43.62200,29.0
43.67000,14.0
43.71800,32.0
43.76600,17.0
43.81400,15.0
43.86200,21.0
43.91000,16.0
43.95800,14.0
44.00600,20.0
44.05400,28.0
44.10200,25.0
44.15000,17.0
44.19800,19.0
44.24600,25.0
44.29400,22.0
44.34200,18.0
44.39000,29.0
44.43800,19.0
44.48600,24.0
44.53400,33.0
44.58200,13.0
44.63000,29.0
44.67800,28.0
44.72600,24.0
44.77400,20.0
44.82200,24.0
44.87000,21.0
44.91800,22.0
44.96600,28.0
45.01400,31.0
45.06200,22.0
45.11000,38.0
45.15800,25.0
45.20600,19.0
45.25400,32.0
45.30200,22.0
45.35000,31.0
45.39800,17.0
45.44600,23.0
45.49400,32.0
45.54200,26.0
45.59000,12.0
45.63800,23.0
45.68600,19.0
45.73400,17.0
45.78200,22.0
45.83000,17.0
45.87800,19.0
45.92600,20.0
45.97400,27.0
46.02200,25.0
46.07000,21.0
46.11800,14.0
46.16600,27.0
46.21400,24.0
46.26200,20.0
46.31000,22.0
46.35800,31.0
46.40600,27.0
46.45400,22.0
46.50200,21.0
46.55000,21.0
46.59800,26.0
46.64600,22.0
46.69400,27.0
46.74200,24.0
46.79000,35.0
46.83800,23.0
46.88600,27.0
46.93400,24.0
46.98200,21.0
47.03000,14.0
47.07800,12.0
47.12600,21.0
47.17400,19.0
47.22200,21.0
47.27000,19.0
47.31800,22.0
47.36600,29.0
47.41400,22.0
47.46200,23.0
47.51000,25.0
47.55800,18.0
47.60600,20.0
47.65400,14.0
47.70200,21.0
47.75000,19.0
47.79800,19.0
47.84600,17.0
47.89400,19.0
47.94200,21.0
47.99000,17.0
48.03800,15.0
48.08600,20.0
48.13400,25.0
48.18200,11.0
48.23000,21.0
48.27800,22.0
48.32600,15.0
48.37400,21.0
48.42200,23.0
48.47000,19.0
48.51800,19.0
48.56600,21.0
48.61400,26.0
48.66200,13.0
48.71000,11.0
48.75800,17.0
48.80600,27.0
48.85400,14.0
48.90200,20.0
48.95000,14.0
48.99800,17.0
49.04600,19.0
49.09400,21.0
49.14200,28.0
49.19000,19.0
49.23800,20.0
49.28600,19.0
49.33400,24.0
49.38200,26.0
49.43000,22.0
49.47800,19.0
49.52600,18.0
49.57400,16.0
49.62200,21.0
49.67000,17.0
49.71800,17.0
49.76600,23.0
49.81400,21.0
49.86200,25.0
49.91000,26.0
49.95800,21.0
50.00600,19.0
50.05400,26.0
50.10200,19.0
50.15000,27.0
50.19800,17.0
50.24600,25.0
50.29400,17.0
50.34200,17.0
50.39000,24.0
50.43800,25.0
50.48600,17.0
50.53400,19.0
50.58200,17.0
50.63000,16.0
50.67800,21.0
50.72600,21.0
50.77400,26.0
50.82200,13.0
50.87000,20.0
50.91800,14.0
50.96600,27.0
51.01400,17.0
51.06200,23.0
51.11000,20.0
51.15800,22.0
51.20600,13.0
51.25400,22.0
51.30200,20.0
51.35000,22.0
51.39800,14.0
51.44600,27.0
51.49400,14.0
51.54200,21.0
51.59000,20.0
51.63800,22.0
51.68600,19.0
51.73400,12.0
51.78200,26.0
51.83000,29.0
51.87800,11.0
51.92600,19.0
51.97400,18.0
52.02200,11.0
52.07000,21.0
52.11800,14.0
52.16600,34.0
52.21400,27.0
52.26200,37.0
52.31000,29.0
52.35800,38.0
52.40600,41.0
52.45400,59.0
52.50200,69.0
52.55000,68.0
52.59800,80.0
52.64600,111.0
52.69400,107.0
52.74200,102.0
52.79000,131.0
52.83800,128.0
52.88600,132.0
52.93400,126.0
52.98200,112.0
53.03000,105.0
53.07800,114.0
53.12600,75.0
53.17400,89.0
53.22200,69.0
53.27000,56.0
53.31800,52.0
53.36600,62.0
53.41400,46.0
53.46200,43.0
53.51000,33.0
53.55800,29.0
53.60600,37.0
53.65400,25.0
53.70200,32.0
53.75000,24.0
53.79800,27.0
53.84600,30.0
53.89400,31.0
53.94200,22.0
53.99000,25.0
54.03800,34.0
54.08600,23.0
54.13400,26.0
54.18200,27.0
54.23000,29.0
54.27800,32.0
54.32600,21.0
54.37400,18.0
54.42200,25.0
54.47000,28.0
54.51800,21.0
54.56600,28.0
54.61400,33.0
54.66200,22.0
54.71000,31.0
54.75800,30.0
54.80600,34.0
54.85400,29.0
54.90200,31.0
54.95000,32.0
54.99800,32.0
55.04600,30.0
55.09400,43.0
55.14200,31.0
55.19000,30.0
55.23800,31.0
55.28600,37.0
55.33400,37.0
55.38200,37.0
55.43000,27.0
55.47800,40.0
55.52600,62.0
55.57400,39.0
55.62200,56.0
55.67000,60.0
55.71800,44.0
55.76600,65.0
55.81400,65.0
55.86200,49.0
55.91000,54.0
55.95800,69.0
56.00600,68.0
56.05400,56.0
56.10200,55.0
56.15000,50.0
56.19800,54.0
56.24600,50.0
56.29400,56.0
56.34200,31.0
56.39000,38.0
56.43800,43.0
56.48600,39.0
56.53400,31.0
56.58200,36.0
56.63000,32.0
56.67800,30.0
56.72600,39.0
56.77400,34.0
56.82200,30.0
56.87000,24.0
56.91800,23.0
56.96600,28.0
57.01400,20.0
57.06200,19.0
57.11000,25.0
57.15800,28.0
57.20600,24.0
57.25400,21.0
57.30200,22.0
57.35000,13.0
57.39800,17.0
57.44600,22.0
57.49400,23.0
57.54200,23.0
57.59000,27.0
57.63800,22.0
57.68600,20.0
57.73400,21.0
57.78200,23.0
57.83000,23.0
57.87800,13.0
57.92600,14.0
57.97400,25.0
58.02200,15.0
58.07000,19.0
58.11800,20.0
58.16600,18.0
58.21400,21.0
58.26200,19.0
58.31000,17.0
58.35800,21.0
58.40600,17.0
58.45400,17.0
58.50200,6.0
58.55000,11.0
58.59800,18.0
58.64600,14.0
58.69400,18.0
58.74200,21.0
58.79000,20.0
58.83800,13.0
58.88600,15.0
58.93400,14.0
58.98200,20.0
59.03000,16.0
59.07800,17.0
59.12600,17.0
59.17400,23.0
59.22200,19.0
59.27000,23.0
59.31800,15.0
59.36600,22.0
59.41400,18.0
59.46200,12.0
59.51000,12.0
59.55800,21.0
59.60600,17.0
59.65400,20.0
59.70200,11.0
59.75000,17.0
59.79800,17.0
59.84600,17.0
59.89400,14.0
59.94200,19.0
59.99000,18.0
60.03800,19.0
60.08600,18.0
60.13400,19.0
60.18200,13.0
60.23000,16.0
60.27800,12.0
60.32600,18.0
60.37400,17.0
60.42200,14.0
60.47000,11.0
60.51800,14.0
60.56600,21.0
60.61400,12.0
60.66200,17.0
60.71000,19.0
60.75800,15.0
60.80600,16.0
60.85400,10.0
60.90200,24.0
60.95000,18.0
60.99800,15.0
61.04600,19.0
61.09400,24.0
61.14200,21.0
61.19000,20.0
61.23800,16.0
61.28600,25.0
61.33400,14.0
61.38200,26.0
61.43000,27.0
61.47800,27.0
61.52600,30.0
61.57400,29.0
61.62200,35.0
61.67000,34.0
61.71800,25.0
61.76600,33.0
61.81400,51.0
61.86200,37.0
61.91000,38.0
61.95800,51.0
62.00600,48.0
62.05400,44.0
62.10200,55.0
62.15000,68.0
62.19800,48.0
62.24600,54.0
62.29400,75.0
62.34200,91.0
62.39000,88.0
62.43800,84.0
62.48600,105.0
62.53400,96.0
62.58200,97.0
62.63000,115.0
62.67800,137.0
62.72600,131.0
62.77400,116.0
62.82200,135.0
62.87000,130.0
62.91800,141.0
62.96600,113.0
63.01400,113.0
63.06200,137.0
63.11000,121.0
63.15800,104.0
63.20600,101.0
63.25400,94.0
63.30200,94.0
63.35000,86.0
63.39800,66.0
63.44600,71.0
63.49400,68.0
63.54200,77.0
63.59000,53.0
63.63800,50.0
63.68600,54.0
63.73400,56.0
63.78200,34.0
63.83000,46.0
63.87800,37.0
63.92600,32.0
63.97400,24.0
64.02200,21.0
64.07000,31.0
64.11800,20.0
64.16600,34.0
64.21400,27.0
64.26200,28.0
64.31000,13.0
64.35800,22.0
64.40600,27.0
64.45400,16.0
64.50200,11.0
64.55000,19.0
64.59800,21.0
64.64600,18.0
64.69400,12.0
64.74200,26.0
64.79000,19.0
64.83800,7.0
64.88600,20.0
64.93400,14.0
64.98200,15.0
65.03000,13.0
65.07800,15.0
65.12600,24.0
65.17400,16.0
65.22200,19.0
65.27000,18.0
65.31800,19.0
65.36600,21.0
65.41400,15.0
65.46200,23.0
65.51000,12.0
65.55800,13.0
65.60600,20.0
65.65400,11.0
65.70200,21.0
65.75000,21.0
65.79800,16.0
65.84600,16.0
65.89400,10.0
65.94200,22.0
65.99000,19.0
66.03800,14.0
66.08600,17.0
66.13400,20.0
66.18200,18.0
66.23000,16.0
66.27800,21.0
66.32600,20.0
66.37400,11.0
66.42200,22.0
66.47000,20.0
66.51800,21.0
66.56600,12.0
66.61400,24.0
66.66200,20.0
66.71000,12.0
66.75800,23.0
66.80600,14.0
66.85400,17.0
66.90200,10.0
66.95000,14.0
66.99800,12.0
67.04600,13.0
67.09400,17.0
67.14200,12.0
67.19000,21.0
67.23800,20.0
67.28600,12.0
67.33400,14.0
67.38200,24.0
67.43000,17.0
67.47800,19.0
67.52600,16.0
67.57400,22.0
67.62200,25.0
67.67000,17.0
67.71800,15.0
67.76600,20.0
67.81400,28.0
67.86200,19.0
67.91000,17.0
67.95800,14.0
68.00600,24.0
68.05400,16.0
68.10200,23.0
68.15000,10.0
68.19800,19.0
68.24600,18.0
68.29400,18.0
68.34200,14.0
68.39000,15.0
68.43800,19.0
68.48600,27.0
68.53400,16.0
68.58200,21.0
68.63000,18.0
68.67800,15.0
68.72600,24.0
68.77400,32.0
68.82200,17.0
68.87000,18.0
68.91800,22.0
68.96600,24.0
69.01400,31.0
69.06200,32.0
69.11000,30.0
69.15800,32.0
69.20600,14.0
69.25400,29.0
69.30200,23.0
69.35000,26.0
69.39800,29.0
69.44600,36.0
69.49400,38.0
69.54200,48.0
69.59000,47.0
69.63800,49.0
69.68600,50.0
69.73400,56.0
69.78200,70.0
69.83000,86.0
69.87800,71.0
69.92600,82.0
69.97400,93.0
70.02200,102.0
70.07000,123.0
70.11800,129.0
70.16600,131.0
70.21400,147.0
70.26200,170.0
70.31000,159.0
70.35800,159.0
70.40600,185.0
70.45400,163.0
70.50200,168.0
70.55000,177.0
70.59800,158.0
70.64600,158.0
70.69400,126.0
70.74200,119.0
70.79000,113.0
70.83800,92.0
70.88600,85.0
70.93400,58.0
70.98200,67.0
71.03000,57.0
71.07800,60.0
71.12600,47.0
71.17400,59.0
71.22200,49.0
71.27000,37.0
71.31800,40.0
71.36600,31.0
71.41400,22.0
71.46200,30.0
71.51000,33.0
71.55800,25.0
71.60600,28.0
71.65400,30.0
71.70200,17.0
71.75000,27.0
71.79800,26.0
71.84600,25.0
71.89400,22.0
71.94200,14.0
71.99000,16.0
72.03800,18.0
72.08600,29.0
72.13400,26.0
72.18200,26.0
72.23000,23.0
72.27800,19.0
72.32600,17.0
72.37400,11.0
72.42200,24.0
72.47000,17.0
72.51800,28.0
72.56600,16.0
72.61400,20.0
72.66200,20.0
72.71000,25.0
72.75800,25.0
72.80600,28.0
72.85400,21.0
72.90200,26.0
72.95000,27.0
72.99800,27.0
73.04600,24.0
73.09400,31.0
73.14200,20.0
73.19000,24.0
73.23800,20.0
73.28600,20.0
73.33400,29.0
73.38200,27.0
73.43000,31.0
73.47800,31.0
73.52600,37.0
73.57400,36.0
73.62200,27.0
73.67000,27.0
73.71800,42.0
73.76600,26.0
73.81400,32.0
73.86200,39.0
73.91000,26.0
73.95800,36.0
74.00600,35.0
74.05400,35.0
74.10200,30.0
74.15000,35.0
74.19800,20.0
74.24600,28.0
74.29400,29.0
74.34200,31.0
74.39000,24.0
74.43800,32.0
74.48600,39.0
74.53400,20.0
74.58200,31.0
74.63000,31.0
74.67800,25.0
74.72600,29.0
74.77400,27.0
74.82200,36.0
74.87000,33.0
74.91800,31.0
74.96600,39.0
75.01400,25.0
75.06200,34.0
75.11000,32.0
75.15800,35.0
75.20600,42.0
75.25400,37.0
75.30200,37.0
75.35000,46.0
75.39800,62.0
75.44600,66.0
75.49400,64.0
75.54200,68.0
75.59000,78.0
75.63800,95.0
75.68600,109.0
75.73400,124.0
75.78200,100.0
75.83000,125.0
75.87800,112.0
75.92600,127.0
75.97400,148.0
76.02200,154.0
76.07000,126.0
76.11800,143.0
76.16600,129.0
76.21400,129.0
76.26200,131.0
76.31000,120.0
76.35800,114.0
76.40600,113.0
76.45400,100.0
76.50200,87.0
76.55000,87.0
76.59800,102.0
76.64600,79.0
76.69400,89.0
76.74200,99.0
76.79000,91.0
76.83800,104.0
76.88600,88.0
76.93400,75.0
76.98200,103.0
77.03000,83.0
77.07800,98.0
77.12600,103.0
77.17400,85.0
77.22200,102.0
77.27000,87.0
77.31800,79.0
77.36600,79.0
77.41400,70.0
77.46200,81.0
77.51000,77.0
77.55800,58.0
77.60600,60.0
77.65400,59.0
77.70200,56.0
77.75000,57.0
77.79800,53.0
77.84600,50.0
77.89400,38.0
77.94200,46.0
77.99000,46.0
78.03800,41.0
78.08600,42.0
78.13400,34.0
78.18200,38.0
78.23000,33.0
78.27800,37.0
78.32600,30.0
78.37400,30.0
78.42200,29.0
78.47000,28.0
78.51800,12.0
78.56600,30.0
78.61400,25.0
78.66200,22.0
78.71000,23.0
78.75800,21.0
78.80600,14.0
78.85400,14.0
78.90200,34.0
78.95000,26.0
78.99800,26.0
79.04600,22.0
79.09400,23.0
79.14200,31.0
79.19000,24.0
79.23800,15.0
79.28600,19.0
79.33400,17.0
79.38200,19.0
79.43000,23.0
79.47800,21.0
79.52600,21.0
79.57400,12.0
79.62200,19.0
79.67000,14.0
79.71800,8.0
79.76600,14.0
79.81400,17.0
79.86200,18.0
79.91000,11.0
79.95800,15.0
79.99400,16.0