File: code/data/data_source2/TiZn_GIXRD - Ti_ZnHA-6h-Z=36mm.csv
[Measurement conditions]
Sample identification,
Comment - 1,"Configuration=Filmes Finos 19_1_2015, Owner=User-1, Creation date=19/01/2015 21:17:15"
Comment - 2,"Goniometer=PW3050/60 (Theta/Theta); Minimum step size 2Theta:0.001; Minimum step size Omega:0.001"
Comment - 3,"Sample stage=PW3071/xx Bracket"
Comment - 4,"Diffractometer system=XPERT-PRO"
Comment - 5,"Measurement program=C:\PANalytical\Data Collector\Programs\GrazingIncidence.xrdmp, Identifier={0DC062CD-4409-4D11-BF1B-D0962EB5CB52}"
Anode material,Cu
K-Alpha1 wavelength,1.5405980
K-Alpha2 wavelength,1.5444260
Ratio K-Alpha2/K-Alpha1,0.500
Divergence slit,Fixed,0.10mm
Receiving slit,0.10
Monochromator used,YES
Generator voltage, 40
Tube current, 40
File date and time,30/Jan/2018 19:15
Unit cell,
h k l, 0 0 0
Scan axis,2Theta
Scan range,8.000,55.000
Scan step size,0.0250000
No. of points, 1881
Scan type,STEP
Omega,2.000
Time per step,20.000
[Scan points]
Angle,Intensity
8.000,83
8.050,85
8.100,82
8.150,84
8.200,83
8.250,85
8.300,80
8.350,77
8.400,78
8.450,76
8.500,78
8.550,76
8.600,78
8.650,78
8.700,76
8.750,73
8.800,72
8.850,75
8.900,74
8.950,72
9.000,71
9.050,73
9.100,73
9.150,75
9.200,74
9.250,71
9.300,71
9.350,74
9.400,72
9.450,72
9.500,73
9.550,67
9.600,68
9.650,66
9.700,69
9.750,69
9.800,67
9.850,70
9.900,64
9.950,65
10.000,65
10.050,67
10.100,66
10.150,66
10.200,67
10.250,64
10.300,69
10.350,64
10.400,64
10.450,65
10.500,63
10.550,64
10.600,62
10.650,63
10.700,63
10.750,62
10.800,63
10.850,62
10.900,59
10.950,59
11.000,61
11.050,59
11.100,60
11.150,58
11.200,57
11.250,60
11.300,56
11.350,57
11.400,59
11.450,62
11.500,53
11.550,58
11.600,58
11.650,59
11.700,61
11.750,58
11.800,58
11.850,59
11.900,56
11.950,56
12.000,58
12.050,57
12.100,61
12.150,53
12.200,61
12.250,55
12.300,60
12.350,57
12.400,56
12.450,56
12.500,58
12.550,53
12.600,50
12.650,54
12.700,53
12.750,53
12.800,53
12.850,55
12.900,53
12.950,54
13.000,51
13.050,50
13.100,52
13.150,52
13.200,55
13.250,52
13.300,51
13.350,50
13.400,50
13.450,47
13.500,49
13.550,48
13.600,49
13.650,54
13.700,47
13.750,51
13.800,50
13.850,50
13.900,49
13.950,49
14.000,48
14.050,47
14.100,48
14.150,48
14.200,46
14.250,48
14.300,49
14.350,44
14.400,45
14.450,48
14.500,47
14.550,46
14.600,48
14.650,47
14.700,45
14.750,45
14.800,44
14.850,45
14.900,45
14.950,44
15.000,42
15.050,44
15.100,41
15.150,44
15.200,43
15.250,40
15.300,41
15.350,46
15.400,45
15.450,43
15.500,45
15.550,43
15.600,43
15.650,43
15.700,44
15.750,40
15.800,42
15.850,42
15.900,40
15.950,40
16.000,42
16.050,43
16.100,41
16.150,40
16.200,40
16.250,40
16.300,42
16.350,43
16.400,40
16.450,39
16.500,40
16.550,38
16.600,38
16.650,39
16.700,39
16.750,38
16.800,38
16.850,37
16.900,40
16.950,39
17.000,39
17.050,41
17.100,38
17.150,39
17.200,39
17.250,39
17.300,36
17.350,39
17.400,36
17.450,38
17.500,36
17.550,37
17.600,36
17.650,37
17.700,37
17.750,39
17.800,38
17.850,38
17.900,37
17.950,39
18.000,34
18.050,37
18.100,34
18.150,36
18.200,38
18.250,37
18.300,36
18.350,36
18.400,36
18.450,37
18.500,37
18.550,35
18.600,37
18.650,34
18.700,36
18.750,33
18.800,34
18.850,34
18.900,35
18.950,32
19.000,34
19.050,34
19.100,35
19.150,34
19.200,35
19.250,31
19.300,33
19.350,35
19.400,34
19.450,33
19.500,32
19.550,31
19.600,33
19.650,30
19.700,33
19.750,31
19.800,34
19.850,30
19.900,32
19.950,29
20.000,30
20.050,31
20.100,32
20.150,28
20.200,29
20.250,30
20.300,30
20.350,30
20.400,28
20.450,27
20.500,28
20.550,30
20.600,28
20.650,30
20.700,27
20.750,25
20.800,27
20.850,30
20.900,27
20.950,25
21.000,25
21.050,29
21.100,27
21.150,27
21.200,25
21.250,25
21.300,26
21.350,26
21.400,26
21.450,25
21.500,25
21.550,27
21.600,26
21.650,24
21.700,26
21.750,25
21.800,23
21.850,25
21.900,24
21.950,23
22.000,25
22.050,24
22.100,23
22.150,23
22.200,23
22.250,23
22.300,24
22.350,24
22.400,23
22.450,22
22.500,23
22.550,25
22.600,24
22.650,23
22.700,22
22.750,21
22.800,20
22.850,22
22.900,24
22.950,22
23.000,22
23.050,25
23.100,21
23.150,22
23.200,20
23.250,22
23.300,21
23.350,22
23.400,20
23.450,20
23.500,20
23.550,19
23.600,21
23.650,19
23.700,19
23.750,19
23.800,21
23.850,19
23.900,20
23.950,22
24.000,21
24.050,20
24.100,19
24.150,20
24.200,20
24.250,21
24.300,20
24.350,17
24.400,19
24.450,20
24.500,18
24.550,19
24.600,20
24.650,20
24.700,19
24.750,19
24.800,18
24.850,17
24.900,16
24.950,20
25.000,18
25.050,20
25.100,19
25.150,19
25.200,20
25.250,18
25.300,17
25.350,19
25.400,21
25.450,20
25.500,18
25.550,20
25.600,20
25.650,22
25.700,19
25.750,21
25.800,18
25.850,19
25.900,18
25.950,16
26.000,16
26.050,16
26.100,17
26.150,18
26.200,16
26.250,18
26.300,16
26.350,19
26.400,18
26.450,17
26.500,19
26.550,18
26.600,17
26.650,18
26.700,19
26.750,18
26.800,18
26.850,15
26.900,19
26.950,18
27.000,18
27.050,17
27.100,17
27.150,16
27.200,19
27.250,16
27.300,17
27.350,17
27.400,17
27.450,18
27.500,18
27.550,18
27.600,18
27.650,16
27.700,16
27.750,19
27.800,18
27.850,18
27.900,18
27.950,19
28.000,20
28.050,19
28.100,18
28.150,17
28.200,17
28.250,17
28.300,18
28.350,18
28.400,18
28.450,19
28.500,18
28.550,18
28.600,19
28.650,18
28.700,18
28.750,18
28.800,18
28.850,20
28.900,19
28.950,19
29.000,18
29.050,21
29.100,16
29.150,21
29.200,19
29.250,17
29.300,18
29.350,18
29.400,18
29.450,19
29.500,18
29.550,17
29.600,18
29.650,16
29.700,19
29.750,17
29.800,18
29.850,17
29.900,18
29.950,19
30.000,19
30.050,17
30.100,18
30.150,18
30.200,17
30.250,16
30.300,17
30.350,17
30.400,17
30.450,17
30.500,17
30.550,16
30.600,18
30.650,16
30.700,16
30.750,17
30.800,17
30.850,17
30.900,15
30.950,17
31.000,16
31.050,16
31.100,17
31.150,16
31.200,17
31.250,18
31.300,18
31.350,18
31.400,19
31.450,18
31.500,19
31.550,20
31.600,18
31.650,20
31.700,19
31.750,20
31.800,19
31.850,18
31.900,18
31.950,19
32.000,18
32.050,17
32.100,16
32.150,16
32.200,14
32.250,15
32.300,16
32.350,16
32.400,14
32.450,13
32.500,16
32.550,15
32.600,16
32.650,15
32.700,14
32.750,13
32.800,16
32.850,15
32.900,15
32.950,13
33.000,13
33.050,13
33.100,13
33.150,14
33.200,13
33.250,13
33.300,12
33.350,13
33.400,13
33.450,13
33.500,14
33.550,14
33.600,13
33.650,13
33.700,13
33.750,14
33.800,12
33.850,14
33.900,11
33.950,12
34.000,11
34.050,11
34.100,12
34.150,12
34.200,10
34.250,12
34.300,12
34.350,11
34.400,12
34.450,10
34.500,11
34.550,10
34.600,12
34.650,11
34.700,11
34.750,11
34.800,11
34.850,12
34.900,11
34.950,12
35.000,10
35.050,10
35.100,12
35.150,11
35.200,10
35.250,10
35.300,11
35.350,11
35.400,10
35.450,10
35.500,10
35.550,11
35.600,11
35.650,11
35.700,10
35.750,11
35.800,11
35.850,10
35.900,10
35.950,10
36.000,10
36.050,11
36.100,11
36.150,10
36.200,10
36.250,10
36.300,10
36.350, 9
36.400, 9
36.450, 9
36.500,10
36.550,10
36.600,11
36.650,10
36.700,11
36.750,11
36.800,12
36.850,11
36.900,10
36.950,12
37.000,14
37.050,13
37.100,13
37.150,13
37.200,13
37.250,15
37.300,13
37.350,13
37.400, 9
37.450,12
37.500,13
37.550,10
37.600,10
37.650,10
37.700,10
37.750, 9
37.800, 9
37.850, 9
37.900, 9
37.950, 9
38.000, 9
38.050,10
38.100, 8
38.150, 9
38.200, 9
38.250, 8
38.300,10
38.350,10
38.400, 8
38.450, 8
38.500, 9
38.550,10
38.600, 9
38.650,10
38.700, 9
38.750, 9
38.800, 9
38.850, 7
38.900, 9
38.950, 8
39.000, 9
39.050, 8
39.100, 8
39.150, 9
39.200, 9
39.250, 9
39.300, 9
39.350, 8
39.400, 9
39.450, 9
39.500, 7
39.550, 7
39.600, 9
39.650, 8
39.700, 9
39.750, 9
39.800, 8
39.850, 9
39.900,10
39.950, 9
40.000, 9
40.050, 9
40.100, 8
40.150, 8
40.200, 8
40.250, 9
40.300, 9
40.350, 9
40.400, 9
40.450, 8
40.500, 8
40.550, 8
40.600, 8
40.650, 8
40.700, 9
40.750,10
40.800, 8
40.850, 8
40.900, 8
40.950, 7
41.000,10
41.050, 9
41.100, 9
41.150, 9
41.200, 9
41.250, 8
41.300, 8
41.350, 9
41.400, 8
41.450, 9
41.500, 9
41.550, 8
41.600,10
41.650, 8
41.700, 8
41.750, 9
41.800, 9
41.850,10
41.900, 9
41.950, 9
42.000, 8
42.050, 9
42.100, 9
42.150,10
42.200, 9
42.250, 9
42.300, 9
42.350, 9
42.400,11
42.450,11
42.500,10
42.550,11
42.600,11
42.650,10
42.700,11
42.750,11
42.800,10
42.850,12
42.900,12
42.950,12
43.000,13
43.050,12
43.100,12
43.150,13
43.200,12
43.250,13
43.300,12
43.350,13
43.400,13
43.450,12
43.500,11
43.550,14
43.600,12
43.650,11
43.700,11
43.750,11
43.800,11
43.850,10
43.900,10
43.950,10
44.000, 9
44.050, 9
44.100,10
44.150,10
44.200,10
44.250, 9
44.300, 9
44.350, 9
44.400, 8
44.450,10
44.500, 9
44.550, 9
44.600, 8
44.650, 9
44.700, 8
44.750,10
44.800, 9
44.850,10
44.900, 7
44.950,10
45.000, 8
45.050,10
45.100, 9
45.150, 8
45.200, 9
45.250, 8
45.300, 7
45.350, 8
45.400, 8
45.450, 9
45.500, 9
45.550, 8
45.600, 8
45.650, 8
45.700, 9
45.750, 8
45.800, 8
45.850, 8
45.900, 8
45.950, 8
46.000, 8
46.050, 9
46.100, 8
46.150, 8
46.200, 8
46.250, 8
46.300, 8
46.350, 9
46.400, 8
46.450, 9
46.500, 9
46.550, 9
46.600, 8
46.650, 8
46.700, 8
46.750, 8
46.800, 6
46.850, 8
46.900, 9
46.950, 9
47.000, 8
47.050, 8
47.100, 9
47.150, 8
47.200, 8
47.250, 8
47.300, 8
47.350, 8
47.400, 8
47.450, 9
47.500, 8
47.550, 9
47.600, 8
47.650, 9
47.700, 9
47.750, 8
47.800, 9
47.850, 9
47.900, 8
47.950, 9
48.000, 8
48.050, 7
48.100, 9
48.150, 7
48.200, 8
48.250, 7
48.300, 8
48.350, 8
48.400, 8
48.450, 8
48.500, 8
48.550, 8
48.600, 7
48.650, 8
48.700, 8
48.750, 7
48.800, 8
48.850, 8
48.900, 8
48.950, 7
49.000, 8
49.050,10
49.100, 9
49.150, 9
49.200, 9
49.250, 9
49.300, 9
49.350, 9
49.400, 9
49.450, 8
49.500, 8
49.550, 8
49.600, 9
49.650, 8
49.700, 9
49.750, 8
49.800, 8
49.850, 8
49.900, 9
49.950, 9
50.000, 8
50.050, 8
50.100, 8
50.150, 9
50.200, 9
50.250, 8
50.300, 8
50.350, 8
50.400, 9
50.450, 8
50.500, 8
50.550, 9
50.600,10
50.650, 8
50.700, 8
50.750,10
50.800, 9
50.850, 8
50.900,10
50.950, 9
51.000, 8
51.050,10
51.100, 8
51.150, 9
51.200, 8
51.250,10
51.300, 9
51.350,10
51.400,11
51.450,10
51.500, 8
51.550, 9
51.600,10
51.650, 9
51.700, 9
51.750, 8
51.800,10
51.850, 9
51.900, 9
51.950, 9
52.000,10
52.050, 9
52.100,10
52.150,10
52.200, 9
52.250,10
52.300, 9
52.350,11
52.400,10
52.450,11
52.500,11
52.550,10
52.600, 9
52.650,10
52.700,12
52.750,11
52.800,12
52.850,10
52.900,10
52.950,10
53.000,10
53.050,10
53.100,10
53.150,12
53.200,11
53.250,10
53.300,12
53.350,10
53.400,12
53.450,11
53.500,13
53.550,12
53.600,14
53.650,14
53.700,14
53.750,20
53.800,35
53.850,51
53.900,52
53.950,50
54.000,48
54.050,42
54.100,30
54.150,24
54.200,20
54.250,18
54.300,16
54.350,17
54.400,16
54.450,16
54.500,18
54.550,20
54.600,18
54.650,20
54.700,21
54.750,21
54.800,24
54.850,29
54.900,36
54.950,39
55.000,45