File: code/data/data_source2/TiZn_GIXRD - Ti_ZnHA-300nm-Z=29mm.csv
[Measurement conditions]
Sample identification,
Comment - 1,"Configuration=Filmes Finos 19_1_2015, Owner=User-1, Creation date=19/01/2015 21:17:15"
Comment - 2,"Goniometer=PW3050/60 (Theta/Theta); Minimum step size 2Theta:0.001; Minimum step size Omega:0.001"
Comment - 3,"Sample stage=PW3071/xx Bracket"
Comment - 4,"Diffractometer system=XPERT-PRO"
Comment - 5,"Measurement program=C:\PANalytical\Data Collector\Programs\GrazingIncidence.xrdmp, Identifier={FFFADE1E-4F1E-43E6-AE83-51B7A97F4E56}"
Anode material,Cu
K-Alpha1 wavelength,1.5405980
K-Alpha2 wavelength,1.5444260
Ratio K-Alpha2/K-Alpha1,0.500
Divergence slit,Fixed,0.10mm
Receiving slit,0.10
Monochromator used,YES
Generator voltage, 40
Tube current, 40
File date and time,19/Jan/2018 20:01
Unit cell,
h k l, 0 0 0
Scan axis,2Theta
Scan range,8.000,60.000
Scan step size,0.0250000
No. of points, 2081
Scan type,STEP
Omega,2.000
Time per step,20.000
[Scan points]
Angle,Intensity
8.000,103
8.050,103
8.100,103
8.150,101
8.200,98
8.250,99
8.300,100
8.350,99
8.400,101
8.450,97
8.500,97
8.550,94
8.600,97
8.650,95
8.700,90
8.750,98
8.800,95
8.850,94
8.900,91
8.950,95
9.000,90
9.050,90
9.100,92
9.150,92
9.200,93
9.250,90
9.300,90
9.350,90
9.400,91
9.450,93
9.500,89
9.550,88
9.600,90
9.650,83
9.700,92
9.750,87
9.800,86
9.850,82
9.900,85
9.950,82
10.000,86
10.050,82
10.100,82
10.150,84
10.200,84
10.250,80
10.300,80
10.350,82
10.400,79
10.450,82
10.500,82
10.550,76
10.600,83
10.650,77
10.700,84
10.750,81
10.800,84
10.850,81
10.900,75
10.950,78
11.000,74
11.050,76
11.100,75
11.150,77
11.200,76
11.250,76
11.300,73
11.350,76
11.400,75
11.450,71
11.500,77
11.550,74
11.600,74
11.650,70
11.700,71
11.750,73
11.800,74
11.850,71
11.900,72
11.950,74
12.000,71
12.050,75
12.100,73
12.150,72
12.200,69
12.250,73
12.300,70
12.350,73
12.400,74
12.450,71
12.500,69
12.550,71
12.600,71
12.650,69
12.700,67
12.750,68
12.800,68
12.850,70
12.900,68
12.950,65
13.000,68
13.050,69
13.100,65
13.150,68
13.200,66
13.250,65
13.300,68
13.350,66
13.400,65
13.450,66
13.500,65
13.550,67
13.600,67
13.650,64
13.700,64
13.750,66
13.800,63
13.850,63
13.900,63
13.950,66
14.000,62
14.050,63
14.100,61
14.150,64
14.200,61
14.250,64
14.300,61
14.350,60
14.400,64
14.450,60
14.500,62
14.550,60
14.600,59
14.650,60
14.700,60
14.750,62
14.800,59
14.850,61
14.900,57
14.950,60
15.000,59
15.050,59
15.100,63
15.150,56
15.200,60
15.250,57
15.300,59
15.350,59
15.400,60
15.450,57
15.500,61
15.550,57
15.600,56
15.650,59
15.700,54
15.750,53
15.800,59
15.850,58
15.900,57
15.950,57
16.000,60
16.050,56
16.100,56
16.150,58
16.200,54
16.250,57
16.300,58
16.350,57
16.400,55
16.450,58
16.500,56
16.550,57
16.600,55
16.650,56
16.700,58
16.750,57
16.800,55
16.850,57
16.900,56
16.950,54
17.000,56
17.050,53
17.100,55
17.150,53
17.200,55
17.250,55
17.300,53
17.350,53
17.400,54
17.450,50
17.500,55
17.550,56
17.600,52
17.650,54
17.700,53
17.750,51
17.800,55
17.850,49
17.900,52
17.950,54
18.000,50
18.050,52
18.100,51
18.150,52
18.200,51
18.250,52
18.300,53
18.350,55
18.400,52
18.450,51
18.500,51
18.550,49
18.600,51
18.650,49
18.700,51
18.750,53
18.800,52
18.850,50
18.900,50
18.950,51
19.000,48
19.050,49
19.100,52
19.150,50
19.200,48
19.250,47
19.300,49
19.350,48
19.400,49
19.450,51
19.500,47
19.550,49
19.600,49
19.650,49
19.700,47
19.750,49
19.800,44
19.850,45
19.900,47
19.950,45
20.000,48
20.050,47
20.100,47
20.150,46
20.200,46
20.250,48
20.300,47
20.350,44
20.400,46
20.450,43
20.500,46
20.550,43
20.600,46
20.650,45
20.700,47
20.750,44
20.800,42
20.850,44
20.900,44
20.950,43
21.000,43
21.050,41
21.100,42
21.150,45
21.200,48
21.250,48
21.300,52
21.350,48
21.400,48
21.450,50
21.500,45
21.550,43
21.600,44
21.650,41
21.700,42
21.750,43
21.800,43
21.850,42
21.900,41
21.950,41
22.000,38
22.050,41
22.100,40
22.150,40
22.200,39
22.250,40
22.300,40
22.350,39
22.400,38
22.450,38
22.500,39
22.550,36
22.600,40
22.650,36
22.700,41
22.750,37
22.800,36
22.850,39
22.900,39
22.950,39
23.000,35
23.050,38
23.100,35
23.150,33
23.200,36
23.250,33
23.300,35
23.350,38
23.400,35
23.450,36
23.500,34
23.550,35
23.600,35
23.650,34
23.700,32
23.750,33
23.800,34
23.850,35
23.900,34
23.950,33
24.000,31
24.050,33
24.100,34
24.150,35
24.200,35
24.250,34
24.300,34
24.350,32
24.400,31
24.450,31
24.500,31
24.550,31
24.600,31
24.650,28
24.700,30
24.750,31
24.800,30
24.850,32
24.900,30
24.950,33
25.000,31
25.050,32
25.100,29
25.150,31
25.200,29
25.250,33
25.300,30
25.350,31
25.400,32
25.450,32
25.500,31
25.550,37
25.600,37
25.650,38
25.700,35
25.750,36
25.800,32
25.850,32
25.900,31
25.950,29
26.000,28
26.050,28
26.100,27
26.150,27
26.200,28
26.250,26
26.300,26
26.350,27
26.400,27
26.450,26
26.500,25
26.550,25
26.600,28
26.650,25
26.700,25
26.750,25
26.800,25
26.850,25
26.900,24
26.950,24
27.000,24
27.050,23
27.100,22
27.150,25
27.200,24
27.250,23
27.300,21
27.350,24
27.400,22
27.450,25
27.500,24
27.550,23
27.600,22
27.650,24
27.700,23
27.750,25
27.800,25
27.850,26
27.900,24
27.950,24
28.000,23
28.050,23
28.100,22
28.150,23
28.200,23
28.250,23
28.300,22
28.350,22
28.400,21
28.450,23
28.500,22
28.550,22
28.600,23
28.650,23
28.700,23
28.750,23
28.800,24
28.850,23
28.900,22
28.950,21
29.000,23
29.050,23
29.100,20
29.150,19
29.200,20
29.250,21
29.300,18
29.350,19
29.400,19
29.450,20
29.500,19
29.550,20
29.600,19
29.650,19
29.700,19
29.750,20
29.800,18
29.850,18
29.900,20
29.950,20
30.000,19
30.050,18
30.100,19
30.150,19
30.200,19
30.250,18
30.300,18
30.350,19
30.400,18
30.450,20
30.500,18
30.550,18
30.600,18
30.650,18
30.700,18
30.750,17
30.800,21
30.850,18
30.900,18
30.950,19
31.000,18
31.050,20
31.100,20
31.150,22
31.200,21
31.250,26
31.300,28
31.350,31
31.400,36
31.450,41
31.500,43
31.550,46
31.600,47
31.650,47
31.700,44
31.750,46
31.800,44
31.850,44
31.900,39
31.950,40
32.000,37
32.050,35
32.100,32
32.150,28
32.200,25
32.250,22
32.300,23
32.350,20
32.400,21
32.450,21
32.500,23
32.550,23
32.600,26
32.650,30
32.700,31
32.750,29
32.800,28
32.850,26
32.900,25
32.950,21
33.000,18
33.050,19
33.100,17
33.150,16
33.200,15
33.250,15
33.300,14
33.350,13
33.400,13
33.450,16
33.500,15
33.550,17
33.600,18
33.650,18
33.700,18
33.750,19
33.800,21
33.850,18
33.900,18
33.950,15
34.000,16
34.050,15
34.100,14
34.150,14
34.200,14
34.250,14
34.300,14
34.350,13
34.400,12
34.450,12
34.500,12
34.550,12
34.600,11
34.650,11
34.700,12
34.750,12
34.800,12
34.850,10
34.900,12
34.950,12
35.000,12
35.050,11
35.100,12
35.150,12
35.200,12
35.250,10
35.300,13
35.350,10
35.400,11
35.450,12
35.500,10
35.550,11
35.600,10
35.650,11
35.700,10
35.750,11
35.800,10
35.850,11
35.900,11
35.950, 9
36.000,11
36.050,11
36.100,11
36.150,10
36.200,10
36.250,10
36.300,10
36.350,10
36.400,11
36.450,10
36.500,10
36.550,10
36.600,11
36.650,11
36.700,10
36.750,10
36.800,11
36.850,11
36.900,11
36.950,12
37.000,11
37.050,12
37.100,14
37.150,13
37.200,13
37.250,12
37.300,13
37.350,13
37.400,11
37.450,11
37.500,11
37.550,11
37.600,10
37.650,10
37.700,10
37.750, 8
37.800,10
37.850,10
37.900, 9
37.950, 9
38.000,10
38.050, 8
38.100, 8
38.150, 8
38.200, 9
38.250, 9
38.300, 9
38.350, 9
38.400, 9
38.450, 9
38.500, 8
38.550, 9
38.600,10
38.650, 9
38.700, 9
38.750,10
38.800,10
38.850,10
38.900,10
38.950, 8
39.000,10
39.050, 9
39.100,11
39.150,10
39.200, 8
39.250,10
39.300, 9
39.350,11
39.400,10
39.450,11
39.500,12
39.550,12
39.600,13
39.650,11
39.700,12
39.750,11
39.800,11
39.850,11
39.900,11
39.950,10
40.000,10
40.050, 9
40.100, 9
40.150, 9
40.200, 9
40.250,10
40.300, 8
40.350, 9
40.400,10
40.450, 8
40.500, 8
40.550, 9
40.600, 8
40.650, 9
40.700, 8
40.750, 8
40.800, 9
40.850, 8
40.900, 7
40.950, 8
41.000, 9
41.050, 8
41.100, 8
41.150, 8
41.200, 8
41.250, 8
41.300, 8
41.350, 8
41.400, 9
41.450, 9
41.500, 9
41.550,10
41.600, 8
41.650,10
41.700,10
41.750, 9
41.800,10
41.850,10
41.900,11
41.950,10
42.000, 9
42.050,10
42.100, 9
42.150, 9
42.200,10
42.250, 9
42.300,10
42.350, 9
42.400, 9
42.450, 9
42.500, 9
42.550,10
42.600,11
42.650, 9
42.700,10
42.750,11
42.800,11
42.850,12
42.900,12
42.950,14
43.000,13
43.050,13
43.100,14
43.150,14
43.200,13
43.250,12
43.300,14
43.350,14
43.400,12
43.450,12
43.500,13
43.550,12
43.600,13
43.650,13
43.700,10
43.750,12
43.800,12
43.850,10
43.900,12
43.950,10
44.000,11
44.050, 9
44.100,10
44.150,10
44.200,10
44.250, 9
44.300, 9
44.350, 9
44.400, 9
44.450, 9
44.500, 9
44.550, 9
44.600, 8
44.650,10
44.700, 8
44.750, 9
44.800, 8
44.850,10
44.900,10
44.950, 8
45.000, 8
45.050, 9
45.100,10
45.150, 8
45.200, 8
45.250, 9
45.300, 9
45.350, 8
45.400, 8
45.450, 7
45.500, 8
45.550, 7
45.600, 8
45.650, 8
45.700, 9
45.750, 8
45.800, 9
45.850, 8
45.900,10
45.950,10
46.000, 9
46.050,10
46.100,10
46.150,11
46.200,12
46.250,13
46.300,14
46.350,14
46.400,14
46.450,14
46.500,13
46.550,12
46.600,13
46.650,12
46.700,11
46.750,11
46.800,10
46.850,10
46.900,10
46.950, 8
47.000, 9
47.050, 8
47.100, 8
47.150, 9
47.200, 7
47.250, 8
47.300, 8
47.350,10
47.400, 8
47.450, 9
47.500, 9
47.550,10
47.600,11
47.650,10
47.700,10
47.750,10
47.800,11
47.850,12
47.900, 9
47.950,10
48.000,10
48.050,10
48.100, 9
48.150, 9
48.200, 9
48.250, 9
48.300, 8
48.350, 8
48.400, 8
48.450,10
48.500,10
48.550, 9
48.600,11
48.650,10
48.700,10
48.750,11
48.800,11
48.850,12
48.900,14
48.950,12
49.000,13
49.050,14
49.100,15
49.150,14
49.200,14
49.250,14
49.300,14
49.350,12
49.400,13
49.450,12
49.500,10
49.550,11
49.600,10
49.650, 9
49.700, 9
49.750,10
49.800,10
49.850, 9
49.900,10
49.950, 9
50.000,10
50.050,10
50.100,11
50.150,11
50.200,11
50.250,12
50.300,11
50.350,11
50.400,11
50.450,10
50.500, 9
50.550, 9
50.600, 9
50.650,11
50.700, 9
50.750,10
50.800, 9
50.850, 9
50.900,12
50.950,11
51.000,13
51.050,11
51.100,11
51.150,11
51.200,11
51.250,10
51.300,11
51.350,12
51.400,11
51.450,10
51.500,11
51.550,12
51.600,11
51.650,12
51.700,13
51.750,11
51.800,12
51.850,11
51.900,12
51.950,14
52.000,11
52.050,11
52.100,11
52.150, 9
52.200,10
52.250,10
52.300,11
52.350,11
52.400,10
52.450,10
52.500,11
52.550,13
52.600,13
52.650,13
52.700,11
52.750,13
52.800,14
52.850,14
52.900,13
52.950,13
53.000,13
53.050,13
53.100,13
53.150,12
53.200,14
53.250,16
53.300,24
53.350,28
53.400,29
53.450,30
53.500,31
53.550,28
53.600,22
53.650,20
53.700,16
53.750,14
53.800,14
53.850,13
53.900,14
53.950,16
54.000,14
54.050,15
54.100,16
54.150,16
54.200,15
54.250,16
54.300,17
54.350,17
54.400,18
54.450,19
54.500,19
54.550,23
54.600,26
54.650,32
54.700,32
54.750,34
54.800,37
54.850,33
54.900,29
54.950,28
55.000,29
55.050,27
55.100,29
55.150,29
55.200,30
55.250,31
55.300,32
55.350,30
55.400,33
55.450,34
55.500,33
55.550,34
55.600,36
55.650,37
55.700,34
55.750,36
55.800,33
55.850,34
55.900,35
55.950,33
56.000,32
56.050,30
56.100,30
56.150,30
56.200,29
56.250,29
56.300,26
56.350,25
56.400,25
56.450,23
56.500,22
56.550,21
56.600,21
56.650,21
56.700,19
56.750,18
56.800,19
56.850,17
56.900,16
56.950,18
57.000,16
57.050,16
57.100,14
57.150,15
57.200,14
57.250,15
57.300,13
57.350,13
57.400,13
57.450,12
57.500,14
57.550,11
57.600,12
57.650,13
57.700,11
57.750,11
57.800,13
57.850,11
57.900,11
57.950,11
58.000,10
58.050,11
58.100,10
58.150,11
58.200,10
58.250,11
58.300,10
58.350,11
58.400, 9
58.450, 9
58.500,10
58.550, 8
58.600, 7
58.650, 8
58.700, 8
58.750, 9
58.800, 9
58.850, 7
58.900, 9
58.950, 9
59.000, 8
59.050, 8
59.100, 8
59.150, 9
59.200, 9
59.250, 8
59.300, 7
59.350, 8
59.400, 8
59.450, 9
59.500, 7
59.550, 7
59.600, 8
59.650, 8
59.700, 8
59.750, 7
59.800, 8
59.850, 7
59.900, 9
59.950, 9
60.000, 7