File: code/data/data_source2/TiZn_GIXRD - Ti_ZnHA-Z=22mm.csv
[Measurement conditions]
Sample identification,
Comment - 1,"Configuration=Filmes Finos 19_1_2015, Owner=User-1, Creation date=19/01/2015 21:17:15"
Comment - 2,"Goniometer=PW3050/60 (Theta/Theta); Minimum step size 2Theta:0.001; Minimum step size Omega:0.001"
Comment - 3,"Sample stage=PW3071/xx Bracket"
Comment - 4,"Diffractometer system=XPERT-PRO"
Comment - 5,"Measurement program=C:\PANalytical\Data Collector\Programs\GrazingIncidence.xrdmp, Identifier={66153EEB-86EC-4304-B638-661945051D6C}"
Comment - 6, "Pre-set counts scan: The intensities are reported as counts per second"
Anode material,Cu
K-Alpha1 wavelength,1.5405980
K-Alpha2 wavelength,1.5444260
Ratio K-Alpha2/K-Alpha1,0.500
Divergence slit,Fixed,0.10mm
Receiving slit,0.10
Monochromator used,YES
Generator voltage, 40
Tube current, 40
File date and time,25/Jan/2018 20:40
Unit cell,
h k l, 0 0 0
Scan axis,2Theta
Scan range,8.000,55.000
Scan step size,0.0250000
No. of points, 1881
Scan type,STEP
Omega,2.000
Time per step,1.00
[Scan points]
Angle,Intensity
8.000,97
8.050,96
8.100,96
8.150,94
8.200,93
8.250,93
8.300,95
8.350,93
8.400,90
8.450,90
8.500,89
8.550,93
8.600,90
8.650,88
8.700,94
8.750,92
8.800,89
8.850,91
8.900,89
8.950,90
9.000,88
9.050,89
9.100,88
9.150,86
9.200,91
9.250,85
9.300,93
9.350,92
9.400,94
9.450,89
9.500,84
9.550,85
9.600,84
9.650,83
9.700,81
9.750,82
9.800,83
9.850,82
9.900,77
9.950,79
10.000,80
10.050,81
10.100,78
10.150,77
10.200,77
10.250,77
10.300,79
10.350,78
10.400,75
10.450,75
10.500,77
10.550,79
10.600,76
10.650,79
10.700,74
10.750,77
10.800,77
10.850,73
10.900,77
10.950,73
11.000,77
11.050,75
11.100,72
11.150,71
11.200,67
11.250,69
11.300,75
11.350,68
11.400,68
11.450,69
11.500,70
11.550,69
11.600,67
11.650,69
11.700,68
11.750,69
11.800,68
11.850,66
11.900,69
11.950,67
12.000,71
12.050,72
12.100,68
12.150,70
12.200,71
12.250,73
12.300,70
12.350,72
12.400,70
12.450,69
12.500,67
12.550,66
12.600,67
12.650,63
12.700,66
12.750,62
12.800,63
12.850,64
12.900,66
12.950,66
13.000,67
13.050,64
13.100,63
13.150,61
13.200,63
13.250,63
13.300,62
13.350,62
13.400,61
13.450,61
13.500,62
13.550,61
13.600,62
13.650,61
13.700,60
13.750,61
13.800,63
13.850,61
13.900,65
13.950,61
14.000,61
14.050,63
14.100,61
14.150,61
14.200,59
14.250,60
14.300,58
14.350,61
14.400,56
14.450,57
14.500,56
14.550,62
14.600,56
14.650,58
14.700,59
14.750,60
14.800,57
14.850,57
14.900,58
14.950,57
15.000,54
15.050,57
15.100,57
15.150,57
15.200,55
15.250,56
15.300,56
15.350,57
15.400,54
15.450,54
15.500,55
15.550,57
15.600,54
15.650,58
15.700,53
15.750,53
15.800,53
15.850,53
15.900,54
15.950,54
16.000,52
16.050,53
16.100,55
16.150,53
16.200,56
16.250,54
16.300,53
16.350,53
16.400,53
16.450,52
16.500,55
16.550,56
16.600,52
16.650,55
16.700,55
16.750,54
16.800,57
16.850,52
16.900,55
16.950,55
17.000,54
17.050,54
17.100,53
17.150,53
17.200,53
17.250,50
17.300,50
17.350,51
17.400,53
17.450,51
17.500,49
17.550,52
17.600,52
17.650,51
17.700,52
17.750,50
17.800,51
17.850,53
17.900,52
17.950,49
18.000,51
18.050,49
18.100,49
18.150,48
18.200,50
18.250,49
18.300,52
18.350,50
18.400,49
18.450,51
18.500,51
18.550,53
18.600,50
18.650,48
18.700,49
18.750,49
18.800,51
18.850,52
18.900,47
18.950,47
19.000,49
19.050,48
19.100,48
19.150,49
19.200,49
19.250,48
19.300,46
19.350,47
19.400,44
19.450,47
19.500,46
19.550,45
19.600,47
19.650,46
19.700,49
19.750,48
19.800,42
19.850,48
19.900,47
19.950,43
20.000,45
20.050,46
20.100,46
20.150,44
20.200,45
20.250,45
20.300,44
20.350,42
20.400,43
20.450,45
20.500,43
20.550,43
20.600,43
20.650,43
20.700,43
20.750,41
20.800,44
20.850,42
20.900,40
20.950,42
21.000,43
21.050,47
21.100,48
21.150,45
21.200,47
21.250,49
21.300,49
21.350,48
21.400,46
21.450,45
21.500,42
21.550,44
21.600,44
21.650,42
21.700,40
21.750,38
21.800,41
21.850,42
21.900,40
21.950,37
22.000,39
22.050,38
22.100,39
22.150,41
22.200,39
22.250,41
22.300,37
22.350,37
22.400,39
22.450,38
22.500,37
22.550,42
22.600,41
22.650,39
22.700,36
22.750,39
22.800,40
22.850,34
22.900,37
22.950,37
23.000,39
23.050,38
23.100,35
23.150,37
23.200,35
23.250,34
23.300,34
23.350,34
23.400,35
23.450,34
23.500,35
23.550,34
23.600,34
23.650,32
23.700,35
23.750,32
23.800,34
23.850,33
23.900,34
23.950,32
24.000,32
24.050,34
24.100,30
24.150,29
24.200,32
24.250,32
24.300,31
24.350,33
24.400,30
24.450,29
24.500,32
24.550,27
24.600,30
24.650,32
24.700,30
24.750,29
24.800,30
24.850,30
24.900,27
24.950,29
25.000,31
25.050,30
25.100,31
25.150,30
25.200,30
25.250,29
25.300,29
25.350,32
25.400,34
25.450,38
25.500,47
25.550,54
25.600,60
25.650,60
25.700,56
25.750,53
25.800,45
25.850,35
25.900,31
25.950,27
26.000,28
26.050,27
26.100,27
26.150,26
26.200,24
26.250,26
26.300,23
26.350,25
26.400,23
26.450,26
26.500,24
26.550,26
26.600,23
26.650,22
26.700,22
26.750,22
26.800,25
26.850,23
26.900,23
26.950,24
27.000,23
27.050,24
27.100,21
27.150,24
27.200,22
27.250,21
27.300,22
27.350,23
27.400,22
27.450,24
27.500,22
27.550,24
27.600,22
27.650,24
27.700,23
27.750,25
27.800,28
27.850,29
27.900,27
27.950,28
28.000,26
28.050,24
28.100,23
28.150,23
28.200,21
28.250,23
28.300,24
28.350,23
28.400,22
28.450,25
28.500,23
28.550,24
28.600,25
28.650,25
28.700,27
28.750,24
28.800,25
28.850,25
28.900,24
28.950,23
29.000,22
29.050,21
29.100,21
29.150,21
29.200,22
29.250,20
29.300,20
29.350,20
29.400,22
29.450,23
29.500,21
29.550,22
29.600,22
29.650,22
29.700,22
29.750,19
29.800,21
29.850,22
29.900,21
29.950,20
30.000,21
30.050,22
30.100,20
30.150,22
30.200,20
30.250,21
30.300,21
30.350,20
30.400,21
30.450,23
30.500,20
30.550,20
30.600,21
30.650,18
30.700,20
30.750,20
30.800,20
30.850,21
30.900,20
30.950,21
31.000,21
31.050,21
31.100,22
31.150,25
31.200,27
31.250,29
31.300,33
31.350,42
31.400,48
31.450,58
31.500,61
31.550,64
31.600,66
31.650,63
31.700,63
31.750,60
31.800,61
31.850,67
31.900,66
31.950,67
32.000,67
32.050,61
32.100,61
32.150,51
32.200,45
32.250,43
32.300,37
32.350,31
32.400,35
32.450,33
32.500,33
32.550,34
32.600,38
32.650,40
32.700,38
32.750,34
32.800,32
32.850,27
32.900,24
32.950,22
33.000,20
33.050,16
33.100,18
33.150,18
33.200,18
33.250,15
33.300,17
33.350,17
33.400,17
33.450,16
33.500,16
33.550,19
33.600,20
33.650,23
33.700,24
33.750,23
33.800,28
33.850,26
33.900,23
33.950,19
34.000,21
34.050,17
34.100,17
34.150,13
34.200,17
34.250,14
34.300,15
34.350,13
34.400,12
34.450,13
34.500,13
34.550,12
34.600,13
34.650,13
34.700,11
34.750,11
34.800,14
34.850,13
34.900,13
34.950,13
35.000,14
35.050,14
35.100,13
35.150,14
35.200,14
35.250,14
35.300,13
35.350,14
35.400,13
35.450,11
35.500,11
35.550,12
35.600,12
35.650,11
35.700,12
35.750,12
35.800,12
35.850,12
35.900,12
35.950,11
36.000,11
36.050,12
36.100,12
36.150,11
36.200,10
36.250,10
36.300,11
36.350,12
36.400,11
36.450,11
36.500,12
36.550,12
36.600,12
36.650,12
36.700,12
36.750,11
36.800,13
36.850,11
36.900,13
36.950,13
37.000,12
37.050,12
37.100,14
37.150,14
37.200,14
37.250,14
37.300,14
37.350,15
37.400,12
37.450,12
37.500,11
37.550,12
37.600,12
37.650,11
37.700,11
37.750,10
37.800,10
37.850,10
37.900, 9
37.950,11
38.000,10
38.050,11
38.100, 9
38.150,10
38.200,11
38.250,10
38.300,10
38.350,10
38.400, 9
38.450,10
38.500,10
38.550,10
38.600,10
38.650,11
38.700,11
38.750,11
38.800,12
38.850,13
38.900,12
38.950,12
39.000,11
39.050,12
39.100,12
39.150,12
39.200,12
39.250,11
39.300,13
39.350,13
39.400,15
39.450,14
39.500,16
39.550,16
39.600,16
39.650,14
39.700,14
39.750,14
39.800,13
39.850,11
39.900,11
39.950,10
40.000,10
40.050, 9
40.100, 9
40.150,11
40.200,10
40.250, 9
40.300,11
40.350,10
40.400,11
40.450,10
40.500,10
40.550, 9
40.600,10
40.650,10
40.700,11
40.750, 9
40.800,10
40.850, 8
40.900, 9
40.950,10
41.000, 9
41.050, 9
41.100, 9
41.150,10
41.200,10
41.250,10
41.300,10
41.350,10
41.400, 9
41.450,10
41.500,10
41.550,11
41.600,10
41.650,10
41.700,12
41.750,12
41.800,11
41.850,11
41.900,12
41.950,11
42.000,10
42.050,11
42.100,11
42.150,10
42.200,10
42.250,11
42.300, 9
42.350,10
42.400,10
42.450,11
42.500,10
42.550, 9
42.600,11
42.650,12
42.700,10
42.750,11
42.800,11
42.850,12
42.900,12
42.950,12
43.000,11
43.050,14
43.100,13
43.150,14
43.200,14
43.250,14
43.300,14
43.350,14
43.400,14
43.450,16
43.500,16
43.550,16
43.600,13
43.650,15
43.700,13
43.750,14
43.800,12
43.850,12
43.900,10
43.950,12
44.000,11
44.050,11
44.100,10
44.150,10
44.200,10
44.250, 9
44.300, 9
44.350,10
44.400, 9
44.450,10
44.500,11
44.550, 9
44.600, 8
44.650,10
44.700,10
44.750,10
44.800,10
44.850,10
44.900,10
44.950,11
45.000,13
45.050,11
45.100,12
45.150,11
45.200,10
45.250,10
45.300, 9
45.350, 8
45.400, 7
45.450,10
45.500,10
45.550, 9
45.600, 8
45.650, 9
45.700, 9
45.750,10
45.800, 9
45.850,10
45.900, 9
45.950,11
46.000,10
46.050,11
46.100,12
46.150,13
46.200,15
46.250,16
46.300,17
46.350,20
46.400,20
46.450,19
46.500,19
46.550,18
46.600,16
46.650,13
46.700,14
46.750,12
46.800,13
46.850,11
46.900, 9
46.950,10
47.000, 9
47.050, 9
47.100, 9
47.150,10
47.200, 9
47.250, 9
47.300, 9
47.350,10
47.400, 9
47.450, 9
47.500,11
47.550,11
47.600,11
47.650,12
47.700,13
47.750,12
47.800,11
47.850,14
47.900,12
47.950,11
48.000,10
48.050, 9
48.100,11
48.150,11
48.200,10
48.250,10
48.300,10
48.350,10
48.400,11
48.450,10
48.500,11
48.550, 9
48.600,11
48.650,11
48.700,12
48.750,13
48.800,13
48.850,14
48.900,15
48.950,16
49.000,19
49.050,20
49.100,22
49.150,20
49.200,21
49.250,20
49.300,20
49.350,18
49.400,16
49.450,15
49.500,13
49.550,12
49.600,11
49.650,10
49.700, 8
49.750,10
49.800,10
49.850,11
49.900,10
49.950,11
50.000,12
50.050,12
50.100,14
50.150,11
50.200,13
50.250,12
50.300,12
50.350,11
50.400,12
50.450,10
50.500,10
50.550,10
50.600,11
50.650,11
50.700,10
50.750, 9
50.800,11
50.850,11
50.900,11
50.950,12
51.000,12
51.050,12
51.100,12
51.150,12
51.200,11
51.250,11
51.300,11
51.350,11
51.400,10
51.450,10
51.500,13
51.550,12
51.600,13
51.650,12
51.700,12
51.750,13
51.800,13
51.850,12
51.900,12
51.950,12
52.000,11
52.050,12
52.100,10
52.150,11
52.200,11
52.250,11
52.300,10
52.350,11
52.400,10
52.450,11
52.500,13
52.550,12
52.600,14
52.650,15
52.700,15
52.750,15
52.800,17
52.850,17
52.900,18
52.950,17
53.000,18
53.050,17
53.100,16
53.150,16
53.200,16
53.250,16
53.300,17
53.350,16
53.400,17
53.450,17
53.500,19
53.550,21
53.600,22
53.650,20
53.700,22
53.750,22
53.800,22
53.850,22
53.900,25
53.950,22
54.000,23
54.050,24
54.100,22
54.150,21
54.200,20
54.250,19
54.300,20
54.350,20
54.400,19
54.450,21
54.500,21
54.550,19
54.600,19
54.650,23
54.700,30
54.750,60
54.800,291
54.850,654
54.900,831
54.950,838
55.000,727